Workbook

Sheet Weekly Plan
G1: 101 Line | H1: 46006 | I1: =H1+1 -> 46007 | J1: =I1+1 -> 46008 | K1: =J1+1 -> 46009 | L1: =K1+1 -> 46010 | M1: =L1+1 -> 46011 | P1: Unprotect Password 6941
B2: 4.5ft | C2: 5.5ft | D2: 5.75 | E2: pcs/rack | F2: Part Num | G2: Part | H2: MONDAY | I2: TUESDAY | J2: WEDNESDAY | K2: THURSDAY | L2: FRIDAY | M2: SATURDAY
A3: 4 | F3: Black - Laval
A4: =(E4*4)/$A$3 -> 2 | E4: 2 | F4: 99944 Bezel | G4: Bezel
A5: =(E5*4)/$A$3 -> 20 | E5: 20 | F5: 99633 | G5: IR Cover LH
A6: =(E6*4)/$A$3 -> 20 | E6: 20 | F6: 99646 | G6: IR Cover RH
A7: =(E7*4)/$A$3 -> 6 | E7: 6 | F7: 99635 | G7: Lateral Belt LH
A8: =(E8*4)/$A$3 -> 6 | E8: 6 | F8: 99944 | G8: Lateral Belt RH
A9: =(E9*4)/$A$3 -> 20 | E9: 20 | F9: 99636 | G9: Rear Belt
A10: =(E10*4)/$A$3 -> 0 | E10: 0 | F10: Summit White - Laval
A11: =(E11*4)/$A$3 -> 1 | E11: 1 | F11: 99629 | G11: Main Lower Cover | H11: 30
A12: =(E12*4)/$A$3 -> 1 | E12: 1 | F12: 99631 | G12: Main Upper Cover | H12: 30 | P12: Line speed | Q12: 6 | R12: feet per minute
A13: =(E13*4)/$A$3 -> 20 | E13: 20 | F13: 99638 | G13: Rear Plate | P13: Gap | Q13: 12 min
A14: =(E14*4)/$A$3 -> 1 | E14: 1 | F14: 99630 | G14: Vent Cover | H14: 30
A15: =(E15*4)/$A$3 -> 0 | E15: 0 | F15: Metelix
A16: =(E16*4)/$A$3 -> 1 | E16: 1 | F16: VG0240BL0PA | G16: C223 ACCSRY Spoiler | P16: Shifts | Q16: 1
A17: =(E17*4)/$A$3 -> 6 | E17: 6 | F17: VG0241CM0PB | G17: Y2XX Stanchion - LH | P17: Scheduled | Q17: =7.5*Q16 -> 7.5
A18: =(E18*4)/$A$3 -> 6 | E18: 6 | F18: VG0241CM0PD | G18: Y2XX Stanchion - RH
A19: =(E19*4)/$A$3 -> 6 | E19: 6 | F19: VG0241CM0PC | G19: Y2XX Stanchion - Center
E20: 4 | F20: VG0241CM0PE | G20: Y2XX Winglet -LH | P20: Weekly Timing
E21: 4 | F21: VG0241CM0PF | G21: Y2XX Winglet -RH | Q21: Monday | R21: Tuesday | S21: Wednesday | T21: Thursday | U21: Friday | V21: Saturday
A22: =(E22*4)/$A$3 -> 20 | E22: 20 | F22: VG0241CM0PG | G22: Y2XX Screw Cover - LH | P22: ='Mon (101)'!G28 -> Colour | Q22: ='Mon (101)'!I28 -> Time (mins) | R22: ='Tue (101)'!I28 -> Time (mins) | S22: ='Wed (101)'!I28 -> Time (mins) | T22: ='Thu (101)'!I28 -> Time (mins) | U22: ='Fri (101)'!I28 -> Time (mins) | V22: ='Sat (101)'!I28 -> Time (mins)
A23: =(E23*4)/$A$3 -> 20 | E23: 20 | F23: VG0241CM0PH | G23: Y2XX Screw Cover - RH | P23: ='Mon (101)'!G29 -> Black - Laval | Q23: ='Mon (101)'!I29 -> 0 | R23: ='Tue (101)'!I29 -> 0 | S23: ='Wed (101)'!I29 -> 0 | T23: ='Thu (101)'!I29 -> 0 | U23: ='Fri (101)'!I29 -> 0 | V23: ='Sat (101)'!I29 -> 0
A24: =(E24*4)/$A$3 -> 0 | E24: 0 | F24: Tesla High Gloss Black | P24: ='Mon (101)'!G30 -> Summit White - Laval | Q24: ='Mon (101)'!I30 -> 90 | R24: ='Tue (101)'!I30 -> 0 | S24: ='Wed (101)'!I30 -> 0 | T24: ='Thu (101)'!I30 -> 0 | U24: ='Fri (101)'!I30 -> 0 | V24: ='Sat (101)'!I30 -> 0
A25: =(E25*4)/$A$3 -> 6 | E25: 6 | F25: 9405929P | G25: MX Applique | H25: 260 | P25: ='Mon (101)'!G31 -> Metelix | Q25: ='Mon (101)'!I31 -> 0 | R25: ='Tue (101)'!I31 -> 0 | S25: ='Wed (101)'!I31 -> 0 | T25: ='Thu (101)'!I31 -> 0 | U25: ='Fri (101)'!I31 -> 0 | V25: ='Sat (101)'!I31 -> 0
A26: =(E26*4)/$A$3 -> 6 | E26: 6 | F26: 9405930P | G26: MS Applique | P26: ='Mon (101)'!G32 -> Tesla - High Gloss Black | Q26: ='Mon (101)'!I32 -> 103.33333 | R26: ='Tue (101)'!I32 -> 0 | S26: ='Wed (101)'!I32 -> 0 | T26: ='Thu (101)'!I32 -> 0 | U26: ='Fri (101)'!I32 -> 0 | V26: ='Sat (101)'!I32 -> 0
A27: =(E27*4)/$A$3 -> 6 | E27: 6 | F27: 9405929P-REW | G27: MX Applique Rework | H27: 360 | P27: ='Mon (101)'!G33 -> Stoney Blue | Q27: ='Mon (101)'!I33 -> 0 | R27: ='Tue (101)'!I33 -> 0 | S27: ='Wed (101)'!I33 -> 0 | T27: ='Thu (101)'!I33 -> 0 | U27: ='Fri (101)'!I33 -> 0 | V27: ='Sat (101)'!I33 -> 0
A28: =(E28*4)/$A$3 -> 6 | E28: 6 | F28: 9405930P-REW | G28: MS Applique Rework | P28: ='Mon (101)'!G34 -> Miscellaneous | Q28: ='Mon (101)'!I34 -> 0 | R28: ='Tue (101)'!I34 -> 0 | S28: ='Wed (101)'!I34 -> 0 | T28: ='Thu (101)'!I34 -> 0 | U28: ='Fri (101)'!I34 -> 0 | V28: ='Sat (101)'!I34 -> 0
A29: =(E29*4)/$A$3 -> 0 | E29: 0 | P29: ='Mon (101)'!G35 -> 0 | Q29: ='Mon (101)'!I35 -> 0 | R29: ='Tue (101)'!I35 -> 0 | S29: ='Wed (101)'!I35 -> 0 | T29: ='Thu (101)'!I35 -> 0 | U29: ='Fri (101)'!I35 -> 0 | V29: ='Sat (101)'!I35 -> 0
A30: =(E30*4)/$A$3 -> 0 | E30: 0 | F30: Stoney Blue - KB Components | P30: ='Mon (101)'!G36 -> Total: | Q30: ='Mon (101)'!I36 -> 193.33333 | R30: ='Tue (101)'!I36 -> 0 | S30: ='Wed (101)'!I36 -> 0 | T30: ='Thu (101)'!I36 -> 0 | U30: ='Fri (101)'!I36 -> 0 | V30: ='Sat (101)'!I36 -> 0
A31: =(E31*4)/$A$3 -> 1 | E31: 1 | F31: KB2352 | G31: W12 Roof Top Cover | P31: ='Mon (101)'!G37 -> 0 | Q31: ='Mon (101)'!I37 -> 0 | R31: ='Tue (101)'!I37 -> 0 | S31: ='Wed (101)'!I37 -> 0 | T31: ='Thu (101)'!I37 -> 0 | U31: ='Fri (101)'!I37 -> 0 | V31: ='Sat (101)'!I37 -> 0
A32: =(E32*4)/$A$3 -> 4 | E32: 4 | F32: KB2369 | G32: W12 Mech Bezel Pod 1 | P32: ='Mon (101)'!G38 -> Gaps | Q32: ='Mon (101)'!I38 -> 12 | R32: ='Tue (101)'!I38 -> 0 | S32: ='Wed (101)'!I38 -> 0 | T32: ='Thu (101)'!I38 -> 0 | U32: ='Fri (101)'!I38 -> 0 | V32: ='Sat (101)'!I38 -> 0
A33: =(E33*4)/$A$3 -> 4 | E33: 4 | F33: KB2370L | G33: W12 LH Cover Body Closeout Pod 5 | P33: ='Mon (101)'!G39 -> 0 | Q33: ='Mon (101)'!I39 -> 0 | R33: ='Tue (101)'!I39 -> 0 | S33: ='Wed (101)'!I39 -> 0 | T33: ='Thu (101)'!I39 -> 0 | U33: ='Fri (101)'!I39 -> 0 | V33: ='Sat (101)'!I39 -> 0
A34: =(E34*4)/$A$3 -> 4 | E34: 4 | F34: KB2370R | G34: W12 RH Cover Body Closeout Pod 6 | P34: ='Mon (101)'!G40 -> Total Time (hrs) | Q34: ='Mon (101)'!I40 -> 3.4222222 | R34: ='Tue (101)'!I40 -> 0 | S34: ='Wed (101)'!I40 -> 0 | T34: ='Thu (101)'!I40 -> 0 | U34: ='Fri (101)'!I40 -> 0 | V34: ='Sat (101)'!I40 -> 0
A35: =(E35*4)/$A$3 -> 0 | E35: 0 | F35: Miscellaneous
A36: =(E36*4)/$A$3 -> 0 | E36: 0 | F36: PART#1 | P36: Total Week Run Time: | R36: =SUM(Q34:V34) -> 3.4222222
A37: =(E37*4)/$A$3 -> 0 | E37: 0 | F37: PART#2
A38: =(E38*4)/$A$3 -> 0 | E38: 0 | F38: PART#3
A39: =(E39*4)/$A$3 -> 0 | E39: 0 | F39: PART#4
P67: =30+4+20+2 -> 56
...

Sheet Paint Usage
A1: Part Num | B1: Part | C1: Mon | D1: Tue | E1: Wed | F1: Thur | G1: Friday | H1: Sat
A2: Hyper Silver (Spyder)
A3: 705012348 | B3: LH Trim | C3: =(('Time Matrix'!B3*#REF!)*'Mon (101)'!#REF!) + (('Time Matrix'!B3*#REF!)*'Mon (101)'!#REF!) + (('Time Matrix'!B3*#REF!)*'Mon (101)'!#REF!) + (('Time Matrix'!B3*#REF!)*'Mon (101)'!#REF!) -> #REF! | D3: =(('Time Matrix'!B3*#REF!)*#REF!) + (('Time Matrix'!B3*#REF!)*#REF!) + (('Time Matrix'!B3*#REF!)*#REF!) + (('Time Matrix'!B3*#REF!)*#REF!) -> #REF! | E3: =(('Time Matrix'!B3*#REF!)*#REF!) + (('Time Matrix'!B3*#REF!)*#REF!) + (('Time Matrix'!B3*#REF!)*#REF!) + (('Time Matrix'!B3*#REF!)*#REF!) -> #REF! | F3: =(('Time Matrix'!B3*#REF!)*#REF!) + (('Time Matrix'!B3*#REF!)*#REF!) + (('Time Matrix'!B3*#REF!)*#REF!) + (('Time Matrix'!B3*#REF!)*#REF!) -> #REF! | G3: =(('Time Matrix'!B3*#REF!)*#REF!) + (('Time Matrix'!B3*#REF!)*#REF!) + (('Time Matrix'!B3*#REF!)*#REF!) + (('Time Matrix'!B3*#REF!)*#REF!) -> #REF! | H3: =(('Time Matrix'!B3*#REF!)*#REF!) + (('Time Matrix'!B3*#REF!)*#REF!) + (('Time Matrix'!B3*#REF!)*#REF!) + (('Time Matrix'!B3*#REF!)*#REF!) -> #REF!
A4: 705012350 | B4: RH Trim | C4: =(('Time Matrix'!B4*#REF!)*'Mon (101)'!#REF!) + (('Time Matrix'!B4*#REF!)*'Mon (101)'!#REF!) + (('Time Matrix'!B4*#REF!)*'Mon (101)'!#REF!) + (('Time Matrix'!B4*#REF!)*'Mon (101)'!#REF!) -> #REF! | D4: =(('Time Matrix'!B4*#REF!)*#REF!) + (('Time Matrix'!B4*#REF!)*#REF!) + (('Time Matrix'!B4*#REF!)*#REF!) + (('Time Matrix'!B4*#REF!)*#REF!) -> #REF! | E4: =(('Time Matrix'!B4*#REF!)*#REF!) + (('Time Matrix'!B4*#REF!)*#REF!) + (('Time Matrix'!B4*#REF!)*#REF!) + (('Time Matrix'!B4*#REF!)*#REF!) -> #REF! | F4: =(('Time Matrix'!B4*#REF!)*#REF!) + (('Time Matrix'!B4*#REF!)*#REF!) + (('Time Matrix'!B4*#REF!)*#REF!) + (('Time Matrix'!B4*#REF!)*#REF!) -> #REF! | G4: =(('Time Matrix'!B4*#REF!)*#REF!) + (('Time Matrix'!B4*#REF!)*#REF!) + (('Time Matrix'!B4*#REF!)*#REF!) + (('Time Matrix'!B4*#REF!)*#REF!) -> #REF! | H4: =(('Time Matrix'!B4*#REF!)*#REF!) + (('Time Matrix'!B4*#REF!)*#REF!) + (('Time Matrix'!B4*#REF!)*#REF!) + (('Time Matrix'!B4*#REF!)*#REF!) -> #REF!
A5: 705012868 | B5: RH Fender | C5: =(('Time Matrix'!B5*#REF!)*'Mon (101)'!#REF!) + (('Time Matrix'!B5*#REF!)*'Mon (101)'!#REF!) + (('Time Matrix'!B5*#REF!)*'Mon (101)'!#REF!) + (('Time Matrix'!B5*#REF!)*'Mon (101)'!#REF!) -> #REF! | D5: =(('Time Matrix'!B5*#REF!)*#REF!) + (('Time Matrix'!B5*#REF!)*#REF!) + (('Time Matrix'!B5*#REF!)*#REF!) + (('Time Matrix'!B5*#REF!)*#REF!) -> #REF! | E5: =(('Time Matrix'!B5*#REF!)*#REF!) + (('Time Matrix'!B5*#REF!)*#REF!) + (('Time Matrix'!B5*#REF!)*#REF!) + (('Time Matrix'!B5*#REF!)*#REF!) -> #REF! | F5: =(('Time Matrix'!B5*#REF!)*#REF!) + (('Time Matrix'!B5*#REF!)*#REF!) + (('Time Matrix'!B5*#REF!)*#REF!) + (('Time Matrix'!B5*#REF!)*#REF!) -> #REF! | G5: =(('Time Matrix'!B5*#REF!)*#REF!) + (('Time Matrix'!B5*#REF!)*#REF!) + (('Time Matrix'!B5*#REF!)*#REF!) + (('Time Matrix'!B5*#REF!)*#REF!) -> #REF! | H5: =(('Time Matrix'!B5*#REF!)*#REF!) + (('Time Matrix'!B5*#REF!)*#REF!) + (('Time Matrix'!B5*#REF!)*#REF!) + (('Time Matrix'!B5*#REF!)*#REF!) -> #REF!
A6: 705012976 | B6: LH Fender | C6: =(('Time Matrix'!B6*#REF!)*'Mon (101)'!#REF!) + (('Time Matrix'!B6*#REF!)*'Mon (101)'!#REF!) + (('Time Matrix'!B6*#REF!)*'Mon (101)'!#REF!) + (('Time Matrix'!B6*#REF!)*'Mon (101)'!#REF!) -> #REF! | D6: =(('Time Matrix'!B6*#REF!)*#REF!) + (('Time Matrix'!B6*#REF!)*#REF!) + (('Time Matrix'!B6*#REF!)*#REF!) + (('Time Matrix'!B6*#REF!)*#REF!) -> #REF! | E6: =(('Time Matrix'!B6*#REF!)*#REF!) + (('Time Matrix'!B6*#REF!)*#REF!) + (('Time Matrix'!B6*#REF!)*#REF!) + (('Time Matrix'!B6*#REF!)*#REF!) -> #REF! | F6: =(('Time Matrix'!B6*#REF!)*#REF!) + (('Time Matrix'!B6*#REF!)*#REF!) + (('Time Matrix'!B6*#REF!)*#REF!) + (('Time Matrix'!B6*#REF!)*#REF!) -> #REF! | G6: =(('Time Matrix'!B6*#REF!)*#REF!) + (('Time Matrix'!B6*#REF!)*#REF!) + (('Time Matrix'!B6*#REF!)*#REF!) + (('Time Matrix'!B6*#REF!)*#REF!) -> #REF! | H6: =(('Time Matrix'!B6*#REF!)*#REF!) + (('Time Matrix'!B6*#REF!)*#REF!) + (('Time Matrix'!B6*#REF!)*#REF!) + (('Time Matrix'!B6*#REF!)*#REF!) -> #REF!
A7: 705014100 | B7: LH Upper Fairing | C7: =(('Time Matrix'!B7*#REF!)*'Mon (101)'!#REF!) + (('Time Matrix'!B7*#REF!)*'Mon (101)'!#REF!) + (('Time Matrix'!B7*#REF!)*'Mon (101)'!#REF!) + (('Time Matrix'!B7*#REF!)*'Mon (101)'!#REF!) -> #REF! | D7: =(('Time Matrix'!B7*#REF!)*#REF!) + (('Time Matrix'!B7*#REF!)*#REF!) + (('Time Matrix'!B7*#REF!)*#REF!) + (('Time Matrix'!B7*#REF!)*#REF!) -> #REF! | E7: =(('Time Matrix'!B7*#REF!)*#REF!) + (('Time Matrix'!B7*#REF!)*#REF!) + (('Time Matrix'!B7*#REF!)*#REF!) + (('Time Matrix'!B7*#REF!)*#REF!) -> #REF! | F7: =(('Time Matrix'!B7*#REF!)*#REF!) + (('Time Matrix'!B7*#REF!)*#REF!) + (('Time Matrix'!B7*#REF!)*#REF!) + (('Time Matrix'!B7*#REF!)*#REF!) -> #REF! | G7: =(('Time Matrix'!B7*#REF!)*#REF!) + (('Time Matrix'!B7*#REF!)*#REF!) + (('Time Matrix'!B7*#REF!)*#REF!) + (('Time Matrix'!B7*#REF!)*#REF!) -> #REF! | H7: =(('Time Matrix'!B7*#REF!)*#REF!) + (('Time Matrix'!B7*#REF!)*#REF!) + (('Time Matrix'!B7*#REF!)*#REF!) + (('Time Matrix'!B7*#REF!)*#REF!) -> #REF!
A8: 705014101 | B8: RH Upper Fairing | C8: =(('Time Matrix'!B8*#REF!)*'Mon (101)'!#REF!) + (('Time Matrix'!B8*#REF!)*'Mon (101)'!#REF!) + (('Time Matrix'!B8*#REF!)*'Mon (101)'!#REF!) + (('Time Matrix'!B8*#REF!)*'Mon (101)'!#REF!) -> #REF! | D8: =(('Time Matrix'!B8*#REF!)*#REF!) + (('Time Matrix'!B8*#REF!)*#REF!) + (('Time Matrix'!B8*#REF!)*#REF!) + (('Time Matrix'!B8*#REF!)*#REF!) -> #REF! | E8: =(('Time Matrix'!B8*#REF!)*#REF!) + (('Time Matrix'!B8*#REF!)*#REF!) + (('Time Matrix'!B8*#REF!)*#REF!) + (('Time Matrix'!B8*#REF!)*#REF!) -> #REF! | F8: =(('Time Matrix'!B8*#REF!)*#REF!) + (('Time Matrix'!B8*#REF!)*#REF!) + (('Time Matrix'!B8*#REF!)*#REF!) + (('Time Matrix'!B8*#REF!)*#REF!) -> #REF! | G8: =(('Time Matrix'!B8*#REF!)*#REF!) + (('Time Matrix'!B8*#REF!)*#REF!) + (('Time Matrix'!B8*#REF!)*#REF!) + (('Time Matrix'!B8*#REF!)*#REF!) -> #REF! | H8: =(('Time Matrix'!B8*#REF!)*#REF!) + (('Time Matrix'!B8*#REF!)*#REF!) + (('Time Matrix'!B8*#REF!)*#REF!) + (('Time Matrix'!B8*#REF!)*#REF!) -> #REF!
A9: 708003041 | B9: Rear Fairing | C9: =(('Time Matrix'!B9*#REF!)*'Mon (101)'!#REF!) + (('Time Matrix'!B9*#REF!)*'Mon (101)'!#REF!) + (('Time Matrix'!B9*#REF!)*'Mon (101)'!#REF!) + (('Time Matrix'!B9*#REF!)*'Mon (101)'!#REF!) -> #REF! | D9: =(('Time Matrix'!B9*#REF!)*#REF!) + (('Time Matrix'!B9*#REF!)*#REF!) + (('Time Matrix'!B9*#REF!)*#REF!) + (('Time Matrix'!B9*#REF!)*#REF!) -> #REF! | E9: =(('Time Matrix'!B9*#REF!)*#REF!) + (('Time Matrix'!B9*#REF!)*#REF!) + (('Time Matrix'!B9*#REF!)*#REF!) + (('Time Matrix'!B9*#REF!)*#REF!) -> #REF! | F9: =(('Time Matrix'!B9*#REF!)*#REF!) + (('Time Matrix'!B9*#REF!)*#REF!) + (('Time Matrix'!B9*#REF!)*#REF!) + (('Time Matrix'!B9*#REF!)*#REF!) -> #REF! | G9: =(('Time Matrix'!B9*#REF!)*#REF!) + (('Time Matrix'!B9*#REF!)*#REF!) + (('Time Matrix'!B9*#REF!)*#REF!) + (('Time Matrix'!B9*#REF!)*#REF!) -> #REF! | H9: =(('Time Matrix'!B9*#REF!)*#REF!) + (('Time Matrix'!B9*#REF!)*#REF!) + (('Time Matrix'!B9*#REF!)*#REF!) + (('Time Matrix'!B9*#REF!)*#REF!) -> #REF!
A10: 708200869 | B10: R66 Hood | C10: =(('Time Matrix'!B10*#REF!)*'Mon (101)'!#REF!) + (('Time Matrix'!B10*#REF!)*'Mon (101)'!#REF!) + (('Time Matrix'!B10*#REF!)*'Mon (101)'!#REF!) + (('Time Matrix'!B10*#REF!)*'Mon (101)'!#REF!) -> #REF! | D10: =(('Time Matrix'!B10*#REF!)*#REF!) + (('Time Matrix'!B10*#REF!)*#REF!) + (('Time Matrix'!B10*#REF!)*#REF!) + (('Time Matrix'!B10*#REF!)*#REF!) -> #REF! | E10: =(('Time Matrix'!B10*#REF!)*#REF!) + (('Time Matrix'!B10*#REF!)*#REF!) + (('Time Matrix'!B10*#REF!)*#REF!) + (('Time Matrix'!B10*#REF!)*#REF!) -> #REF! | F10: =(('Time Matrix'!B10*#REF!)*#REF!) + (('Time Matrix'!B10*#REF!)*#REF!) + (('Time Matrix'!B10*#REF!)*#REF!) + (('Time Matrix'!B10*#REF!)*#REF!) -> #REF! | G10: =(('Time Matrix'!B10*#REF!)*#REF!) + (('Time Matrix'!B10*#REF!)*#REF!) + (('Time Matrix'!B10*#REF!)*#REF!) + (('Time Matrix'!B10*#REF!)*#REF!) -> #REF! | H10: =(('Time Matrix'!B10*#REF!)*#REF!) + (('Time Matrix'!B10*#REF!)*#REF!) + (('Time Matrix'!B10*#REF!)*#REF!) + (('Time Matrix'!B10*#REF!)*#REF!) -> #REF!
A11: 708200870 | B11: LH Front Fairing | C11: =(('Time Matrix'!B11*#REF!)*'Mon (101)'!#REF!) + (('Time Matrix'!B11*#REF!)*'Mon (101)'!#REF!) + (('Time Matrix'!B11*#REF!)*'Mon (101)'!#REF!) + (('Time Matrix'!B11*#REF!)*'Mon (101)'!#REF!) -> #REF! | D11: =(('Time Matrix'!B11*#REF!)*#REF!) + (('Time Matrix'!B11*#REF!)*#REF!) + (('Time Matrix'!B11*#REF!)*#REF!) + (('Time Matrix'!B11*#REF!)*#REF!) -> #REF! | E11: =(('Time Matrix'!B11*#REF!)*#REF!) + (('Time Matrix'!B11*#REF!)*#REF!) + (('Time Matrix'!B11*#REF!)*#REF!) + (('Time Matrix'!B11*#REF!)*#REF!) -> #REF! | F11: =(('Time Matrix'!B11*#REF!)*#REF!) + (('Time Matrix'!B11*#REF!)*#REF!) + (('Time Matrix'!B11*#REF!)*#REF!) + (('Time Matrix'!B11*#REF!)*#REF!) -> #REF! | G11: =(('Time Matrix'!B11*#REF!)*#REF!) + (('Time Matrix'!B11*#REF!)*#REF!) + (('Time Matrix'!B11*#REF!)*#REF!) + (('Time Matrix'!B11*#REF!)*#REF!) -> #REF! | H11: =(('Time Matrix'!B11*#REF!)*#REF!) + (('Time Matrix'!B11*#REF!)*#REF!) + (('Time Matrix'!B11*#REF!)*#REF!) + (('Time Matrix'!B11*#REF!)*#REF!) -> #REF!
A12: 708200871 | B12: RH Front Fairing | C12: =(('Time Matrix'!B12*#REF!)*'Mon (101)'!#REF!) + (('Time Matrix'!B12*#REF!)*'Mon (101)'!#REF!) + (('Time Matrix'!B12*#REF!)*'Mon (101)'!#REF!) + (('Time Matrix'!B12*#REF!)*'Mon (101)'!#REF!) -> #REF! | D12: =(('Time Matrix'!B12*#REF!)*#REF!) + (('Time Matrix'!B12*#REF!)*#REF!) + (('Time Matrix'!B12*#REF!)*#REF!) + (('Time Matrix'!B12*#REF!)*#REF!) -> #REF! | E12: =(('Time Matrix'!B12*#REF!)*#REF!) + (('Time Matrix'!B12*#REF!)*#REF!) + (('Time Matrix'!B12*#REF!)*#REF!) + (('Time Matrix'!B12*#REF!)*#REF!) -> #REF! | F12: =(('Time Matrix'!B12*#REF!)*#REF!) + (('Time Matrix'!B12*#REF!)*#REF!) + (('Time Matrix'!B12*#REF!)*#REF!) + (('Time Matrix'!B12*#REF!)*#REF!) -> #REF! | G12: =(('Time Matrix'!B12*#REF!)*#REF!) + (('Time Matrix'!B12*#REF!)*#REF!) + (('Time Matrix'!B12*#REF!)*#REF!) + (('Time Matrix'!B12*#REF!)*#REF!) -> #REF! | H12: =(('Time Matrix'!B12*#REF!)*#REF!) + (('Time Matrix'!B12*#REF!)*#REF!) + (('Time Matrix'!B12*#REF!)*#REF!) + (('Time Matrix'!B12*#REF!)*#REF!) -> #REF!
A13: 708302947 | B13: LH Box Cover | C13: =(('Time Matrix'!B13*#REF!)*'Mon (101)'!#REF!) + (('Time Matrix'!B13*#REF!)*'Mon (101)'!#REF!) + (('Time Matrix'!B13*#REF!)*'Mon (101)'!#REF!) + (('Time Matrix'!B13*#REF!)*'Mon (101)'!#REF!) -> #REF! | D13: =(('Time Matrix'!B13*#REF!)*#REF!) + (('Time Matrix'!B13*#REF!)*#REF!) + (('Time Matrix'!B13*#REF!)*#REF!) + (('Time Matrix'!B13*#REF!)*#REF!) -> #REF! | E13: =(('Time Matrix'!B13*#REF!)*#REF!) + (('Time Matrix'!B13*#REF!)*#REF!) + (('Time Matrix'!B13*#REF!)*#REF!) + (('Time Matrix'!B13*#REF!)*#REF!) -> #REF! | F13: =(('Time Matrix'!B13*#REF!)*#REF!) + (('Time Matrix'!B13*#REF!)*#REF!) + (('Time Matrix'!B13*#REF!)*#REF!) + (('Time Matrix'!B13*#REF!)*#REF!) -> #REF! | G13: =(('Time Matrix'!B13*#REF!)*#REF!) + (('Time Matrix'!B13*#REF!)*#REF!) + (('Time Matrix'!B13*#REF!)*#REF!) + (('Time Matrix'!B13*#REF!)*#REF!) -> #REF! | H13: =(('Time Matrix'!B13*#REF!)*#REF!) + (('Time Matrix'!B13*#REF!)*#REF!) + (('Time Matrix'!B13*#REF!)*#REF!) + (('Time Matrix'!B13*#REF!)*#REF!) -> #REF!
A14: 708302948 | B14: RH Box Cover | C14: =(('Time Matrix'!B14*#REF!)*'Mon (101)'!#REF!) + (('Time Matrix'!B14*#REF!)*'Mon (101)'!#REF!) + (('Time Matrix'!B14*#REF!)*'Mon (101)'!#REF!) + (('Time Matrix'!B14*#REF!)*'Mon (101)'!#REF!) -> #REF! | D14: =(('Time Matrix'!B14*#REF!)*#REF!) + (('Time Matrix'!B14*#REF!)*#REF!) + (('Time Matrix'!B14*#REF!)*#REF!) + (('Time Matrix'!B14*#REF!)*#REF!) -> #REF! | E14: =(('Time Matrix'!B14*#REF!)*#REF!) + (('Time Matrix'!B14*#REF!)*#REF!) + (('Time Matrix'!B14*#REF!)*#REF!) + (('Time Matrix'!B14*#REF!)*#REF!) -> #REF! | F14: =(('Time Matrix'!B14*#REF!)*#REF!) + (('Time Matrix'!B14*#REF!)*#REF!) + (('Time Matrix'!B14*#REF!)*#REF!) + (('Time Matrix'!B14*#REF!)*#REF!) -> #REF! | G14: =(('Time Matrix'!B14*#REF!)*#REF!) + (('Time Matrix'!B14*#REF!)*#REF!) + (('Time Matrix'!B14*#REF!)*#REF!) + (('Time Matrix'!B14*#REF!)*#REF!) -> #REF! | H14: =(('Time Matrix'!B14*#REF!)*#REF!) + (('Time Matrix'!B14*#REF!)*#REF!) + (('Time Matrix'!B14*#REF!)*#REF!) + (('Time Matrix'!B14*#REF!)*#REF!) -> #REF!
... A18: 708400463 | B18: RH Mirror Shell | C18: =(('Time Matrix'!B18*#REF!)*'Mon (101)'!#REF!) + (('Time Matrix'!B18*#REF!)*'Mon (101)'!#REF!) + (('Time Matrix'!B18*#REF!)*'Mon (101)'!#REF!) + (('Time Matrix'!B18*#REF!)*'Mon (101)'!#REF!) -> #REF! | D18: =(('Time Matrix'!B18*#REF!)*#REF!) + (('Time Matrix'!B18*#REF!)*#REF!) + (('Time Matrix'!B18*#REF!)*#REF!) + (('Time Matrix'!B18*#REF!)*#REF!) -> #REF! | E18: =(('Time Matrix'!B18*#REF!)*#REF!) + (('Time Matrix'!B18*#REF!)*#REF!) + (('Time Matrix'!B18*#REF!)*#REF!) + (('Time Matrix'!B18*#REF!)*#REF!) -> #REF! | F18: =(('Time Matrix'!B18*#REF!)*#REF!) + (('Time Matrix'!B18*#REF!)*#REF!) + (('Time Matrix'!B18*#REF!)*#REF!) + (('Time Matrix'!B18*#REF!)*#REF!) -> #REF! | G18: =(('Time Matrix'!B18*#REF!)*#REF!) + (('Time Matrix'!B18*#REF!)*#REF!) + (('Time Matrix'!B18*#REF!)*#REF!) + (('Time Matrix'!B18*#REF!)*#REF!) -> #REF! | H18: =(('Time Matrix'!B18*#REF!)*#REF!) + (('Time Matrix'!B18*#REF!)*#REF!) + (('Time Matrix'!B18*#REF!)*#REF!) + (('Time Matrix'!B18*#REF!)*#REF!) -> #REF!
A19: Total: | C19: =SUM(C3:C18) -> #REF! | D19: =SUM(D3:D18) -> #REF! | E19: =SUM(E3:E18) -> #REF! | F19: =SUM(F3:F18) -> #REF! | G19: =SUM(G3:G18) -> #REF! | H19: =SUM(H3:H18) -> #REF!
A20: Deep Black (Spyder)
A21: 708001528 | B21: Tail Fairing | C21: =(('Time Matrix'!C19*#REF!)*'Mon (101)'!#REF!) + (('Time Matrix'!C19*#REF!)*'Mon (101)'!#REF!) + (('Time Matrix'!C19*#REF!)*'Mon (101)'!#REF!) + (('Time Matrix'!C19*#REF!)*'Mon (101)'!#REF!) -> #REF! | D21: =(('Time Matrix'!C19*#REF!)*#REF!) + (('Time Matrix'!C19*#REF!)*#REF!) + (('Time Matrix'!C19*#REF!)*#REF!) + (('Time Matrix'!C19*#REF!)*#REF!) -> #REF! | E21: =(('Time Matrix'!C19*#REF!)*#REF!) + (('Time Matrix'!C19*#REF!)*#REF!) + (('Time Matrix'!C19*#REF!)*#REF!) + (('Time Matrix'!C19*#REF!)*#REF!) -> #REF! | F21: =(('Time Matrix'!C19*#REF!)*#REF!) + (('Time Matrix'!C19*#REF!)*#REF!) + (('Time Matrix'!C19*#REF!)*#REF!) + (('Time Matrix'!C19*#REF!)*#REF!) -> #REF! | G21: =(('Time Matrix'!C19*#REF!)*#REF!) + (('Time Matrix'!C19*#REF!)*#REF!) + (('Time Matrix'!C19*#REF!)*#REF!) + (('Time Matrix'!C19*#REF!)*#REF!) -> #REF! | H21: =(('Time Matrix'!C19*#REF!)*#REF!) + (('Time Matrix'!C19*#REF!)*#REF!) + (('Time Matrix'!C19*#REF!)*#REF!) + (('Time Matrix'!C19*#REF!)*#REF!) -> #REF!
A22: 708400001 | B22: LH Console Panel | C22: =(('Time Matrix'!C20*#REF!)*'Mon (101)'!#REF!) + (('Time Matrix'!C20*#REF!)*'Mon (101)'!#REF!) + (('Time Matrix'!C20*#REF!)*'Mon (101)'!#REF!) + (('Time Matrix'!C20*#REF!)*'Mon (101)'!#REF!) -> #REF! | D22: =(('Time Matrix'!C20*#REF!)*#REF!) + (('Time Matrix'!C20*#REF!)*#REF!) + (('Time Matrix'!C20*#REF!)*#REF!) + (('Time Matrix'!C20*#REF!)*#REF!) -> #REF! | E22: =(('Time Matrix'!C20*#REF!)*#REF!) + (('Time Matrix'!C20*#REF!)*#REF!) + (('Time Matrix'!C20*#REF!)*#REF!) + (('Time Matrix'!C20*#REF!)*#REF!) -> #REF! | F22: =(('Time Matrix'!C20*#REF!)*#REF!) + (('Time Matrix'!C20*#REF!)*#REF!) + (('Time Matrix'!C20*#REF!)*#REF!) + (('Time Matrix'!C20*#REF!)*#REF!) -> #REF! | G22: =(('Time Matrix'!C20*#REF!)*#REF!) + (('Time Matrix'!C20*#REF!)*#REF!) + (('Time Matrix'!C20*#REF!)*#REF!) + (('Time Matrix'!C20*#REF!)*#REF!) -> #REF! | H22: =(('Time Matrix'!C20*#REF!)*#REF!) + (('Time Matrix'!C20*#REF!)*#REF!) + (('Time Matrix'!C20*#REF!)*#REF!) + (('Time Matrix'!C20*#REF!)*#REF!) -> #REF!
A23: 708400002 | B23: RH Console Panel | C23: =(('Time Matrix'!C21*#REF!)*'Mon (101)'!#REF!) + (('Time Matrix'!C21*#REF!)*'Mon (101)'!#REF!) + (('Time Matrix'!C21*#REF!)*'Mon (101)'!#REF!) + (('Time Matrix'!C21*#REF!)*'Mon (101)'!#REF!) -> #REF! | D23: =(('Time Matrix'!C21*#REF!)*#REF!) + (('Time Matrix'!C21*#REF!)*#REF!) + (('Time Matrix'!C21*#REF!)*#REF!) + (('Time Matrix'!C21*#REF!)*#REF!) -> #REF! | E23: =(('Time Matrix'!C21*#REF!)*#REF!) + (('Time Matrix'!C21*#REF!)*#REF!) + (('Time Matrix'!C21*#REF!)*#REF!) + (('Time Matrix'!C21*#REF!)*#REF!) -> #REF! | F23: =(('Time Matrix'!C21*#REF!)*#REF!) + (('Time Matrix'!C21*#REF!)*#REF!) + (('Time Matrix'!C21*#REF!)*#REF!) + (('Time Matrix'!C21*#REF!)*#REF!) -> #REF! | G23: =(('Time Matrix'!C21*#REF!)*#REF!) + (('Time Matrix'!C21*#REF!)*#REF!) + (('Time Matrix'!C21*#REF!)*#REF!) + (('Time Matrix'!C21*#REF!)*#REF!) -> #REF! | H23: =(('Time Matrix'!C21*#REF!)*#REF!) + (('Time Matrix'!C21*#REF!)*#REF!) + (('Time Matrix'!C21*#REF!)*#REF!) + (('Time Matrix'!C21*#REF!)*#REF!) -> #REF!
A24: 708400067 | B24: LH Console Fairing | C24: =(('Time Matrix'!C22*#REF!)*'Mon (101)'!#REF!) + (('Time Matrix'!C22*#REF!)*'Mon (101)'!#REF!) + (('Time Matrix'!C22*#REF!)*'Mon (101)'!#REF!) + (('Time Matrix'!C22*#REF!)*'Mon (101)'!#REF!) -> #REF! | D24: =(('Time Matrix'!C22*#REF!)*#REF!) + (('Time Matrix'!C22*#REF!)*#REF!) + (('Time Matrix'!C22*#REF!)*#REF!) + (('Time Matrix'!C22*#REF!)*#REF!) -> #REF! | E24: =(('Time Matrix'!C22*#REF!)*#REF!) + (('Time Matrix'!C22*#REF!)*#REF!) + (('Time Matrix'!C22*#REF!)*#REF!) + (('Time Matrix'!C22*#REF!)*#REF!) -> #REF! | F24: =(('Time Matrix'!C22*#REF!)*#REF!) + (('Time Matrix'!C22*#REF!)*#REF!) + (('Time Matrix'!C22*#REF!)*#REF!) + (('Time Matrix'!C22*#REF!)*#REF!) -> #REF! | G24: =(('Time Matrix'!C22*#REF!)*#REF!) + (('Time Matrix'!C22*#REF!)*#REF!) + (('Time Matrix'!C22*#REF!)*#REF!) + (('Time Matrix'!C22*#REF!)*#REF!) -> #REF! | H24: =(('Time Matrix'!C22*#REF!)*#REF!) + (('Time Matrix'!C22*#REF!)*#REF!) + (('Time Matrix'!C22*#REF!)*#REF!) + (('Time Matrix'!C22*#REF!)*#REF!) -> #REF!
A25: 708400069 | B25: RH Console Fairing | C25: =(('Time Matrix'!C23*#REF!)*'Mon (101)'!#REF!) + (('Time Matrix'!C23*#REF!)*'Mon (101)'!#REF!) + (('Time Matrix'!C23*#REF!)*'Mon (101)'!#REF!) + (('Time Matrix'!C23*#REF!)*'Mon (101)'!#REF!) -> #REF! | D25: =(('Time Matrix'!C23*#REF!)*#REF!) + (('Time Matrix'!C23*#REF!)*#REF!) + (('Time Matrix'!C23*#REF!)*#REF!) + (('Time Matrix'!C23*#REF!)*#REF!) -> #REF! | E25: =(('Time Matrix'!C23*#REF!)*#REF!) + (('Time Matrix'!C23*#REF!)*#REF!) + (('Time Matrix'!C23*#REF!)*#REF!) + (('Time Matrix'!C23*#REF!)*#REF!) -> #REF! | F25: =(('Time Matrix'!C23*#REF!)*#REF!) + (('Time Matrix'!C23*#REF!)*#REF!) + (('Time Matrix'!C23*#REF!)*#REF!) + (('Time Matrix'!C23*#REF!)*#REF!) -> #REF! | G25: =(('Time Matrix'!C23*#REF!)*#REF!) + (('Time Matrix'!C23*#REF!)*#REF!) + (('Time Matrix'!C23*#REF!)*#REF!) + (('Time Matrix'!C23*#REF!)*#REF!) -> #REF! | H25: =(('Time Matrix'!C23*#REF!)*#REF!) + (('Time Matrix'!C23*#REF!)*#REF!) + (('Time Matrix'!C23*#REF!)*#REF!) + (('Time Matrix'!C23*#REF!)*#REF!) -> #REF!
A26: 708400287 | B26: Tank Cover | C26: =(('Time Matrix'!C24*#REF!)*'Mon (101)'!#REF!) + (('Time Matrix'!C24*#REF!)*'Mon (101)'!#REF!) + (('Time Matrix'!C24*#REF!)*'Mon (101)'!#REF!) + (('Time Matrix'!C24*#REF!)*'Mon (101)'!#REF!) -> #REF! | D26: =(('Time Matrix'!C24*#REF!)*#REF!) + (('Time Matrix'!C24*#REF!)*#REF!) + (('Time Matrix'!C24*#REF!)*#REF!) + (('Time Matrix'!C24*#REF!)*#REF!) -> #REF! | E26: =(('Time Matrix'!C24*#REF!)*#REF!) + (('Time Matrix'!C24*#REF!)*#REF!) + (('Time Matrix'!C24*#REF!)*#REF!) + (('Time Matrix'!C24*#REF!)*#REF!) -> #REF! | F26: =(('Time Matrix'!C24*#REF!)*#REF!) + (('Time Matrix'!C24*#REF!)*#REF!) + (('Time Matrix'!C24*#REF!)*#REF!) + (('Time Matrix'!C24*#REF!)*#REF!) -> #REF! | G26: =(('Time Matrix'!C24*#REF!)*#REF!) + (('Time Matrix'!C24*#REF!)*#REF!) + (('Time Matrix'!C24*#REF!)*#REF!) + (('Time Matrix'!C24*#REF!)*#REF!) -> #REF! | H26: =(('Time Matrix'!C24*#REF!)*#REF!) + (('Time Matrix'!C24*#REF!)*#REF!) + (('Time Matrix'!C24*#REF!)*#REF!) + (('Time Matrix'!C24*#REF!)*#REF!) -> #REF!
A27: 708400398 | B27: Tank Cover with Hole | C27: =(('Time Matrix'!C25*#REF!)*'Mon (101)'!#REF!) + (('Time Matrix'!C25*#REF!)*'Mon (101)'!#REF!) + (('Time Matrix'!C25*#REF!)*'Mon (101)'!#REF!) + (('Time Matrix'!C25*#REF!)*'Mon (101)'!#REF!) -> #REF! | D27: =(('Time Matrix'!C25*#REF!)*#REF!) + (('Time Matrix'!C25*#REF!)*#REF!) + (('Time Matrix'!C25*#REF!)*#REF!) + (('Time Matrix'!C25*#REF!)*#REF!) -> #REF! | E27: =(('Time Matrix'!C25*#REF!)*#REF!) + (('Time Matrix'!C25*#REF!)*#REF!) + (('Time Matrix'!C25*#REF!)*#REF!) + (('Time Matrix'!C25*#REF!)*#REF!) -> #REF! | F27: =(('Time Matrix'!C25*#REF!)*#REF!) + (('Time Matrix'!C25*#REF!)*#REF!) + (('Time Matrix'!C25*#REF!)*#REF!) + (('Time Matrix'!C25*#REF!)*#REF!) -> #REF! | G27: =(('Time Matrix'!C25*#REF!)*#REF!) + (('Time Matrix'!C25*#REF!)*#REF!) + (('Time Matrix'!C25*#REF!)*#REF!) + (('Time Matrix'!C25*#REF!)*#REF!) -> #REF! | H27: =(('Time Matrix'!C25*#REF!)*#REF!) + (('Time Matrix'!C25*#REF!)*#REF!) + (('Time Matrix'!C25*#REF!)*#REF!) + (('Time Matrix'!C25*#REF!)*#REF!) -> #REF!
A28: Total: | C28: =SUM(C21:C27) -> #REF! | D28: =SUM(D21:D27) -> #REF! | E28: =SUM(E21:E27) -> #REF! | F28: =SUM(F21:F27) -> #REF! | G28: =SUM(G21:G27) -> #REF! | H28: =SUM(H21:H27) -> #REF!
A29: Manta Green (Spyder F3 / F3T)
A30: 705007790 | B30: LH LOW FAIRING | C30: =(('Time Matrix'!D26*#REF!)*'Mon (101)'!#REF!) + (('Time Matrix'!D26*#REF!)*'Mon (101)'!#REF!) + (('Time Matrix'!D26*#REF!)*'Mon (101)'!#REF!) + (('Time Matrix'!D26*#REF!)*'Mon (101)'!#REF!) -> #REF! | D30: =(('Time Matrix'!D26*#REF!)*#REF!) + (('Time Matrix'!D26*#REF!)*#REF!) + (('Time Matrix'!D26*#REF!)*#REF!) + (('Time Matrix'!D26*#REF!)*#REF!) -> #REF! | E30: =(('Time Matrix'!D26*#REF!)*#REF!) + (('Time Matrix'!D26*#REF!)*#REF!) + (('Time Matrix'!D26*#REF!)*#REF!) + (('Time Matrix'!D26*#REF!)*#REF!) -> #REF! | F30: =(('Time Matrix'!D26*#REF!)*#REF!) + (('Time Matrix'!D26*#REF!)*#REF!) + (('Time Matrix'!D26*#REF!)*#REF!) + (('Time Matrix'!D26*#REF!)*#REF!) -> #REF! | G30: =(('Time Matrix'!D26*#REF!)*#REF!) + (('Time Matrix'!D26*#REF!)*#REF!) + (('Time Matrix'!D26*#REF!)*#REF!) + (('Time Matrix'!D26*#REF!)*#REF!) -> #REF! | H30: =(('Time Matrix'!D26*#REF!)*#REF!) + (('Time Matrix'!D26*#REF!)*#REF!) + (('Time Matrix'!D26*#REF!)*#REF!) + (('Time Matrix'!D26*#REF!)*#REF!) -> #REF!
A31: 705007791 | B31: RH LOW FAIRING | C31: =(('Time Matrix'!D27*#REF!)*'Mon (101)'!#REF!) + (('Time Matrix'!D27*#REF!)*'Mon (101)'!#REF!) + (('Time Matrix'!D27*#REF!)*'Mon (101)'!#REF!) + (('Time Matrix'!D27*#REF!)*'Mon (101)'!#REF!) -> #REF! | D31: =(('Time Matrix'!D27*#REF!)*#REF!) + (('Time Matrix'!D27*#REF!)*#REF!) + (('Time Matrix'!D27*#REF!)*#REF!) + (('Time Matrix'!D27*#REF!)*#REF!) -> #REF! | E31: =(('Time Matrix'!D27*#REF!)*#REF!) + (('Time Matrix'!D27*#REF!)*#REF!) + (('Time Matrix'!D27*#REF!)*#REF!) + (('Time Matrix'!D27*#REF!)*#REF!) -> #REF! | F31: =(('Time Matrix'!D27*#REF!)*#REF!) + (('Time Matrix'!D27*#REF!)*#REF!) + (('Time Matrix'!D27*#REF!)*#REF!) + (('Time Matrix'!D27*#REF!)*#REF!) -> #REF! | G31: =(('Time Matrix'!D27*#REF!)*#REF!) + (('Time Matrix'!D27*#REF!)*#REF!) + (('Time Matrix'!D27*#REF!)*#REF!) + (('Time Matrix'!D27*#REF!)*#REF!) -> #REF! | H31: =(('Time Matrix'!D27*#REF!)*#REF!) + (('Time Matrix'!D27*#REF!)*#REF!) + (('Time Matrix'!D27*#REF!)*#REF!) + (('Time Matrix'!D27*#REF!)*#REF!) -> #REF!
A32: 705010835 | B32: RH FAIRING | C32: =(('Time Matrix'!D28*#REF!)*'Mon (101)'!#REF!) + (('Time Matrix'!D28*#REF!)*'Mon (101)'!#REF!) + (('Time Matrix'!D28*#REF!)*'Mon (101)'!#REF!) + (('Time Matrix'!D28*#REF!)*'Mon (101)'!#REF!) -> #REF! | D32: =(('Time Matrix'!D28*#REF!)*#REF!) + (('Time Matrix'!D28*#REF!)*#REF!) + (('Time Matrix'!D28*#REF!)*#REF!) + (('Time Matrix'!D28*#REF!)*#REF!) -> #REF! | E32: =(('Time Matrix'!D28*#REF!)*#REF!) + (('Time Matrix'!D28*#REF!)*#REF!) + (('Time Matrix'!D28*#REF!)*#REF!) + (('Time Matrix'!D28*#REF!)*#REF!) -> #REF! | F32: =(('Time Matrix'!D28*#REF!)*#REF!) + (('Time Matrix'!D28*#REF!)*#REF!) + (('Time Matrix'!D28*#REF!)*#REF!) + (('Time Matrix'!D28*#REF!)*#REF!) -> #REF! | G32: =(('Time Matrix'!D28*#REF!)*#REF!) + (('Time Matrix'!D28*#REF!)*#REF!) + (('Time Matrix'!D28*#REF!)*#REF!) + (('Time Matrix'!D28*#REF!)*#REF!) -> #REF! | H32: =(('Time Matrix'!D28*#REF!)*#REF!) + (('Time Matrix'!D28*#REF!)*#REF!) + (('Time Matrix'!D28*#REF!)*#REF!) + (('Time Matrix'!D28*#REF!)*#REF!) -> #REF!
A33: 705010851 | B33: LH FAIRING | C33: =(('Time Matrix'!D29*#REF!)*'Mon (101)'!#REF!) + (('Time Matrix'!D29*#REF!)*'Mon (101)'!#REF!) + (('Time Matrix'!D29*#REF!)*'Mon (101)'!#REF!) + (('Time Matrix'!D29*#REF!)*'Mon (101)'!#REF!) -> #REF! | D33: =(('Time Matrix'!D29*#REF!)*#REF!) + (('Time Matrix'!D29*#REF!)*#REF!) + (('Time Matrix'!D29*#REF!)*#REF!) + (('Time Matrix'!D29*#REF!)*#REF!) -> #REF! | E33: =(('Time Matrix'!D29*#REF!)*#REF!) + (('Time Matrix'!D29*#REF!)*#REF!) + (('Time Matrix'!D29*#REF!)*#REF!) + (('Time Matrix'!D29*#REF!)*#REF!) -> #REF! | F33: =(('Time Matrix'!D29*#REF!)*#REF!) + (('Time Matrix'!D29*#REF!)*#REF!) + (('Time Matrix'!D29*#REF!)*#REF!) + (('Time Matrix'!D29*#REF!)*#REF!) -> #REF! | G33: =(('Time Matrix'!D29*#REF!)*#REF!) + (('Time Matrix'!D29*#REF!)*#REF!) + (('Time Matrix'!D29*#REF!)*#REF!) + (('Time Matrix'!D29*#REF!)*#REF!) -> #REF! | H33: =(('Time Matrix'!D29*#REF!)*#REF!) + (('Time Matrix'!D29*#REF!)*#REF!) + (('Time Matrix'!D29*#REF!)*#REF!) + (('Time Matrix'!D29*#REF!)*#REF!) -> #REF!
A34: 708200366 | B34: HOOD | C34: =(('Time Matrix'!D30*#REF!)*'Mon (101)'!#REF!) + (('Time Matrix'!D30*#REF!)*'Mon (101)'!#REF!) + (('Time Matrix'!D30*#REF!)*'Mon (101)'!#REF!) + (('Time Matrix'!D30*#REF!)*'Mon (101)'!#REF!) -> #REF! | D34: =(('Time Matrix'!D30*#REF!)*#REF!) + (('Time Matrix'!D30*#REF!)*#REF!) + (('Time Matrix'!D30*#REF!)*#REF!) + (('Time Matrix'!D30*#REF!)*#REF!) -> #REF! | E34: =(('Time Matrix'!D30*#REF!)*#REF!) + (('Time Matrix'!D30*#REF!)*#REF!) + (('Time Matrix'!D30*#REF!)*#REF!) + (('Time Matrix'!D30*#REF!)*#REF!) -> #REF! | F34: =(('Time Matrix'!D30*#REF!)*#REF!) + (('Time Matrix'!D30*#REF!)*#REF!) + (('Time Matrix'!D30*#REF!)*#REF!) + (('Time Matrix'!D30*#REF!)*#REF!) -> #REF! | G34: =(('Time Matrix'!D30*#REF!)*#REF!) + (('Time Matrix'!D30*#REF!)*#REF!) + (('Time Matrix'!D30*#REF!)*#REF!) + (('Time Matrix'!D30*#REF!)*#REF!) -> #REF! | H34: =(('Time Matrix'!D30*#REF!)*#REF!) + (('Time Matrix'!D30*#REF!)*#REF!) + (('Time Matrix'!D30*#REF!)*#REF!) + (('Time Matrix'!D30*#REF!)*#REF!) -> #REF!
A35: 708200401 | B35: LH VENT PANEL | C35: =(('Time Matrix'!D31*#REF!)*'Mon (101)'!#REF!) + (('Time Matrix'!D31*#REF!)*'Mon (101)'!#REF!) + (('Time Matrix'!D31*#REF!)*'Mon (101)'!#REF!) + (('Time Matrix'!D31*#REF!)*'Mon (101)'!#REF!) -> #REF! | D35: =(('Time Matrix'!D31*#REF!)*#REF!) + (('Time Matrix'!D31*#REF!)*#REF!) + (('Time Matrix'!D31*#REF!)*#REF!) + (('Time Matrix'!D31*#REF!)*#REF!) -> #REF! | E35: =(('Time Matrix'!D31*#REF!)*#REF!) + (('Time Matrix'!D31*#REF!)*#REF!) + (('Time Matrix'!D31*#REF!)*#REF!) + (('Time Matrix'!D31*#REF!)*#REF!) -> #REF! | F35: =(('Time Matrix'!D31*#REF!)*#REF!) + (('Time Matrix'!D31*#REF!)*#REF!) + (('Time Matrix'!D31*#REF!)*#REF!) + (('Time Matrix'!D31*#REF!)*#REF!) -> #REF! | G35: =(('Time Matrix'!D31*#REF!)*#REF!) + (('Time Matrix'!D31*#REF!)*#REF!) + (('Time Matrix'!D31*#REF!)*#REF!) + (('Time Matrix'!D31*#REF!)*#REF!) -> #REF! | H35: =(('Time Matrix'!D31*#REF!)*#REF!) + (('Time Matrix'!D31*#REF!)*#REF!) + (('Time Matrix'!D31*#REF!)*#REF!) + (('Time Matrix'!D31*#REF!)*#REF!) -> #REF!
A36: 708200402 | B36: RH VENT PANEL | C36: =(('Time Matrix'!D32*#REF!)*'Mon (101)'!#REF!) + (('Time Matrix'!D32*#REF!)*'Mon (101)'!#REF!) + (('Time Matrix'!D32*#REF!)*'Mon (101)'!#REF!) + (('Time Matrix'!D32*#REF!)*'Mon (101)'!#REF!) -> #REF! | D36: =(('Time Matrix'!D32*#REF!)*#REF!) + (('Time Matrix'!D32*#REF!)*#REF!) + (('Time Matrix'!D32*#REF!)*#REF!) + (('Time Matrix'!D32*#REF!)*#REF!) -> #REF! | E36: =(('Time Matrix'!D32*#REF!)*#REF!) + (('Time Matrix'!D32*#REF!)*#REF!) + (('Time Matrix'!D32*#REF!)*#REF!) + (('Time Matrix'!D32*#REF!)*#REF!) -> #REF! | F36: =(('Time Matrix'!D32*#REF!)*#REF!) + (('Time Matrix'!D32*#REF!)*#REF!) + (('Time Matrix'!D32*#REF!)*#REF!) + (('Time Matrix'!D32*#REF!)*#REF!) -> #REF! | G36: =(('Time Matrix'!D32*#REF!)*#REF!) + (('Time Matrix'!D32*#REF!)*#REF!) + (('Time Matrix'!D32*#REF!)*#REF!) + (('Time Matrix'!D32*#REF!)*#REF!) -> #REF! | H36: =(('Time Matrix'!D32*#REF!)*#REF!) + (('Time Matrix'!D32*#REF!)*#REF!) + (('Time Matrix'!D32*#REF!)*#REF!) + (('Time Matrix'!D32*#REF!)*#REF!) -> #REF!
A37: 708200698 | B37: FRONT FASCIA | C37: =(('Time Matrix'!D33*#REF!)*'Mon (101)'!#REF!) + (('Time Matrix'!D33*#REF!)*'Mon (101)'!#REF!) + (('Time Matrix'!D33*#REF!)*'Mon (101)'!#REF!) + (('Time Matrix'!D33*#REF!)*'Mon (101)'!#REF!) -> #REF! | D37: =(('Time Matrix'!D33*#REF!)*#REF!) + (('Time Matrix'!D33*#REF!)*#REF!) + (('Time Matrix'!D33*#REF!)*#REF!) + (('Time Matrix'!D33*#REF!)*#REF!) -> #REF! | E37: =(('Time Matrix'!D33*#REF!)*#REF!) + (('Time Matrix'!D33*#REF!)*#REF!) + (('Time Matrix'!D33*#REF!)*#REF!) + (('Time Matrix'!D33*#REF!)*#REF!) -> #REF! | F37: =(('Time Matrix'!D33*#REF!)*#REF!) + (('Time Matrix'!D33*#REF!)*#REF!) + (('Time Matrix'!D33*#REF!)*#REF!) + (('Time Matrix'!D33*#REF!)*#REF!) -> #REF! | G37: =(('Time Matrix'!D33*#REF!)*#REF!) + (('Time Matrix'!D33*#REF!)*#REF!) + (('Time Matrix'!D33*#REF!)*#REF!) + (('Time Matrix'!D33*#REF!)*#REF!) -> #REF! | H37: =(('Time Matrix'!D33*#REF!)*#REF!) + (('Time Matrix'!D33*#REF!)*#REF!) + (('Time Matrix'!D33*#REF!)*#REF!) + (('Time Matrix'!D33*#REF!)*#REF!) -> #REF!
A38: 708301201 | B38: COVER BOX | C38: =(('Time Matrix'!D34*#REF!)*'Mon (101)'!#REF!) + (('Time Matrix'!D34*#REF!)*'Mon (101)'!#REF!) + (('Time Matrix'!D34*#REF!)*'Mon (101)'!#REF!) + (('Time Matrix'!D34*#REF!)*'Mon (101)'!#REF!) -> #REF! | D38: =(('Time Matrix'!D34*#REF!)*#REF!) + (('Time Matrix'!D34*#REF!)*#REF!) + (('Time Matrix'!D34*#REF!)*#REF!) + (('Time Matrix'!D34*#REF!)*#REF!) -> #REF! | E38: =(('Time Matrix'!D34*#REF!)*#REF!) + (('Time Matrix'!D34*#REF!)*#REF!) + (('Time Matrix'!D34*#REF!)*#REF!) + (('Time Matrix'!D34*#REF!)*#REF!) -> #REF! | F38: =(('Time Matrix'!D34*#REF!)*#REF!) + (('Time Matrix'!D34*#REF!)*#REF!) + (('Time Matrix'!D34*#REF!)*#REF!) + (('Time Matrix'!D34*#REF!)*#REF!) -> #REF! | G38: =(('Time Matrix'!D34*#REF!)*#REF!) + (('Time Matrix'!D34*#REF!)*#REF!) + (('Time Matrix'!D34*#REF!)*#REF!) + (('Time Matrix'!D34*#REF!)*#REF!) -> #REF! | H38: =(('Time Matrix'!D34*#REF!)*#REF!) + (('Time Matrix'!D34*#REF!)*#REF!) + (('Time Matrix'!D34*#REF!)*#REF!) + (('Time Matrix'!D34*#REF!)*#REF!) -> #REF!
A39: Total: | C39: =SUM(C30:C38) -> #REF! | D39: =SUM(D30:D38) -> #REF! | E39: =SUM(E30:E38) -> #REF! | F39: =SUM(F30:F38) -> #REF! | G39: =SUM(G30:G38) -> #REF! | H39: =SUM(H30:H38) -> #REF!
A40: Vegas White (Spyder)
A41: 705009213 | B41: LH F3T LOW FAIRING | C41: =(('Time Matrix'!E35*#REF!)*'Mon (101)'!#REF!) + (('Time Matrix'!E35*#REF!)*'Mon (101)'!#REF!) + (('Time Matrix'!E35*#REF!)*'Mon (101)'!#REF!) + (('Time Matrix'!E35*#REF!)*'Mon (101)'!#REF!) -> #REF! | D41: =(('Time Matrix'!E35*#REF!)*#REF!) + (('Time Matrix'!E35*#REF!)*#REF!) + (('Time Matrix'!E35*#REF!)*#REF!) + (('Time Matrix'!E35*#REF!)*#REF!) -> #REF! | E41: =(('Time Matrix'!E35*#REF!)*#REF!) + (('Time Matrix'!E35*#REF!)*#REF!) + (('Time Matrix'!E35*#REF!)*#REF!) + (('Time Matrix'!E35*#REF!)*#REF!) -> #REF! | F41: =(('Time Matrix'!E35*#REF!)*#REF!) + (('Time Matrix'!E35*#REF!)*#REF!) + (('Time Matrix'!E35*#REF!)*#REF!) + (('Time Matrix'!E35*#REF!)*#REF!) -> #REF! | G41: =(('Time Matrix'!E35*#REF!)*#REF!) + (('Time Matrix'!E35*#REF!)*#REF!) + (('Time Matrix'!E35*#REF!)*#REF!) + (('Time Matrix'!E35*#REF!)*#REF!) -> #REF! | H41: =(('Time Matrix'!E35*#REF!)*#REF!) + (('Time Matrix'!E35*#REF!)*#REF!) + (('Time Matrix'!E35*#REF!)*#REF!) + (('Time Matrix'!E35*#REF!)*#REF!) -> #REF!
A42: 705009214 | B42: RH F3T LOW FAIRING | C42: =(('Time Matrix'!E36*#REF!)*'Mon (101)'!#REF!) + (('Time Matrix'!E36*#REF!)*'Mon (101)'!#REF!) + (('Time Matrix'!E36*#REF!)*'Mon (101)'!#REF!) + (('Time Matrix'!E36*#REF!)*'Mon (101)'!#REF!) -> #REF! | D42: =(('Time Matrix'!E36*#REF!)*#REF!) + (('Time Matrix'!E36*#REF!)*#REF!) + (('Time Matrix'!E36*#REF!)*#REF!) + (('Time Matrix'!E36*#REF!)*#REF!) -> #REF! | E42: =(('Time Matrix'!E36*#REF!)*#REF!) + (('Time Matrix'!E36*#REF!)*#REF!) + (('Time Matrix'!E36*#REF!)*#REF!) + (('Time Matrix'!E36*#REF!)*#REF!) -> #REF! | F42: =(('Time Matrix'!E36*#REF!)*#REF!) + (('Time Matrix'!E36*#REF!)*#REF!) + (('Time Matrix'!E36*#REF!)*#REF!) + (('Time Matrix'!E36*#REF!)*#REF!) -> #REF! | G42: =(('Time Matrix'!E36*#REF!)*#REF!) + (('Time Matrix'!E36*#REF!)*#REF!) + (('Time Matrix'!E36*#REF!)*#REF!) + (('Time Matrix'!E36*#REF!)*#REF!) -> #REF! | H42: =(('Time Matrix'!E36*#REF!)*#REF!) + (('Time Matrix'!E36*#REF!)*#REF!) + (('Time Matrix'!E36*#REF!)*#REF!) + (('Time Matrix'!E36*#REF!)*#REF!) -> #REF!
A43: 705010835 | B43: RH FAIRING | C43: =(('Time Matrix'!E37*#REF!)*'Mon (101)'!#REF!) + (('Time Matrix'!E37*#REF!)*'Mon (101)'!#REF!) + (('Time Matrix'!E37*#REF!)*'Mon (101)'!#REF!) + (('Time Matrix'!E37*#REF!)*'Mon (101)'!#REF!) -> #REF! | D43: =(('Time Matrix'!E37*#REF!)*#REF!) + (('Time Matrix'!E37*#REF!)*#REF!) + (('Time Matrix'!E37*#REF!)*#REF!) + (('Time Matrix'!E37*#REF!)*#REF!) -> #REF! | E43: =(('Time Matrix'!E37*#REF!)*#REF!) + (('Time Matrix'!E37*#REF!)*#REF!) + (('Time Matrix'!E37*#REF!)*#REF!) + (('Time Matrix'!E37*#REF!)*#REF!) -> #REF! | F43: =(('Time Matrix'!E37*#REF!)*#REF!) + (('Time Matrix'!E37*#REF!)*#REF!) + (('Time Matrix'!E37*#REF!)*#REF!) + (('Time Matrix'!E37*#REF!)*#REF!) -> #REF! | G43: =(('Time Matrix'!E37*#REF!)*#REF!) + (('Time Matrix'!E37*#REF!)*#REF!) + (('Time Matrix'!E37*#REF!)*#REF!) + (('Time Matrix'!E37*#REF!)*#REF!) -> #REF! | H43: =(('Time Matrix'!E37*#REF!)*#REF!) + (('Time Matrix'!E37*#REF!)*#REF!) + (('Time Matrix'!E37*#REF!)*#REF!) + (('Time Matrix'!E37*#REF!)*#REF!) -> #REF!
...

Sheet Time Matrix
A1: Gun on Time
A2: Part | B2: Hyper Silver (Spyder) | C2: Deep Black (Spyder) | D2: Manta Green (Spyder F3 / F3T) | E2: Vegas White (Spyder) | F2: Metelix - Spoilers | G2: Electrolux (Smoke) | H2: Laval Summit White | I2: Laval Waymo Black | J2: Manterra - Hyper Silver | K2: Splash Guards - Black Carbon | L2: Mitchell Plastics | M2: Evinrude White | N2: Smoke Grey (Evinrude) | O2: Red Mica Snipe | P2: Red Mica Osprey | Q2: Orbital Blue Snipe | R2: Orbital Blue Osprey
A3: LH Trim | B3: 0.066666667
A4: RH Trim | B4: 0.066666667
A5: RH Fender | B5: 0.066666667
A6: LH Fender | B6: 0.066666667
A7: LH Upper Fairing | B7: 0.066666667
A8: RH Upper Fairing | B8: 0.066666667
A9: Rear Fairing | B9: 0.066666667
A10: R66 Hood | B10: 0.066666667
A11: LH Front Fairing | B11: 0.066666667
A12: RH Front Fairing | B12: 0.066666667
A13: LH Box Cover | B13: 0.066666667
A14: RH Box Cover | B14: 0.066666667
... A18: RH Mirror Shell | B18: 0.066666667
A19: Tail Fairing | C19: 0.066666667
A20: LH Console Panel | C20: 0.066666667
A21: RH Console Panel | C21: 0.066666667
A22: LH Console Fairing | C22: 0.066666667
A23: RH Console Fairing | C23: 0.066666667
A24: Tank Cover | C24: 0.066666667
A25: Tank Cover with Hole | C25: 0.066666667
A26: LH LOW FAIRING | D26: 0.066666667
A27: RH LOW FAIRING | D27: 0.066666667
A28: RH FAIRING | D28: 0.066666667
A29: LH FAIRING | D29: 0.066666667
A30: HOOD | D30: 0.066666667
A31: LH VENT PANEL | D31: 0.066666667
A32: RH VENT PANEL | D32: 0.066666667
A33: FRONT FASCIA | D33: 0.066666667
A34: COVER BOX | D34: 0.066666667
A35: LH F3T LOW FAIRING | E35: 0.066666667
A36: RH F3T LOW FAIRING | E36: 0.066666667
A37: RH FAIRING | E37: 0.066666667
A38: LH FAIRING | E38: 0.066666667
A39: RH FENDER | E39: 0.066666667
A40: LH FENDER | E40: 0.066666667
A41: HOOD | E41: 0.066666667
A42: LH VENT PANEL | E42: 0.066666667
A43: RH VENT PANEL | E43: 0.066666667
...

Sheet Mon (101)
A1: 101 LINE LOAD SHEET | O1: Unprotect Password 6941
C2: MONDAY | G2: Date: | I2: ='Weekly Plan'!H1 -> 46006
A3: Order of Colours: | C3: 1)Tesla -Black 2) Summit White
A5: Black - Laval | G5: Metelix
A6: ='Weekly Plan'!F4 -> 99944 Bezel | B6: Black | C6: ='Weekly Plan'!G4 -> Bezel | D6: =IF(INDEX('Weekly Plan'!$F$2:$M$79,MATCH(A6,'Weekly Plan'!$F$2:$F$79,0),MATCH($C$2,'Weekly Plan'!$F$2:$M$2,0))=0,"",INDEX('Weekly Plan'!$F$2:$M$79,MATCH(A6,'Weekly Plan'!$F$2:$F$79,0),MATCH($C$2,'Weekly Plan'!$F$2:$M$2,0))) | E6: ='Weekly Plan'!A4 -> 2 | F6: =IFERROR(D6/E6,0) -> 0 | G6: ='Weekly Plan'!F16 -> VG0240BL0PA | I6: ='Weekly Plan'!G16 -> C223 ACCSRY Spoiler | J6: =IF(INDEX('Weekly Plan'!$F$2:$M$79,MATCH(G6,'Weekly Plan'!$F$2:$F$79,0),MATCH($C$2,'Weekly Plan'!$F$2:$M$2,0))=0,"",INDEX('Weekly Plan'!$F$2:$M$79,MATCH(G6,'Weekly Plan'!$F$2:$F$79,0),MATCH($C$2,'Weekly Plan'!$F$2:$M$2,0))) | K6: ='Weekly Plan'!A16 -> 1 | L6: =IFERROR(J6/K6,0) -> 0
A7: ='Weekly Plan'!F5 -> 99633 | B7: Black | C7: ='Weekly Plan'!G5 -> IR Cover LH | D7: =IF(INDEX('Weekly Plan'!$F$2:$M$79,MATCH(A7,'Weekly Plan'!$F$2:$F$79,0),MATCH($C$2,'Weekly Plan'!$F$2:$M$2,0))=0,"",INDEX('Weekly Plan'!$F$2:$M$79,MATCH(A7,'Weekly Plan'!$F$2:$F$79,0),MATCH($C$2,'Weekly Plan'!$F$2:$M$2,0))) | E7: ='Weekly Plan'!A5 -> 20 | F7: =IFERROR(D7/E7,0) -> 0 | G7: ='Weekly Plan'!F17 -> VG0241CM0PB | I7: ='Weekly Plan'!G17 -> Y2XX Stanchion - LH | J7: =IF(INDEX('Weekly Plan'!$F$2:$M$79,MATCH(G7,'Weekly Plan'!$F$2:$F$79,0),MATCH($C$2,'Weekly Plan'!$F$2:$M$2,0))=0,"",INDEX('Weekly Plan'!$F$2:$M$79,MATCH(G7,'Weekly Plan'!$F$2:$F$79,0),MATCH($C$2,'Weekly Plan'!$F$2:$M$2,0))) | K7: ='Weekly Plan'!A17 -> 6 | L7: =IFERROR(J7/K7,0) -> 0
A8: ='Weekly Plan'!F6 -> 99646 | B8: Black | C8: ='Weekly Plan'!G6 -> IR Cover RH | D8: =IF(INDEX('Weekly Plan'!$F$2:$M$79,MATCH(A8,'Weekly Plan'!$F$2:$F$79,0),MATCH($C$2,'Weekly Plan'!$F$2:$M$2,0))=0,"",INDEX('Weekly Plan'!$F$2:$M$79,MATCH(A8,'Weekly Plan'!$F$2:$F$79,0),MATCH($C$2,'Weekly Plan'!$F$2:$M$2,0))) | E8: ='Weekly Plan'!A6 -> 20 | F8: =IFERROR(D8/E8,0) -> 0 | G8: ='Weekly Plan'!F18 -> VG0241CM0PD | I8: ='Weekly Plan'!G18 -> Y2XX Stanchion - RH | J8: =IF(INDEX('Weekly Plan'!$F$2:$M$79,MATCH(G8,'Weekly Plan'!$F$2:$F$79,0),MATCH($C$2,'Weekly Plan'!$F$2:$M$2,0))=0,"",INDEX('Weekly Plan'!$F$2:$M$79,MATCH(G8,'Weekly Plan'!$F$2:$F$79,0),MATCH($C$2,'Weekly Plan'!$F$2:$M$2,0))) | K8: ='Weekly Plan'!A18 -> 6 | L8: =IFERROR(J8/K8,0) -> 0
A9: ='Weekly Plan'!F7 -> 99635 | B9: Black | C9: ='Weekly Plan'!G7 -> Lateral Belt LH | D9: =IF(INDEX('Weekly Plan'!$F$2:$M$79,MATCH(A9,'Weekly Plan'!$F$2:$F$79,0),MATCH($C$2,'Weekly Plan'!$F$2:$M$2,0))=0,"",INDEX('Weekly Plan'!$F$2:$M$79,MATCH(A9,'Weekly Plan'!$F$2:$F$79,0),MATCH($C$2,'Weekly Plan'!$F$2:$M$2,0))) | E9: ='Weekly Plan'!A7 -> 6 | F9: =IFERROR(D9/E9,0) -> 0 | G9: ='Weekly Plan'!F19 -> VG0241CM0PC | I9: ='Weekly Plan'!G19 -> Y2XX Stanchion - Center | J9: =IF(INDEX('Weekly Plan'!$F$2:$M$79,MATCH(G9,'Weekly Plan'!$F$2:$F$79,0),MATCH($C$2,'Weekly Plan'!$F$2:$M$2,0))=0,"",INDEX('Weekly Plan'!$F$2:$M$79,MATCH(G9,'Weekly Plan'!$F$2:$F$79,0),MATCH($C$2,'Weekly Plan'!$F$2:$M$2,0))) | K9: ='Weekly Plan'!A19 -> 6 | L9: =IFERROR(J9/K9,0) -> 0
A10: ='Weekly Plan'!F8 -> 99944 | B10: Black | C10: ='Weekly Plan'!G8 -> Lateral Belt RH | D10: =IF(INDEX('Weekly Plan'!$F$2:$M$79,MATCH(A10,'Weekly Plan'!$F$2:$F$79,0),MATCH($C$2,'Weekly Plan'!$F$2:$M$2,0))=0,"",INDEX('Weekly Plan'!$F$2:$M$79,MATCH(A10,'Weekly Plan'!$F$2:$F$79,0),MATCH($C$2,'Weekly Plan'!$F$2:$M$2,0))) | E10: ='Weekly Plan'!A8 -> 6 | F10: =IFERROR(D10/E10,0) -> 0 | G10: ='Weekly Plan'!F20 -> VG0241CM0PE | I10: ='Weekly Plan'!G20 -> Y2XX Winglet -LH | J10: =IF(INDEX('Weekly Plan'!$F$2:$M$79,MATCH(G10,'Weekly Plan'!$F$2:$F$79,0),MATCH($C$2,'Weekly Plan'!$F$2:$M$2,0))=0,"",INDEX('Weekly Plan'!$F$2:$M$79,MATCH(G10,'Weekly Plan'!$F$2:$F$79,0),MATCH($C$2,'Weekly Plan'!$F$2:$M$2,0))) | K10: ='Weekly Plan'!A20 -> 0 | L10: =IFERROR(J12/K10,0) -> 0
A11: ='Weekly Plan'!F9 -> 99636 | B11: Black | C11: ='Weekly Plan'!G9 -> Rear Belt | D11: =IF(INDEX('Weekly Plan'!$F$2:$M$79,MATCH(A11,'Weekly Plan'!$F$2:$F$79,0),MATCH($C$2,'Weekly Plan'!$F$2:$M$2,0))=0,"",INDEX('Weekly Plan'!$F$2:$M$79,MATCH(A11,'Weekly Plan'!$F$2:$F$79,0),MATCH($C$2,'Weekly Plan'!$F$2:$M$2,0))) | E11: ='Weekly Plan'!A9 -> 20 | F11: =IFERROR(D11/E11,0) -> 0 | G11: ='Weekly Plan'!F21 -> VG0241CM0PF | I11: ='Weekly Plan'!G21 -> Y2XX Winglet -RH | J11: =IF(INDEX('Weekly Plan'!$F$2:$M$79,MATCH(G11,'Weekly Plan'!$F$2:$F$79,0),MATCH($C$2,'Weekly Plan'!$F$2:$M$2,0))=0,"",INDEX('Weekly Plan'!$F$2:$M$79,MATCH(G11,'Weekly Plan'!$F$2:$F$79,0),MATCH($C$2,'Weekly Plan'!$F$2:$M$2,0))) | K11: ='Weekly Plan'!A21 -> 0 | L11: =IFERROR(J13/K11,0) -> 0
G12: ='Weekly Plan'!F22 -> VG0241CM0PG | I12: ='Weekly Plan'!G22 -> Y2XX Screw Cover - LH | J12: =IF(INDEX('Weekly Plan'!$F$2:$M$79,MATCH(G12,'Weekly Plan'!$F$2:$F$79,0),MATCH($C$2,'Weekly Plan'!$F$2:$M$2,0))=0,"",INDEX('Weekly Plan'!$F$2:$M$79,MATCH(G12,'Weekly Plan'!$F$2:$F$79,0),MATCH($C$2,'Weekly Plan'!$F$2:$M$2,0))) | K12: ='Weekly Plan'!A22 -> 20 | L12: =IFERROR(J14/K12,0) -> 0
G13: ='Weekly Plan'!F23 -> VG0241CM0PH | I13: ='Weekly Plan'!G23 -> Y2XX Screw Cover - RH | J13: =IF(INDEX('Weekly Plan'!$F$2:$M$79,MATCH(G13,'Weekly Plan'!$F$2:$F$79,0),MATCH($C$2,'Weekly Plan'!$F$2:$M$2,0))=0,"",INDEX('Weekly Plan'!$F$2:$M$79,MATCH(G13,'Weekly Plan'!$F$2:$F$79,0),MATCH($C$2,'Weekly Plan'!$F$2:$M$2,0))) | K13: ='Weekly Plan'!A23 -> 20 | L13: =IFERROR(J15/K13,0) -> 0
A15: Summit White - Laval | G15: Tesla - High Gloss Black
A16: ='Weekly Plan'!F11 -> 99629 | B16: Summit White | C16: ='Weekly Plan'!G11 -> Main Lower Cover | D16: =IF(INDEX('Weekly Plan'!$F$2:$M$79,MATCH(A16,'Weekly Plan'!$F$2:$F$79,0),MATCH($C$2,'Weekly Plan'!$F$2:$M$2,0))=0,"",INDEX('Weekly Plan'!$F$2:$M$79,MATCH(A16,'Weekly Plan'!$F$2:$F$79,0),MATCH($C$2,'Weekly Plan'!$F$2:$M$2,0))) -> 30 | E16: ='Weekly Plan'!A11 -> 1 | F16: =IFERROR(D16/E16,0) -> 30 | G16: ='Weekly Plan'!F25 -> 9405929P | I16: ='Weekly Plan'!G25 -> MX Applique | J16: =IF(INDEX('Weekly Plan'!$F$2:$M$79,MATCH(G16,'Weekly Plan'!$F$2:$F$79,0),MATCH($C$2,'Weekly Plan'!$F$2:$M$2,0))=0,"",INDEX('Weekly Plan'!$F$2:$M$79,MATCH(G16,'Weekly Plan'!$F$2:$F$79,0),MATCH($C$2,'Weekly Plan'!$F$2:$M$2,0))) -> 260 | K16: ='Weekly Plan'!A25 -> 6 | L16: =IFERROR(J16/K16,0) -> 43.333333
A17: ='Weekly Plan'!F12 -> 99631 | B17: Summit White | C17: ='Weekly Plan'!G12 -> Main Upper Cover | D17: =IF(INDEX('Weekly Plan'!$F$2:$M$79,MATCH(A17,'Weekly Plan'!$F$2:$F$79,0),MATCH($C$2,'Weekly Plan'!$F$2:$M$2,0))=0,"",INDEX('Weekly Plan'!$F$2:$M$79,MATCH(A17,'Weekly Plan'!$F$2:$F$79,0),MATCH($C$2,'Weekly Plan'!$F$2:$M$2,0))) -> 30 | E17: ='Weekly Plan'!A12 -> 1 | F17: =IFERROR(D17/E17,0) -> 30 | G17: ='Weekly Plan'!F26 -> 9405930P | I17: ='Weekly Plan'!G26 -> MS Applique | J17: =IF(INDEX('Weekly Plan'!$F$2:$M$79,MATCH(G17,'Weekly Plan'!$F$2:$F$79,0),MATCH($C$2,'Weekly Plan'!$F$2:$M$2,0))=0,"",INDEX('Weekly Plan'!$F$2:$M$79,MATCH(G17,'Weekly Plan'!$F$2:$F$79,0),MATCH($C$2,'Weekly Plan'!$F$2:$M$2,0))) | K17: ='Weekly Plan'!A26 -> 6 | L17: =IFERROR(J17/K17,0) -> 0
A18: ='Weekly Plan'!F13 -> 99638 | B18: Summit White | C18: ='Weekly Plan'!G13 -> Rear Plate | D18: =IF(INDEX('Weekly Plan'!$F$2:$M$79,MATCH(A18,'Weekly Plan'!$F$2:$F$79,0),MATCH($C$2,'Weekly Plan'!$F$2:$M$2,0))=0,"",INDEX('Weekly Plan'!$F$2:$M$79,MATCH(A18,'Weekly Plan'!$F$2:$F$79,0),MATCH($C$2,'Weekly Plan'!$F$2:$M$2,0))) | E18: ='Weekly Plan'!A13 -> 20 | F18: =IFERROR(D18/E18,0) -> 0 | G18: ='Weekly Plan'!F27 -> 9405929P-REW | I18: ='Weekly Plan'!G27 -> MX Applique Rework | J18: =IF(INDEX('Weekly Plan'!$F$2:$M$79,MATCH(G18,'Weekly Plan'!$F$2:$F$79,0),MATCH($C$2,'Weekly Plan'!$F$2:$M$2,0))=0,"",INDEX('Weekly Plan'!$F$2:$M$79,MATCH(G18,'Weekly Plan'!$F$2:$F$79,0),MATCH($C$2,'Weekly Plan'!$F$2:$M$2,0))) -> 360 | K18: ='Weekly Plan'!A27 -> 6 | L18: =IFERROR(J18/K18,0) -> 60
A19: ='Weekly Plan'!F14 -> 99630 | B19: Summit White | C19: ='Weekly Plan'!G14 -> Vent Cover | D19: =IF(INDEX('Weekly Plan'!$F$2:$M$79,MATCH(A19,'Weekly Plan'!$F$2:$F$79,0),MATCH($C$2,'Weekly Plan'!$F$2:$M$2,0))=0,"",INDEX('Weekly Plan'!$F$2:$M$79,MATCH(A19,'Weekly Plan'!$F$2:$F$79,0),MATCH($C$2,'Weekly Plan'!$F$2:$M$2,0))) -> 30 | E19: ='Weekly Plan'!A14 -> 1 | F19: =IFERROR(D19/E19,0) -> 30 | G19: ='Weekly Plan'!F28 -> 9405930P-REW | I19: ='Weekly Plan'!G28 -> MS Applique Rework | J19: =IF(INDEX('Weekly Plan'!$F$2:$M$79,MATCH(G19,'Weekly Plan'!$F$2:$F$79,0),MATCH($C$2,'Weekly Plan'!$F$2:$M$2,0))=0,"",INDEX('Weekly Plan'!$F$2:$M$79,MATCH(G19,'Weekly Plan'!$F$2:$F$79,0),MATCH($C$2,'Weekly Plan'!$F$2:$M$2,0))) | K19: ='Weekly Plan'!A28 -> 6 | L19: =IFERROR(J19/K19,0) -> 0
A21: Stoney Blue - KB Components | G21: Miscellaneous
A22: ='Weekly Plan'!F31 -> KB2352 | B22: Stoney Blue | C22: ='Weekly Plan'!G31 -> W12 Roof Top Cover | D22: =IF(INDEX('Weekly Plan'!$F$2:$M$79,MATCH(A22,'Weekly Plan'!$F$2:$F$79,0),MATCH($C$2,'Weekly Plan'!$F$2:$M$2,0))=0,"",INDEX('Weekly Plan'!$F$2:$M$79,MATCH(A22,'Weekly Plan'!$F$2:$F$79,0),MATCH($C$2,'Weekly Plan'!$F$2:$M$2,0))) | E22: ='Weekly Plan'!A31 -> 1 | F22: =IFERROR(D22/E22,0) -> 0 | G22: ='Weekly Plan'!F36 -> PART#1 | J22: =IF(INDEX('Weekly Plan'!$F$2:$M$79,MATCH(G22,'Weekly Plan'!$F$2:$F$79,0),MATCH($C$2,'Weekly Plan'!$F$2:$M$2,0))=0,"",INDEX('Weekly Plan'!$F$2:$M$79,MATCH(G22,'Weekly Plan'!$F$2:$F$79,0),MATCH($C$2,'Weekly Plan'!$F$2:$M$2,0))) | K22: ='Weekly Plan'!A36 -> 0 | L22: =IFERROR(J22/K22,0) -> 0
A23: ='Weekly Plan'!F32 -> KB2369 | B23: Stoney Blue | C23: ='Weekly Plan'!G32 -> W12 Mech Bezel Pod 1 | D23: =IF(INDEX('Weekly Plan'!$F$2:$M$79,MATCH(A23,'Weekly Plan'!$F$2:$F$79,0),MATCH($C$2,'Weekly Plan'!$F$2:$M$2,0))=0,"",INDEX('Weekly Plan'!$F$2:$M$79,MATCH(A23,'Weekly Plan'!$F$2:$F$79,0),MATCH($C$2,'Weekly Plan'!$F$2:$M$2,0))) | E23: ='Weekly Plan'!A32 -> 4 | F23: =IFERROR(D23/E23,0) -> 0 | G23: ='Weekly Plan'!F37 -> PART#2 | J23: =IF(INDEX('Weekly Plan'!$F$2:$M$79,MATCH(G23,'Weekly Plan'!$F$2:$F$79,0),MATCH($C$2,'Weekly Plan'!$F$2:$M$2,0))=0,"",INDEX('Weekly Plan'!$F$2:$M$79,MATCH(G23,'Weekly Plan'!$F$2:$F$79,0),MATCH($C$2,'Weekly Plan'!$F$2:$M$2,0))) | K23: ='Weekly Plan'!A37 -> 0 | L23: =IFERROR(J23/K23,0) -> 0
A24: ='Weekly Plan'!F33 -> KB2370L | B24: Stoney Blue | C24: ='Weekly Plan'!G33 -> W12 LH Cover Body Closeout Pod 5 | D24: =IF(INDEX('Weekly Plan'!$F$2:$M$79,MATCH(A24,'Weekly Plan'!$F$2:$F$79,0),MATCH($C$2,'Weekly Plan'!$F$2:$M$2,0))=0,"",INDEX('Weekly Plan'!$F$2:$M$79,MATCH(A24,'Weekly Plan'!$F$2:$F$79,0),MATCH($C$2,'Weekly Plan'!$F$2:$M$2,0))) | E24: ='Weekly Plan'!A33 -> 4 | F24: =IFERROR(D24/E24,0) -> 0 | G24: ='Weekly Plan'!F38 -> PART#3 | J24: =IF(INDEX('Weekly Plan'!$F$2:$M$79,MATCH(G24,'Weekly Plan'!$F$2:$F$79,0),MATCH($C$2,'Weekly Plan'!$F$2:$M$2,0))=0,"",INDEX('Weekly Plan'!$F$2:$M$79,MATCH(G24,'Weekly Plan'!$F$2:$F$79,0),MATCH($C$2,'Weekly Plan'!$F$2:$M$2,0))) | K24: ='Weekly Plan'!A38 -> 0 | L24: =IFERROR(J24/K24,0) -> 0
A25: ='Weekly Plan'!F34 -> KB2370R | B25: Stoney Blue | C25: ='Weekly Plan'!G34 -> W12 RH Cover Body Closeout Pod 6 | D25: =IF(INDEX('Weekly Plan'!$F$2:$M$79,MATCH(A25,'Weekly Plan'!$F$2:$F$79,0),MATCH($C$2,'Weekly Plan'!$F$2:$M$2,0))=0,"",INDEX('Weekly Plan'!$F$2:$M$79,MATCH(A25,'Weekly Plan'!$F$2:$F$79,0),MATCH($C$2,'Weekly Plan'!$F$2:$M$2,0))) | E25: ='Weekly Plan'!A34 -> 4 | F25: =IFERROR(D25/E25,0) -> 0 | G25: ='Weekly Plan'!F39 -> PART#4 | J25: =IF(INDEX('Weekly Plan'!$F$2:$M$79,MATCH(G25,'Weekly Plan'!$F$2:$F$79,0),MATCH($C$2,'Weekly Plan'!$F$2:$M$2,0))=0,"",INDEX('Weekly Plan'!$F$2:$M$79,MATCH(G25,'Weekly Plan'!$F$2:$F$79,0),MATCH($C$2,'Weekly Plan'!$F$2:$M$2,0))) | K25: ='Weekly Plan'!A39 -> 0 | L25: =IFERROR(J25/K25,0) -> 0
A28: Notes: | G28: Colour | I28: Time (mins)
A29: **Tesla MX- Rework first, Raw, then 10 rack trial of Conductive Grey Primer | G29: =A5 -> Black - Laval | I29: =SUM(F6:F11) -> 0
G30: =A15 -> Summit White - Laval | I30: =SUM(F16:F19) -> 90
G31: =G5 -> Metelix | I31: =SUM(L6:L13) -> 0
G32: =G15 -> Tesla - High Gloss Black | I32: =SUM(L16:L19) -> 103.33333
G33: Stoney Blue | I33: =SUM(D22:D25) -> 0
G34: =G21 -> Miscellaneous | I34: =SUM(L22:L25) -> 0
G36: Total: | I36: =SUM(I29:I35) -> 193.33333
G38: Gaps | I38: =(COUNTIF(I29:I35, ">0")-1)*(IF(I36>0, 12, 0)) -> 12
G40: Total Time (hrs) | I40: =(I36+I38)/60 -> 3.4222222

Sheet Tue (101)
A1: 101 LINE LOAD SHEET | O1: Unprotect Password 6941
C2: TUESDAY | G2: Date: | I2: ='Weekly Plan'!H1+1 -> 46007
A3: Order of Colours: | C3: 1) Summit White 2) Tesla -Black 4) Laval- Black
A5: Black - Laval | G5: Metelix
A6: ='Weekly Plan'!F4 -> 99944 Bezel | B6: Black | C6: ='Weekly Plan'!G4 -> Bezel | D6: =IF(INDEX('Weekly Plan'!$F$2:$M$79,MATCH(A6,'Weekly Plan'!$F$2:$F$79,0),MATCH($C$2,'Weekly Plan'!$F$2:$M$2,0))=0,"",INDEX('Weekly Plan'!$F$2:$M$79,MATCH(A6,'Weekly Plan'!$F$2:$F$79,0),MATCH($C$2,'Weekly Plan'!$F$2:$M$2,0))) | E6: ='Weekly Plan'!A4 -> 2 | F6: =IFERROR(D6/E6,0) -> 0 | G6: ='Weekly Plan'!F16 -> VG0240BL0PA | I6: ='Weekly Plan'!G16 -> C223 ACCSRY Spoiler | J6: =IF(INDEX('Weekly Plan'!$F$2:$M$79,MATCH(G6,'Weekly Plan'!$F$2:$F$79,0),MATCH($C$2,'Weekly Plan'!$F$2:$M$2,0))=0,"",INDEX('Weekly Plan'!$F$2:$M$79,MATCH(G6,'Weekly Plan'!$F$2:$F$79,0),MATCH($C$2,'Weekly Plan'!$F$2:$M$2,0))) | K6: ='Weekly Plan'!A16 -> 1 | L6: =IFERROR(J6/K6,0) -> 0
A7: ='Weekly Plan'!F5 -> 99633 | B7: Black | C7: ='Weekly Plan'!G5 -> IR Cover LH | D7: =IF(INDEX('Weekly Plan'!$F$2:$M$79,MATCH(A7,'Weekly Plan'!$F$2:$F$79,0),MATCH($C$2,'Weekly Plan'!$F$2:$M$2,0))=0,"",INDEX('Weekly Plan'!$F$2:$M$79,MATCH(A7,'Weekly Plan'!$F$2:$F$79,0),MATCH($C$2,'Weekly Plan'!$F$2:$M$2,0))) | E7: ='Weekly Plan'!A5 -> 20 | F7: =IFERROR(D7/E7,0) -> 0 | G7: ='Weekly Plan'!F17 -> VG0241CM0PB | I7: ='Weekly Plan'!G17 -> Y2XX Stanchion - LH | J7: =IF(INDEX('Weekly Plan'!$F$2:$M$79,MATCH(G7,'Weekly Plan'!$F$2:$F$79,0),MATCH($C$2,'Weekly Plan'!$F$2:$M$2,0))=0,"",INDEX('Weekly Plan'!$F$2:$M$79,MATCH(G7,'Weekly Plan'!$F$2:$F$79,0),MATCH($C$2,'Weekly Plan'!$F$2:$M$2,0))) | K7: ='Weekly Plan'!A17 -> 6 | L7: =IFERROR(J7/K7,0) -> 0
A8: ='Weekly Plan'!F6 -> 99646 | B8: Black | C8: ='Weekly Plan'!G6 -> IR Cover RH | D8: =IF(INDEX('Weekly Plan'!$F$2:$M$79,MATCH(A8,'Weekly Plan'!$F$2:$F$79,0),MATCH($C$2,'Weekly Plan'!$F$2:$M$2,0))=0,"",INDEX('Weekly Plan'!$F$2:$M$79,MATCH(A8,'Weekly Plan'!$F$2:$F$79,0),MATCH($C$2,'Weekly Plan'!$F$2:$M$2,0))) | E8: ='Weekly Plan'!A6 -> 20 | F8: =IFERROR(D8/E8,0) -> 0 | G8: ='Weekly Plan'!F18 -> VG0241CM0PD | I8: ='Weekly Plan'!G18 -> Y2XX Stanchion - RH | J8: =IF(INDEX('Weekly Plan'!$F$2:$M$79,MATCH(G8,'Weekly Plan'!$F$2:$F$79,0),MATCH($C$2,'Weekly Plan'!$F$2:$M$2,0))=0,"",INDEX('Weekly Plan'!$F$2:$M$79,MATCH(G8,'Weekly Plan'!$F$2:$F$79,0),MATCH($C$2,'Weekly Plan'!$F$2:$M$2,0))) | K8: ='Weekly Plan'!A18 -> 6 | L8: =IFERROR(J8/K8,0) -> 0
A9: ='Weekly Plan'!F7 -> 99635 | B9: Black | C9: ='Weekly Plan'!G7 -> Lateral Belt LH | D9: =IF(INDEX('Weekly Plan'!$F$2:$M$79,MATCH(A9,'Weekly Plan'!$F$2:$F$79,0),MATCH($C$2,'Weekly Plan'!$F$2:$M$2,0))=0,"",INDEX('Weekly Plan'!$F$2:$M$79,MATCH(A9,'Weekly Plan'!$F$2:$F$79,0),MATCH($C$2,'Weekly Plan'!$F$2:$M$2,0))) | E9: ='Weekly Plan'!A7 -> 6 | F9: =IFERROR(D9/E9,0) -> 0 | G9: ='Weekly Plan'!F19 -> VG0241CM0PC | I9: ='Weekly Plan'!G19 -> Y2XX Stanchion - Center | J9: =IF(INDEX('Weekly Plan'!$F$2:$M$79,MATCH(G9,'Weekly Plan'!$F$2:$F$79,0),MATCH($C$2,'Weekly Plan'!$F$2:$M$2,0))=0,"",INDEX('Weekly Plan'!$F$2:$M$79,MATCH(G9,'Weekly Plan'!$F$2:$F$79,0),MATCH($C$2,'Weekly Plan'!$F$2:$M$2,0))) | K9: ='Weekly Plan'!A19 -> 6 | L9: =IFERROR(J9/K9,0) -> 0
A10: ='Weekly Plan'!F8 -> 99944 | B10: Black | C10: ='Weekly Plan'!G8 -> Lateral Belt RH | D10: =IF(INDEX('Weekly Plan'!$F$2:$M$79,MATCH(A10,'Weekly Plan'!$F$2:$F$79,0),MATCH($C$2,'Weekly Plan'!$F$2:$M$2,0))=0,"",INDEX('Weekly Plan'!$F$2:$M$79,MATCH(A10,'Weekly Plan'!$F$2:$F$79,0),MATCH($C$2,'Weekly Plan'!$F$2:$M$2,0))) | E10: ='Weekly Plan'!A8 -> 6 | F10: =IFERROR(D10/E10,0) -> 0 | G10: ='Weekly Plan'!F20 -> VG0241CM0PE | I10: ='Weekly Plan'!G20 -> Y2XX Winglet -LH | J10: =IF(INDEX('Weekly Plan'!$F$2:$M$79,MATCH(G10,'Weekly Plan'!$F$2:$F$79,0),MATCH($C$2,'Weekly Plan'!$F$2:$M$2,0))=0,"",INDEX('Weekly Plan'!$F$2:$M$79,MATCH(G10,'Weekly Plan'!$F$2:$F$79,0),MATCH($C$2,'Weekly Plan'!$F$2:$M$2,0))) | K10: ='Weekly Plan'!A20 -> 0 | L10: =IFERROR(J12/K10,0) -> 0
A11: ='Weekly Plan'!F9 -> 99636 | B11: Black | C11: ='Weekly Plan'!G9 -> Rear Belt | D11: =IF(INDEX('Weekly Plan'!$F$2:$M$79,MATCH(A11,'Weekly Plan'!$F$2:$F$79,0),MATCH($C$2,'Weekly Plan'!$F$2:$M$2,0))=0,"",INDEX('Weekly Plan'!$F$2:$M$79,MATCH(A11,'Weekly Plan'!$F$2:$F$79,0),MATCH($C$2,'Weekly Plan'!$F$2:$M$2,0))) | E11: ='Weekly Plan'!A9 -> 20 | F11: =IFERROR(D11/E11,0) -> 0 | G11: ='Weekly Plan'!F21 -> VG0241CM0PF | I11: ='Weekly Plan'!G21 -> Y2XX Winglet -RH | J11: =IF(INDEX('Weekly Plan'!$F$2:$M$79,MATCH(G11,'Weekly Plan'!$F$2:$F$79,0),MATCH($C$2,'Weekly Plan'!$F$2:$M$2,0))=0,"",INDEX('Weekly Plan'!$F$2:$M$79,MATCH(G11,'Weekly Plan'!$F$2:$F$79,0),MATCH($C$2,'Weekly Plan'!$F$2:$M$2,0))) | K11: ='Weekly Plan'!A21 -> 0 | L11: =IFERROR(J13/K11,0) -> 0
G12: ='Weekly Plan'!F22 -> VG0241CM0PG | I12: ='Weekly Plan'!G22 -> Y2XX Screw Cover - LH | J12: =IF(INDEX('Weekly Plan'!$F$2:$M$79,MATCH(G12,'Weekly Plan'!$F$2:$F$79,0),MATCH($C$2,'Weekly Plan'!$F$2:$M$2,0))=0,"",INDEX('Weekly Plan'!$F$2:$M$79,MATCH(G12,'Weekly Plan'!$F$2:$F$79,0),MATCH($C$2,'Weekly Plan'!$F$2:$M$2,0))) | K12: ='Weekly Plan'!A22 -> 20 | L12: =IFERROR(J14/K12,0) -> 0
G13: ='Weekly Plan'!F23 -> VG0241CM0PH | I13: ='Weekly Plan'!G23 -> Y2XX Screw Cover - RH | J13: =IF(INDEX('Weekly Plan'!$F$2:$M$79,MATCH(G13,'Weekly Plan'!$F$2:$F$79,0),MATCH($C$2,'Weekly Plan'!$F$2:$M$2,0))=0,"",INDEX('Weekly Plan'!$F$2:$M$79,MATCH(G13,'Weekly Plan'!$F$2:$F$79,0),MATCH($C$2,'Weekly Plan'!$F$2:$M$2,0))) | K13: ='Weekly Plan'!A23 -> 20 | L13: =IFERROR(J15/K13,0) -> 0
A15: Summit White - Laval | G15: Tesla - High Gloss Black
