Workbook

Sheet Instructions
A1: Packing Slip and Shipping log
B2: Note: | C2: the "Packing List" tab is protected for editing except for the cells
B3: that need to be changed. If any changes need to be done the password is laval
A4: 1. Change the Packing Slip number to the next sequence (+ 1)
A5: 2. Change the date to reflect the date the parts are shipped
A6: 3. Update "Shipper Init:" (if required)
A7: 4. Choose the part numbers shipped from the drop down, or type in
A8: 5. Type the respective quantities and number of skids
A9: 6. Update the total weight
A10: 7. Click the button at the end of each row to update the log
A11: 8. Double check the Shipping Log tab
B12: - make sure all the parts were exported
B13: - in case of dupplication delete the extra row(s) in the log
A14: 9. Save the file as PDF
B16: - in the window that comes up go to the folder in which you want to save the PDF file
A35: Receiving log
A36: Enter all the parts received and their quantities
A37: To enter the part nuber there are 3 options:
B38: - type the part number
B39: - pick from the drop down list
B40: - start typing then pick from the list

Sheet Receiving
C1: RECEIVING | F1: TOTAL | G1: =SUM(G4:G18) -> 0 | H1: =SUM(H4:H18) -> 0 | I1: =SUM(I4:I18) -> 0 | J1: =SUM(J4:J18) -> 0 | K1: =SUM(K4:K18) -> 0 | L1: =SUM(L4:L18) -> 0 | M1: =SUM(M4:M18) -> 0 | N1: =SUM(N4:N18) -> 0 | ... AF1: =SUM(AF4:AF18) -> 0
E3: Inventory | F3: Total received starting 11/11
B4: 99629 | C4: =VLOOKUP(B4,'Parts Legend'!$B:$D,2,FALSE) -> Main Lower Cover | D4: =VLOOKUP(B4,'Parts Legend'!$B:$D,3,FALSE) -> White | E4: =F4-VLOOKUP(B4,Shipping!$I$4:$L$18,4,FALSE) -> 0 | F4: =SUM(G4:CC4) -> 0
B5: 99630 | C5: =VLOOKUP(B5,'Parts Legend'!$B:$D,2,FALSE) -> Vent Cover | D5: =VLOOKUP(B5,'Parts Legend'!$B:$D,3,FALSE) -> White | E5: =F5-VLOOKUP(B5,Shipping!$I$4:$L$18,4,FALSE) -> 0 | F5: =SUM(G5:CC5) -> 0
B6: 99638 | C6: =VLOOKUP(B6,'Parts Legend'!$B:$D,2,FALSE) -> Rear Plate | D6: =VLOOKUP(B6,'Parts Legend'!$B:$D,3,FALSE) -> White | E6: =F6-VLOOKUP(B6,Shipping!$I$4:$L$18,4,FALSE) -> 0 | F6: =SUM(G6:CC6) -> 0
B7: 99632 | C7: =VLOOKUP(B7,'Parts Legend'!$B:$D,2,FALSE) -> Bezel | D7: =VLOOKUP(B7,'Parts Legend'!$B:$D,3,FALSE) -> Black | E7: =F7-VLOOKUP(B7,Shipping!$I$4:$L$18,4,FALSE) -> 0 | F7: =SUM(G7:CC7) -> 0
B8: 99633 | C8: =VLOOKUP(B8,'Parts Legend'!$B:$D,2,FALSE) -> LH IR Cover | D8: =VLOOKUP(B8,'Parts Legend'!$B:$D,3,FALSE) -> Black | E8: =F8-VLOOKUP(B8,Shipping!$I$4:$L$18,4,FALSE) -> 0 | F8: =SUM(G8:CC8) -> 0
B9: 99646 | C9: =VLOOKUP(B9,'Parts Legend'!$B:$D,2,FALSE) -> RH IR Cover | D9: =VLOOKUP(B9,'Parts Legend'!$B:$D,3,FALSE) -> Black | E9: =F9-VLOOKUP(B9,Shipping!$I$4:$L$18,4,FALSE) -> 0 | F9: =SUM(G9:CC9) -> 0
B10: 99635 | C10: =VLOOKUP(B10,'Parts Legend'!$B:$D,2,FALSE) -> LH Lateral Belt | D10: =VLOOKUP(B10,'Parts Legend'!$B:$D,3,FALSE) -> Black | E10: =F10-VLOOKUP(B10,Shipping!$I$4:$L$18,4,FALSE) -> 0 | F10: =SUM(G10:CC10) -> 0
B11: 99944 | C11: =VLOOKUP(B11,'Parts Legend'!$B:$D,2,FALSE) -> RH Lateral Belt | D11: =VLOOKUP(B11,'Parts Legend'!$B:$D,3,FALSE) -> Black | E11: =F11-VLOOKUP(B11,Shipping!$I$4:$L$18,4,FALSE) -> 0 | F11: =SUM(G11:CC11) -> 0
B12: 99636 | C12: =VLOOKUP(B12,'Parts Legend'!$B:$D,2,FALSE) -> Rear Belt | D12: =VLOOKUP(B12,'Parts Legend'!$B:$D,3,FALSE) -> Black | E12: =F12-VLOOKUP(B12,Shipping!$I$4:$L$18,4,FALSE) -> 0 | F12: =SUM(G12:CC12) -> 0
B13: 99631 | C13: =VLOOKUP(B13,'Parts Legend'!$B:$D,2,FALSE) -> Main Upper Cover | D13: =VLOOKUP(B13,'Parts Legend'!$B:$D,3,FALSE) -> White | E13: =F13-VLOOKUP(B13,Shipping!$I$4:$L$18,4,FALSE) -> 0 | F13: =SUM(G13:CC13) -> 0

Sheet Shipping
J1: SHIPPING | L1: TOTAL | M1: =SUM(M4:M19) -> 0 | N1: =SUM(N4:N19) -> 0 | O1: =SUM(O4:O19) -> 0 | P1: =SUM(P4:P19) -> 0 | Q1: =SUM(Q4:Q19) -> 0 | R1: =SUM(R4:R19) -> 0 | S1: =SUM(S4:S19) -> 0 | T1: =SUM(T4:T19) -> 0 | ... DF1: =SUM(DF4:DF19) -> 0
A2: Packing Slip # | B2: Date | C2: Part# | D2: Description | E2: Qty Shipped | F2: Initial | G2: Week of | L2: =SUM(L4:L14) -> 0
A4: LT050 | B4: 45643 | C4: 99646 | D4: RH IR Cover | E4: 20 | F4: KN | G4: =B4-WEEKDAY(B4,3) -> 45642 | I4: 99629 | J4: =VLOOKUP(I4,'Parts Legend'!$B:$D,2,FALSE) -> Main Lower Cover | K4: =VLOOKUP(I4,'Parts Legend'!$B:$D,3,FALSE) -> White | L4: =SUM(M4:DF4) -> 0
A5: LT050 | B5: 45643 | C5: 99630 | D5: Vent Cover | E5: 3 | F5: KN | G5: =B5-WEEKDAY(B5,3) -> 45642 | I5: 99630 | J5: =VLOOKUP(I5,'Parts Legend'!$B:$D,2,FALSE) -> Vent Cover | K5: =VLOOKUP(I5,'Parts Legend'!$B:$D,3,FALSE) -> White | L5: =SUM(M5:DF5) -> 0
A6: LT050 | B6: 45643 | C6: 99632 | D6: Bezel | E6: 13 | F6: KN | G6: =B6-WEEKDAY(B6,3) -> 45642 | I6: 99638 | J6: =VLOOKUP(I6,'Parts Legend'!$B:$D,2,FALSE) -> Rear Plate | K6: =VLOOKUP(I6,'Parts Legend'!$B:$D,3,FALSE) -> White | L6: =SUM(M6:DF6) -> 0
A7: LT050 | B7: 45643 | C7: 99629 | D7: Main Lower Cover | E7: 1 | F7: KN | G7: =B7-WEEKDAY(B7,3) -> 45642 | I7: 99632 | J7: =VLOOKUP(I7,'Parts Legend'!$B:$D,2,FALSE) -> Bezel | K7: =VLOOKUP(I7,'Parts Legend'!$B:$D,3,FALSE) -> Black | L7: =SUM(M7:DF7) -> 0
A8: LT050 | B8: 45643 | C8: 99630 | D8: Vent Cover | E8: 3 | F8: KN | G8: =B8-WEEKDAY(B8,3) -> 45642 | I8: 99633 | J8: =VLOOKUP(I8,'Parts Legend'!$B:$D,2,FALSE) -> LH IR Cover | K8: =VLOOKUP(I8,'Parts Legend'!$B:$D,3,FALSE) -> Black | L8: =SUM(M8:DF8) -> 0
A9: LT050 | B9: 45638 | C9: 99629 | D9: Main Lower Cover | E9: 36 | F9: KN | G9: =B9-WEEKDAY(B9,3) -> 45635 | I9: 99646 | J9: =VLOOKUP(I9,'Parts Legend'!$B:$D,2,FALSE) -> RH IR Cover | K9: =VLOOKUP(I9,'Parts Legend'!$B:$D,3,FALSE) -> Black | L9: =SUM(M9:DF9) -> 0
A10: LT050 | B10: 45643 | C10: 99630 | D10: Vent Cover | E10: 2 | F10: KN | G10: =B10-WEEKDAY(B10,3) -> 45642 | I10: 99635 | J10: =VLOOKUP(I10,'Parts Legend'!$B:$D,2,FALSE) -> LH Lateral Belt | K10: =VLOOKUP(I10,'Parts Legend'!$B:$D,3,FALSE) -> Black | L10: =SUM(M10:DF10) -> 0
A11: LT050 | B11: 45638 | C11: 99630 | D11: Vent Cover | E11: 18 | F11: KN | G11: =B11-WEEKDAY(B11,3) -> 45635 | I11: 99944 | J11: =VLOOKUP(I11,'Parts Legend'!$B:$D,2,FALSE) -> RH Lateral Belt | K11: =VLOOKUP(I11,'Parts Legend'!$B:$D,3,FALSE) -> Black | L11: =SUM(M11:DF11) -> 0
A12: LT050 | B12: 45643 | C12: 99629 | D12: Main Lower Cover | E12: 1 | F12: KN | G12: =B12-WEEKDAY(B12,3) -> 45642 | I12: 99636 | J12: =VLOOKUP(I12,'Parts Legend'!$B:$D,2,FALSE) -> Rear Belt | K12: =VLOOKUP(I12,'Parts Legend'!$B:$D,3,FALSE) -> Black | L12: =SUM(M12:DF12) -> 0
A13: LT050 | B13: 45643 | C13: 99630 | D13: Vent Cover | E13: 2 | F13: KN | G13: =B13-WEEKDAY(B13,3) -> 45642 | I13: 99631 | J13: =VLOOKUP(I13,'Parts Legend'!$B:$D,2,FALSE) -> Main Upper Cover | K13: =VLOOKUP(I13,'Parts Legend'!$B:$D,3,FALSE) -> White | L13: =SUM(M13:DF13) -> 0
A14: LT050 | B14: 45638 | C14: 99629 | D14: Main Lower Cover | E14: 36 | F14: KN | G14: =B14-WEEKDAY(B14,3) -> 45635 | I14: Raw | L14: =SUM(M14:DF14) -> 0
A15: LT050 | B15: 45638 | C15: 99629 | D15: Main Lower Cover | E15: 36 | F15: KN | G15: =B15-WEEKDAY(B15,3) -> 45635
A16: LT050 | B16: 45638 | C16: 99629 | D16: Main Lower Cover | E16: 36 | F16: KN | G16: =B16-WEEKDAY(B16,3) -> 45635
A17: LT050 | B17: 45638 | C17: 99629 | D17: Main Lower Cover | E17: 36 | F17: KN | G17: =B17-WEEKDAY(B17,3) -> 45635
A18: LT050 | B18: 45638 | C18: 99629 | D18: Main Lower Cover | E18: 36 | F18: KN | G18: =B18-WEEKDAY(B18,3) -> 45635 | BK18: average sets white | BL18: =AVERAGE(BL4:BL6,BL13) -> #DIV/0! | BM18: =AVERAGE(BM4:BM6,BM13) -> #DIV/0! | BO18: =AVERAGE(BO4:BO6,BO13) -> #DIV/0! | BP18: =AVERAGE(BP4:BP6,BP13) -> #DIV/0! | BQ18: =AVERAGE(BQ4:BQ6,BQ13) -> #DIV/0!
A19: LT050 | B19: 45638 | C19: 99630 | D19: Vent Cover | E19: 18 | F19: KN | G19: =B19-WEEKDAY(B19,3) -> 45635 | BK19: summit white | BL19: 119 | BM19: 103 | BO19: 81 | BP19: 58 | BQ19: 43
A20: LT050 | B20: 45638 | C20: 99630 | D20: Vent Cover | E20: 18 | F20: KN | G20: =B20-WEEKDAY(B20,3) -> 45635 | BR20: per set
A21: LT050 | B21: 45638 | C21: 99629 | D21: Main Lower Cover | E21: 36 | F21: KN | G21: =B21-WEEKDAY(B21,3) -> 45635 | BR21: sets need to EOP
A22: LT050 | B22: 45638 | C22: 99629 | D22: Main Lower Cover | E22: 36 | F22: KN | G22: =B22-WEEKDAY(B22,3) -> 45635 | BR22: Summit white need
A23: LT050 | B23: 45638 | C23: 99629 | D23: Main Lower Cover | E23: 36 | F23: KN | G23: =B23-WEEKDAY(B23,3) -> 45635 | BR23: on hand
A24: LT050 | B24: 45638 | C24: 99629 | D24: Main Lower Cover | E24: 36 | F24: KN | G24: =B24-WEEKDAY(B24,3) -> 45635 | BR24: on order
A25: LT051 | B25: 45643 | C25: 99629 | D25: Main Lower Cover | E25: 33 | F25: KN | G25: =B25-WEEKDAY(B25,3) -> 45642 | BR25: gallons need to EOP
A26: LT051 | B26: 45643 | C26: 99630 | D26: Vent Cover | E26: 43 | F26: KN | G26: =B26-WEEKDAY(B26,3) -> 45642
A27: LT051 | B27: 45643 | C27: 99632 | D27: Bezel | E27: 48 | F27: KN | G27: =B27-WEEKDAY(B27,3) -> 45642
A28: LT051 | B28: 45643 | C28: 99633 | D28: LH IR Cover | E28: 33 | F28: KN | G28: =B28-WEEKDAY(B28,3) -> 45642 | BK28: average sets white | BO28: =AVERAGE(BO4:BO6,BO13) -> #DIV/0! | BP28: =AVERAGE(BP4:BP6,BP13) -> #DIV/0! | BQ28: =AVERAGE(BQ4:BQ6,BQ13) -> #DIV/0!
A29: LT051 | B29: 45643 | C29: 99646 | D29: RH IR Cover | E29: 49 | F29: KN | G29: =B29-WEEKDAY(B29,3) -> 45642 | BK29: summit white | BO29: 81 | BP29: 58 | BQ29: 43
A30: LT051 | B30: 45643 | C30: 99635 | D30: LH Lateral Belt | E30: 50 | F30: KN | G30: =B30-WEEKDAY(B30,3) -> 45642 | BR30: per set
A31: LT051 | B31: 45643 | C31: 99944 | D31: RH Lateral Belt | E31: 64 | F31: KN | G31: =B31-WEEKDAY(B31,3) -> 45642 | BR31: sets need to EOP
A32: LT051 | B32: 45643 | C32: 99636 | D32: Rear Belt | E32: 70 | F32: KN | G32: =B32-WEEKDAY(B32,3) -> 45642 | BR32: Summit white need
A33: LT052 | B33: 45645 | C33: 99631 | D33: Main Upper Cover | E33: 36 | F33: KN | G33: =B33-WEEKDAY(B33,3) -> 45642 | BR33: on hand
A34: LT053 | B34: 45650 | C34: 99629 | D34: Main Lower Cover | E34: 11 | F34: KN | G34: =B34-WEEKDAY(B34,3) -> 45649 | BR34: on order
A35: LT053 | B35: 45650 | C35: 99631 | D35: Main Upper Cover | E35: 36 | F35: KN | G35: =B35-WEEKDAY(B35,3) -> 45649 | BR35: gallons need to EOP
A36: LT053 | B36: 45650 | C36: 99638 | D36: Rear Plate | E36: 137 | F36: KN | G36: =B36-WEEKDAY(B36,3) -> 45649
A37: LT053 | B37: 45650 | C37: 99632 | D37: Bezel | E37: 100 | F37: KN | G37: =B37-WEEKDAY(B37,3) -> 45649 | BK37: average sets white | BQ37: =AVERAGE(BQ4:BQ6,BQ13) -> #DIV/0!
A38: LT053 | B38: 45650 | C38: 99633 | D38: LH IR Cover | E38: 130 | F38: KN | G38: =B38-WEEKDAY(B38,3) -> 45649 | BK38: summit white | BP38: 43 | BQ38: 23
A39: LT053 | B39: 45650 | C39: 99646 | D39: RH IR Cover | E39: 78 | F39: KN | G39: =B39-WEEKDAY(B39,3) -> 45649 | BR39: per set
A40: LT053 | B40: 45650 | C40: 99636 | D40: Rear Belt | E40: 37 | F40: KN | G40: =B40-WEEKDAY(B40,3) -> 45649 | BR40: sets need to EOP
A41: LT054 | B41: 45664 | C41: 99629 | D41: Main Lower Cover | E41: 66 | F41: KN | G41: =B41-WEEKDAY(B41,3) -> 45663 | BR41: Summit white need
...

Sheet MRP
F10: =CHOOSE(WEEKDAY(F11),"Sun","Mon","Tue","Wed","Thu","Fri","Sat") -> Mon | G10: =CHOOSE(WEEKDAY(G11),"Sun","Mon","Tue","Wed","Thu","Fri","Sat") -> Mon | H10: =CHOOSE(WEEKDAY(H11),"Sun","Mon","Tue","Wed","Thu","Fri","Sat") -> Mon | I10: =CHOOSE(WEEKDAY(I11),"Sun","Mon","Tue","Wed","Thu","Fri","Sat") -> Mon | J10: =CHOOSE(WEEKDAY(J11),"Sun","Mon","Tue","Wed","Thu","Fri","Sat") -> Mon | K10: =CHOOSE(WEEKDAY(K11),"Sun","Mon","Tue","Wed","Thu","Fri","Sat") -> Mon | L10: =CHOOSE(WEEKDAY(L11),"Sun","Mon","Tue","Wed","Thu","Fri","Sat") -> Mon | M10: =CHOOSE(WEEKDAY(M11),"Sun","Mon","Tue","Wed","Thu","Fri","Sat") -> Mon | ... Z10: =CHOOSE(WEEKDAY(Z11),"Sun","Mon","Tue","Wed","Thu","Fri","Sat") -> Mon
A11: FG Part# | B11: RAW Part# | C11: Description | D11: Line Type | F11: 45663 | G11: =F11+7 -> 45670 | H11: =G11+7 -> 45677 | I11: =H11+7 -> 45684 | J11: =I11+7 -> 45691 | K11: =J11+7 -> 45698 | L11: =K11+7 -> 45705 | M11: =L11+7 -> 45712 | N11: =M11+7 -> 45719 | ... AT11: =AS11+7 -> 45943
A12: =B12 -> 99629 | B12: 99629 | C12: Main Lower Cover | D12: demand | F12: =IFERROR(INDEX(Releases!$C$5:$V$21,MATCH($A12,Releases!$C$5:$C$82,0),MATCH(F$11,Releases!$C$5:$V$5,0)),0) -> 0 | G12: =IFERROR(INDEX(Releases!$C$5:$V$21,MATCH($A12,Releases!$C$5:$C$82,0),MATCH(G$11,Releases!$C$5:$V$5,0)),0) -> 0 | H12: =IFERROR(INDEX(Releases!$C$5:$V$21,MATCH($A12,Releases!$C$5:$C$82,0),MATCH(H$11,Releases!$C$5:$V$5,0)),0) -> 0 | I12: =IFERROR(INDEX(Releases!$C$5:$V$21,MATCH($A12,Releases!$C$5:$C$82,0),MATCH(I$11,Releases!$C$5:$V$5,0)),0) -> 0 | J12: =IFERROR(INDEX(Releases!$C$5:$V$21,MATCH($A12,Releases!$C$5:$C$82,0),MATCH(J$11,Releases!$C$5:$V$5,0)),0) -> 0 | K12: =IFERROR(INDEX(Releases!$C$5:$V$21,MATCH($A12,Releases!$C$5:$C$82,0),MATCH(K$11,Releases!$C$5:$V$5,0)),0) -> 0 | L12: =IFERROR(INDEX(Releases!$C$5:$V$21,MATCH($A12,Releases!$C$5:$C$82,0),MATCH(L$11,Releases!$C$5:$V$5,0)),0) -> 0 | M12: =IFERROR(INDEX(Releases!$C$5:$V$21,MATCH($A12,Releases!$C$5:$C$82,0),MATCH(M$11,Releases!$C$5:$V$5,0)),0) -> 0 | ... Z12: =IFERROR(INDEX(Releases!$C$5:$V$21,MATCH($A12,Releases!$C$5:$C$82,0),MATCH(Z$11,Releases!$C$5:$V$5,0)),0) -> 0
A13: =B13 -> 99629 | B13: 99629 | C13: Main Lower Cover | D13: received | F13: {=IFERROR(INDEX(Receiving!#REF!,MATCH($B13&F$11,Receiving!#REF!&Receiving!#REF!,0),MATCH("Qty",Receiving!#REF!,0)),0)} -> 0 | G13: {=IFERROR(INDEX(Receiving!#REF!,MATCH($B13&G$11,Receiving!#REF!&Receiving!#REF!,0),MATCH("Qty",Receiving!#REF!,0)),0)} -> 0 | H13: {=IFERROR(INDEX(Receiving!#REF!,MATCH($B13&H$11,Receiving!#REF!&Receiving!#REF!,0),MATCH("Qty",Receiving!#REF!,0)),0)} -> 0 | I13: {=IFERROR(INDEX(Receiving!#REF!,MATCH($B13&I$11,Receiving!#REF!&Receiving!#REF!,0),MATCH("Qty",Receiving!#REF!,0)),0)} -> 0 | J13: {=IFERROR(INDEX(Receiving!#REF!,MATCH($B13&J$11,Receiving!#REF!&Receiving!#REF!,0),MATCH("Qty",Receiving!#REF!,0)),0)} -> 0 | K13: {=IFERROR(INDEX(Receiving!#REF!,MATCH($B13&K$11,Receiving!#REF!&Receiving!#REF!,0),MATCH("Qty",Receiving!#REF!,0)),0)} -> 0 | L13: {=IFERROR(INDEX(Receiving!#REF!,MATCH($B13&L$11,Receiving!#REF!&Receiving!#REF!,0),MATCH("Qty",Receiving!#REF!,0)),0)} -> 0 | M13: {=IFERROR(INDEX(Receiving!#REF!,MATCH($B13&M$11,Receiving!#REF!&Receiving!#REF!,0),MATCH("Qty",Receiving!#REF!,0)),0)} -> 0 | ... Z13: {=IFERROR(INDEX(Receiving!#REF!,MATCH($B13&Z$11,Receiving!#REF!&Receiving!#REF!,0),MATCH("Qty",Receiving!#REF!,0)),0)} -> 0
A14: =B14 -> 99629 | B14: 99629 | C14: Main Lower Cover | D14: inventory | F14: {=IFERROR(INDEX(Shipping!$A$2:$F$1216,MATCH($A14&F$11,Shipping!$E$2:$E$1216&Shipping!$B$2:$B$1216,0),MATCH("Qty",Shipping!$A$2:$F$2,0)),0)} -> 0 | G14: {=IFERROR(INDEX(Shipping!$A$2:$F$1216,MATCH($A14&G$11,Shipping!$E$2:$E$1216&Shipping!$B$2:$B$1216,0),MATCH("Qty",Shipping!$A$2:$F$2,0)),0)} -> 0 | H14: {=IFERROR(INDEX(Shipping!$A$2:$F$1216,MATCH($A14&H$11,Shipping!$E$2:$E$1216&Shipping!$B$2:$B$1216,0),MATCH("Qty",Shipping!$A$2:$F$2,0)),0)} -> 0 | I14: {=IFERROR(INDEX(Shipping!$A$2:$F$1216,MATCH($A14&I$11,Shipping!$E$2:$E$1216&Shipping!$B$2:$B$1216,0),MATCH("Qty",Shipping!$A$2:$F$2,0)),0)} -> 0 | J14: {=IFERROR(INDEX(Shipping!$A$2:$F$1216,MATCH($A14&J$11,Shipping!$E$2:$E$1216&Shipping!$B$2:$B$1216,0),MATCH("Qty",Shipping!$A$2:$F$2,0)),0)} -> 0 | K14: {=IFERROR(INDEX(Shipping!$A$2:$F$1216,MATCH($A14&K$11,Shipping!$E$2:$E$1216&Shipping!$B$2:$B$1216,0),MATCH("Qty",Shipping!$A$2:$F$2,0)),0)} -> 0 | L14: {=IFERROR(INDEX(Shipping!$A$2:$F$1216,MATCH($A14&L$11,Shipping!$E$2:$E$1216&Shipping!$B$2:$B$1216,0),MATCH("Qty",Shipping!$A$2:$F$2,0)),0)} -> 0 | M14: {=IFERROR(INDEX(Shipping!$A$2:$F$1216,MATCH($A14&M$11,Shipping!$E$2:$E$1216&Shipping!$B$2:$B$1216,0),MATCH("Qty",Shipping!$A$2:$F$2,0)),0)} -> 0 | ... Z14: {=IFERROR(INDEX(Shipping!$A$2:$F$1216,MATCH($A14&Z$11,Shipping!$E$2:$E$1216&Shipping!$B$2:$B$1216,0),MATCH("Qty",Shipping!$A$2:$F$2,0)),0)} -> 0
A15: =B15 -> 99629 | B15: 99629 | C15: Main Lower Cover | D15: shipped | F15: =F13-F14 -> 0 | G15: =G13-G14 -> 0 | H15: =G15-G16+H13 -> 0 | I15: =H15-H16+I13 -> 0 | J15: =I15-I16+J13 -> 0 | K15: =J15-J16+K13 -> 0 | L15: =K15-K16+L13 -> 0 | M15: =L15-L16+M13 -> 0 | N15: =M15-M16+N13 -> 0 | O15: =N15-N16+O13 -> 0 | ... Z15: =Y15-Y16+Z13 -> 0
A16: =B16 -> 99629 | B16: 99629 | C16: Main Lower Cover | D16: left to ship | F16: =F12-F15 -> 0 | G16: =F16+G12-G15 -> 0 | H16: =G16+H12-H15 -> 0 | I16: =H16+I12-I15 -> 0 | J16: =I16+J12-J15 -> 0 | K16: =J16+K12-K15 -> 0 | L16: =K16+L12-L15 -> 0 | M16: =L16+M12-M15 -> 0 | N16: =M16+N12-N15 -> 0 | ... Z16: =Y16+Z12-Z15 -> 0
A17: =B17 -> 99631 | B17: 99631 | C17: Main Upper Cover | D17: demand | F17: =IFERROR(INDEX(Releases!$C$5:$V$21,MATCH($A17,Releases!$C$5:$C$82,0),MATCH(F$11,Releases!$C$5:$V$5,0)),0) -> 0 | G17: =IFERROR(INDEX(Releases!$C$5:$V$21,MATCH($A17,Releases!$C$5:$C$82,0),MATCH(G$11,Releases!$C$5:$V$5,0)),0) -> 0 | H17: =IFERROR(INDEX(Releases!$C$5:$V$21,MATCH($A17,Releases!$C$5:$C$82,0),MATCH(H$11,Releases!$C$5:$V$5,0)),0) -> 0 | I17: =IFERROR(INDEX(Releases!$C$5:$V$21,MATCH($A17,Releases!$C$5:$C$82,0),MATCH(I$11,Releases!$C$5:$V$5,0)),0) -> 0 | J17: =IFERROR(INDEX(Releases!$C$5:$V$21,MATCH($A17,Releases!$C$5:$C$82,0),MATCH(J$11,Releases!$C$5:$V$5,0)),0) -> 0 | K17: =IFERROR(INDEX(Releases!$C$5:$V$21,MATCH($A17,Releases!$C$5:$C$82,0),MATCH(K$11,Releases!$C$5:$V$5,0)),0) -> 0 | L17: =IFERROR(INDEX(Releases!$C$5:$V$21,MATCH($A17,Releases!$C$5:$C$82,0),MATCH(L$11,Releases!$C$5:$V$5,0)),0) -> 0 | M17: =IFERROR(INDEX(Releases!$C$5:$V$21,MATCH($A17,Releases!$C$5:$C$82,0),MATCH(M$11,Releases!$C$5:$V$5,0)),0) -> 0 | ... Z17: =IFERROR(INDEX(Releases!$C$5:$V$21,MATCH($A17,Releases!$C$5:$C$82,0),MATCH(Z$11,Releases!$C$5:$V$5,0)),0) -> 0
A18: =B18 -> 99631 | B18: 99631 | C18: Main Upper Cover | D18: received | F18: {=IFERROR(INDEX(Receiving!#REF!,MATCH($B18&F$11,Receiving!#REF!&Receiving!#REF!,0),MATCH("Qty",Receiving!#REF!,0)),0)} -> 0 | G18: {=IFERROR(INDEX(Receiving!#REF!,MATCH($B18&G$11,Receiving!#REF!&Receiving!#REF!,0),MATCH("Qty",Receiving!#REF!,0)),0)} -> 0 | H18: {=IFERROR(INDEX(Receiving!#REF!,MATCH($B18&H$11,Receiving!#REF!&Receiving!#REF!,0),MATCH("Qty",Receiving!#REF!,0)),0)} -> 0 | I18: {=IFERROR(INDEX(Receiving!#REF!,MATCH($B18&I$11,Receiving!#REF!&Receiving!#REF!,0),MATCH("Qty",Receiving!#REF!,0)),0)} -> 0 | J18: {=IFERROR(INDEX(Receiving!#REF!,MATCH($B18&J$11,Receiving!#REF!&Receiving!#REF!,0),MATCH("Qty",Receiving!#REF!,0)),0)} -> 0 | K18: {=IFERROR(INDEX(Receiving!#REF!,MATCH($B18&K$11,Receiving!#REF!&Receiving!#REF!,0),MATCH("Qty",Receiving!#REF!,0)),0)} -> 0 | L18: {=IFERROR(INDEX(Receiving!#REF!,MATCH($B18&L$11,Receiving!#REF!&Receiving!#REF!,0),MATCH("Qty",Receiving!#REF!,0)),0)} -> 0 | M18: {=IFERROR(INDEX(Receiving!#REF!,MATCH($B18&M$11,Receiving!#REF!&Receiving!#REF!,0),MATCH("Qty",Receiving!#REF!,0)),0)} -> 0 | ... Z18: {=IFERROR(INDEX(Receiving!#REF!,MATCH($B18&Z$11,Receiving!#REF!&Receiving!#REF!,0),MATCH("Qty",Receiving!#REF!,0)),0)} -> 0
A19: =B19 -> 99631 | B19: 99631 | C19: Main Upper Cover | D19: shipped | F19: {=IFERROR(INDEX(Shipping!$A$2:$F$1216,MATCH($A19&F$11,Shipping!$E$2:$E$1216&Shipping!$B$2:$B$1216,0),MATCH("Qty",Shipping!$A$2:$F$2,0)),0)} -> 0 | G19: {=IFERROR(INDEX(Shipping!$A$2:$F$1216,MATCH($A19&G$11,Shipping!$E$2:$E$1216&Shipping!$B$2:$B$1216,0),MATCH("Qty",Shipping!$A$2:$F$2,0)),0)} -> 0 | H19: {=IFERROR(INDEX(Shipping!$A$2:$F$1216,MATCH($A19&H$11,Shipping!$E$2:$E$1216&Shipping!$B$2:$B$1216,0),MATCH("Qty",Shipping!$A$2:$F$2,0)),0)} -> 0 | I19: {=IFERROR(INDEX(Shipping!$A$2:$F$1216,MATCH($A19&I$11,Shipping!$E$2:$E$1216&Shipping!$B$2:$B$1216,0),MATCH("Qty",Shipping!$A$2:$F$2,0)),0)} -> 0 | J19: {=IFERROR(INDEX(Shipping!$A$2:$F$1216,MATCH($A19&J$11,Shipping!$E$2:$E$1216&Shipping!$B$2:$B$1216,0),MATCH("Qty",Shipping!$A$2:$F$2,0)),0)} -> 0 | K19: {=IFERROR(INDEX(Shipping!$A$2:$F$1216,MATCH($A19&K$11,Shipping!$E$2:$E$1216&Shipping!$B$2:$B$1216,0),MATCH("Qty",Shipping!$A$2:$F$2,0)),0)} -> 0 | L19: {=IFERROR(INDEX(Shipping!$A$2:$F$1216,MATCH($A19&L$11,Shipping!$E$2:$E$1216&Shipping!$B$2:$B$1216,0),MATCH("Qty",Shipping!$A$2:$F$2,0)),0)} -> 0 | M19: {=IFERROR(INDEX(Shipping!$A$2:$F$1216,MATCH($A19&M$11,Shipping!$E$2:$E$1216&Shipping!$B$2:$B$1216,0),MATCH("Qty",Shipping!$A$2:$F$2,0)),0)} -> 0 | ... Z19: {=IFERROR(INDEX(Shipping!$A$2:$F$1216,MATCH($A19&Z$11,Shipping!$E$2:$E$1216&Shipping!$B$2:$B$1216,0),MATCH("Qty",Shipping!$A$2:$F$2,0)),0)} -> 0
A20: =B20 -> 99631 | B20: 99631 | C20: Main Upper Cover | D20: inv raw | F20: =F18-F19 -> 0 | G20: =G18-G19 -> 0 | H20: =G20-G21+H18 -> 0 | I20: =H20-H21+I18 -> 0 | J20: =I20-I21+J18 -> 0 | K20: =J20-J21+K18 -> 0 | L20: =K20-K21+L18 -> 0 | M20: =L20-L21+M18 -> 0 | N20: =M20-M21+N18 -> 0 | O20: =N20-N21+O18 -> 0 | ... Z20: =Y20-Y21+Z18 -> 0
A21: =B21 -> 99631 | B21: 99631 | C21: Main Upper Cover | D21: production
A22: =B22 -> 99631 | B22: 99631 | C22: Main Upper Cover | D22: line time | E22: 3 | F22: =$E22*F21 -> 0 | G22: =$E22*G21 -> 0 | I22: =$E22*I21 -> 0 | J22: =$E22*J21 -> 0 | K22: =$E22*K21 -> 0 | L22: =$E22*L21 -> 0 | M22: =$E22*M21 -> 0 | N22: =$E22*N21 -> 0 | O22: =$E22*O21 -> 0 | P22: =$E22*P21 -> 0 | ... Z22: =$E22*Z21 -> 0
A23: =B23 -> 99631 | B23: 99631 | C23: Main Upper Cover | D23: labour time | E23: 3 | F23: =$E23*F21 -> 0 | G23: =$E23*G21 -> 0 | H23: =$E23*H21 -> 0 | I23: =$E23*I21 -> 0 | J23: =$E23*J21 -> 0 | K23: =$E23*K21 -> 0 | L23: =$E23*L21 -> 0 | M23: =$E23*M21 -> 0 | ... Z23: =$E23*Z21 -> 0
A24: =B24 -> 99630 | B24: 99630 | C24: Vent Cover | D24: demand | F24: =IFERROR(INDEX(Releases!$C$5:$V$21,MATCH($A24,Releases!$C$5:$C$82,0),MATCH(F$11,Releases!$C$5:$V$5,0)),0) -> 0 | G24: =IFERROR(INDEX(Releases!$C$5:$V$21,MATCH($A24,Releases!$C$5:$C$82,0),MATCH(G$11,Releases!$C$5:$V$5,0)),0) -> 0 | H24: =IFERROR(INDEX(Releases!$C$5:$V$21,MATCH($A24,Releases!$C$5:$C$82,0),MATCH(H$11,Releases!$C$5:$V$5,0)),0) -> 0 | I24: =IFERROR(INDEX(Releases!$C$5:$V$21,MATCH($A24,Releases!$C$5:$C$82,0),MATCH(I$11,Releases!$C$5:$V$5,0)),0) -> 0 | J24: =IFERROR(INDEX(Releases!$C$5:$V$21,MATCH($A24,Releases!$C$5:$C$82,0),MATCH(J$11,Releases!$C$5:$V$5,0)),0) -> 0 | K24: =IFERROR(INDEX(Releases!$C$5:$V$21,MATCH($A24,Releases!$C$5:$C$82,0),MATCH(K$11,Releases!$C$5:$V$5,0)),0) -> 0 | L24: =IFERROR(INDEX(Releases!$C$5:$V$21,MATCH($A24,Releases!$C$5:$C$82,0),MATCH(L$11,Releases!$C$5:$V$5,0)),0) -> 0 | M24: =IFERROR(INDEX(Releases!$C$5:$V$21,MATCH($A24,Releases!$C$5:$C$82,0),MATCH(M$11,Releases!$C$5:$V$5,0)),0) -> 0 | ... Z24: =IFERROR(INDEX(Releases!$C$5:$V$21,MATCH($A24,Releases!$C$5:$C$82,0),MATCH(Z$11,Releases!$C$5:$V$5,0)),0) -> 0
A25: =B25 -> 99630 | B25: 99630 | C25: Vent Cover | D25: received | F25: {=IFERROR(INDEX(Receiving!#REF!,MATCH($B25&F$11,Receiving!#REF!&Receiving!#REF!,0),MATCH("Qty",Receiving!#REF!,0)),0)} -> 0 | G25: {=IFERROR(INDEX(Receiving!#REF!,MATCH($B25&G$11,Receiving!#REF!&Receiving!#REF!,0),MATCH("Qty",Receiving!#REF!,0)),0)} -> 0 | H25: {=IFERROR(INDEX(Receiving!#REF!,MATCH($B25&H$11,Receiving!#REF!&Receiving!#REF!,0),MATCH("Qty",Receiving!#REF!,0)),0)} -> 0 | I25: {=IFERROR(INDEX(Receiving!#REF!,MATCH($B25&I$11,Receiving!#REF!&Receiving!#REF!,0),MATCH("Qty",Receiving!#REF!,0)),0)} -> 0 | J25: {=IFERROR(INDEX(Receiving!#REF!,MATCH($B25&J$11,Receiving!#REF!&Receiving!#REF!,0),MATCH("Qty",Receiving!#REF!,0)),0)} -> 0 | K25: {=IFERROR(INDEX(Receiving!#REF!,MATCH($B25&K$11,Receiving!#REF!&Receiving!#REF!,0),MATCH("Qty",Receiving!#REF!,0)),0)} -> 0 | L25: {=IFERROR(INDEX(Receiving!#REF!,MATCH($B25&L$11,Receiving!#REF!&Receiving!#REF!,0),MATCH("Qty",Receiving!#REF!,0)),0)} -> 0 | M25: {=IFERROR(INDEX(Receiving!#REF!,MATCH($B25&M$11,Receiving!#REF!&Receiving!#REF!,0),MATCH("Qty",Receiving!#REF!,0)),0)} -> 0 | ... Z25: {=IFERROR(INDEX(Receiving!#REF!,MATCH($B25&Z$11,Receiving!#REF!&Receiving!#REF!,0),MATCH("Qty",Receiving!#REF!,0)),0)} -> 0
A26: =B26 -> 99630 | B26: 99630 | C26: Vent Cover | D26: shipped | F26: {=IFERROR(INDEX(Shipping!$A$2:$F$1216,MATCH($A26&F$11,Shipping!$E$2:$E$1216&Shipping!$B$2:$B$1216,0),MATCH("Qty",Shipping!$A$2:$F$2,0)),0)} -> 0 | G26: {=IFERROR(INDEX(Shipping!$A$2:$F$1216,MATCH($A26&G$11,Shipping!$E$2:$E$1216&Shipping!$B$2:$B$1216,0),MATCH("Qty",Shipping!$A$2:$F$2,0)),0)} -> 0 | H26: {=IFERROR(INDEX(Shipping!$A$2:$F$1216,MATCH($A26&H$11,Shipping!$E$2:$E$1216&Shipping!$B$2:$B$1216,0),MATCH("Qty",Shipping!$A$2:$F$2,0)),0)} -> 0 | I26: {=IFERROR(INDEX(Shipping!$A$2:$F$1216,MATCH($A26&I$11,Shipping!$E$2:$E$1216&Shipping!$B$2:$B$1216,0),MATCH("Qty",Shipping!$A$2:$F$2,0)),0)} -> 0 | J26: {=IFERROR(INDEX(Shipping!$A$2:$F$1216,MATCH($A26&J$11,Shipping!$E$2:$E$1216&Shipping!$B$2:$B$1216,0),MATCH("Qty",Shipping!$A$2:$F$2,0)),0)} -> 0 | K26: {=IFERROR(INDEX(Shipping!$A$2:$F$1216,MATCH($A26&K$11,Shipping!$E$2:$E$1216&Shipping!$B$2:$B$1216,0),MATCH("Qty",Shipping!$A$2:$F$2,0)),0)} -> 0 | L26: {=IFERROR(INDEX(Shipping!$A$2:$F$1216,MATCH($A26&L$11,Shipping!$E$2:$E$1216&Shipping!$B$2:$B$1216,0),MATCH("Qty",Shipping!$A$2:$F$2,0)),0)} -> 0 | M26: {=IFERROR(INDEX(Shipping!$A$2:$F$1216,MATCH($A26&M$11,Shipping!$E$2:$E$1216&Shipping!$B$2:$B$1216,0),MATCH("Qty",Shipping!$A$2:$F$2,0)),0)} -> 0 | ... Z26: {=IFERROR(INDEX(Shipping!$A$2:$F$1216,MATCH($A26&Z$11,Shipping!$E$2:$E$1216&Shipping!$B$2:$B$1216,0),MATCH("Qty",Shipping!$A$2:$F$2,0)),0)} -> 0
A27: =B27 -> 99630 | B27: 99630 | C27: Vent Cover | D27: inv raw | F27: =F25-F26 -> 0 | G27: =G25-G26 -> 0 | H27: =G27-G28+H25 -> 0 | I27: =H27-H28+I25 -> 0 | J27: =I27-I28+J25 -> 0 | K27: =J27-J28+K25 -> 0 | L27: =K27-K28+L25 -> -1 | M27: =L27-L28+M25 -> -1 | N27: =M27-M28+N25 -> -1 | O27: =N27-N28+O25 -> -1 | ... Z27: =Y27-Y28+Z25 -> -1
A28: =B28 -> 99630 | B28: 99630 | C28: Vent Cover | D28: production | K28: 1
A29: =B29 -> 99630 | B29: 99630 | C29: Vent Cover | D29: line time | E29: 2.5 | F29: =$E29*F28 -> 0 | G29: =$E29*G28 -> 0 | H29: =$E29*H28 -> 0 | I29: =$E29*I28 -> 0 | J29: =$E29*J28 -> 0 | K29: =$E29*K28 -> 2.5 | L29: =$E29*L28 -> 0 | M29: =$E29*M28 -> 0 | ... Z29: =$E29*Z28 -> 0
A30: =B30 -> 99630 | B30: 99630 | C30: Vent Cover | D30: labour time | E30: 2.5 | F30: =$E30*F28 -> 0 | G30: =$E30*G28 -> 0 | H30: =$E30*H28 -> 0 | I30: =$E30*I28 -> 0 | J30: =$E30*J28 -> 0 | K30: =$E30*K28 -> 2.5 | L30: =$E30*L28 -> 0 | M30: =$E30*M28 -> 0 | ... Z30: =$E30*Z28 -> 0
A31: =B31 -> 99638 | B31: 99638 | C31: Rear Plate | D31: demand | F31: =IFERROR(INDEX(Releases!$C$5:$V$21,MATCH($A31,Releases!$C$5:$C$82,0),MATCH(F$11,Releases!$C$5:$V$5,0)),0) -> 0 | G31: =IFERROR(INDEX(Releases!$C$5:$V$21,MATCH($A31,Releases!$C$5:$C$82,0),MATCH(G$11,Releases!$C$5:$V$5,0)),0) -> 0 | H31: =IFERROR(INDEX(Releases!$C$5:$V$21,MATCH($A31,Releases!$C$5:$C$82,0),MATCH(H$11,Releases!$C$5:$V$5,0)),0) -> 0 | I31: =IFERROR(INDEX(Releases!$C$5:$V$21,MATCH($A31,Releases!$C$5:$C$82,0),MATCH(I$11,Releases!$C$5:$V$5,0)),0) -> 0 | J31: =IFERROR(INDEX(Releases!$C$5:$V$21,MATCH($A31,Releases!$C$5:$C$82,0),MATCH(J$11,Releases!$C$5:$V$5,0)),0) -> 0 | K31: =IFERROR(INDEX(Releases!$C$5:$V$21,MATCH($A31,Releases!$C$5:$C$82,0),MATCH(K$11,Releases!$C$5:$V$5,0)),0) -> 0 | L31: =IFERROR(INDEX(Releases!$C$5:$V$21,MATCH($A31,Releases!$C$5:$C$82,0),MATCH(L$11,Releases!$C$5:$V$5,0)),0) -> 0 | M31: =IFERROR(INDEX(Releases!$C$5:$V$21,MATCH($A31,Releases!$C$5:$C$82,0),MATCH(M$11,Releases!$C$5:$V$5,0)),0) -> 0 | ... Z31: =IFERROR(INDEX(Releases!$C$5:$V$21,MATCH($A31,Releases!$C$5:$C$82,0),MATCH(Z$11,Releases!$C$5:$V$5,0)),0) -> 0
A32: =B32 -> 99638 | B32: 99638 | C32: Rear Plate | D32: received | F32: {=IFERROR(INDEX(Receiving!#REF!,MATCH($B32&F$11,Receiving!#REF!&Receiving!#REF!,0),MATCH("Qty",Receiving!#REF!,0)),0)} -> 0 | G32: {=IFERROR(INDEX(Receiving!#REF!,MATCH($B32&G$11,Receiving!#REF!&Receiving!#REF!,0),MATCH("Qty",Receiving!#REF!,0)),0)} -> 0 | H32: {=IFERROR(INDEX(Receiving!#REF!,MATCH($B32&H$11,Receiving!#REF!&Receiving!#REF!,0),MATCH("Qty",Receiving!#REF!,0)),0)} -> 0 | I32: {=IFERROR(INDEX(Receiving!#REF!,MATCH($B32&I$11,Receiving!#REF!&Receiving!#REF!,0),MATCH("Qty",Receiving!#REF!,0)),0)} -> 0 | J32: {=IFERROR(INDEX(Receiving!#REF!,MATCH($B32&J$11,Receiving!#REF!&Receiving!#REF!,0),MATCH("Qty",Receiving!#REF!,0)),0)} -> 0 | K32: {=IFERROR(INDEX(Receiving!#REF!,MATCH($B32&K$11,Receiving!#REF!&Receiving!#REF!,0),MATCH("Qty",Receiving!#REF!,0)),0)} -> 0 | L32: {=IFERROR(INDEX(Receiving!#REF!,MATCH($B32&L$11,Receiving!#REF!&Receiving!#REF!,0),MATCH("Qty",Receiving!#REF!,0)),0)} -> 0 | M32: {=IFERROR(INDEX(Receiving!#REF!,MATCH($B32&M$11,Receiving!#REF!&Receiving!#REF!,0),MATCH("Qty",Receiving!#REF!,0)),0)} -> 0 | ... Z32: {=IFERROR(INDEX(Receiving!#REF!,MATCH($B32&Z$11,Receiving!#REF!&Receiving!#REF!,0),MATCH("Qty",Receiving!#REF!,0)),0)} -> 0
A33: =B33 -> 99638 | B33: 99638 | C33: Rear Plate | D33: shipped | F33: {=IFERROR(INDEX(Shipping!$A$2:$F$1216,MATCH($A33&F$11,Shipping!$E$2:$E$1216&Shipping!$B$2:$B$1216,0),MATCH("Qty",Shipping!$A$2:$F$2,0)),0)} -> 0 | G33: {=IFERROR(INDEX(Shipping!$A$2:$F$1216,MATCH($A33&G$11,Shipping!$E$2:$E$1216&Shipping!$B$2:$B$1216,0),MATCH("Qty",Shipping!$A$2:$F$2,0)),0)} -> 0 | H33: {=IFERROR(INDEX(Shipping!$A$2:$F$1216,MATCH($A33&H$11,Shipping!$E$2:$E$1216&Shipping!$B$2:$B$1216,0),MATCH("Qty",Shipping!$A$2:$F$2,0)),0)} -> 0 | I33: {=IFERROR(INDEX(Shipping!$A$2:$F$1216,MATCH($A33&I$11,Shipping!$E$2:$E$1216&Shipping!$B$2:$B$1216,0),MATCH("Qty",Shipping!$A$2:$F$2,0)),0)} -> 0 | J33: {=IFERROR(INDEX(Shipping!$A$2:$F$1216,MATCH($A33&J$11,Shipping!$E$2:$E$1216&Shipping!$B$2:$B$1216,0),MATCH("Qty",Shipping!$A$2:$F$2,0)),0)} -> 0 | K33: {=IFERROR(INDEX(Shipping!$A$2:$F$1216,MATCH($A33&K$11,Shipping!$E$2:$E$1216&Shipping!$B$2:$B$1216,0),MATCH("Qty",Shipping!$A$2:$F$2,0)),0)} -> 0 | L33: {=IFERROR(INDEX(Shipping!$A$2:$F$1216,MATCH($A33&L$11,Shipping!$E$2:$E$1216&Shipping!$B$2:$B$1216,0),MATCH("Qty",Shipping!$A$2:$F$2,0)),0)} -> 0 | M33: {=IFERROR(INDEX(Shipping!$A$2:$F$1216,MATCH($A33&M$11,Shipping!$E$2:$E$1216&Shipping!$B$2:$B$1216,0),MATCH("Qty",Shipping!$A$2:$F$2,0)),0)} -> 0 | ... Z33: {=IFERROR(INDEX(Shipping!$A$2:$F$1216,MATCH($A33&Z$11,Shipping!$E$2:$E$1216&Shipping!$B$2:$B$1216,0),MATCH("Qty",Shipping!$A$2:$F$2,0)),0)} -> 0
A34: =B34 -> 99638 | B34: 99638 | C34: Rear Plate | D34: inv raw | F34: =F32-F33 -> 0 | G34: =G32-G33 -> 0 | H34: =G34-G35+H32 -> 0 | I34: =H34-H35+I32 -> 0 | J34: =I34-I35+J32 -> 0 | K34: =J34-J35+K32 -> 0 | L34: =K34-K35+L32 -> -2 | M34: =L34-L35+M32 -> -2 | N34: =M34-M35+N32 -> -2 | O34: =N34-N35+O32 -> -2 | ... Z34: =Y34-Y35+Z32 -> -2
A35: =B35 -> 99638 | B35: 99638 | C35: Rear Plate | D35: production | K35: 2
A36: =B36 -> 99638 | B36: 99638 | C36: Rear Plate | D36: line time | E36: 0.5 | F36: =$E36*F35 -> 0 | G36: =$E36*G35 -> 0 | H36: =$E36*H35 -> 0 | I36: =$E36*I35 -> 0 | J36: =$E36*J35 -> 0 | K36: =$E36*K35 -> 1 | L36: =$E36*L35 -> 0 | M36: =$E36*M35 -> 0 | ... Z36: =$E36*Z35 -> 0
A37: =B37 -> 99638 | B37: 99638 | C37: Rear Plate | D37: labour time | E37: 0.5 | F37: =$E37*F35 -> 0 | G37: =$E37*G35 -> 0 | H37: =$E37*H35 -> 0 | I37: =$E37*I35 -> 0 | J37: =$E37*J35 -> 0 | K37: =$E37*K35 -> 1 | L37: =$E37*L35 -> 0 | M37: =$E37*M35 -> 0 | ... Z37: =$E37*Z35 -> 0
A38: =B38 -> 99632 | B38: 99632 | C38: Bezel | D38: demand | F38: =IFERROR(INDEX(Releases!$C$5:$V$21,MATCH($A38,Releases!$C$5:$C$82,0),MATCH(F$11,Releases!$C$5:$V$5,0)),0) -> 0 | G38: =IFERROR(INDEX(Releases!$C$5:$V$21,MATCH($A38,Releases!$C$5:$C$82,0),MATCH(G$11,Releases!$C$5:$V$5,0)),0) -> 0 | H38: =IFERROR(INDEX(Releases!$C$5:$V$21,MATCH($A38,Releases!$C$5:$C$82,0),MATCH(H$11,Releases!$C$5:$V$5,0)),0) -> 0 | I38: =IFERROR(INDEX(Releases!$C$5:$V$21,MATCH($A38,Releases!$C$5:$C$82,0),MATCH(I$11,Releases!$C$5:$V$5,0)),0) -> 0 | J38: =IFERROR(INDEX(Releases!$C$5:$V$21,MATCH($A38,Releases!$C$5:$C$82,0),MATCH(J$11,Releases!$C$5:$V$5,0)),0) -> 0 | K38: =IFERROR(INDEX(Releases!$C$5:$V$21,MATCH($A38,Releases!$C$5:$C$82,0),MATCH(K$11,Releases!$C$5:$V$5,0)),0) -> 0 | L38: =IFERROR(INDEX(Releases!$C$5:$V$21,MATCH($A38,Releases!$C$5:$C$82,0),MATCH(L$11,Releases!$C$5:$V$5,0)),0) -> 0 | M38: =IFERROR(INDEX(Releases!$C$5:$V$21,MATCH($A38,Releases!$C$5:$C$82,0),MATCH(M$11,Releases!$C$5:$V$5,0)),0) -> 0 | ... Z38: =IFERROR(INDEX(Releases!$C$5:$V$21,MATCH($A38,Releases!$C$5:$C$82,0),MATCH(Z$11,Releases!$C$5:$V$5,0)),0) -> 0
A39: =B39 -> 99632 | B39: 99632 | C39: Bezel | D39: received | F39: {=IFERROR(INDEX(Receiving!#REF!,MATCH($B39&F$11,Receiving!#REF!&Receiving!#REF!,0),MATCH("Qty",Receiving!#REF!,0)),0)} -> 0 | G39: {=IFERROR(INDEX(Receiving!#REF!,MATCH($B39&G$11,Receiving!#REF!&Receiving!#REF!,0),MATCH("Qty",Receiving!#REF!,0)),0)} -> 0 | H39: {=IFERROR(INDEX(Receiving!#REF!,MATCH($B39&H$11,Receiving!#REF!&Receiving!#REF!,0),MATCH("Qty",Receiving!#REF!,0)),0)} -> 0 | I39: {=IFERROR(INDEX(Receiving!#REF!,MATCH($B39&I$11,Receiving!#REF!&Receiving!#REF!,0),MATCH("Qty",Receiving!#REF!,0)),0)} -> 0 | J39: {=IFERROR(INDEX(Receiving!#REF!,MATCH($B39&J$11,Receiving!#REF!&Receiving!#REF!,0),MATCH("Qty",Receiving!#REF!,0)),0)} -> 0 | K39: {=IFERROR(INDEX(Receiving!#REF!,MATCH($B39&K$11,Receiving!#REF!&Receiving!#REF!,0),MATCH("Qty",Receiving!#REF!,0)),0)} -> 0 | L39: {=IFERROR(INDEX(Receiving!#REF!,MATCH($B39&L$11,Receiving!#REF!&Receiving!#REF!,0),MATCH("Qty",Receiving!#REF!,0)),0)} -> 0 | M39: {=IFERROR(INDEX(Receiving!#REF!,MATCH($B39&M$11,Receiving!#REF!&Receiving!#REF!,0),MATCH("Qty",Receiving!#REF!,0)),0)} -> 0 | ... Z39: {=IFERROR(INDEX(Receiving!#REF!,MATCH($B39&Z$11,Receiving!#REF!&Receiving!#REF!,0),MATCH("Qty",Receiving!#REF!,0)),0)} -> 0
A40: =B40 -> 99632 | B40: 99632 | C40: Bezel | D40: shipped | F40: {=IFERROR(INDEX(Shipping!$A$2:$F$1216,MATCH($A40&F$11,Shipping!$E$2:$E$1216&Shipping!$B$2:$B$1216,0),MATCH("Qty",Shipping!$A$2:$F$2,0)),0)} -> 0 | G40: {=IFERROR(INDEX(Shipping!$A$2:$F$1216,MATCH($A40&G$11,Shipping!$E$2:$E$1216&Shipping!$B$2:$B$1216,0),MATCH("Qty",Shipping!$A$2:$F$2,0)),0)} -> 0 | H40: {=IFERROR(INDEX(Shipping!$A$2:$F$1216,MATCH($A40&H$11,Shipping!$E$2:$E$1216&Shipping!$B$2:$B$1216,0),MATCH("Qty",Shipping!$A$2:$F$2,0)),0)} -> 0 | I40: {=IFERROR(INDEX(Shipping!$A$2:$F$1216,MATCH($A40&I$11,Shipping!$E$2:$E$1216&Shipping!$B$2:$B$1216,0),MATCH("Qty",Shipping!$A$2:$F$2,0)),0)} -> 0 | J40: {=IFERROR(INDEX(Shipping!$A$2:$F$1216,MATCH($A40&J$11,Shipping!$E$2:$E$1216&Shipping!$B$2:$B$1216,0),MATCH("Qty",Shipping!$A$2:$F$2,0)),0)} -> 0 | K40: {=IFERROR(INDEX(Shipping!$A$2:$F$1216,MATCH($A40&K$11,Shipping!$E$2:$E$1216&Shipping!$B$2:$B$1216,0),MATCH("Qty",Shipping!$A$2:$F$2,0)),0)} -> 0 | L40: {=IFERROR(INDEX(Shipping!$A$2:$F$1216,MATCH($A40&L$11,Shipping!$E$2:$E$1216&Shipping!$B$2:$B$1216,0),MATCH("Qty",Shipping!$A$2:$F$2,0)),0)} -> 0 | M40: {=IFERROR(INDEX(Shipping!$A$2:$F$1216,MATCH($A40&M$11,Shipping!$E$2:$E$1216&Shipping!$B$2:$B$1216,0),MATCH("Qty",Shipping!$A$2:$F$2,0)),0)} -> 0 | ... Z40: {=IFERROR(INDEX(Shipping!$A$2:$F$1216,MATCH($A40&Z$11,Shipping!$E$2:$E$1216&Shipping!$B$2:$B$1216,0),MATCH("Qty",Shipping!$A$2:$F$2,0)),0)} -> 0
A41: =B41 -> 99632 | B41: 99632 | C41: Bezel | D41: inv raw | F41: =F39-F40 -> 0 | G41: =G39-G40 -> 0 | H41: =G41-G42+H39 -> 0 | I41: =H41-H42+I39 -> 0 | J41: =I41-I42+J39 -> 0 | K41: =J41-J42+K39 -> 0 | L41: =K41-K42+L39 -> -2 | M41: =L41-L42+M39 -> -2 | N41: =M41-M42+N39 -> -2 | O41: =N41-N42+O39 -> -2 | ... Z41: =Y41-Y42+Z39 -> -2
A42: =B42 -> 99632 | B42: 99632 | C42: Bezel | D42: production | K42: 2
A43: =B43 -> 99632 | B43: 99632 | C43: Bezel | D43: line time | E43: 0.5 | F43: =$E43*F42 -> 0 | G43: =$E43*G42 -> 0 | H43: =$E43*H42 -> 0 | I43: =$E43*I42 -> 0 | J43: =$E43*J42 -> 0 | K43: =$E43*K42 -> 1 | L43: =$E43*L42 -> 0 | M43: =$E43*M42 -> 0 | ... Z43: =$E43*Z42 -> 0
A44: =B44 -> 99632 | B44: 99632 | C44: Bezel | D44: labour time | E44: 0.5 | F44: =$E44*F42 -> 0 | G44: =$E44*G42 -> 0 | H44: =$E44*H42 -> 0 | I44: =$E44*I42 -> 0 | J44: =$E44*J42 -> 0 | K44: =$E44*K42 -> 1 | L44: =$E44*L42 -> 0 | M44: =$E44*M42 -> 0 | ... Z44: =$E44*Z42 -> 0
A45: =B45 -> 99633 | B45: 99633 | C45: LH IR Cover | D45: demand | F45: =IFERROR(INDEX(Releases!$C$5:$V$21,MATCH($A45,Releases!$C$5:$C$82,0),MATCH(F$11,Releases!$C$5:$V$5,0)),0) -> 0 | G45: =IFERROR(INDEX(Releases!$C$5:$V$21,MATCH($A45,Releases!$C$5:$C$82,0),MATCH(G$11,Releases!$C$5:$V$5,0)),0) -> 0 | H45: =IFERROR(INDEX(Releases!$C$5:$V$21,MATCH($A45,Releases!$C$5:$C$82,0),MATCH(H$11,Releases!$C$5:$V$5,0)),0) -> 0 | I45: =IFERROR(INDEX(Releases!$C$5:$V$21,MATCH($A45,Releases!$C$5:$C$82,0),MATCH(I$11,Releases!$C$5:$V$5,0)),0) -> 0 | J45: =IFERROR(INDEX(Releases!$C$5:$V$21,MATCH($A45,Releases!$C$5:$C$82,0),MATCH(J$11,Releases!$C$5:$V$5,0)),0) -> 0 | K45: =IFERROR(INDEX(Releases!$C$5:$V$21,MATCH($A45,Releases!$C$5:$C$82,0),MATCH(K$11,Releases!$C$5:$V$5,0)),0) -> 0 | L45: =IFERROR(INDEX(Releases!$C$5:$V$21,MATCH($A45,Releases!$C$5:$C$82,0),MATCH(L$11,Releases!$C$5:$V$5,0)),0) -> 0 | M45: =IFERROR(INDEX(Releases!$C$5:$V$21,MATCH($A45,Releases!$C$5:$C$82,0),MATCH(M$11,Releases!$C$5:$V$5,0)),0) -> 0 | ... Z45: =IFERROR(INDEX(Releases!$C$5:$V$21,MATCH($A45,Releases!$C$5:$C$82,0),MATCH(Z$11,Releases!$C$5:$V$5,0)),0) -> 0
A46: =B46 -> 99633 | B46: 99633 | C46: LH IR Cover | D46: received | F46: {=IFERROR(INDEX(Receiving!#REF!,MATCH($B46&F$11,Receiving!#REF!&Receiving!#REF!,0),MATCH("Qty",Receiving!#REF!,0)),0)} -> 0 | G46: {=IFERROR(INDEX(Receiving!#REF!,MATCH($B46&G$11,Receiving!#REF!&Receiving!#REF!,0),MATCH("Qty",Receiving!#REF!,0)),0)} -> 0 | H46: {=IFERROR(INDEX(Receiving!#REF!,MATCH($B46&H$11,Receiving!#REF!&Receiving!#REF!,0),MATCH("Qty",Receiving!#REF!,0)),0)} -> 0 | I46: {=IFERROR(INDEX(Receiving!#REF!,MATCH($B46&I$11,Receiving!#REF!&Receiving!#REF!,0),MATCH("Qty",Receiving!#REF!,0)),0)} -> 0 | J46: {=IFERROR(INDEX(Receiving!#REF!,MATCH($B46&J$11,Receiving!#REF!&Receiving!#REF!,0),MATCH("Qty",Receiving!#REF!,0)),0)} -> 0 | K46: {=IFERROR(INDEX(Receiving!#REF!,MATCH($B46&K$11,Receiving!#REF!&Receiving!#REF!,0),MATCH("Qty",Receiving!#REF!,0)),0)} -> 0 | L46: {=IFERROR(INDEX(Receiving!#REF!,MATCH($B46&L$11,Receiving!#REF!&Receiving!#REF!,0),MATCH("Qty",Receiving!#REF!,0)),0)} -> 0 | M46: {=IFERROR(INDEX(Receiving!#REF!,MATCH($B46&M$11,Receiving!#REF!&Receiving!#REF!,0),MATCH("Qty",Receiving!#REF!,0)),0)} -> 0 | ... Z46: {=IFERROR(INDEX(Receiving!#REF!,MATCH($B46&Z$11,Receiving!#REF!&Receiving!#REF!,0),MATCH("Qty",Receiving!#REF!,0)),0)} -> 0
A47: =B47 -> 99633 | B47: 99633 | C47: LH IR Cover | D47: shipped | F47: {=IFERROR(INDEX(Shipping!$A$2:$F$1216,MATCH($A47&F$11,Shipping!$E$2:$E$1216&Shipping!$B$2:$B$1216,0),MATCH("Qty",Shipping!$A$2:$F$2,0)),0)} -> 0 | G47: {=IFERROR(INDEX(Shipping!$A$2:$F$1216,MATCH($A47&G$11,Shipping!$E$2:$E$1216&Shipping!$B$2:$B$1216,0),MATCH("Qty",Shipping!$A$2:$F$2,0)),0)} -> 0 | H47: {=IFERROR(INDEX(Shipping!$A$2:$F$1216,MATCH($A47&H$11,Shipping!$E$2:$E$1216&Shipping!$B$2:$B$1216,0),MATCH("Qty",Shipping!$A$2:$F$2,0)),0)} -> 0 | I47: {=IFERROR(INDEX(Shipping!$A$2:$F$1216,MATCH($A47&I$11,Shipping!$E$2:$E$1216&Shipping!$B$2:$B$1216,0),MATCH("Qty",Shipping!$A$2:$F$2,0)),0)} -> 0 | J47: {=IFERROR(INDEX(Shipping!$A$2:$F$1216,MATCH($A47&J$11,Shipping!$E$2:$E$1216&Shipping!$B$2:$B$1216,0),MATCH("Qty",Shipping!$A$2:$F$2,0)),0)} -> 0 | K47: {=IFERROR(INDEX(Shipping!$A$2:$F$1216,MATCH($A47&K$11,Shipping!$E$2:$E$1216&Shipping!$B$2:$B$1216,0),MATCH("Qty",Shipping!$A$2:$F$2,0)),0)} -> 0 | L47: {=IFERROR(INDEX(Shipping!$A$2:$F$1216,MATCH($A47&L$11,Shipping!$E$2:$E$1216&Shipping!$B$2:$B$1216,0),MATCH("Qty",Shipping!$A$2:$F$2,0)),0)} -> 0 | M47: {=IFERROR(INDEX(Shipping!$A$2:$F$1216,MATCH($A47&M$11,Shipping!$E$2:$E$1216&Shipping!$B$2:$B$1216,0),MATCH("Qty",Shipping!$A$2:$F$2,0)),0)} -> 0 | ... Z47: {=IFERROR(INDEX(Shipping!$A$2:$F$1216,MATCH($A47&Z$11,Shipping!$E$2:$E$1216&Shipping!$B$2:$B$1216,0),MATCH("Qty",Shipping!$A$2:$F$2,0)),0)} -> 0
A48: =B48 -> 99633 | B48: 99633 | C48: LH IR Cover | D48: inv raw | F48: =F46-F47 -> 0 | G48: =G46-G47 -> 0 | H48: =G48-G49+H46 -> 0 | I48: =H48-H49+I46 -> 0 | J48: =I48-I49+J46 -> 0 | K48: =J48-J49+K46 -> 0 | L48: =K48-K49+L46 -> -2 | M48: =L48-L49+M46 -> -2 | N48: =M48-M49+N46 -> -2 | O48: =N48-N49+O46 -> -4 | ... Z48: =Y48-Y49+Z46 -> -12
A49: =B49 -> 99633 | B49: 99633 | C49: LH IR Cover | D49: production | K49: 2 | N49: 2 | O49: 2 | P49: 2 | Q49: 2 | R49: 2
...

Sheet Releases
C1: Instructions:
C2: "Select All" (CTRL-A) in the file sent by Multimatic
C6: Material | D6: Material Description
C7: 99629 | D7: Main Lower Cover | E7: White
C8: 99630 | D8: Vent Cover | E8: White
C9: 99638 | D9: Rear Plate | E9: White
C10: 99632 | D10: Bezel | E10: Black
C11: 99633 | D11: LH IR Cover | E11: Black
C12: 99646 | D12: RH IR Cover | E12: Black
C13: 99635 | D13: LH Lateral Belt | E13: Black
C14: 99944 | D14: RH Lateral Belt | E14: Black
C15: 99636 | D15: Rear Belt | E15: Black
C16: 99631 | D16: Main Upper Cover | E16: White

Sheet Parts Legend
A2: FG Part# | B2: RAW Part# | C2: Description | D2: Color | E2: PO#
A3: 99629 | B3: 99629 | C3: Main Lower Cover | D3: White | E3: PO# P067875
A4: 99631 | B4: 99631 | C4: Main Upper Cover | D4: White | E4: PO# P067875
A5: 99630 | B5: 99630 | C5: Vent Cover | D5: White | E5: PO# P067875
A6: 99638 | B6: 99638 | C6: Rear Plate | D6: White | E6: PO# P067875
A7: 99632 | B7: 99632 | C7: Bezel | D7: Black | E7: PO# P067875
A8: 99633 | B8: 99633 | C8: LH IR Cover | D8: Black | E8: PO# P067875
A9: 99646 | B9: 99646 | C9: RH IR Cover | D9: Black | E9: PO# P067875
A10: 99635 | B10: 99635 | C10: LH Lateral Belt | D10: Black | E10: PO# P067875
A11: 99944 | B11: 99944 | C11: RH Lateral Belt | D11: Black | E11: PO# P067875
A12: 99636 | B12: 99636 | C12: Rear Belt | D12: Black | E12: PO# P067875
A13: EMPTY BOX | B13: EMPTY BOX | C13: EMPTY BOX

Sheet Shipping total
B2: =B4-WEEKDAY(B4,3) -> 45635 | C2: =C4-WEEKDAY(C4,3) -> 45642 | D2: =D4-WEEKDAY(D4,3) -> 45642 | E2: =E4-WEEKDAY(E4,3) -> 45649 | F2: =F4-WEEKDAY(F4,3) -> 45663 | G2: =G4-WEEKDAY(G4,3) -> 45670 | H2: =H4-WEEKDAY(H4,3) -> 45677 | I2: =I4-WEEKDAY(I4,3) -> 45684 | ... AE2: =AE4-WEEKDAY(AE4,3) -> 45810
A3: Sum of Qty Shipped | B3: Column Labels
A4: Row Labels | B4: 45638 | C4: 45643 | D4: 45645 | E4: 45650 | F4: 45664 | G4: 45671 | H4: 45678 | I4: 45685 | J4: 45692 | K4: 45699 | L4: 45708 | M4: 45713 | N4: 45706 | O4: 45720 | P4: 45727 | Q4: 45734 | R4: 45735 | S4: 45741 | T4: 45748 | U4: 45755 | V4: 45762 | W4: 45769 | X4: 45404 | Y4: 45776 | Z4: 45783 | AA4: 45790 | AB4: 45797 | AC4: 45804 | AD4: 45811 | AE4: 45813 | AF4: 45817 | AG4: 45818 | AH4: (blank) | AI4: Grand Total
A5: 99629 | B5: 360 | C5: 35 | E5: 11 | F5: 66 | G5: 66 | H5: 11 | J5: 21 | L5: 110 | M5: 132 | N5: 11 | O5: 66 | P5: 44 | Q5: 33 | S5: 66 | T5: 33 | U5: 77 | V5: 66 | W5: 66 | Y5: 66 | Z5: 66 | AA5: 66 | AB5: 33 | AC5: 55 | AD5: 11 | AE5: 33 | AI5: 1604
A6: 99630 | B6: 54 | C6: 53 | F6: 100 | G6: 60 | H6: 38 | I6: 31 | K6: 72 | M6: 110 | O6: 41 | R6: 40 | S6: 80 | T6: 102 | U6: 60 | V6: 61 | X6: 20 | Y6: 60 | Z6: 80 | AA6: 35 | AC6: 40 | AD6: 20 | AE6: 40 | AI6: 1197
A7: 99631 | D7: 36 | E7: 36 | F7: 72 | G7: 54 | H7: 62 | I7: 46 | J7: 48 | K7: 60 | M7: 108 | N7: 54 | O7: 72 | P7: 35 | Q7: 36 | S7: 36 | T7: 36 | U7: 54 | V7: 67 | X7: 68 | Z7: 32 | AA7: 72 | AB7: 54 | AC7: 36 | AE7: 35 | AI7: 1209
A8: 99632 | C8: 61 | E8: 100 | F8: 65 | G8: 26 | H8: 43 | I8: 75 | J8: 65 | K8: 9 | L8: 84 | M8: 78 | N8: 26 | O8: 25 | P8: 41 | R8: 36 | S8: 66 | T8: 66 | U8: 66 | V8: 66 | X8: 51 | Z8: 66 | AA8: 66 | AB8: 132 | AC8: 44 | AD8: 17 | AE8: 66 | AI8: 1440
A9: 99633 | C9: 33 | E9: 130 | F9: 102 | G9: 43 | H9: 17 | I9: 54 | K9: 9 | M9: 188 | N9: 25 | O9: 136 | P9: 20 | R9: 50 | U9: 72 | V9: 66 | X9: 66 | Y9: 63 | AE9: 71 | AI9: 1145
A10: 99635 | C10: 50 | F10: 100 | G10: 24 | H10: 32 | I10: 66 | J10: 46 | M10: 164 | N10: 88 | O10: 50 | P10: 32 | T10: 106 | U10: 72 | V10: 60 | X10: 66 | Y10: 44 | AD10: 22 | AE10: 38 | AI10: 1060
A11: 99636 | C11: 70 | E11: 37 | F11: 84 | G11: 48 | H11: 60 | I11: 77 | J11: 36 | M11: 80 | N11: 38 | O11: 79 | P11: 35 | R11: 39 | U11: 115 | V11: 66 | X11: 50 | Y11: 26 | AE11: 66 | AI11: 1006
A12: 99638 | E12: 137 | F12: 62 | G12: 49 | H12: 51 | J12: 33 | K12: 88 | M12: 68 | N12: 31 | O12: 26 | P12: 35 | R12: 24 | S12: 13 | U12: 80 | V12: 50 | X12: 20 | Y12: 36 | AC12: 84 | AI12: 887
A13: 99646 | C13: 69 | E13: 78 | F13: 116 | G13: 54 | H13: 18 | I13: 44 | K13: 18 | M13: 206 | N13: 21 | O13: 108 | P13: 26 | R13: 45 | U13: 73 | V13: 66 | X13: 66 | Y13: 47 | AE13: 79 | AI13: 1134
A14: 99944 | C14: 64 | F14: 105 | G14: 29 | H14: 38 | I14: 44 | J14: 48 | M14: 172 | N14: 82 | O14: 58 | P14: 42 | T14: 96 | U14: 76 | V14: 66 | X14: 66 | Y14: 36 | AD14: 24 | AE14: 36 | AI14: 1082
A15: (blank) | AF15: -960 | AG15: 490 | AI15: -470
A16: Grand Total | B16: 414 | C16: 435 | D16: 36 | E16: 529 | F16: 872 | G16: 453 | H16: 370 | I16: 437 | J16: 297 | K16: 256 | L16: 194 | M16: 1306 | N16: 376 | O16: 661 | P16: 310 | Q16: 69 | R16: 234 | S16: 261 | T16: 439 | U16: 745 | V16: 634 | W16: 66 | X16: 473 | Y16: 378 | Z16: 244 | AA16: 239 | AB16: 219 | AC16: 259 | AD16: 94 | AE16: 464 | AF16: -960 | AG16: 490 | AI16: 11294
