Workbook

Sheet Monday
F2: 102 Line Paint Schedule
O4: Part | P4: Length | Q4: Colour
L5: Summary | O5: Empties | P5: BMW | Q5: Agate Black
A6: Notes | C6: Notes | D6: Part | E6: Length | G6: # of Parts | H6: # of Racks | I6: Time (Mins) | J6: # of Racks | L6: Total Hours with Colour Change: | M6: =(SUM(I7:I43)/60) -> 0 | O6: LH w/Holes | P6: Empties | Q6: Black II
A7: {=IFERROR(IF(SEARCH("LU",D7:D43,1),"JOMI Wash Prep",""),"")} | B7: =A7 | I7: =H7*5 -> 0 | L7: Total hours without Colour Change: | M7: =(SUM(I7:I40)/60) -> 0 | O7: Long | P7: Small | Q7: Dark Matter Gray
B8: =A8 | C8: =IF(B8=B7,"",B8) | I8: =H8*5 -> 0 | L8: Total Racks: | M8: =SUM(H7:H40) -> 0 | O8: RH w/Holes | Q8: Empties
B9: =A9 | C9: =IF(B9=B8,"",B9) | I9: =H9*5 -> 0 | L9: Total Parts: | M9: =SUM(G7:G40) -> 0 | O9: Short | Q9: Flight Blue
B10: =A10 | C10: =IF(B10=B9,"",B10) | I10: =H10*5 -> 0 | O10: U22X | Q10: Iconic Silver
B11: =A11 | C11: =IF(B11=B10,"",B11) | I11: =H11*5 -> 0 | Q11: Infinite Blue
B12: =A12 | I12: =H12*5 -> 0 | M12: 46 | Q12: Jewel Red
B13: =A13 | I13: =H13*5 -> 0 | Q13: LG Carbonized Gray
B14: =A14 | I14: =H14*5 -> 0 | Q14: Primer
B15: =A15 | I15: =H15*5 -> 0 | Q15: Star White
B16: =A16 | I16: =H16*5 -> 0 | Q16: Stone Gray
B17: =A17 | C17: =IF(B17=B16,"",B17) | I17: =H17*5 -> 0 | Q17: Trial
B18: =A18 | C18: =IF(B18=B17,"",B18) | I18: =H18*5 -> 0 | Q18: Scrap Rack
B19: =A19 | C19: =IF(B19=B18,"",B19) | I19: =H19*5 -> 0
B20: =A20 | C20: =IF(B20=B19,"",B20) | I20: =H20*5 -> 0
B21: =A21 | C21: =IF(B21=B20,"",B21) | I21: =H21*5 -> 0
B22: =A22 | C22: =IF(B22=B21,"",B22) | I22: =H22*5 -> 0
B23: =A23 | C23: =IF(B23=B22,"",B23) | I23: =H23*5 -> 0
B24: =A24 | C24: =IF(B24=B23,"",B24) | I24: =H24*5 -> 0
B25: =A25 | C25: =IF(B25=B24,"",B25) | I25: =H25*5 -> 0
B26: =A26 | C26: =IF(B26=B25,"",B26) | I26: =H26*5 -> 0
B27: =A27 | C27: =IF(B27=B26,"",B27) | I27: =H27*5 -> 0
B28: =A28 | C28: =IF(B28=B27,"",B28) | I28: =H28*5 -> 0
B29: =A29 | C29: =IF(B29=B28,"",B29) | I29: =H29*5 -> 0
B30: =A30 | C30: =IF(B30=B29,"",B30) | I30: =H30*5 -> 0
... B39: =A39 | C39: =IF(B39=B38,"",B39) | I39: =H39*5 -> 0
B40: =A40 | C40: =IF(B40=B39,"",B40) | G40: Number of | I40: =IFERROR(INDEX(MasterTimeRef!G2:AE17,MATCH(Monday!D40,MasterTimeRef!F2:F17,0),MATCH(Monday!F40,MasterTimeRef!G1:AF1,0))*H40,"")
B41: =A41 | C41: =IF(B41=B40,"",B41) | G41: Colour Changes | I41: =IFERROR(INDEX(MasterTimeRef!G2:AE17,MATCH(Monday!D41,MasterTimeRef!F2:F17,0),MATCH(Monday!F41,MasterTimeRef!G1:AF1,0))*H41,"")
B42: =A42 | C42: =IF(B42=B41,"",B42) | H42: =G42*15 -> 0 | I42: =H42 -> 0
B43: =A43 | C43: =IF(B43=B42,"",B43)

Sheet Tuesday
F2: 102 Line Paint Schedule
O4: Part | P4: Length | Q4: Colour
L5: Summary | O5: Empties | P5: BMW | Q5: Agate Black
A6: Notes | C6: Notes | D6: Part | E6: Length | G6: # of Parts | H6: # of Racks | I6: Time (Mins) | J6: # of Racks | L6: Total Hours with Colour Change: | M6: =(SUM(I7:I43)/60) -> 0 | O6: LH w/Holes | P6: Empties | Q6: Black II
A7: {=IFERROR(IF(SEARCH("LU",D7:D43,1),"JOMI Wash Prep",""),"")} | B7: =A7 | I7: =H7*5 -> 0 | L7: Total hours without Colour Change: | M7: =(SUM(I7:I40)/60) -> 0 | O7: Long | P7: Small | Q7: Dark Matter Gray
B8: =A8 | C8: =IF(B8=B7,"",B8) | I8: =H8*5 -> 0 | L8: Total Racks: | M8: =SUM(H7:H40) -> 0 | O8: RH w/Holes | Q8: Empties
B9: =A9 | C9: =IF(B9=B8,"",B9) | I9: =H9*5 -> 0 | L9: Total Parts: | M9: =SUM(G7:G40) -> 0 | O9: Short | Q9: Flight Blue
B10: =A10 | C10: =IF(B10=B9,"",B10) | I10: =H10*5 -> 0 | O10: U22X | Q10: Iconic Silver
B11: =A11 | C11: =IF(B11=B10,"",B11) | I11: =H11*5 -> 0 | Q11: Infinite Blue
B12: =A12 | I12: =H12*5 -> 0 | M12: 46 | Q12: Jewel Red
B13: =A13 | I13: =H13*5 -> 0 | Q13: LG Carbonized Gray
B14: =A14 | I14: =H14*5 -> 0 | Q14: Primer
B15: =A15 | I15: =H15*5 -> 0 | Q15: Star White
B16: =A16 | I16: =H16*5 -> 0 | Q16: Stone Gray
B17: =A17 | C17: =IF(B17=B16,"",B17) | I17: =H17*5 -> 0 | Q17: Trial
B18: =A18 | C18: =IF(B18=B17,"",B18) | I18: =H18*5 -> 0 | Q18: Scrap Rack
B19: =A19 | C19: =IF(B19=B18,"",B19) | I19: =H19*5 -> 0
B20: =A20 | C20: =IF(B20=B19,"",B20) | I20: =H20*5 -> 0
B21: =A21 | C21: =IF(B21=B20,"",B21) | I21: =H21*5 -> 0
B22: =A22 | C22: =IF(B22=B21,"",B22) | I22: =H22*5 -> 0
B23: =A23 | C23: =IF(B23=B22,"",B23) | I23: =H23*5 -> 0
B24: =A24 | C24: =IF(B24=B23,"",B24) | I24: =H24*5 -> 0
B25: =A25 | C25: =IF(B25=B24,"",B25) | I25: =H25*5 -> 0
B26: =A26 | C26: =IF(B26=B25,"",B26) | I26: =H26*5 -> 0
B27: =A27 | C27: =IF(B27=B26,"",B27) | I27: =H27*5 -> 0
B28: =A28 | C28: =IF(B28=B27,"",B28) | I28: =H28*5 -> 0
B29: =A29 | C29: =IF(B29=B28,"",B29) | I29: =H29*5 -> 0
B30: =A30 | C30: =IF(B30=B29,"",B30) | I30: =H30*5 -> 0
... B39: =A39 | C39: =IF(B39=B38,"",B39) | I39: =H39*5 -> 0
B40: =A40 | C40: =IF(B40=B39,"",B40) | G40: Number of | I40: =IFERROR(INDEX(MasterTimeRef!G2:AE17,MATCH(Monday!D40,MasterTimeRef!F2:F17,0),MATCH(Monday!F40,MasterTimeRef!G1:AF1,0))*H40,"")
B41: =A41 | C41: =IF(B41=B40,"",B41) | G41: Colour Changes | I41: =IFERROR(INDEX(MasterTimeRef!G2:AE17,MATCH(Monday!D41,MasterTimeRef!F2:F17,0),MATCH(Monday!F41,MasterTimeRef!G1:AF1,0))*H41,"")
B42: =A42 | C42: =IF(B42=B41,"",B42) | H42: =G42*15 -> 0 | I42: =H42 -> 0
B43: =A43 | C43: =IF(B43=B42,"",B43)

Sheet Wednesday
F2: 102 Line Paint Schedule
O4: Part | P4: Length | Q4: Colour
L5: Summary | O5: Empties | P5: BMW | Q5: Agate Black
A6: Notes | C6: Notes | D6: Part | E6: Length | G6: # of Parts | H6: # of Racks | I6: Time (Mins) | J6: # of Racks | L6: Total Hours with Colour Change: | M6: =(SUM(I7:I43)/60) -> 0 | O6: LH w/Holes | P6: Empties | Q6: Black II
A7: {=IFERROR(IF(SEARCH("LU",D7:D43,1),"JOMI Wash Prep",""),"")} | B7: =A7 | I7: =H7*5 -> 0 | L7: Total hours without Colour Change: | M7: =(SUM(I7:I40)/60) -> 0 | O7: Long | P7: Small | Q7: Dark Matter Gray
B8: =A8 | C8: =IF(B8=B7,"",B8) | I8: =H8*5 -> 0 | L8: Total Racks: | M8: =SUM(H7:H40) -> 0 | O8: RH w/Holes | Q8: Empties
B9: =A9 | C9: =IF(B9=B8,"",B9) | I9: =H9*5 -> 0 | L9: Total Parts: | M9: =SUM(G7:G40) -> 0 | O9: Short | Q9: Flight Blue
B10: =A10 | C10: =IF(B10=B9,"",B10) | I10: =H10*5 -> 0 | O10: U22X | Q10: Iconic Silver
B11: =A11 | C11: =IF(B11=B10,"",B11) | I11: =H11*5 -> 0 | Q11: Infinite Blue
B12: =A12 | I12: =H12*5 -> 0 | M12: 46 | Q12: Jewel Red
B13: =A13 | I13: =H13*5 -> 0 | Q13: LG Carbonized Gray
B14: =A14 | I14: =H14*5 -> 0 | Q14: Primer
B15: =A15 | I15: =H15*5 -> 0 | Q15: Star White
B16: =A16 | I16: =H16*5 -> 0 | Q16: Stone Gray
B17: =A17 | C17: =IF(B17=B16,"",B17) | I17: =H17*5 -> 0 | Q17: Trial
B18: =A18 | C18: =IF(B18=B17,"",B18) | I18: =H18*5 -> 0 | Q18: Scrap Rack
B19: =A19 | C19: =IF(B19=B18,"",B19) | I19: =H19*5 -> 0
B20: =A20 | C20: =IF(B20=B19,"",B20) | I20: =H20*5 -> 0
B21: =A21 | C21: =IF(B21=B20,"",B21) | I21: =H21*5 -> 0
B22: =A22 | C22: =IF(B22=B21,"",B22) | I22: =H22*5 -> 0
B23: =A23 | C23: =IF(B23=B22,"",B23) | I23: =H23*5 -> 0
B24: =A24 | C24: =IF(B24=B23,"",B24) | I24: =H24*5 -> 0
B25: =A25 | C25: =IF(B25=B24,"",B25) | I25: =H25*5 -> 0
B26: =A26 | C26: =IF(B26=B25,"",B26) | I26: =H26*5 -> 0
B27: =A27 | C27: =IF(B27=B26,"",B27) | I27: =H27*5 -> 0
B28: =A28 | C28: =IF(B28=B27,"",B28) | I28: =H28*5 -> 0
B29: =A29 | C29: =IF(B29=B28,"",B29) | I29: =H29*5 -> 0
B30: =A30 | C30: =IF(B30=B29,"",B30) | I30: =H30*5 -> 0
... B39: =A39 | C39: =IF(B39=B38,"",B39) | I39: =H39*5 -> 0
B40: =A40 | C40: =IF(B40=B39,"",B40) | G40: Number of | I40: =IFERROR(INDEX(MasterTimeRef!G2:AE17,MATCH(Monday!D40,MasterTimeRef!F2:F17,0),MATCH(Monday!F40,MasterTimeRef!G1:AF1,0))*H40,"")
B41: =A41 | C41: =IF(B41=B40,"",B41) | G41: Colour Changes | I41: =IFERROR(INDEX(MasterTimeRef!G2:AE17,MATCH(Monday!D41,MasterTimeRef!F2:F17,0),MATCH(Monday!F41,MasterTimeRef!G1:AF1,0))*H41,"")
B42: =A42 | C42: =IF(B42=B41,"",B42) | H42: =G42*15 -> 0 | I42: =H42 -> 0
B43: =A43 | C43: =IF(B43=B42,"",B43)

Sheet Thursday
F2: 102 Line Paint Schedule
O4: Part | P4: Length | Q4: Colour
L5: Summary | O5: Empties | P5: BMW | Q5: Agate Black
A6: Notes | C6: Notes | D6: Part | E6: Length | G6: # of Parts | H6: # of Racks | I6: Time (Mins) | J6: # of Racks | L6: Total Hours with Colour Change: | M6: =(SUM(I7:I43)/60) -> 0 | O6: LH w/Holes | P6: Empties | Q6: Black II
A7: {=IFERROR(IF(SEARCH("LU",D7:D43,1),"JOMI Wash Prep",""),"")} | B7: =A7 | I7: =H7*5 -> 0 | L7: Total hours without Colour Change: | M7: =(SUM(I7:I40)/60) -> 0 | O7: Long | P7: Small | Q7: Dark Matter Gray
B8: =A8 | C8: =IF(B8=B7,"",B8) | I8: =H8*5 -> 0 | L8: Total Racks: | M8: =SUM(H7:H40) -> 0 | O8: RH w/Holes | Q8: Empties
B9: =A9 | C9: =IF(B9=B8,"",B9) | I9: =H9*5 -> 0 | L9: Total Parts: | M9: =SUM(G7:G40) -> 0 | O9: Short | Q9: Flight Blue
B10: =A10 | C10: =IF(B10=B9,"",B10) | I10: =H10*5 -> 0 | O10: U22X | Q10: Iconic Silver
B11: =A11 | C11: =IF(B11=B10,"",B11) | I11: =H11*5 -> 0 | Q11: Infinite Blue
B12: =A12 | I12: =H12*5 -> 0 | M12: 46 | Q12: Jewel Red
B13: =A13 | I13: =H13*5 -> 0 | Q13: LG Carbonized Gray
B14: =A14 | I14: =H14*5 -> 0 | Q14: Primer
B15: =A15 | I15: =H15*5 -> 0 | Q15: Star White
B16: =A16 | I16: =H16*5 -> 0 | Q16: Stone Gray
B17: =A17 | C17: =IF(B17=B16,"",B17) | I17: =H17*5 -> 0 | Q17: Trial
B18: =A18 | C18: =IF(B18=B17,"",B18) | I18: =H18*5 -> 0 | Q18: Scrap Rack
B19: =A19 | C19: =IF(B19=B18,"",B19) | I19: =H19*5 -> 0
B20: =A20 | C20: =IF(B20=B19,"",B20) | I20: =H20*5 -> 0
B21: =A21 | C21: =IF(B21=B20,"",B21) | I21: =H21*5 -> 0
B22: =A22 | C22: =IF(B22=B21,"",B22) | I22: =H22*5 -> 0
B23: =A23 | C23: =IF(B23=B22,"",B23) | I23: =H23*5 -> 0
B24: =A24 | C24: =IF(B24=B23,"",B24) | I24: =H24*5 -> 0
B25: =A25 | C25: =IF(B25=B24,"",B25) | I25: =H25*5 -> 0
B26: =A26 | C26: =IF(B26=B25,"",B26) | I26: =H26*5 -> 0
B27: =A27 | C27: =IF(B27=B26,"",B27) | I27: =H27*5 -> 0
B28: =A28 | C28: =IF(B28=B27,"",B28) | I28: =H28*5 -> 0
B29: =A29 | C29: =IF(B29=B28,"",B29) | I29: =H29*5 -> 0
B30: =A30 | C30: =IF(B30=B29,"",B30) | I30: =H30*5 -> 0
... B39: =A39 | C39: =IF(B39=B38,"",B39) | I39: =H39*5 -> 0
B40: =A40 | C40: =IF(B40=B39,"",B40) | G40: Number of | I40: =IFERROR(INDEX(MasterTimeRef!G2:AE17,MATCH(Monday!D40,MasterTimeRef!F2:F17,0),MATCH(Monday!F40,MasterTimeRef!G1:AF1,0))*H40,"")
B41: =A41 | C41: =IF(B41=B40,"",B41) | G41: Colour Changes | I41: =IFERROR(INDEX(MasterTimeRef!G2:AE17,MATCH(Monday!D41,MasterTimeRef!F2:F17,0),MATCH(Monday!F41,MasterTimeRef!G1:AF1,0))*H41,"")
B42: =A42 | C42: =IF(B42=B41,"",B42) | H42: =G42*15 -> 0 | I42: =H42 -> 0
B43: =A43 | C43: =IF(B43=B42,"",B43)

Sheet Friday
F2: 102 Line Paint Schedule
O4: Part | P4: Length | Q4: Colour
L5: Summary | O5: Empties | P5: BMW | Q5: Agate Black
A6: Notes | C6: Notes | D6: Part | E6: Length | G6: # of Parts | H6: # of Racks | I6: Time (Mins) | J6: # of Racks | L6: Total Hours with Colour Change: | M6: =(SUM(I7:I43)/60) -> 0 | O6: LH w/Holes | P6: Empties | Q6: Black II
A7: {=IFERROR(IF(SEARCH("LU",D7:D43,1),"JOMI Wash Prep",""),"")} | B7: =A7 | I7: =H7*5 -> 0 | L7: Total hours without Colour Change: | M7: =(SUM(I7:I40)/60) -> 0 | O7: Long | P7: Small | Q7: Dark Matter Gray
B8: =A8 | C8: =IF(B8=B7,"",B8) | I8: =H8*5 -> 0 | L8: Total Racks: | M8: =SUM(H7:H40) -> 0 | O8: RH w/Holes | Q8: Empties
B9: =A9 | C9: =IF(B9=B8,"",B9) | I9: =H9*5 -> 0 | L9: Total Parts: | M9: =SUM(G7:G40) -> 0 | O9: Short | Q9: Flight Blue
B10: =A10 | C10: =IF(B10=B9,"",B10) | I10: =H10*5 -> 0 | O10: U22X | Q10: Iconic Silver
B11: =A11 | C11: =IF(B11=B10,"",B11) | I11: =H11*5 -> 0 | Q11: Infinite Blue
B12: =A12 | I12: =H12*5 -> 0 | M12: 46 | Q12: Jewel Red
B13: =A13 | I13: =H13*5 -> 0 | Q13: LG Carbonized Gray
B14: =A14 | I14: =H14*5 -> 0 | Q14: Primer
B15: =A15 | I15: =H15*5 -> 0 | Q15: Star White
B16: =A16 | I16: =H16*5 -> 0 | Q16: Stone Gray
B17: =A17 | C17: =IF(B17=B16,"",B17) | I17: =H17*5 -> 0 | Q17: Trial
B18: =A18 | C18: =IF(B18=B17,"",B18) | I18: =H18*5 -> 0 | Q18: Scrap Rack
B19: =A19 | C19: =IF(B19=B18,"",B19) | I19: =H19*5 -> 0
B20: =A20 | C20: =IF(B20=B19,"",B20) | I20: =H20*5 -> 0
B21: =A21 | C21: =IF(B21=B20,"",B21) | I21: =H21*5 -> 0
B22: =A22 | C22: =IF(B22=B21,"",B22) | I22: =H22*5 -> 0
B23: =A23 | C23: =IF(B23=B22,"",B23) | I23: =H23*5 -> 0
B24: =A24 | C24: =IF(B24=B23,"",B24) | I24: =H24*5 -> 0
B25: =A25 | C25: =IF(B25=B24,"",B25) | I25: =H25*5 -> 0
B26: =A26 | C26: =IF(B26=B25,"",B26) | I26: =H26*5 -> 0
B27: =A27 | C27: =IF(B27=B26,"",B27) | I27: =H27*5 -> 0
B28: =A28 | C28: =IF(B28=B27,"",B28) | I28: =H28*5 -> 0
B29: =A29 | C29: =IF(B29=B28,"",B29) | I29: =H29*5 -> 0
B30: =A30 | C30: =IF(B30=B29,"",B30) | I30: =H30*5 -> 0
... B39: =A39 | C39: =IF(B39=B38,"",B39) | I39: =H39*5 -> 0
B40: =A40 | C40: =IF(B40=B39,"",B40) | G40: Number of | I40: =IFERROR(INDEX(MasterTimeRef!G2:AE17,MATCH(Monday!D40,MasterTimeRef!F2:F17,0),MATCH(Monday!F40,MasterTimeRef!G1:AF1,0))*H40,"")
B41: =A41 | C41: =IF(B41=B40,"",B41) | G41: Colour Changes | I41: =IFERROR(INDEX(MasterTimeRef!G2:AE17,MATCH(Monday!D41,MasterTimeRef!F2:F17,0),MATCH(Monday!F41,MasterTimeRef!G1:AF1,0))*H41,"")
B42: =A42 | C42: =IF(B42=B41,"",B42) | H42: =G42*15 -> 0 | I42: =H42 -> 0
B43: =A43 | C43: =IF(B43=B42,"",B43)

Sheet Saturday
F2: 102 Line Paint Schedule
F4: =Friday!F4+1 -> 1 | O4: Part | P4: Length | Q4: Colour
L5: Summary | O5: Empties | P5: BMW | Q5: Agate Black
A6: Notes | C6: Notes | D6: Part | E6: Length | F6: Colour | G6: # of Parts | H6: # of Racks | I6: Time (Mins) | J6: # of Racks | L6: Total Hours with Colour Change: | M6: =(SUM(I7:I43)/60) -> 0 | O6: LH w/Holes | P6: Empties | Q6: Black II
A7: {=IFERROR(IF(SEARCH("LU",D7:D43,1),"JOMI Wash Prep",""),"")} | B7: =A7 | I7: =H7*5 -> 0 | L7: Total hours without Colour Change: | M7: =(SUM(I7:I40)/60) -> 0 | O7: Long | P7: Small | Q7: Dark Matter Gray
B8: =A8 | C8: =IF(B8=B7,"",B8) | I8: =H8*5 -> 0 | L8: Total Racks: | M8: =SUM(H7:H40) -> 0 | O8: RH w/Holes | Q8: Empties
B9: =A9 | C9: =IF(B9=B8,"",B9) | I9: =H9*5 -> 0 | L9: Total Parts: | M9: =SUM(G7:G40) -> 0 | O9: Short | Q9: Flight Blue
B10: =A10 | C10: =IF(B10=B9,"",B10) | I10: =H10*5 -> 0 | O10: U22X | Q10: Iconic Silver
B11: =A11 | C11: =IF(B11=B10,"",B11) | I11: =H11*5 -> 0 | Q11: Infinite Blue
B12: =A12 | C12: =IF(B12=B11,"",B12) | I12: =H12*5 -> 0 | Q12: Jewel Red
B13: =A13 | C13: =IF(B13=B12,"",B13) | I13: =H13*5 -> 0 | Q13: LG Carbonized Gray
B14: =A14 | C14: =IF(B14=B13,"",B14) | I14: =H14*5 -> 0 | Q14: Primer
B15: =A15 | C15: =IF(B15=B14,"",B15) | I15: =H15*5 -> 0 | Q15: Star White
B16: =A16 | C16: =IF(B16=B15,"",B16) | I16: =H16*5 -> 0 | Q16: Stone Gray
B17: =A17 | C17: =IF(B17=B16,"",B17) | I17: =H17*5 -> 0 | Q17: Trial
B18: =A18 | C18: =IF(B18=B17,"",B18) | I18: =H18*5 -> 0
B19: =A19 | C19: =IF(B19=B18,"",B19) | I19: =H19*5 -> 0
B20: =A20 | C20: =IF(B20=B19,"",B20) | I20: =H20*5 -> 0
B21: =A21 | C21: =IF(B21=B20,"",B21) | I21: =H21*5 -> 0
B22: =A22 | C22: =IF(B22=B21,"",B22) | I22: =H22*5 -> 0
B23: =A23 | C23: =IF(B23=B22,"",B23) | I23: =H23*5 -> 0
B24: =A24 | C24: =IF(B24=B23,"",B24) | I24: =H24*5 -> 0
B25: =A25 | C25: =IF(B25=B24,"",B25) | I25: =H25*5 -> 0
B26: =A26 | C26: =IF(B26=B25,"",B26) | I26: =H26*5 -> 0
B27: =A27 | C27: =IF(B27=B26,"",B27) | I27: =H27*5 -> 0
B28: =A28 | C28: =IF(B28=B27,"",B28) | I28: =H28*5 -> 0
B29: =A29 | C29: =IF(B29=B28,"",B29) | I29: =H29*5 -> 0
... B39: =A39 | C39: =IF(B39=B38,"",B39) | I39: =H39*5 -> 0
B40: =A40 | C40: =IF(B40=B39,"",B40) | G40: Number of | I40: =IFERROR(INDEX(MasterTimeRef!G2:AE17,MATCH(Monday!D40,MasterTimeRef!F2:F17,0),MATCH(Monday!F40,MasterTimeRef!G1:AF1,0))*H40,"")
B41: =A41 | C41: =IF(B41=B40,"",B41) | G41: Colour Changes | I41: =IFERROR(INDEX(MasterTimeRef!G2:AE17,MATCH(Monday!D41,MasterTimeRef!F2:F17,0),MATCH(Monday!F41,MasterTimeRef!G1:AF1,0))*H41,"")
B42: =A42 | C42: =IF(B42=B41,"",B42) | H42: =G42*15 -> 0 | I42: =H42 -> 0
B43: =A43 | C43: =IF(B43=B42,"",B43)

Sheet ScheduleMasterRef
A1: Part | B1: Length | C1: Colour
A2: Long | B2: Small | C2: Black II
A3: Short | B3: BMW | C3: Star White
A4: LH w/Holes | B4: LH Cantrial | C4: Stone Gray
A5: RH w/Holes | B5: RH Cantrial | C5: Black
A6: LU-01 | B6: Roof Bow | C6: Empties
A7: LU-02 | B7: Hood Trim | C7: LG Magnetic
A8: LU-03 | B8: Decklid | C8: Prime
A9: LU-04 | B9: LH
A10: LU-05 | B10: RH
A11: LU-06
A12: LU-07
A13: LU-08
A14: LU-09
A15: LU-10
A16: Empties

Sheet MasterTimeRef
F1: Part | G1: Prime | H1: MidGloss | I1: High Gloss Clear | J1: Black | K1: Black II | L1: Prime/Base | M1: Prime/Base/Clear | N1: Base/Clear | O1: Star White | P1: Empties | Q1: Trial | R1: Stone Gray | S1: High Gloss | T1: Stone Gray | U1: Agate Black | V1: Burgundy Velvet | W1: Red Hot | X1: Kodiak Brown | Y1: Anti Matter Blue | Z1: Dark Matter Gray | AA1: Forged Green | AB1: LG Carbonized Gray | AC1: Infinite Blue | AD1: LG Magnetic | AE1: Flight Blue
F2: LU-01 | G2: 4 | H2: 4 | I2: 4 | L2: 4 | M2: 4 | N2: 4 | Q2: 4
F3: LU-02 | G3: 4 | H3: 4 | I3: 4 | L3: 4 | M3: 4 | N3: 4 | Q3: 4
F4: LU-03 | G4: 1.3 | J4: 4 | L4: 4 | M4: 4 | N4: 4 | Q4: 4
F5: LU-04 | G5: 1.3 | J5: 4 | L5: 4 | M5: 4 | N5: 4 | Q5: 4
F6: LU-05 | G6: 1.3 | J6: 4 | L6: 4 | M6: 4 | N6: 4 | Q6: 4
F7: LU-06 | G7: 1.3 | J7: 4 | L7: 4 | M7: 4 | N7: 4 | Q7: 4
F8: LU-07 | G8: 1.3 | J8: 4 | L8: 4 | M8: 4 | N8: 4 | Q8: 4
F9: LU-08 | G9: 1.3 | J9: 4 | L9: 4 | M9: 4 | N9: 4 | Q9: 4
F10: LU-09 | G10: 1.3 | J10: 4 | L10: 4 | M10: 4 | N10: 4 | Q10: 4
F11: LU-10 | G11: 1.3 | J11: 4 | L11: 4 | M11: 4 | N11: 4 | Q11: 4
F12: ACS Spoilers | G12: 4 | L12: 4 | M12: 4 | Q12: 4
F13: Long | G13: 4 | O13: 7 | Q13: 4 | R13: 4 | S13: 4 | T13: 4 | U13: 4 | V13: 4 | W13: 4 | X13: 4 | Y13: 4 | Z13: 4 | AA13: 4 | AB13: 4 | AC13: 4 | AD13: 4 | AE13: 4
F14: Short | G14: 4 | O14: 7 | Q14: 4 | R14: 4 | S14: 4 | T14: 4 | U14: 4 | V14: 4 | W14: 4 | X14: 4 | Y14: 4 | Z14: 4 | AA14: 4 | AB14: 4 | AC14: 4 | AD14: 4 | AE14: 4
F15: Empties | P15: 4 | Q15: 4
F16: LH w/Holes | K16: 4 | Q16: 4
F17: RH w/Holes | K17: 4 | Q17: 4

Sheet MasterJobRef
A1: JOB Ref
A2: Part | B2: Prime | C2: MidGloss | D2: Black | E2: Black II | F2: Prime/Base | G2: Prime/Base/Clear | H2: Base/Clear | I2: Star White | J2: Empties | K2: LG Magnetic | L2: Trial | M2: High Gloss Clear | N2: Red Hot | O2: Primer | P2: High Gloss Part trial | Q2: Stone Gray
A3: LU-01 | B3: 901/902 | C3: 901/902 | G3: 901/902 | L3: - | M3: 901/902 | P3: 901/902
A4: LU-02 | B4: 903 | C4: 903 | G4: 903 | L4: - | M4: 903 | P4: 903
A5: LU-03 | B5: 146 | D5: 161 | G5: 161 | H5: 156 | L5: -
A6: LU-04 | B6: 146 | D6: 160 | G6: 160 | H6: 156 | L6: -
A7: LU-05 | B7: 105 | D7: 205 | G7: 205 | H7: 205 | L7: -
A8: LU-06 | B8: 106 | D8: 206 | G8: 206 | H8: 206 | L8: -
A9: LU-07 | B9: 107 | D9: 207 | G9: 207 | H9: 207 | L9: -
A10: LU-08 | B10: 108 | D10: 208 | G10: 208 | H10: 208 | L10: -
A11: LU-09 | B11: 109 | D11: 209 | G11: 209 | H11: 209 | L11: -
A12: LU-10 | B12: 110 | D12: 210 | G12: 210 | H12: 210 | L12: -
A13: ACS Spoilers | B13: - | F13: - | G13: - | L13: -
A14: Long | B14: 33 | I14: 55 | K14: 33 (2K) | L14: - | N14: 33 | O14: 33 (2K) | Q14: 33
A15: Short | B15: 3 | I15: 5 | K15: 3 (2K) | L15: - | N15: 3 | O15: 3 (2K) | Q15: 3
A16: Harley | B16: 33 (2K)
A17: U22X | B17: 33 (2K)
A18: Empties | J18: 95 | L18: -
A19: LH w/Holes | E19: 36 | L19: -
A20: RH w/Holes | E20: 35 | L20: -
L21: -
L22: -
L23: -
L24: -
A30: Base JOB | B30: Base Colour | C30: Base Presets | D30: General Base Cup Shot | E30: Target Base Cup Shot | F30: Clear Job | G30: Clear Colour | I30: Clear Presets | J30: General Clear Cup Shot | K30: Target Clear Cup Shot
A31: 901/902 | B31: 4 | C31: 1/2 | D31: 20-40ml | E31: 25-28ml | F31: 901/902 | G31: 1 | I31: 1/2 | J31: 30-50ml | K31: 138-148cc/min
A32: 101 | B32: 4 | C32: 2 | D32: 20-40ml | E32: 25-32ml | F32: 102 | G32: 1 | I32: 2 | J32: 30-50ml | K32: 155-165cc/min
A33: 903 | B33: 4 | C33: 1/2 | D33: 20-40ml | E33: 25-28ml | F33: 903 | G33: 1 | I33: 1/2 | J33: 40-60ml | K33: 150-160cc/min
A34: 146 | B34: 4 | C34: 1 | D34: 20-40ml | E34: 25-32ml | F34: 95 | G34: 1 | I34: - | J34: - | K34: -
A35: 146 | B35: 4 | C35: 1 | D35: 20-40ml | E35: 25-32ml | F35: 95 | G35: 1 | I35: - | J35: - | K35: -
A36: 105 | B36: 4 | C36: 1 | D36: 20-40ml | E36: 25-32ml | F36: 95 | G36: 1 | I36: - | J36: - | K36: -
A37: 106 | B37: 4 | C37: 1 | D37: 20-40ml | E37: 25-32ml | F37: 95 | G37: 1 | I37: - | J37: - | K37: -
A38: 107 | B38: 4 | C38: 1 | D38: 20-40ml | E38: 25-32ml | F38: 95 | G38: 1 | I38: - | J38: - | K38: -
A39: 108 | B39: 4 | C39: 1 | D39: 20-40ml | E39: 25-32ml | F39: 95 | G39: 1 | I39: - | J39: - | K39: -
A40: 109 | B40: 4 | C40: 1 | D40: 20-40ml | E40: 25-32ml | F40: 95 | G40: 1 | I40: - | J40: - | K40: -
A41: 110 | B41: 4 | C41: 1 | D41: 20-40ml | E41: 25-32ml | F41: 95 | G41: 1 | I41: - | J41: - | K41: -
A42: 156 | B42: 1 | C42: 1 | D42: 20-40ml | E42: 20-30ml | F42: 304 | G42: 1 | I42: 1 | J42: 90-120cc/min | K42: 95-105cc/min
A43: 161 | B43: 1 | C43: 1/2 | D43: 30-45ml | E43: 28-35ml | F43: 306 | G43: 1 | I43: 1/2 | J43: 95-110cc/min | K43: 100-110cc/min
A44: 160 | B44: 1 | C44: 1/2 | D44: 30-45ml | E44: 28-35ml | F44: 306 | G44: 1 | I44: 1/2 | J44: 95-110cc/min | K44: 100-110cc/min
A45: 205 | B45: 1 | C45: 1/2 | D45: 30-45ml | E45: 30-35ml | F45: 205 | G45: 1 | I45: 1/2 | J45: 30-50ml | K45: 115-125cc/min
...
