Workbook

Sheet Weekly Plan
G1: 103 | H1: 45299 | I1: =H1+1 -> 45300 | J1: =I1+1 -> 45301 | K1: =J1+1 -> 45302 | L1: =K1+1 -> 45303 | M1: =L1+1 -> 45304
B2: 4.5ft | C2: 5.5ft | D2: 5.75 | E2: pcs/rack | F2: Part Num | G2: Part | H2: Mon | I2: Tue | J2: Wed | K2: Thur | L2: Friday | M2: Sat
A3: 4 | F3: Hyper Silver (Spyder)
A4: =(E4*4)/$A$3 -> 2 | E4: 2 | F4: 705014100 | G4: LH Upper Fairing
A5: =(E5*4)/$A$3 -> 2 | E5: 2 | F5: 705014101 | G5: RH Upper Fairing
A6: =(E6*4)/$A$3 -> 2 | E6: 2 | F6: 705012976 | G6: LH Fender
A7: =(E7*4)/$A$3 -> 2 | E7: 2 | F7: 705012868 | G7: RH Fender
A8: =(E8*4)/$A$3 -> 2 | E8: 2 | F8: 708003041 | G8: Rear Fairing
A9: =(E9*4)/$A$3 -> 1 | E9: 1 | F9: 708200870 | G9: LH Front Fairing
A10: =(E10*4)/$A$3 -> 1 | E10: 1 | F10: 708200871 | G10: RH Front Fairing
A11: =(E11*4)/$A$3 -> 1 | E11: 1 | F11: 708200869 | G11: R66 Hood
A12: =(E12*4)/$A$3 -> 2 | E12: 2 | F12: 708302947 | G12: LH Box Cover
A13: =(E13*4)/$A$3 -> 2 | E13: 2 | F13: 708302948 | G13: RH Box Cover
A14: =(E14*4)/$A$3 -> 4 | E14: 4 | F14: 708303800 | G14: LH F3T Panel
A15: =(E15*4)/$A$3 -> 4 | E15: 4 | F15: 708303801 | G15: RH F3T Panel
... A17: =(E17*4)/$A$3 -> 2 | E17: 2 | F17: 708400463 | G17: RH Mirror Shell - No Hole
A18: =(E18*4)/$A$3 -> 0 | E18: 0 | F18: British Green (Spyder) | P18: Weekly Timing
A19: =(E19*4)/$A$3 -> 2 | E19: 2 | F19: 705009213 | G19: LH F3T Low Fairing | Q19: Monday | R19: Tuesday | T19: Wednesday | V19: Thursday | X19: Friday | Z19: Saturday
A20: =(E20*4)/$A$3 -> 2 | E20: 2 | F20: 705009214 | G20: RH F3T Low Fairing | P20: ='Mon (103)'!M35 -> Colour | Q20: ='Mon (103)'!N35 -> Time (mins) | R20: ='Tue (103)'!N35 -> Time (mins) | T20: ='Wed (103)'!N35 -> Time (mins) | V20: ='Thur (103)'!N35 -> Time (mins) | X20: ='Fri (103)'!N35 -> Time (mins) | Z20: ='Sat (103)'!N35 -> Time (mins)
A21: =(E21*4)/$A$3 -> 1 | E21: 1 | F21: 705010835 | G21: RH Fairing | P21: ='Mon (103)'!M36 -> Hyper Silver | Q21: ='Mon (103)'!N36 -> 0 | R21: ='Tue (103)'!N36 -> 0 | T21: ='Wed (103)'!N36 -> 0 | V21: ='Thur (103)'!N36 -> 0 | X21: ='Fri (103)'!N36 -> 0 | Z21: ='Sat (103)'!N36 -> 0
A22: =(E22*4)/$A$3 -> 1 | E22: 1 | F22: 705010851 | G22: LH Fairing | P22: ='Mon (103)'!M37 -> Deep Black | Q22: ='Mon (103)'!N37 -> 0 | R22: ='Tue (103)'!N37 -> 0 | T22: ='Wed (103)'!N37 -> 0 | V22: ='Thur (103)'!N37 -> 0 | X22: ='Fri (103)'!N37 -> 0 | Z22: ='Sat (103)'!N37 -> 0
A23: =(E23*4)/$A$3 -> 2 | E23: 2 | F23: 705012976 | G23: LH Fender | P23: ='Mon (103)'!M38 -> British Green | Q23: ='Mon (103)'!N38 -> 0 | R23: ='Tue (103)'!N38 -> 0 | T23: ='Wed (103)'!N38 -> 0 | V23: ='Thur (103)'!N38 -> 0 | X23: ='Fri (103)'!N38 -> 0 | Z23: ='Sat (103)'!N38 -> 0
A24: =(E24*4)/$A$3 -> 2 | E24: 2 | F24: 705012868 | G24: RH Fender | P24: ='Mon (103)'!M39 -> Vegas White | Q24: ='Mon (103)'!N39 -> 0 | R24: ='Tue (103)'!N39 -> 0 | T24: ='Wed (103)'!N39 -> 0 | V24: ='Thur (103)'!N39 -> 0 | X24: ='Fri (103)'!N39 -> 0 | Z24: ='Sat (103)'!N39 -> 0
A25: =(E25*4)/$A$3 -> 1 | E25: 1 | F25: 708200366 | G25: Hood | P25: ='Mon (103)'!M40 -> Black - Laval | Q25: ='Mon (103)'!N40 -> 0 | R25: ='Tue (103)'!N40 -> 0 | T25: ='Wed (103)'!N40 -> 0 | V25: ='Thur (103)'!N40 -> 0 | X25: ='Fri (103)'!N40 -> 0 | Z25: ='Sat (103)'!N40 -> 0
A26: =(E26*4)/$A$3 -> 2 | E26: 2 | F26: 708200401 | G26: LH Vent Panel | P26: ='Mon (103)'!M41 -> Summit White - Laval | Q26: ='Mon (103)'!N41 -> 0 | R26: ='Tue (103)'!N41 -> 0 | T26: ='Wed (103)'!N41 -> 0 | V26: ='Thur (103)'!N41 -> 0 | X26: ='Fri (103)'!N41 -> 0 | Z26: ='Sat (103)'!N41 -> 0
A27: =(E27*4)/$A$3 -> 2 | E27: 2 | F27: 708200402 | G27: RH Vent Panel | P27: ='Mon (103)'!M42 -> Mitchell Plastics | Q27: ='Mon (103)'!N42 -> 0 | R27: ='Tue (103)'!N42 -> 0 | T27: ='Wed (103)'!N42 -> 0 | V27: ='Thur (103)'!N42 -> 0 | X27: ='Fri (103)'!N42 -> 0 | Z27: ='Sat (103)'!N42 -> 0
A28: =(E28*4)/$A$3 -> 1 | E28: 1 | F28: 708200698 | G28: Fascia | P28: ='Mon (103)'!M43 -> Seastar | Q28: ='Mon (103)'!N43 -> 0 | R28: ='Tue (103)'!N43 -> 0 | T28: ='Wed (103)'!N43 -> 0 | V28: ='Thur (103)'!N43 -> 0 | X28: ='Fri (103)'!N43 -> 0 | Z28: ='Sat (103)'!N43 -> 0
A29: =(E29*4)/$A$3 -> 1 | E29: 1 | F29: 708301214 | G29: LH Cover | P29: ='Mon (103)'!M44 -> Manterra - Hyper Silver | Q29: ='Mon (103)'!N44 -> 0 | R29: ='Tue (103)'!N44 -> 0 | T29: ='Wed (103)'!N44 -> 0 | V29: ='Thur (103)'!N44 -> 0 | X29: ='Fri (103)'!N44 -> 0 | Z29: ='Sat (103)'!N44 -> 0
A30: =(E30*4)/$A$3 -> 1 | E30: 1 | F30: 708301215 | G30: RH Cover | P30: ='Mon (103)'!M45 -> Falcon Lakeside Hyper Silver | Q30: ='Mon (103)'!N45 -> 0 | R30: ='Tue (103)'!N45 -> 0 | T30: ='Wed (103)'!N45 -> 0 | V30: ='Thur (103)'!N45 -> 0 | X30: ='Fri (103)'!N45 -> 0 | Z30: ='Sat (103)'!N45 -> 0
A31: =(E31*4)/$A$3 -> 4 | E31: 4 | F31: 708303800 | G31: LH F3T Panel | P31: ='Mon (103)'!M46 -> Tesla - High Gloss Black | Q31: ='Mon (103)'!N46 -> 0 | R31: ='Tue (103)'!N46 -> 0 | T31: ='Wed (103)'!N46 -> 0 | V31: ='Thur (103)'!N46 -> 0 | X31: ='Fri (103)'!N46 -> 0 | Z31: ='Sat (103)'!N46 -> 0
A32: =(E32*4)/$A$3 -> 4 | E32: 4 | F32: 708303801 | G32: RH F3T Panel | P32: ='Mon (103)'!M47 -> 0 | R32: ='Tue (103)'!N47 -> 0 | T32: ='Wed (103)'!N47 -> 0 | V32: ='Thur (103)'!N47 -> 0 | X32: ='Fri (103)'!N47 -> 0 | Z32: ='Sat (103)'!N47 -> 0
A33: =(E33*4)/$A$3 -> 0 | E33: 0 | F33: Deep Black (Spyder) | P33: ='Mon (103)'!M48 -> 0 | Q33: ='Mon (103)'!N47 -> 0 | R33: ='Tue (103)'!N48 -> 0 | T33: ='Wed (103)'!N48 -> 0 | V33: ='Thur (103)'!N48 -> 0 | X33: ='Fri (103)'!N48 -> 0 | Z33: ='Sat (103)'!N48 -> 0
A34: =(E34*4)/$A$3 -> 2 | E34: 2 | F34: 708400287 | G34: Tank Cover | P34: ='Mon (103)'!M49 -> 0 | Q34: ='Mon (103)'!N48 -> 0 | R34: ='Tue (103)'!N49 -> 0 | T34: ='Wed (103)'!N49 -> 0 | V34: ='Thur (103)'!N49 -> 0 | X34: ='Fri (103)'!N49 -> 0 | Z34: ='Sat (103)'!N49 -> 0
A35: =(E35*4)/$A$3 -> 2 | E35: 2 | F35: 705019189 | G35: New Tank Cover | Q35: ='Mon (103)'!N49 -> 0 | R35: ='Tue (103)'!N50 -> 0 | T35: ='Wed (103)'!N50 -> 0 | V35: ='Thur (103)'!N50 -> 0 | X35: ='Fri (103)'!N50 -> 0 | Z35: ='Sat (103)'!N50 -> 0
A36: =(E36*4)/$A$3 -> 2 | E36: 2 | F36: 708001528 | G36: Tail Fairing | P36: ='Mon (103)'!M50 -> Total: | Q36: ='Mon (103)'!N50 -> 0 | R36: ='Tue (103)'!N51 -> 0 | T36: ='Wed (103)'!N51 -> 0 | V36: ='Thur (103)'!N51 -> 0 | X36: ='Fri (103)'!N51 -> 0 | Z36: ='Sat (103)'!N51 -> 0
A37: =(E37*4)/$A$3 -> 2 | E37: 2 | F37: 708400069 | G37: RH Consol Fairing | P37: ='Mon (103)'!M51 -> 0 | Q37: ='Mon (103)'!N51 -> 0 | R37: ='Tue (103)'!N52 -> 0 | T37: ='Wed (103)'!N52 -> 0 | V37: ='Thur (103)'!N52 -> 0 | X37: ='Fri (103)'!N52 -> 0 | Z37: ='Sat (103)'!N52 -> 0
A38: =(E38*4)/$A$3 -> 2 | E38: 2 | F38: 708400067 | G38: LH Consol Fairing | P38: ='Mon (103)'!M52 -> Gaps | Q38: ='Mon (103)'!N52 -> 0 | R38: ='Tue (103)'!N53 -> 0 | T38: ='Wed (103)'!N53 -> 0 | V38: ='Thur (103)'!N53 -> 0 | X38: ='Fri (103)'!N53 -> 0 | Z38: ='Sat (103)'!N53 -> 0
A39: =(E39*4)/$A$3 -> 2 | E39: 2 | F39: 708400956 | G39: New LH Console Panel | P39: ='Mon (103)'!M53 -> 0 | Q39: ='Mon (103)'!N53 -> 0 | R39: ='Tue (103)'!N54 -> 0 | T39: ='Wed (103)'!N54 -> 0 | V39: ='Thur (103)'!N54 -> 0 | X39: ='Fri (103)'!N54 -> 0 | Z39: ='Sat (103)'!N54 -> 0
A40: =(E40*4)/$A$3 -> 2 | E40: 2 | F40: 708400957 | G40: New RH Console Panel | P40: ='Mon (103)'!M54 -> Total Time (hrs) | Q40: ='Mon (103)'!N54 -> 0 | R40: ='Tue (103)'!N55 -> 0 | T40: ='Wed (103)'!N55 -> 0 | V40: ='Thur (103)'!N55 -> 0 | X40: ='Fri (103)'!N55 -> 0 | Z40: ='Sat (103)'!N55 -> 0
A41: =(E41*4)/$A$3 -> 2 | E41: 2 | F41: 708400722 | G41: New Nose Fairing | P41: Total Week Run Time: | R41: =SUM(Q40:AA40) -> 0
...

Sheet Paint Usage
A1: Part Num | B1: Part | C1: Mon | D1: Tue | E1: Wed | F1: Thur | G1: Friday | H1: Sat
A2: Hyper Silver (Spyder)
A3: 705012348 | B3: LH Trim | C3: =(('Time Matrix'!B3*#REF!)*'Mon (103)'!#REF!) + (('Time Matrix'!B3*#REF!)*'Mon (103)'!#REF!) + (('Time Matrix'!B3*#REF!)*'Mon (103)'!#REF!) + (('Time Matrix'!B3*#REF!)*'Mon (103)'!#REF!) -> #REF! | D3: =(('Time Matrix'!B3*#REF!)*#REF!) + (('Time Matrix'!B3*#REF!)*#REF!) + (('Time Matrix'!B3*#REF!)*#REF!) + (('Time Matrix'!B3*#REF!)*#REF!) -> #REF! | E3: =(('Time Matrix'!B3*#REF!)*#REF!) + (('Time Matrix'!B3*#REF!)*#REF!) + (('Time Matrix'!B3*#REF!)*#REF!) + (('Time Matrix'!B3*#REF!)*#REF!) -> #REF! | F3: =(('Time Matrix'!B3*#REF!)*#REF!) + (('Time Matrix'!B3*#REF!)*#REF!) + (('Time Matrix'!B3*#REF!)*#REF!) + (('Time Matrix'!B3*#REF!)*#REF!) -> #REF! | G3: =(('Time Matrix'!B3*#REF!)*#REF!) + (('Time Matrix'!B3*#REF!)*#REF!) + (('Time Matrix'!B3*#REF!)*#REF!) + (('Time Matrix'!B3*#REF!)*#REF!) -> #REF! | H3: =(('Time Matrix'!B3*#REF!)*#REF!) + (('Time Matrix'!B3*#REF!)*#REF!) + (('Time Matrix'!B3*#REF!)*#REF!) + (('Time Matrix'!B3*#REF!)*#REF!) -> #REF!
A4: 705012350 | B4: RH Trim | C4: =(('Time Matrix'!B4*#REF!)*'Mon (103)'!#REF!) + (('Time Matrix'!B4*#REF!)*'Mon (103)'!#REF!) + (('Time Matrix'!B4*#REF!)*'Mon (103)'!#REF!) + (('Time Matrix'!B4*#REF!)*'Mon (103)'!#REF!) -> #REF! | D4: =(('Time Matrix'!B4*#REF!)*#REF!) + (('Time Matrix'!B4*#REF!)*#REF!) + (('Time Matrix'!B4*#REF!)*#REF!) + (('Time Matrix'!B4*#REF!)*#REF!) -> #REF! | E4: =(('Time Matrix'!B4*#REF!)*#REF!) + (('Time Matrix'!B4*#REF!)*#REF!) + (('Time Matrix'!B4*#REF!)*#REF!) + (('Time Matrix'!B4*#REF!)*#REF!) -> #REF! | F4: =(('Time Matrix'!B4*#REF!)*#REF!) + (('Time Matrix'!B4*#REF!)*#REF!) + (('Time Matrix'!B4*#REF!)*#REF!) + (('Time Matrix'!B4*#REF!)*#REF!) -> #REF! | G4: =(('Time Matrix'!B4*#REF!)*#REF!) + (('Time Matrix'!B4*#REF!)*#REF!) + (('Time Matrix'!B4*#REF!)*#REF!) + (('Time Matrix'!B4*#REF!)*#REF!) -> #REF! | H4: =(('Time Matrix'!B4*#REF!)*#REF!) + (('Time Matrix'!B4*#REF!)*#REF!) + (('Time Matrix'!B4*#REF!)*#REF!) + (('Time Matrix'!B4*#REF!)*#REF!) -> #REF!
A5: 705012868 | B5: RH Fender | C5: =(('Time Matrix'!B5*#REF!)*'Mon (103)'!#REF!) + (('Time Matrix'!B5*#REF!)*'Mon (103)'!#REF!) + (('Time Matrix'!B5*#REF!)*'Mon (103)'!#REF!) + (('Time Matrix'!B5*#REF!)*'Mon (103)'!#REF!) -> #REF! | D5: =(('Time Matrix'!B5*#REF!)*#REF!) + (('Time Matrix'!B5*#REF!)*#REF!) + (('Time Matrix'!B5*#REF!)*#REF!) + (('Time Matrix'!B5*#REF!)*#REF!) -> #REF! | E5: =(('Time Matrix'!B5*#REF!)*#REF!) + (('Time Matrix'!B5*#REF!)*#REF!) + (('Time Matrix'!B5*#REF!)*#REF!) + (('Time Matrix'!B5*#REF!)*#REF!) -> #REF! | F5: =(('Time Matrix'!B5*#REF!)*#REF!) + (('Time Matrix'!B5*#REF!)*#REF!) + (('Time Matrix'!B5*#REF!)*#REF!) + (('Time Matrix'!B5*#REF!)*#REF!) -> #REF! | G5: =(('Time Matrix'!B5*#REF!)*#REF!) + (('Time Matrix'!B5*#REF!)*#REF!) + (('Time Matrix'!B5*#REF!)*#REF!) + (('Time Matrix'!B5*#REF!)*#REF!) -> #REF! | H5: =(('Time Matrix'!B5*#REF!)*#REF!) + (('Time Matrix'!B5*#REF!)*#REF!) + (('Time Matrix'!B5*#REF!)*#REF!) + (('Time Matrix'!B5*#REF!)*#REF!) -> #REF!
A6: 705012976 | B6: LH Fender | C6: =(('Time Matrix'!B6*#REF!)*'Mon (103)'!#REF!) + (('Time Matrix'!B6*#REF!)*'Mon (103)'!#REF!) + (('Time Matrix'!B6*#REF!)*'Mon (103)'!#REF!) + (('Time Matrix'!B6*#REF!)*'Mon (103)'!#REF!) -> #REF! | D6: =(('Time Matrix'!B6*#REF!)*#REF!) + (('Time Matrix'!B6*#REF!)*#REF!) + (('Time Matrix'!B6*#REF!)*#REF!) + (('Time Matrix'!B6*#REF!)*#REF!) -> #REF! | E6: =(('Time Matrix'!B6*#REF!)*#REF!) + (('Time Matrix'!B6*#REF!)*#REF!) + (('Time Matrix'!B6*#REF!)*#REF!) + (('Time Matrix'!B6*#REF!)*#REF!) -> #REF! | F6: =(('Time Matrix'!B6*#REF!)*#REF!) + (('Time Matrix'!B6*#REF!)*#REF!) + (('Time Matrix'!B6*#REF!)*#REF!) + (('Time Matrix'!B6*#REF!)*#REF!) -> #REF! | G6: =(('Time Matrix'!B6*#REF!)*#REF!) + (('Time Matrix'!B6*#REF!)*#REF!) + (('Time Matrix'!B6*#REF!)*#REF!) + (('Time Matrix'!B6*#REF!)*#REF!) -> #REF! | H6: =(('Time Matrix'!B6*#REF!)*#REF!) + (('Time Matrix'!B6*#REF!)*#REF!) + (('Time Matrix'!B6*#REF!)*#REF!) + (('Time Matrix'!B6*#REF!)*#REF!) -> #REF!
A7: 705014100 | B7: LH Upper Fairing | C7: =(('Time Matrix'!B7*#REF!)*'Mon (103)'!#REF!) + (('Time Matrix'!B7*#REF!)*'Mon (103)'!#REF!) + (('Time Matrix'!B7*#REF!)*'Mon (103)'!#REF!) + (('Time Matrix'!B7*#REF!)*'Mon (103)'!#REF!) -> #REF! | D7: =(('Time Matrix'!B7*#REF!)*#REF!) + (('Time Matrix'!B7*#REF!)*#REF!) + (('Time Matrix'!B7*#REF!)*#REF!) + (('Time Matrix'!B7*#REF!)*#REF!) -> #REF! | E7: =(('Time Matrix'!B7*#REF!)*#REF!) + (('Time Matrix'!B7*#REF!)*#REF!) + (('Time Matrix'!B7*#REF!)*#REF!) + (('Time Matrix'!B7*#REF!)*#REF!) -> #REF! | F7: =(('Time Matrix'!B7*#REF!)*#REF!) + (('Time Matrix'!B7*#REF!)*#REF!) + (('Time Matrix'!B7*#REF!)*#REF!) + (('Time Matrix'!B7*#REF!)*#REF!) -> #REF! | G7: =(('Time Matrix'!B7*#REF!)*#REF!) + (('Time Matrix'!B7*#REF!)*#REF!) + (('Time Matrix'!B7*#REF!)*#REF!) + (('Time Matrix'!B7*#REF!)*#REF!) -> #REF! | H7: =(('Time Matrix'!B7*#REF!)*#REF!) + (('Time Matrix'!B7*#REF!)*#REF!) + (('Time Matrix'!B7*#REF!)*#REF!) + (('Time Matrix'!B7*#REF!)*#REF!) -> #REF!
A8: 705014101 | B8: RH Upper Fairing | C8: =(('Time Matrix'!B8*#REF!)*'Mon (103)'!#REF!) + (('Time Matrix'!B8*#REF!)*'Mon (103)'!#REF!) + (('Time Matrix'!B8*#REF!)*'Mon (103)'!#REF!) + (('Time Matrix'!B8*#REF!)*'Mon (103)'!#REF!) -> #REF! | D8: =(('Time Matrix'!B8*#REF!)*#REF!) + (('Time Matrix'!B8*#REF!)*#REF!) + (('Time Matrix'!B8*#REF!)*#REF!) + (('Time Matrix'!B8*#REF!)*#REF!) -> #REF! | E8: =(('Time Matrix'!B8*#REF!)*#REF!) + (('Time Matrix'!B8*#REF!)*#REF!) + (('Time Matrix'!B8*#REF!)*#REF!) + (('Time Matrix'!B8*#REF!)*#REF!) -> #REF! | F8: =(('Time Matrix'!B8*#REF!)*#REF!) + (('Time Matrix'!B8*#REF!)*#REF!) + (('Time Matrix'!B8*#REF!)*#REF!) + (('Time Matrix'!B8*#REF!)*#REF!) -> #REF! | G8: =(('Time Matrix'!B8*#REF!)*#REF!) + (('Time Matrix'!B8*#REF!)*#REF!) + (('Time Matrix'!B8*#REF!)*#REF!) + (('Time Matrix'!B8*#REF!)*#REF!) -> #REF! | H8: =(('Time Matrix'!B8*#REF!)*#REF!) + (('Time Matrix'!B8*#REF!)*#REF!) + (('Time Matrix'!B8*#REF!)*#REF!) + (('Time Matrix'!B8*#REF!)*#REF!) -> #REF!
A9: 708003041 | B9: Rear Fairing | C9: =(('Time Matrix'!B9*#REF!)*'Mon (103)'!#REF!) + (('Time Matrix'!B9*#REF!)*'Mon (103)'!#REF!) + (('Time Matrix'!B9*#REF!)*'Mon (103)'!#REF!) + (('Time Matrix'!B9*#REF!)*'Mon (103)'!#REF!) -> #REF! | D9: =(('Time Matrix'!B9*#REF!)*#REF!) + (('Time Matrix'!B9*#REF!)*#REF!) + (('Time Matrix'!B9*#REF!)*#REF!) + (('Time Matrix'!B9*#REF!)*#REF!) -> #REF! | E9: =(('Time Matrix'!B9*#REF!)*#REF!) + (('Time Matrix'!B9*#REF!)*#REF!) + (('Time Matrix'!B9*#REF!)*#REF!) + (('Time Matrix'!B9*#REF!)*#REF!) -> #REF! | F9: =(('Time Matrix'!B9*#REF!)*#REF!) + (('Time Matrix'!B9*#REF!)*#REF!) + (('Time Matrix'!B9*#REF!)*#REF!) + (('Time Matrix'!B9*#REF!)*#REF!) -> #REF! | G9: =(('Time Matrix'!B9*#REF!)*#REF!) + (('Time Matrix'!B9*#REF!)*#REF!) + (('Time Matrix'!B9*#REF!)*#REF!) + (('Time Matrix'!B9*#REF!)*#REF!) -> #REF! | H9: =(('Time Matrix'!B9*#REF!)*#REF!) + (('Time Matrix'!B9*#REF!)*#REF!) + (('Time Matrix'!B9*#REF!)*#REF!) + (('Time Matrix'!B9*#REF!)*#REF!) -> #REF!
A10: 708200869 | B10: R66 Hood | C10: =(('Time Matrix'!B10*#REF!)*'Mon (103)'!#REF!) + (('Time Matrix'!B10*#REF!)*'Mon (103)'!#REF!) + (('Time Matrix'!B10*#REF!)*'Mon (103)'!#REF!) + (('Time Matrix'!B10*#REF!)*'Mon (103)'!#REF!) -> #REF! | D10: =(('Time Matrix'!B10*#REF!)*#REF!) + (('Time Matrix'!B10*#REF!)*#REF!) + (('Time Matrix'!B10*#REF!)*#REF!) + (('Time Matrix'!B10*#REF!)*#REF!) -> #REF! | E10: =(('Time Matrix'!B10*#REF!)*#REF!) + (('Time Matrix'!B10*#REF!)*#REF!) + (('Time Matrix'!B10*#REF!)*#REF!) + (('Time Matrix'!B10*#REF!)*#REF!) -> #REF! | F10: =(('Time Matrix'!B10*#REF!)*#REF!) + (('Time Matrix'!B10*#REF!)*#REF!) + (('Time Matrix'!B10*#REF!)*#REF!) + (('Time Matrix'!B10*#REF!)*#REF!) -> #REF! | G10: =(('Time Matrix'!B10*#REF!)*#REF!) + (('Time Matrix'!B10*#REF!)*#REF!) + (('Time Matrix'!B10*#REF!)*#REF!) + (('Time Matrix'!B10*#REF!)*#REF!) -> #REF! | H10: =(('Time Matrix'!B10*#REF!)*#REF!) + (('Time Matrix'!B10*#REF!)*#REF!) + (('Time Matrix'!B10*#REF!)*#REF!) + (('Time Matrix'!B10*#REF!)*#REF!) -> #REF!
A11: 708200870 | B11: LH Front Fairing | C11: =(('Time Matrix'!B11*#REF!)*'Mon (103)'!#REF!) + (('Time Matrix'!B11*#REF!)*'Mon (103)'!#REF!) + (('Time Matrix'!B11*#REF!)*'Mon (103)'!#REF!) + (('Time Matrix'!B11*#REF!)*'Mon (103)'!#REF!) -> #REF! | D11: =(('Time Matrix'!B11*#REF!)*#REF!) + (('Time Matrix'!B11*#REF!)*#REF!) + (('Time Matrix'!B11*#REF!)*#REF!) + (('Time Matrix'!B11*#REF!)*#REF!) -> #REF! | E11: =(('Time Matrix'!B11*#REF!)*#REF!) + (('Time Matrix'!B11*#REF!)*#REF!) + (('Time Matrix'!B11*#REF!)*#REF!) + (('Time Matrix'!B11*#REF!)*#REF!) -> #REF! | F11: =(('Time Matrix'!B11*#REF!)*#REF!) + (('Time Matrix'!B11*#REF!)*#REF!) + (('Time Matrix'!B11*#REF!)*#REF!) + (('Time Matrix'!B11*#REF!)*#REF!) -> #REF! | G11: =(('Time Matrix'!B11*#REF!)*#REF!) + (('Time Matrix'!B11*#REF!)*#REF!) + (('Time Matrix'!B11*#REF!)*#REF!) + (('Time Matrix'!B11*#REF!)*#REF!) -> #REF! | H11: =(('Time Matrix'!B11*#REF!)*#REF!) + (('Time Matrix'!B11*#REF!)*#REF!) + (('Time Matrix'!B11*#REF!)*#REF!) + (('Time Matrix'!B11*#REF!)*#REF!) -> #REF!
A12: 708200871 | B12: RH Front Fairing | C12: =(('Time Matrix'!B12*#REF!)*'Mon (103)'!#REF!) + (('Time Matrix'!B12*#REF!)*'Mon (103)'!#REF!) + (('Time Matrix'!B12*#REF!)*'Mon (103)'!#REF!) + (('Time Matrix'!B12*#REF!)*'Mon (103)'!#REF!) -> #REF! | D12: =(('Time Matrix'!B12*#REF!)*#REF!) + (('Time Matrix'!B12*#REF!)*#REF!) + (('Time Matrix'!B12*#REF!)*#REF!) + (('Time Matrix'!B12*#REF!)*#REF!) -> #REF! | E12: =(('Time Matrix'!B12*#REF!)*#REF!) + (('Time Matrix'!B12*#REF!)*#REF!) + (('Time Matrix'!B12*#REF!)*#REF!) + (('Time Matrix'!B12*#REF!)*#REF!) -> #REF! | F12: =(('Time Matrix'!B12*#REF!)*#REF!) + (('Time Matrix'!B12*#REF!)*#REF!) + (('Time Matrix'!B12*#REF!)*#REF!) + (('Time Matrix'!B12*#REF!)*#REF!) -> #REF! | G12: =(('Time Matrix'!B12*#REF!)*#REF!) + (('Time Matrix'!B12*#REF!)*#REF!) + (('Time Matrix'!B12*#REF!)*#REF!) + (('Time Matrix'!B12*#REF!)*#REF!) -> #REF! | H12: =(('Time Matrix'!B12*#REF!)*#REF!) + (('Time Matrix'!B12*#REF!)*#REF!) + (('Time Matrix'!B12*#REF!)*#REF!) + (('Time Matrix'!B12*#REF!)*#REF!) -> #REF!
A13: 708302947 | B13: LH Box Cover | C13: =(('Time Matrix'!B13*#REF!)*'Mon (103)'!#REF!) + (('Time Matrix'!B13*#REF!)*'Mon (103)'!#REF!) + (('Time Matrix'!B13*#REF!)*'Mon (103)'!#REF!) + (('Time Matrix'!B13*#REF!)*'Mon (103)'!#REF!) -> #REF! | D13: =(('Time Matrix'!B13*#REF!)*#REF!) + (('Time Matrix'!B13*#REF!)*#REF!) + (('Time Matrix'!B13*#REF!)*#REF!) + (('Time Matrix'!B13*#REF!)*#REF!) -> #REF! | E13: =(('Time Matrix'!B13*#REF!)*#REF!) + (('Time Matrix'!B13*#REF!)*#REF!) + (('Time Matrix'!B13*#REF!)*#REF!) + (('Time Matrix'!B13*#REF!)*#REF!) -> #REF! | F13: =(('Time Matrix'!B13*#REF!)*#REF!) + (('Time Matrix'!B13*#REF!)*#REF!) + (('Time Matrix'!B13*#REF!)*#REF!) + (('Time Matrix'!B13*#REF!)*#REF!) -> #REF! | G13: =(('Time Matrix'!B13*#REF!)*#REF!) + (('Time Matrix'!B13*#REF!)*#REF!) + (('Time Matrix'!B13*#REF!)*#REF!) + (('Time Matrix'!B13*#REF!)*#REF!) -> #REF! | H13: =(('Time Matrix'!B13*#REF!)*#REF!) + (('Time Matrix'!B13*#REF!)*#REF!) + (('Time Matrix'!B13*#REF!)*#REF!) + (('Time Matrix'!B13*#REF!)*#REF!) -> #REF!
A14: 708302948 | B14: RH Box Cover | C14: =(('Time Matrix'!B14*#REF!)*'Mon (103)'!#REF!) + (('Time Matrix'!B14*#REF!)*'Mon (103)'!#REF!) + (('Time Matrix'!B14*#REF!)*'Mon (103)'!#REF!) + (('Time Matrix'!B14*#REF!)*'Mon (103)'!#REF!) -> #REF! | D14: =(('Time Matrix'!B14*#REF!)*#REF!) + (('Time Matrix'!B14*#REF!)*#REF!) + (('Time Matrix'!B14*#REF!)*#REF!) + (('Time Matrix'!B14*#REF!)*#REF!) -> #REF! | E14: =(('Time Matrix'!B14*#REF!)*#REF!) + (('Time Matrix'!B14*#REF!)*#REF!) + (('Time Matrix'!B14*#REF!)*#REF!) + (('Time Matrix'!B14*#REF!)*#REF!) -> #REF! | F14: =(('Time Matrix'!B14*#REF!)*#REF!) + (('Time Matrix'!B14*#REF!)*#REF!) + (('Time Matrix'!B14*#REF!)*#REF!) + (('Time Matrix'!B14*#REF!)*#REF!) -> #REF! | G14: =(('Time Matrix'!B14*#REF!)*#REF!) + (('Time Matrix'!B14*#REF!)*#REF!) + (('Time Matrix'!B14*#REF!)*#REF!) + (('Time Matrix'!B14*#REF!)*#REF!) -> #REF! | H14: =(('Time Matrix'!B14*#REF!)*#REF!) + (('Time Matrix'!B14*#REF!)*#REF!) + (('Time Matrix'!B14*#REF!)*#REF!) + (('Time Matrix'!B14*#REF!)*#REF!) -> #REF!
... A18: 708400463 | B18: RH Mirror Shell | C18: =(('Time Matrix'!B18*#REF!)*'Mon (103)'!#REF!) + (('Time Matrix'!B18*#REF!)*'Mon (103)'!#REF!) + (('Time Matrix'!B18*#REF!)*'Mon (103)'!#REF!) + (('Time Matrix'!B18*#REF!)*'Mon (103)'!#REF!) -> #REF! | D18: =(('Time Matrix'!B18*#REF!)*#REF!) + (('Time Matrix'!B18*#REF!)*#REF!) + (('Time Matrix'!B18*#REF!)*#REF!) + (('Time Matrix'!B18*#REF!)*#REF!) -> #REF! | E18: =(('Time Matrix'!B18*#REF!)*#REF!) + (('Time Matrix'!B18*#REF!)*#REF!) + (('Time Matrix'!B18*#REF!)*#REF!) + (('Time Matrix'!B18*#REF!)*#REF!) -> #REF! | F18: =(('Time Matrix'!B18*#REF!)*#REF!) + (('Time Matrix'!B18*#REF!)*#REF!) + (('Time Matrix'!B18*#REF!)*#REF!) + (('Time Matrix'!B18*#REF!)*#REF!) -> #REF! | G18: =(('Time Matrix'!B18*#REF!)*#REF!) + (('Time Matrix'!B18*#REF!)*#REF!) + (('Time Matrix'!B18*#REF!)*#REF!) + (('Time Matrix'!B18*#REF!)*#REF!) -> #REF! | H18: =(('Time Matrix'!B18*#REF!)*#REF!) + (('Time Matrix'!B18*#REF!)*#REF!) + (('Time Matrix'!B18*#REF!)*#REF!) + (('Time Matrix'!B18*#REF!)*#REF!) -> #REF!
A19: Total: | C19: =SUM(C3:C18) -> #REF! | D19: =SUM(D3:D18) -> #REF! | E19: =SUM(E3:E18) -> #REF! | F19: =SUM(F3:F18) -> #REF! | G19: =SUM(G3:G18) -> #REF! | H19: =SUM(H3:H18) -> #REF!
A20: Deep Black (Spyder)
A21: 708001528 | B21: Tail Fairing | C21: =(('Time Matrix'!C19*#REF!)*'Mon (103)'!#REF!) + (('Time Matrix'!C19*#REF!)*'Mon (103)'!#REF!) + (('Time Matrix'!C19*#REF!)*'Mon (103)'!#REF!) + (('Time Matrix'!C19*#REF!)*'Mon (103)'!#REF!) -> #REF! | D21: =(('Time Matrix'!C19*#REF!)*#REF!) + (('Time Matrix'!C19*#REF!)*#REF!) + (('Time Matrix'!C19*#REF!)*#REF!) + (('Time Matrix'!C19*#REF!)*#REF!) -> #REF! | E21: =(('Time Matrix'!C19*#REF!)*#REF!) + (('Time Matrix'!C19*#REF!)*#REF!) + (('Time Matrix'!C19*#REF!)*#REF!) + (('Time Matrix'!C19*#REF!)*#REF!) -> #REF! | F21: =(('Time Matrix'!C19*#REF!)*#REF!) + (('Time Matrix'!C19*#REF!)*#REF!) + (('Time Matrix'!C19*#REF!)*#REF!) + (('Time Matrix'!C19*#REF!)*#REF!) -> #REF! | G21: =(('Time Matrix'!C19*#REF!)*#REF!) + (('Time Matrix'!C19*#REF!)*#REF!) + (('Time Matrix'!C19*#REF!)*#REF!) + (('Time Matrix'!C19*#REF!)*#REF!) -> #REF! | H21: =(('Time Matrix'!C19*#REF!)*#REF!) + (('Time Matrix'!C19*#REF!)*#REF!) + (('Time Matrix'!C19*#REF!)*#REF!) + (('Time Matrix'!C19*#REF!)*#REF!) -> #REF!
A22: 708400001 | B22: LH Console Panel | C22: =(('Time Matrix'!C20*#REF!)*'Mon (103)'!#REF!) + (('Time Matrix'!C20*#REF!)*'Mon (103)'!#REF!) + (('Time Matrix'!C20*#REF!)*'Mon (103)'!#REF!) + (('Time Matrix'!C20*#REF!)*'Mon (103)'!#REF!) -> #REF! | D22: =(('Time Matrix'!C20*#REF!)*#REF!) + (('Time Matrix'!C20*#REF!)*#REF!) + (('Time Matrix'!C20*#REF!)*#REF!) + (('Time Matrix'!C20*#REF!)*#REF!) -> #REF! | E22: =(('Time Matrix'!C20*#REF!)*#REF!) + (('Time Matrix'!C20*#REF!)*#REF!) + (('Time Matrix'!C20*#REF!)*#REF!) + (('Time Matrix'!C20*#REF!)*#REF!) -> #REF! | F22: =(('Time Matrix'!C20*#REF!)*#REF!) + (('Time Matrix'!C20*#REF!)*#REF!) + (('Time Matrix'!C20*#REF!)*#REF!) + (('Time Matrix'!C20*#REF!)*#REF!) -> #REF! | G22: =(('Time Matrix'!C20*#REF!)*#REF!) + (('Time Matrix'!C20*#REF!)*#REF!) + (('Time Matrix'!C20*#REF!)*#REF!) + (('Time Matrix'!C20*#REF!)*#REF!) -> #REF! | H22: =(('Time Matrix'!C20*#REF!)*#REF!) + (('Time Matrix'!C20*#REF!)*#REF!) + (('Time Matrix'!C20*#REF!)*#REF!) + (('Time Matrix'!C20*#REF!)*#REF!) -> #REF!
A23: 708400002 | B23: RH Console Panel | C23: =(('Time Matrix'!C21*#REF!)*'Mon (103)'!#REF!) + (('Time Matrix'!C21*#REF!)*'Mon (103)'!#REF!) + (('Time Matrix'!C21*#REF!)*'Mon (103)'!#REF!) + (('Time Matrix'!C21*#REF!)*'Mon (103)'!#REF!) -> #REF! | D23: =(('Time Matrix'!C21*#REF!)*#REF!) + (('Time Matrix'!C21*#REF!)*#REF!) + (('Time Matrix'!C21*#REF!)*#REF!) + (('Time Matrix'!C21*#REF!)*#REF!) -> #REF! | E23: =(('Time Matrix'!C21*#REF!)*#REF!) + (('Time Matrix'!C21*#REF!)*#REF!) + (('Time Matrix'!C21*#REF!)*#REF!) + (('Time Matrix'!C21*#REF!)*#REF!) -> #REF! | F23: =(('Time Matrix'!C21*#REF!)*#REF!) + (('Time Matrix'!C21*#REF!)*#REF!) + (('Time Matrix'!C21*#REF!)*#REF!) + (('Time Matrix'!C21*#REF!)*#REF!) -> #REF! | G23: =(('Time Matrix'!C21*#REF!)*#REF!) + (('Time Matrix'!C21*#REF!)*#REF!) + (('Time Matrix'!C21*#REF!)*#REF!) + (('Time Matrix'!C21*#REF!)*#REF!) -> #REF! | H23: =(('Time Matrix'!C21*#REF!)*#REF!) + (('Time Matrix'!C21*#REF!)*#REF!) + (('Time Matrix'!C21*#REF!)*#REF!) + (('Time Matrix'!C21*#REF!)*#REF!) -> #REF!
A24: 708400067 | B24: LH Console Fairing | C24: =(('Time Matrix'!C22*#REF!)*'Mon (103)'!#REF!) + (('Time Matrix'!C22*#REF!)*'Mon (103)'!#REF!) + (('Time Matrix'!C22*#REF!)*'Mon (103)'!#REF!) + (('Time Matrix'!C22*#REF!)*'Mon (103)'!#REF!) -> #REF! | D24: =(('Time Matrix'!C22*#REF!)*#REF!) + (('Time Matrix'!C22*#REF!)*#REF!) + (('Time Matrix'!C22*#REF!)*#REF!) + (('Time Matrix'!C22*#REF!)*#REF!) -> #REF! | E24: =(('Time Matrix'!C22*#REF!)*#REF!) + (('Time Matrix'!C22*#REF!)*#REF!) + (('Time Matrix'!C22*#REF!)*#REF!) + (('Time Matrix'!C22*#REF!)*#REF!) -> #REF! | F24: =(('Time Matrix'!C22*#REF!)*#REF!) + (('Time Matrix'!C22*#REF!)*#REF!) + (('Time Matrix'!C22*#REF!)*#REF!) + (('Time Matrix'!C22*#REF!)*#REF!) -> #REF! | G24: =(('Time Matrix'!C22*#REF!)*#REF!) + (('Time Matrix'!C22*#REF!)*#REF!) + (('Time Matrix'!C22*#REF!)*#REF!) + (('Time Matrix'!C22*#REF!)*#REF!) -> #REF! | H24: =(('Time Matrix'!C22*#REF!)*#REF!) + (('Time Matrix'!C22*#REF!)*#REF!) + (('Time Matrix'!C22*#REF!)*#REF!) + (('Time Matrix'!C22*#REF!)*#REF!) -> #REF!
A25: 708400069 | B25: RH Console Fairing | C25: =(('Time Matrix'!C23*#REF!)*'Mon (103)'!#REF!) + (('Time Matrix'!C23*#REF!)*'Mon (103)'!#REF!) + (('Time Matrix'!C23*#REF!)*'Mon (103)'!#REF!) + (('Time Matrix'!C23*#REF!)*'Mon (103)'!#REF!) -> #REF! | D25: =(('Time Matrix'!C23*#REF!)*#REF!) + (('Time Matrix'!C23*#REF!)*#REF!) + (('Time Matrix'!C23*#REF!)*#REF!) + (('Time Matrix'!C23*#REF!)*#REF!) -> #REF! | E25: =(('Time Matrix'!C23*#REF!)*#REF!) + (('Time Matrix'!C23*#REF!)*#REF!) + (('Time Matrix'!C23*#REF!)*#REF!) + (('Time Matrix'!C23*#REF!)*#REF!) -> #REF! | F25: =(('Time Matrix'!C23*#REF!)*#REF!) + (('Time Matrix'!C23*#REF!)*#REF!) + (('Time Matrix'!C23*#REF!)*#REF!) + (('Time Matrix'!C23*#REF!)*#REF!) -> #REF! | G25: =(('Time Matrix'!C23*#REF!)*#REF!) + (('Time Matrix'!C23*#REF!)*#REF!) + (('Time Matrix'!C23*#REF!)*#REF!) + (('Time Matrix'!C23*#REF!)*#REF!) -> #REF! | H25: =(('Time Matrix'!C23*#REF!)*#REF!) + (('Time Matrix'!C23*#REF!)*#REF!) + (('Time Matrix'!C23*#REF!)*#REF!) + (('Time Matrix'!C23*#REF!)*#REF!) -> #REF!
A26: 708400287 | B26: Tank Cover | C26: =(('Time Matrix'!C24*#REF!)*'Mon (103)'!#REF!) + (('Time Matrix'!C24*#REF!)*'Mon (103)'!#REF!) + (('Time Matrix'!C24*#REF!)*'Mon (103)'!#REF!) + (('Time Matrix'!C24*#REF!)*'Mon (103)'!#REF!) -> #REF! | D26: =(('Time Matrix'!C24*#REF!)*#REF!) + (('Time Matrix'!C24*#REF!)*#REF!) + (('Time Matrix'!C24*#REF!)*#REF!) + (('Time Matrix'!C24*#REF!)*#REF!) -> #REF! | E26: =(('Time Matrix'!C24*#REF!)*#REF!) + (('Time Matrix'!C24*#REF!)*#REF!) + (('Time Matrix'!C24*#REF!)*#REF!) + (('Time Matrix'!C24*#REF!)*#REF!) -> #REF! | F26: =(('Time Matrix'!C24*#REF!)*#REF!) + (('Time Matrix'!C24*#REF!)*#REF!) + (('Time Matrix'!C24*#REF!)*#REF!) + (('Time Matrix'!C24*#REF!)*#REF!) -> #REF! | G26: =(('Time Matrix'!C24*#REF!)*#REF!) + (('Time Matrix'!C24*#REF!)*#REF!) + (('Time Matrix'!C24*#REF!)*#REF!) + (('Time Matrix'!C24*#REF!)*#REF!) -> #REF! | H26: =(('Time Matrix'!C24*#REF!)*#REF!) + (('Time Matrix'!C24*#REF!)*#REF!) + (('Time Matrix'!C24*#REF!)*#REF!) + (('Time Matrix'!C24*#REF!)*#REF!) -> #REF!
A27: 708400398 | B27: Tank Cover with Hole | C27: =(('Time Matrix'!C25*#REF!)*'Mon (103)'!#REF!) + (('Time Matrix'!C25*#REF!)*'Mon (103)'!#REF!) + (('Time Matrix'!C25*#REF!)*'Mon (103)'!#REF!) + (('Time Matrix'!C25*#REF!)*'Mon (103)'!#REF!) -> #REF! | D27: =(('Time Matrix'!C25*#REF!)*#REF!) + (('Time Matrix'!C25*#REF!)*#REF!) + (('Time Matrix'!C25*#REF!)*#REF!) + (('Time Matrix'!C25*#REF!)*#REF!) -> #REF! | E27: =(('Time Matrix'!C25*#REF!)*#REF!) + (('Time Matrix'!C25*#REF!)*#REF!) + (('Time Matrix'!C25*#REF!)*#REF!) + (('Time Matrix'!C25*#REF!)*#REF!) -> #REF! | F27: =(('Time Matrix'!C25*#REF!)*#REF!) + (('Time Matrix'!C25*#REF!)*#REF!) + (('Time Matrix'!C25*#REF!)*#REF!) + (('Time Matrix'!C25*#REF!)*#REF!) -> #REF! | G27: =(('Time Matrix'!C25*#REF!)*#REF!) + (('Time Matrix'!C25*#REF!)*#REF!) + (('Time Matrix'!C25*#REF!)*#REF!) + (('Time Matrix'!C25*#REF!)*#REF!) -> #REF! | H27: =(('Time Matrix'!C25*#REF!)*#REF!) + (('Time Matrix'!C25*#REF!)*#REF!) + (('Time Matrix'!C25*#REF!)*#REF!) + (('Time Matrix'!C25*#REF!)*#REF!) -> #REF!
A28: Total: | C28: =SUM(C21:C27) -> #REF! | D28: =SUM(D21:D27) -> #REF! | E28: =SUM(E21:E27) -> #REF! | F28: =SUM(F21:F27) -> #REF! | G28: =SUM(G21:G27) -> #REF! | H28: =SUM(H21:H27) -> #REF!
A29: Manta Green (Spyder F3 / F3T)
A30: 705007790 | B30: LH LOW FAIRING | C30: =(('Time Matrix'!D26*#REF!)*'Mon (103)'!#REF!) + (('Time Matrix'!D26*#REF!)*'Mon (103)'!#REF!) + (('Time Matrix'!D26*#REF!)*'Mon (103)'!#REF!) + (('Time Matrix'!D26*#REF!)*'Mon (103)'!#REF!) -> #REF! | D30: =(('Time Matrix'!D26*#REF!)*#REF!) + (('Time Matrix'!D26*#REF!)*#REF!) + (('Time Matrix'!D26*#REF!)*#REF!) + (('Time Matrix'!D26*#REF!)*#REF!) -> #REF! | E30: =(('Time Matrix'!D26*#REF!)*#REF!) + (('Time Matrix'!D26*#REF!)*#REF!) + (('Time Matrix'!D26*#REF!)*#REF!) + (('Time Matrix'!D26*#REF!)*#REF!) -> #REF! | F30: =(('Time Matrix'!D26*#REF!)*#REF!) + (('Time Matrix'!D26*#REF!)*#REF!) + (('Time Matrix'!D26*#REF!)*#REF!) + (('Time Matrix'!D26*#REF!)*#REF!) -> #REF! | G30: =(('Time Matrix'!D26*#REF!)*#REF!) + (('Time Matrix'!D26*#REF!)*#REF!) + (('Time Matrix'!D26*#REF!)*#REF!) + (('Time Matrix'!D26*#REF!)*#REF!) -> #REF! | H30: =(('Time Matrix'!D26*#REF!)*#REF!) + (('Time Matrix'!D26*#REF!)*#REF!) + (('Time Matrix'!D26*#REF!)*#REF!) + (('Time Matrix'!D26*#REF!)*#REF!) -> #REF!
A31: 705007791 | B31: RH LOW FAIRING | C31: =(('Time Matrix'!D27*#REF!)*'Mon (103)'!#REF!) + (('Time Matrix'!D27*#REF!)*'Mon (103)'!#REF!) + (('Time Matrix'!D27*#REF!)*'Mon (103)'!#REF!) + (('Time Matrix'!D27*#REF!)*'Mon (103)'!#REF!) -> #REF! | D31: =(('Time Matrix'!D27*#REF!)*#REF!) + (('Time Matrix'!D27*#REF!)*#REF!) + (('Time Matrix'!D27*#REF!)*#REF!) + (('Time Matrix'!D27*#REF!)*#REF!) -> #REF! | E31: =(('Time Matrix'!D27*#REF!)*#REF!) + (('Time Matrix'!D27*#REF!)*#REF!) + (('Time Matrix'!D27*#REF!)*#REF!) + (('Time Matrix'!D27*#REF!)*#REF!) -> #REF! | F31: =(('Time Matrix'!D27*#REF!)*#REF!) + (('Time Matrix'!D27*#REF!)*#REF!) + (('Time Matrix'!D27*#REF!)*#REF!) + (('Time Matrix'!D27*#REF!)*#REF!) -> #REF! | G31: =(('Time Matrix'!D27*#REF!)*#REF!) + (('Time Matrix'!D27*#REF!)*#REF!) + (('Time Matrix'!D27*#REF!)*#REF!) + (('Time Matrix'!D27*#REF!)*#REF!) -> #REF! | H31: =(('Time Matrix'!D27*#REF!)*#REF!) + (('Time Matrix'!D27*#REF!)*#REF!) + (('Time Matrix'!D27*#REF!)*#REF!) + (('Time Matrix'!D27*#REF!)*#REF!) -> #REF!
A32: 705010835 | B32: RH FAIRING | C32: =(('Time Matrix'!D28*#REF!)*'Mon (103)'!#REF!) + (('Time Matrix'!D28*#REF!)*'Mon (103)'!#REF!) + (('Time Matrix'!D28*#REF!)*'Mon (103)'!#REF!) + (('Time Matrix'!D28*#REF!)*'Mon (103)'!#REF!) -> #REF! | D32: =(('Time Matrix'!D28*#REF!)*#REF!) + (('Time Matrix'!D28*#REF!)*#REF!) + (('Time Matrix'!D28*#REF!)*#REF!) + (('Time Matrix'!D28*#REF!)*#REF!) -> #REF! | E32: =(('Time Matrix'!D28*#REF!)*#REF!) + (('Time Matrix'!D28*#REF!)*#REF!) + (('Time Matrix'!D28*#REF!)*#REF!) + (('Time Matrix'!D28*#REF!)*#REF!) -> #REF! | F32: =(('Time Matrix'!D28*#REF!)*#REF!) + (('Time Matrix'!D28*#REF!)*#REF!) + (('Time Matrix'!D28*#REF!)*#REF!) + (('Time Matrix'!D28*#REF!)*#REF!) -> #REF! | G32: =(('Time Matrix'!D28*#REF!)*#REF!) + (('Time Matrix'!D28*#REF!)*#REF!) + (('Time Matrix'!D28*#REF!)*#REF!) + (('Time Matrix'!D28*#REF!)*#REF!) -> #REF! | H32: =(('Time Matrix'!D28*#REF!)*#REF!) + (('Time Matrix'!D28*#REF!)*#REF!) + (('Time Matrix'!D28*#REF!)*#REF!) + (('Time Matrix'!D28*#REF!)*#REF!) -> #REF!
A33: 705010851 | B33: LH FAIRING | C33: =(('Time Matrix'!D29*#REF!)*'Mon (103)'!#REF!) + (('Time Matrix'!D29*#REF!)*'Mon (103)'!#REF!) + (('Time Matrix'!D29*#REF!)*'Mon (103)'!#REF!) + (('Time Matrix'!D29*#REF!)*'Mon (103)'!#REF!) -> #REF! | D33: =(('Time Matrix'!D29*#REF!)*#REF!) + (('Time Matrix'!D29*#REF!)*#REF!) + (('Time Matrix'!D29*#REF!)*#REF!) + (('Time Matrix'!D29*#REF!)*#REF!) -> #REF! | E33: =(('Time Matrix'!D29*#REF!)*#REF!) + (('Time Matrix'!D29*#REF!)*#REF!) + (('Time Matrix'!D29*#REF!)*#REF!) + (('Time Matrix'!D29*#REF!)*#REF!) -> #REF! | F33: =(('Time Matrix'!D29*#REF!)*#REF!) + (('Time Matrix'!D29*#REF!)*#REF!) + (('Time Matrix'!D29*#REF!)*#REF!) + (('Time Matrix'!D29*#REF!)*#REF!) -> #REF! | G33: =(('Time Matrix'!D29*#REF!)*#REF!) + (('Time Matrix'!D29*#REF!)*#REF!) + (('Time Matrix'!D29*#REF!)*#REF!) + (('Time Matrix'!D29*#REF!)*#REF!) -> #REF! | H33: =(('Time Matrix'!D29*#REF!)*#REF!) + (('Time Matrix'!D29*#REF!)*#REF!) + (('Time Matrix'!D29*#REF!)*#REF!) + (('Time Matrix'!D29*#REF!)*#REF!) -> #REF!
A34: 708200366 | B34: HOOD | C34: =(('Time Matrix'!D30*#REF!)*'Mon (103)'!#REF!) + (('Time Matrix'!D30*#REF!)*'Mon (103)'!#REF!) + (('Time Matrix'!D30*#REF!)*'Mon (103)'!#REF!) + (('Time Matrix'!D30*#REF!)*'Mon (103)'!#REF!) -> #REF! | D34: =(('Time Matrix'!D30*#REF!)*#REF!) + (('Time Matrix'!D30*#REF!)*#REF!) + (('Time Matrix'!D30*#REF!)*#REF!) + (('Time Matrix'!D30*#REF!)*#REF!) -> #REF! | E34: =(('Time Matrix'!D30*#REF!)*#REF!) + (('Time Matrix'!D30*#REF!)*#REF!) + (('Time Matrix'!D30*#REF!)*#REF!) + (('Time Matrix'!D30*#REF!)*#REF!) -> #REF! | F34: =(('Time Matrix'!D30*#REF!)*#REF!) + (('Time Matrix'!D30*#REF!)*#REF!) + (('Time Matrix'!D30*#REF!)*#REF!) + (('Time Matrix'!D30*#REF!)*#REF!) -> #REF! | G34: =(('Time Matrix'!D30*#REF!)*#REF!) + (('Time Matrix'!D30*#REF!)*#REF!) + (('Time Matrix'!D30*#REF!)*#REF!) + (('Time Matrix'!D30*#REF!)*#REF!) -> #REF! | H34: =(('Time Matrix'!D30*#REF!)*#REF!) + (('Time Matrix'!D30*#REF!)*#REF!) + (('Time Matrix'!D30*#REF!)*#REF!) + (('Time Matrix'!D30*#REF!)*#REF!) -> #REF!
A35: 708200401 | B35: LH VENT PANEL | C35: =(('Time Matrix'!D31*#REF!)*'Mon (103)'!#REF!) + (('Time Matrix'!D31*#REF!)*'Mon (103)'!#REF!) + (('Time Matrix'!D31*#REF!)*'Mon (103)'!#REF!) + (('Time Matrix'!D31*#REF!)*'Mon (103)'!#REF!) -> #REF! | D35: =(('Time Matrix'!D31*#REF!)*#REF!) + (('Time Matrix'!D31*#REF!)*#REF!) + (('Time Matrix'!D31*#REF!)*#REF!) + (('Time Matrix'!D31*#REF!)*#REF!) -> #REF! | E35: =(('Time Matrix'!D31*#REF!)*#REF!) + (('Time Matrix'!D31*#REF!)*#REF!) + (('Time Matrix'!D31*#REF!)*#REF!) + (('Time Matrix'!D31*#REF!)*#REF!) -> #REF! | F35: =(('Time Matrix'!D31*#REF!)*#REF!) + (('Time Matrix'!D31*#REF!)*#REF!) + (('Time Matrix'!D31*#REF!)*#REF!) + (('Time Matrix'!D31*#REF!)*#REF!) -> #REF! | G35: =(('Time Matrix'!D31*#REF!)*#REF!) + (('Time Matrix'!D31*#REF!)*#REF!) + (('Time Matrix'!D31*#REF!)*#REF!) + (('Time Matrix'!D31*#REF!)*#REF!) -> #REF! | H35: =(('Time Matrix'!D31*#REF!)*#REF!) + (('Time Matrix'!D31*#REF!)*#REF!) + (('Time Matrix'!D31*#REF!)*#REF!) + (('Time Matrix'!D31*#REF!)*#REF!) -> #REF!
A36: 708200402 | B36: RH VENT PANEL | C36: =(('Time Matrix'!D32*#REF!)*'Mon (103)'!#REF!) + (('Time Matrix'!D32*#REF!)*'Mon (103)'!#REF!) + (('Time Matrix'!D32*#REF!)*'Mon (103)'!#REF!) + (('Time Matrix'!D32*#REF!)*'Mon (103)'!#REF!) -> #REF! | D36: =(('Time Matrix'!D32*#REF!)*#REF!) + (('Time Matrix'!D32*#REF!)*#REF!) + (('Time Matrix'!D32*#REF!)*#REF!) + (('Time Matrix'!D32*#REF!)*#REF!) -> #REF! | E36: =(('Time Matrix'!D32*#REF!)*#REF!) + (('Time Matrix'!D32*#REF!)*#REF!) + (('Time Matrix'!D32*#REF!)*#REF!) + (('Time Matrix'!D32*#REF!)*#REF!) -> #REF! | F36: =(('Time Matrix'!D32*#REF!)*#REF!) + (('Time Matrix'!D32*#REF!)*#REF!) + (('Time Matrix'!D32*#REF!)*#REF!) + (('Time Matrix'!D32*#REF!)*#REF!) -> #REF! | G36: =(('Time Matrix'!D32*#REF!)*#REF!) + (('Time Matrix'!D32*#REF!)*#REF!) + (('Time Matrix'!D32*#REF!)*#REF!) + (('Time Matrix'!D32*#REF!)*#REF!) -> #REF! | H36: =(('Time Matrix'!D32*#REF!)*#REF!) + (('Time Matrix'!D32*#REF!)*#REF!) + (('Time Matrix'!D32*#REF!)*#REF!) + (('Time Matrix'!D32*#REF!)*#REF!) -> #REF!
A37: 708200698 | B37: FRONT FASCIA | C37: =(('Time Matrix'!D33*#REF!)*'Mon (103)'!#REF!) + (('Time Matrix'!D33*#REF!)*'Mon (103)'!#REF!) + (('Time Matrix'!D33*#REF!)*'Mon (103)'!#REF!) + (('Time Matrix'!D33*#REF!)*'Mon (103)'!#REF!) -> #REF! | D37: =(('Time Matrix'!D33*#REF!)*#REF!) + (('Time Matrix'!D33*#REF!)*#REF!) + (('Time Matrix'!D33*#REF!)*#REF!) + (('Time Matrix'!D33*#REF!)*#REF!) -> #REF! | E37: =(('Time Matrix'!D33*#REF!)*#REF!) + (('Time Matrix'!D33*#REF!)*#REF!) + (('Time Matrix'!D33*#REF!)*#REF!) + (('Time Matrix'!D33*#REF!)*#REF!) -> #REF! | F37: =(('Time Matrix'!D33*#REF!)*#REF!) + (('Time Matrix'!D33*#REF!)*#REF!) + (('Time Matrix'!D33*#REF!)*#REF!) + (('Time Matrix'!D33*#REF!)*#REF!) -> #REF! | G37: =(('Time Matrix'!D33*#REF!)*#REF!) + (('Time Matrix'!D33*#REF!)*#REF!) + (('Time Matrix'!D33*#REF!)*#REF!) + (('Time Matrix'!D33*#REF!)*#REF!) -> #REF! | H37: =(('Time Matrix'!D33*#REF!)*#REF!) + (('Time Matrix'!D33*#REF!)*#REF!) + (('Time Matrix'!D33*#REF!)*#REF!) + (('Time Matrix'!D33*#REF!)*#REF!) -> #REF!
A38: 708301201 | B38: COVER BOX | C38: =(('Time Matrix'!D34*#REF!)*'Mon (103)'!#REF!) + (('Time Matrix'!D34*#REF!)*'Mon (103)'!#REF!) + (('Time Matrix'!D34*#REF!)*'Mon (103)'!#REF!) + (('Time Matrix'!D34*#REF!)*'Mon (103)'!#REF!) -> #REF! | D38: =(('Time Matrix'!D34*#REF!)*#REF!) + (('Time Matrix'!D34*#REF!)*#REF!) + (('Time Matrix'!D34*#REF!)*#REF!) + (('Time Matrix'!D34*#REF!)*#REF!) -> #REF! | E38: =(('Time Matrix'!D34*#REF!)*#REF!) + (('Time Matrix'!D34*#REF!)*#REF!) + (('Time Matrix'!D34*#REF!)*#REF!) + (('Time Matrix'!D34*#REF!)*#REF!) -> #REF! | F38: =(('Time Matrix'!D34*#REF!)*#REF!) + (('Time Matrix'!D34*#REF!)*#REF!) + (('Time Matrix'!D34*#REF!)*#REF!) + (('Time Matrix'!D34*#REF!)*#REF!) -> #REF! | G38: =(('Time Matrix'!D34*#REF!)*#REF!) + (('Time Matrix'!D34*#REF!)*#REF!) + (('Time Matrix'!D34*#REF!)*#REF!) + (('Time Matrix'!D34*#REF!)*#REF!) -> #REF! | H38: =(('Time Matrix'!D34*#REF!)*#REF!) + (('Time Matrix'!D34*#REF!)*#REF!) + (('Time Matrix'!D34*#REF!)*#REF!) + (('Time Matrix'!D34*#REF!)*#REF!) -> #REF!
A39: Total: | C39: =SUM(C30:C38) -> #REF! | D39: =SUM(D30:D38) -> #REF! | E39: =SUM(E30:E38) -> #REF! | F39: =SUM(F30:F38) -> #REF! | G39: =SUM(G30:G38) -> #REF! | H39: =SUM(H30:H38) -> #REF!
A40: Vegas White (Spyder)
A41: 705009213 | B41: LH F3T LOW FAIRING | C41: =(('Time Matrix'!E35*#REF!)*'Mon (103)'!#REF!) + (('Time Matrix'!E35*#REF!)*'Mon (103)'!#REF!) + (('Time Matrix'!E35*#REF!)*'Mon (103)'!#REF!) + (('Time Matrix'!E35*#REF!)*'Mon (103)'!#REF!) -> #REF! | D41: =(('Time Matrix'!E35*#REF!)*#REF!) + (('Time Matrix'!E35*#REF!)*#REF!) + (('Time Matrix'!E35*#REF!)*#REF!) + (('Time Matrix'!E35*#REF!)*#REF!) -> #REF! | E41: =(('Time Matrix'!E35*#REF!)*#REF!) + (('Time Matrix'!E35*#REF!)*#REF!) + (('Time Matrix'!E35*#REF!)*#REF!) + (('Time Matrix'!E35*#REF!)*#REF!) -> #REF! | F41: =(('Time Matrix'!E35*#REF!)*#REF!) + (('Time Matrix'!E35*#REF!)*#REF!) + (('Time Matrix'!E35*#REF!)*#REF!) + (('Time Matrix'!E35*#REF!)*#REF!) -> #REF! | G41: =(('Time Matrix'!E35*#REF!)*#REF!) + (('Time Matrix'!E35*#REF!)*#REF!) + (('Time Matrix'!E35*#REF!)*#REF!) + (('Time Matrix'!E35*#REF!)*#REF!) -> #REF! | H41: =(('Time Matrix'!E35*#REF!)*#REF!) + (('Time Matrix'!E35*#REF!)*#REF!) + (('Time Matrix'!E35*#REF!)*#REF!) + (('Time Matrix'!E35*#REF!)*#REF!) -> #REF!
A42: 705009214 | B42: RH F3T LOW FAIRING | C42: =(('Time Matrix'!E36*#REF!)*'Mon (103)'!#REF!) + (('Time Matrix'!E36*#REF!)*'Mon (103)'!#REF!) + (('Time Matrix'!E36*#REF!)*'Mon (103)'!#REF!) + (('Time Matrix'!E36*#REF!)*'Mon (103)'!#REF!) -> #REF! | D42: =(('Time Matrix'!E36*#REF!)*#REF!) + (('Time Matrix'!E36*#REF!)*#REF!) + (('Time Matrix'!E36*#REF!)*#REF!) + (('Time Matrix'!E36*#REF!)*#REF!) -> #REF! | E42: =(('Time Matrix'!E36*#REF!)*#REF!) + (('Time Matrix'!E36*#REF!)*#REF!) + (('Time Matrix'!E36*#REF!)*#REF!) + (('Time Matrix'!E36*#REF!)*#REF!) -> #REF! | F42: =(('Time Matrix'!E36*#REF!)*#REF!) + (('Time Matrix'!E36*#REF!)*#REF!) + (('Time Matrix'!E36*#REF!)*#REF!) + (('Time Matrix'!E36*#REF!)*#REF!) -> #REF! | G42: =(('Time Matrix'!E36*#REF!)*#REF!) + (('Time Matrix'!E36*#REF!)*#REF!) + (('Time Matrix'!E36*#REF!)*#REF!) + (('Time Matrix'!E36*#REF!)*#REF!) -> #REF! | H42: =(('Time Matrix'!E36*#REF!)*#REF!) + (('Time Matrix'!E36*#REF!)*#REF!) + (('Time Matrix'!E36*#REF!)*#REF!) + (('Time Matrix'!E36*#REF!)*#REF!) -> #REF!
A43: 705010835 | B43: RH FAIRING | C43: =(('Time Matrix'!E37*#REF!)*'Mon (103)'!#REF!) + (('Time Matrix'!E37*#REF!)*'Mon (103)'!#REF!) + (('Time Matrix'!E37*#REF!)*'Mon (103)'!#REF!) + (('Time Matrix'!E37*#REF!)*'Mon (103)'!#REF!) -> #REF! | D43: =(('Time Matrix'!E37*#REF!)*#REF!) + (('Time Matrix'!E37*#REF!)*#REF!) + (('Time Matrix'!E37*#REF!)*#REF!) + (('Time Matrix'!E37*#REF!)*#REF!) -> #REF! | E43: =(('Time Matrix'!E37*#REF!)*#REF!) + (('Time Matrix'!E37*#REF!)*#REF!) + (('Time Matrix'!E37*#REF!)*#REF!) + (('Time Matrix'!E37*#REF!)*#REF!) -> #REF! | F43: =(('Time Matrix'!E37*#REF!)*#REF!) + (('Time Matrix'!E37*#REF!)*#REF!) + (('Time Matrix'!E37*#REF!)*#REF!) + (('Time Matrix'!E37*#REF!)*#REF!) -> #REF! | G43: =(('Time Matrix'!E37*#REF!)*#REF!) + (('Time Matrix'!E37*#REF!)*#REF!) + (('Time Matrix'!E37*#REF!)*#REF!) + (('Time Matrix'!E37*#REF!)*#REF!) -> #REF! | H43: =(('Time Matrix'!E37*#REF!)*#REF!) + (('Time Matrix'!E37*#REF!)*#REF!) + (('Time Matrix'!E37*#REF!)*#REF!) + (('Time Matrix'!E37*#REF!)*#REF!) -> #REF!
...

Sheet Time Matrix
A1: Gun on Time
A2: Part | B2: Hyper Silver (Spyder) | C2: Deep Black (Spyder) | D2: Manta Green (Spyder F3 / F3T) | E2: Vegas White (Spyder) | F2: Metelix - Spoilers | G2: Electrolux (Smoke) | H2: Laval Summit White | I2: Laval Waymo Black | J2: Manterra - Hyper Silver | K2: Splash Guards - Black Carbon | L2: Mitchell Plastics | M2: Evinrude White | N2: Smoke Grey (Evinrude) | O2: Red Mica Snipe | P2: Red Mica Osprey | Q2: Orbital Blue Snipe | R2: Orbital Blue Osprey
A3: LH Trim | B3: 0.066666667
A4: RH Trim | B4: 0.066666667
A5: RH Fender | B5: 0.066666667
A6: LH Fender | B6: 0.066666667
A7: LH Upper Fairing | B7: 0.066666667
A8: RH Upper Fairing | B8: 0.066666667
A9: Rear Fairing | B9: 0.066666667
A10: R66 Hood | B10: 0.066666667
A11: LH Front Fairing | B11: 0.066666667
A12: RH Front Fairing | B12: 0.066666667
A13: LH Box Cover | B13: 0.066666667
A14: RH Box Cover | B14: 0.066666667
... A18: RH Mirror Shell | B18: 0.066666667
A19: Tail Fairing | C19: 0.066666667
A20: LH Console Panel | C20: 0.066666667
A21: RH Console Panel | C21: 0.066666667
A22: LH Console Fairing | C22: 0.066666667
A23: RH Console Fairing | C23: 0.066666667
A24: Tank Cover | C24: 0.066666667
A25: Tank Cover with Hole | C25: 0.066666667
A26: LH LOW FAIRING | D26: 0.066666667
A27: RH LOW FAIRING | D27: 0.066666667
A28: RH FAIRING | D28: 0.066666667
A29: LH FAIRING | D29: 0.066666667
A30: HOOD | D30: 0.066666667
A31: LH VENT PANEL | D31: 0.066666667
A32: RH VENT PANEL | D32: 0.066666667
A33: FRONT FASCIA | D33: 0.066666667
A34: COVER BOX | D34: 0.066666667
A35: LH F3T LOW FAIRING | E35: 0.066666667
A36: RH F3T LOW FAIRING | E36: 0.066666667
A37: RH FAIRING | E37: 0.066666667
A38: LH FAIRING | E38: 0.066666667
A39: RH FENDER | E39: 0.066666667
A40: LH FENDER | E40: 0.066666667
A41: HOOD | E41: 0.066666667
A42: LH VENT PANEL | E42: 0.066666667
A43: RH VENT PANEL | E43: 0.066666667
...

Sheet Mon (103)
A1: 103 LINE LOAD SHEET | J1: Date: | M1: ='Weekly Plan'!H1 -> 45299
A2: Order of Colours:
A4: Hyper Silver | G4: Black - Laval | M4: Mitchell Plastics
A5: ='Weekly Plan'!F4 -> 705014100 | B5: Hyper Silver | C5: ='Weekly Plan'!G4 -> LH Upper Fairing | D5: =IF('Weekly Plan'!H4=0,"",'Weekly Plan'!H4) | E5: ='Weekly Plan'!A4 -> 2 | F5: =IFERROR(D5/E5,0) -> 0 | G5: ='Weekly Plan'!F69 -> 99944 | H5: Black | I5: ='Weekly Plan'!G69 -> Bezel | J5: =IF('Weekly Plan'!H69=0,"",'Weekly Plan'!H69) | K5: ='Weekly Plan'!A69 -> 2 | L5: =IFERROR(J5/K5,0) -> 0 | M5: ='Weekly Plan'!F94 -> 80931 | N5: ='Weekly Plan'!G94 -> Black - LH | O5: =IF('Weekly Plan'!H94=0,"",'Weekly Plan'!H94) | P5: ='Weekly Plan'!A94 -> 2 | Q5: =IFERROR(O5/P5,0) -> 0 | AC5: 3
A6: ='Weekly Plan'!F5 -> 705014101 | B6: Hyper Silver | C6: ='Weekly Plan'!G5 -> RH Upper Fairing | D6: =IF('Weekly Plan'!H5=0,"",'Weekly Plan'!H5) | E6: ='Weekly Plan'!A5 -> 2 | F6: =IFERROR(D6/E6,0) -> 0 | G6: ='Weekly Plan'!F70 -> 99633 | H6: Black | I6: ='Weekly Plan'!G70 -> IR Cover LH | J6: =IF('Weekly Plan'!H70=0,"",'Weekly Plan'!H70) | K6: ='Weekly Plan'!A70 -> 20 | L6: =IFERROR(J6/K6,0) -> 0 | M6: ='Weekly Plan'!F95 -> 80930 | N6: ='Weekly Plan'!G95 -> Black - RH | O6: =IF('Weekly Plan'!H95=0,"",'Weekly Plan'!H95) | P6: ='Weekly Plan'!A95 -> 2 | Q6: =IFERROR(O6/P6,0) -> 0 | AC6: 4
A7: ='Weekly Plan'!F6 -> 705012976 | B7: Hyper Silver | C7: ='Weekly Plan'!G6 -> LH Fender | D7: =IF('Weekly Plan'!H6=0,"",'Weekly Plan'!H6) | E7: ='Weekly Plan'!A6 -> 2 | F7: =IFERROR(D7/E7,0) -> 0 | G7: ='Weekly Plan'!F71 -> 99646 | H7: Black | I7: ='Weekly Plan'!G71 -> IR Cover RH | J7: =IF('Weekly Plan'!H71=0,"",'Weekly Plan'!H71) | K7: ='Weekly Plan'!A71 -> 20 | L7: =IFERROR(J7/K7,0) -> 0 | M7: ='Weekly Plan'!F96 -> 80933 | N7: ='Weekly Plan'!G96 -> Red - LH | O7: =IF('Weekly Plan'!H96=0,"",'Weekly Plan'!H96) | P7: ='Weekly Plan'!A96 -> 2 | Q7: =IFERROR(O7/P7,0) -> 0 | AC7: 4
A8: ='Weekly Plan'!F7 -> 705012868 | B8: Hyper Silver | C8: ='Weekly Plan'!G7 -> RH Fender | D8: =IF('Weekly Plan'!H7=0,"",'Weekly Plan'!H7) | E8: ='Weekly Plan'!A7 -> 2 | F8: =IFERROR(D8/E8,0) -> 0 | G8: ='Weekly Plan'!F72 -> 99635 | H8: Black | I8: ='Weekly Plan'!G72 -> Lateral Belt LH | J8: =IF('Weekly Plan'!H72=0,"",'Weekly Plan'!H72) | K8: ='Weekly Plan'!A72 -> 6 | L8: =IFERROR(J8/K8,0) -> 0 | M8: ='Weekly Plan'!F97 -> 80932 | N8: ='Weekly Plan'!G97 -> Red - RH | O8: =IF('Weekly Plan'!H97=0,"",'Weekly Plan'!H97) | P8: ='Weekly Plan'!A97 -> 2 | Q8: =IFERROR(O8/P8,0) -> 0 | AC8: 1
A9: ='Weekly Plan'!F8 -> 708003041 | B9: Hyper Silver | C9: ='Weekly Plan'!G8 -> Rear Fairing | D9: =IF('Weekly Plan'!H8=0,"",'Weekly Plan'!H8) | E9: ='Weekly Plan'!A8 -> 2 | F9: =IFERROR(D9/E9,0) -> 0 | G9: ='Weekly Plan'!F73 -> 99944 | H9: Black | I9: ='Weekly Plan'!G73 -> Lateral Belt RH | J9: =IF('Weekly Plan'!H73=0,"",'Weekly Plan'!H73) | K9: ='Weekly Plan'!A73 -> 6 | L9: =IFERROR(J9/K9,0) -> 0 | M9: ='Weekly Plan'!F98 -> Other | N9: ='Weekly Plan'!G98 -> White - LH | O9: =IF('Weekly Plan'!H98=0,"",'Weekly Plan'!H98) | P9: ='Weekly Plan'!A98 -> 2 | Q9: =IFERROR(O9/P9,0) -> 0 | AC9: 1
A10: ='Weekly Plan'!F9 -> 708200870 | B10: Hyper Silver | C10: ='Weekly Plan'!G9 -> LH Front Fairing | D10: =IF('Weekly Plan'!H9=0,"",'Weekly Plan'!H9) | E10: ='Weekly Plan'!A9 -> 1 | F10: =IFERROR(D10/E10,0) -> 0 | G10: ='Weekly Plan'!F74 -> 99636 | H10: Black | I10: ='Weekly Plan'!G74 -> Rear Belt | J10: =IF('Weekly Plan'!H74=0,"",'Weekly Plan'!H74) | K10: ='Weekly Plan'!A74 -> 20 | L10: =IFERROR(J10/K10,0) -> 0 | M10: ='Weekly Plan'!F99 -> Other | N10: ='Weekly Plan'!G99 -> White - RH | O10: =IF('Weekly Plan'!H99=0,"",'Weekly Plan'!H99) | P10: ='Weekly Plan'!A99 -> 2 | Q10: =IFERROR(O10/P10,0) -> 0 | AC10: 3
A11: ='Weekly Plan'!F10 -> 708200871 | B11: Hyper Silver | C11: ='Weekly Plan'!G10 -> RH Front Fairing | D11: =IF('Weekly Plan'!H10=0,"",'Weekly Plan'!H10) | E11: ='Weekly Plan'!A10 -> 1 | F11: =IFERROR(D11/E11,0) -> 0 | AC11: 3
A12: ='Weekly Plan'!F11 -> 708200869 | B12: Hyper Silver | C12: ='Weekly Plan'!G11 -> R66 Hood | D12: =IF('Weekly Plan'!H11=0,"",'Weekly Plan'!H11) | E12: ='Weekly Plan'!A11 -> 1 | F12: =IFERROR(D12/E12,0) -> 0 | G12: Summit White - Laval | M12: Seastar | AC12: 3
A13: ='Weekly Plan'!F12 -> 708302947 | B13: Hyper Silver | C13: ='Weekly Plan'!G12 -> LH Box Cover | D13: =IF('Weekly Plan'!H12=0,"",'Weekly Plan'!H12) | E13: ='Weekly Plan'!A12 -> 2 | F13: =IFERROR(D13/E13,0) -> 0 | G13: ='Weekly Plan'!F76 -> 99629 | H13: Summit White | I13: ='Weekly Plan'!G76 -> Main Lower Cover | J13: =IF('Weekly Plan'!H76=0,"",'Weekly Plan'!H76) | K13: ='Weekly Plan'!A76 -> 1 | L13: =IFERROR(J13/K13,0) -> 0 | M13: ='Weekly Plan'!F81 -> 0 | N13: ='Weekly Plan'!G81 -> Handles | O13: =IF('Weekly Plan'!H81=0,"",'Weekly Plan'!H81) | P13: ='Weekly Plan'!A81 -> 18 | Q13: =IFERROR(O13/P13,0) -> 0 | AC13: 4
A14: ='Weekly Plan'!F13 -> 708302948 | B14: Hyper Silver | C14: ='Weekly Plan'!G13 -> RH Box Cover | D14: =IF('Weekly Plan'!H13=0,"",'Weekly Plan'!H13) | E14: ='Weekly Plan'!A13 -> 2 | F14: =IFERROR(D14/E14,0) -> 0 | G14: ='Weekly Plan'!F77 -> 99631 | H14: Summit White | I14: ='Weekly Plan'!G77 -> Main Upper Cover | J14: =IF('Weekly Plan'!H77=0,"",'Weekly Plan'!H77) | K14: ='Weekly Plan'!A77 -> 1 | L14: =IFERROR(J14/K14,0) -> 0 | M14: ='Weekly Plan'!F82 -> 0 | N14: ='Weekly Plan'!G82 -> 0 | O14: =IF('Weekly Plan'!H82=0,"",'Weekly Plan'!H82) | P14: ='Weekly Plan'!A82 -> 0 | Q14: =IFERROR(O14/P14,0) -> 0 | AC14: 4
A15: ='Weekly Plan'!F14 -> 708303800 | B15: Hyper Silver | C15: ='Weekly Plan'!G14 -> LH F3T Panel | D15: =IF('Weekly Plan'!H14=0,"",'Weekly Plan'!H14) | E15: ='Weekly Plan'!A14 -> 4 | F15: =IFERROR(D15/E15,0) -> 0 | G15: ='Weekly Plan'!F78 -> 99638 | H15: Summit White | I15: ='Weekly Plan'!G78 -> Rear Plate | J15: =IF('Weekly Plan'!H78=0,"",'Weekly Plan'!H78) | K15: ='Weekly Plan'!A78 -> 20 | L15: =IFERROR(J15/K15,0) -> 0 | M15: ='Weekly Plan'!F83 -> 0 | N15: ='Weekly Plan'!G83 -> 0 | O15: =IF('Weekly Plan'!H83=0,"",'Weekly Plan'!H83) | P15: ='Weekly Plan'!A83 -> 0 | Q15: =IFERROR(O15/P15,0) -> 0 | AC15: 4
A16: ='Weekly Plan'!F15 -> 708303801 | B16: Hyper Silver | C16: ='Weekly Plan'!G15 -> RH F3T Panel | D16: =IF('Weekly Plan'!H15=0,"",'Weekly Plan'!H15) | E16: ='Weekly Plan'!A15 -> 4 | F16: =IFERROR(D16/E16,0) -> 0 | G16: ='Weekly Plan'!F79 -> 99630 | H16: Summit White | I16: ='Weekly Plan'!G79 -> Vent Cover | J16: =IF('Weekly Plan'!H79=0,"",'Weekly Plan'!H79) | K16: ='Weekly Plan'!A79 -> 1 | L16: =IFERROR(J16/K16,0) -> 0 | AC16: 2
A17: ='Weekly Plan'!F16 -> 708400461 | B17: Hyper Silver | C17: ='Weekly Plan'!G16 -> LH Mirror Shell -No Hole | D17: =IF('Weekly Plan'!H16=0,"",'Weekly Plan'!H16) | E17: ='Weekly Plan'!A16 -> 2 | F17: =IFERROR(D17/E17,0) -> 0 | M17: Manterra - Hyper Silver | AC17: 1
A18: ='Weekly Plan'!F17 -> 708400463 | B18: Hyper Silver | C18: ='Weekly Plan'!G17 -> RH Mirror Shell - No Hole | D18: =IF('Weekly Plan'!H17=0,"",'Weekly Plan'!H17) | E18: ='Weekly Plan'!A17 -> 2 | F18: =IFERROR(D18/E18,0) -> 0 | G18: British Green | M18: ='Weekly Plan'!F85 -> 0 | N18: ='Weekly Plan'!G85 -> Base Dual | O18: =IF('Weekly Plan'!H85=0,"",'Weekly Plan'!H85) | P18: ='Weekly Plan'!A85 -> 6 | Q18: =IFERROR(O18/P18,0) -> 0 | AC18: 1
G19: ='Weekly Plan'!F19 -> 705009213 | H19: British Green | I19: ='Weekly Plan'!G19 -> LH F3T Low Fairing | J19: =IF('Weekly Plan'!H19=0,"",'Weekly Plan'!H19) | K19: ='Weekly Plan'!A19 -> 2 | L19: =IFERROR(J19/K19,0) -> 0 | M19: ='Weekly Plan'!F86 -> 500458 | N19: ='Weekly Plan'!G86 -> Face Plate, DTM, SSR | O19: =IF('Weekly Plan'!H86=0,"",'Weekly Plan'!H86) | P19: ='Weekly Plan'!A86 -> 16 | Q19: =IFERROR(O19/P19,0) -> 0 | AC19: 1
A20: Deep Black | G20: ='Weekly Plan'!F20 -> 705009214 | H20: British Green | I20: ='Weekly Plan'!G20 -> RH F3T Low Fairing | J20: =IF('Weekly Plan'!H20=0,"",'Weekly Plan'!H20) | K20: ='Weekly Plan'!A20 -> 2 | L20: =IFERROR(J20/K20,0) -> 0 | M20: ='Weekly Plan'!F87 -> 500458 | N20: ='Weekly Plan'!G87 -> Face Plate, STM, SSR | O20: =IF('Weekly Plan'!H87=0,"",'Weekly Plan'!H87) | P20: ='Weekly Plan'!A87 -> 16 | Q20: =IFERROR(O20/P20,0) -> 0 | AC20: 2
A21: ='Weekly Plan'!F34 -> 708400287 | B21: Deep Black | C21: ='Weekly Plan'!G34 -> Tank Cover | D21: =IF('Weekly Plan'!H34=0,"",'Weekly Plan'!H34) | E21: ='Weekly Plan'!A34 -> 2 | F21: =IFERROR(D21/E21,0) -> 0 | G21: ='Weekly Plan'!F21 -> 705010835 | H21: British Green | I21: ='Weekly Plan'!G21 -> RH Fairing | J21: =IF('Weekly Plan'!H21=0,"",'Weekly Plan'!H21) | K21: ='Weekly Plan'!A21 -> 1 | L21: =IFERROR(J21/K21,0) -> 0 | AC21: 1
A22: ='Weekly Plan'!F35 -> 705019189 | B22: Deep Black | C22: ='Weekly Plan'!G35 -> New Tank Cover | D22: =IF('Weekly Plan'!H35=0,"",'Weekly Plan'!H35) | E22: ='Weekly Plan'!A35 -> 2 | F22: =IFERROR(D22/E22,0) -> 0 | G22: ='Weekly Plan'!F22 -> 705010851 | H22: British Green | I22: ='Weekly Plan'!G22 -> LH Fairing | J22: =IF('Weekly Plan'!H22=0,"",'Weekly Plan'!H22) | K22: ='Weekly Plan'!A22 -> 1 | L22: =IFERROR(J22/K22,0) -> 0 | M22: Falcon Lakeside Hyper Silver | AC22: 2
A23: ='Weekly Plan'!F36 -> 708001528 | B23: Deep Black | C23: ='Weekly Plan'!G36 -> Tail Fairing | D23: =IF('Weekly Plan'!H36=0,"",'Weekly Plan'!H36) | E23: ='Weekly Plan'!A36 -> 2 | F23: =IFERROR(D23/E23,0) -> 0 | G23: ='Weekly Plan'!F23 -> 705012976 | H23: British Green | I23: ='Weekly Plan'!G23 -> LH Fender | J23: =IF('Weekly Plan'!H23=0,"",'Weekly Plan'!H23) | K23: ='Weekly Plan'!A23 -> 2 | L23: =IFERROR(J23/K23,0) -> 0 | M23: ='Weekly Plan'!F89 -> 2650 | N23: ='Weekly Plan'!G89 -> LH Side Puck | O23: =IF('Weekly Plan'!H89=0,"",'Weekly Plan'!H89) | P23: ='Weekly Plan'!A89 -> 6 | Q23: =IFERROR(O23/P23,0) -> 0 | AC23: 1
A24: ='Weekly Plan'!F37 -> 708400069 | B24: Deep Black | C24: ='Weekly Plan'!G37 -> RH Consol Fairing | D24: =IF('Weekly Plan'!H37=0,"",'Weekly Plan'!H37) | E24: ='Weekly Plan'!A37 -> 2 | F24: =IFERROR(D24/E24,0) -> 0 | G24: ='Weekly Plan'!F24 -> 705012868 | H24: British Green | I24: ='Weekly Plan'!G24 -> RH Fender | J24: =IF('Weekly Plan'!H24=0,"",'Weekly Plan'!H24) | K24: ='Weekly Plan'!A24 -> 2 | L24: =IFERROR(J24/K24,0) -> 0 | M24: ='Weekly Plan'!F90 -> 2651 | N24: ='Weekly Plan'!G90 -> RH Side Puck | O24: =IF('Weekly Plan'!H90=0,"",'Weekly Plan'!H90) | P24: ='Weekly Plan'!A90 -> 6 | Q24: =IFERROR(O24/P24,0) -> 0 | AC24: 2
A25: ='Weekly Plan'!F38 -> 708400067 | B25: Deep Black | C25: ='Weekly Plan'!G38 -> LH Consol Fairing | D25: =IF('Weekly Plan'!H38=0,"",'Weekly Plan'!H38) | E25: ='Weekly Plan'!A38 -> 2 | F25: =IFERROR(D25/E25,0) -> 0 | G25: ='Weekly Plan'!F25 -> 708200366 | H25: British Green | I25: ='Weekly Plan'!G25 -> Hood | J25: =IF('Weekly Plan'!H25=0,"",'Weekly Plan'!H25) | K25: ='Weekly Plan'!A25 -> 1 | L25: =IFERROR(J25/K25,0) -> 0 | M25: ='Weekly Plan'!F91 -> 2647 | N25: ='Weekly Plan'!G91 -> Front Puck | O25: =IF('Weekly Plan'!H91=0,"",'Weekly Plan'!H91) | P25: ='Weekly Plan'!A91 -> 6 | Q25: =IFERROR(O25/P25,0) -> 0 | R25: 18 | AC25: 1
A26: ='Weekly Plan'!F39 -> 708400956 | B26: Deep Black | C26: ='Weekly Plan'!G39 -> New LH Console Panel | D26: =IF('Weekly Plan'!H39=0,"",'Weekly Plan'!H39) | E26: ='Weekly Plan'!A39 -> 2 | F26: =IFERROR(D26/E26,0) -> 0 | G26: ='Weekly Plan'!F26 -> 708200401 | H26: British Green | I26: ='Weekly Plan'!G26 -> LH Vent Panel | J26: =IF('Weekly Plan'!H26=0,"",'Weekly Plan'!H26) | K26: ='Weekly Plan'!A26 -> 2 | L26: =IFERROR(J26/K26,0) -> 0 | M26: ='Weekly Plan'!F92 -> 0 | N26: ='Weekly Plan'!G92 -> 0 | O26: =IF('Weekly Plan'!H92=0,"",'Weekly Plan'!H92) | P26: ='Weekly Plan'!A92 -> 0 | Q26: =IFERROR(O26/P26,0) -> 0 | AC26: 1
A27: ='Weekly Plan'!F40 -> 708400957 | B27: Deep Black | C27: ='Weekly Plan'!G40 -> New RH Console Panel | D27: =IF('Weekly Plan'!H40=0,"",'Weekly Plan'!H40) | E27: ='Weekly Plan'!A40 -> 2 | F27: =IFERROR(D27/E27,0) -> 0 | G27: ='Weekly Plan'!F27 -> 708200402 | H27: British Green | I27: ='Weekly Plan'!G27 -> RH Vent Panel | J27: =IF('Weekly Plan'!H27=0,"",'Weekly Plan'!H27) | K27: ='Weekly Plan'!A27 -> 2 | L27: =IFERROR(J27/K27,0) -> 0 | P27: ='Weekly Plan'!A93 -> 0 | AC27: 1
A28: ='Weekly Plan'!F41 -> 708400722 | B28: Deep Black | C28: ='Weekly Plan'!G41 -> New Nose Fairing | D28: =IF('Weekly Plan'!H41=0,"",'Weekly Plan'!H41) | E28: ='Weekly Plan'!A41 -> 2 | F28: =IFERROR(D28/E28,0) -> 0 | G28: ='Weekly Plan'!F28 -> 708200698 | H28: British Green | I28: ='Weekly Plan'!G28 -> Fascia | J28: =IF('Weekly Plan'!H28=0,"",'Weekly Plan'!H28) | K28: ='Weekly Plan'!A28 -> 1 | L28: =IFERROR(J28/K28,0) -> 0 | M28: Tesla - High Gloss Black | P28: ='Weekly Plan'!A94 -> 2 | AC28: 2
A29: ='Weekly Plan'!F42 -> 708400721 | B29: Deep Black | C29: ='Weekly Plan'!G42 -> New Tail Fairing | D29: =IF('Weekly Plan'!H42=0,"",'Weekly Plan'!H42) | E29: ='Weekly Plan'!A42 -> 8 | F29: =IFERROR(D29/E29,0) -> 0 | G29: ='Weekly Plan'!F29 -> 708301214 | H29: British Green | I29: ='Weekly Plan'!G29 -> LH Cover | J29: =IF('Weekly Plan'!H29=0,"",'Weekly Plan'!H29) | K29: ='Weekly Plan'!A29 -> 1 | L29: =IFERROR(J29/K29,0) -> 0 | M29: ='Weekly Plan'!F101 -> 9929 | N29: ='Weekly Plan'!G101 -> MS Applique | O29: =IF('Weekly Plan'!H101=0,"",'Weekly Plan'!H101) | P29: ='Weekly Plan'!A101 -> 6 | Q29: =IFERROR(O29/P29,0) -> 0 | R29: 21
A30: ='Weekly Plan'!F43 -> 708400462 | B30: Deep Black | C30: ='Weekly Plan'!G43 -> LH Mirror Shell | D30: =IF('Weekly Plan'!H43=0,"",'Weekly Plan'!H43) | E30: ='Weekly Plan'!A43 -> 2 | F30: =IFERROR(D30/E30,0) -> 0 | G30: ='Weekly Plan'!F30 -> 708301215 | H30: British Green | I30: ='Weekly Plan'!G30 -> RH Cover | J30: =IF('Weekly Plan'!H30=0,"",'Weekly Plan'!H30) | K30: ='Weekly Plan'!A30 -> 1 | L30: =IFERROR(J30/K30,0) -> 0 | M30: ='Weekly Plan'!F102 -> 9931 | N30: ='Weekly Plan'!G102 -> MX Applique | O30: =IF('Weekly Plan'!H102=0,"",'Weekly Plan'!H102) | P30: ='Weekly Plan'!A102 -> 6 | Q30: =IFERROR(O30/P30,0) -> 0 | AC30: 1
A31: ='Weekly Plan'!F44 -> 708400464 | B31: Deep Black | C31: ='Weekly Plan'!G44 -> RH Mirror Shell | D31: =IF('Weekly Plan'!H44=0,"",'Weekly Plan'!H44) | E31: ='Weekly Plan'!A44 -> 2 | F31: =IFERROR(D31/E31,0) -> 0 | G31: ='Weekly Plan'!F31 -> 708303800 | H31: British Green | I31: ='Weekly Plan'!G31 -> LH F3T Panel | J31: =IF('Weekly Plan'!H31=0,"",'Weekly Plan'!H31) | K31: ='Weekly Plan'!A31 -> 4 | L31: =IFERROR(J31/K31,0) -> 0 | M31: ='Weekly Plan'!F103 -> 0 | N31: ='Weekly Plan'!G103 -> MS Applique Rework | O31: =IF('Weekly Plan'!H103=0,"",'Weekly Plan'!H103) | P31: ='Weekly Plan'!A103 -> 6 | Q31: =IFERROR(O31/P31,0) -> 0 | AC31: 1
A32: ='Weekly Plan'!F45 -> 708400461 | B32: Deep Black | C32: ='Weekly Plan'!G45 -> LH Mirror Shell - No Hole | D32: =IF('Weekly Plan'!H45=0,"",'Weekly Plan'!H45) | E32: ='Weekly Plan'!A45 -> 2 | F32: =IFERROR(D32/E32,0) -> 0 | G32: ='Weekly Plan'!F32 -> 708303801 | H32: British Green | I32: ='Weekly Plan'!G32 -> RH F3T Panel | J32: =IF('Weekly Plan'!H32=0,"",'Weekly Plan'!H32) | K32: ='Weekly Plan'!A32 -> 4 | L32: =IFERROR(J32/K32,0) -> 0 | M32: ='Weekly Plan'!F104 -> 0 | N32: ='Weekly Plan'!G104 -> MX Applique Rework | O32: =IF('Weekly Plan'!H104=0,"",'Weekly Plan'!H104) | P32: ='Weekly Plan'!A104 -> 6 | Q32: =IFERROR(O32/P32,0) -> 0 | AC32: 1
A33: ='Weekly Plan'!F46 -> 708400463 | B33: Deep Black | C33: ='Weekly Plan'!G46 -> RH Mirror Shell - No Hole | D33: =IF('Weekly Plan'!H46=0,"",'Weekly Plan'!H46) | E33: ='Weekly Plan'!A46 -> 2 | F33: =IFERROR(D33/E33,0) -> 0 | K33: ='Weekly Plan'!A33 -> 0 | L33: =IFERROR(J33/K33,0) -> 0 | AC33: 1
A34: ='Weekly Plan'!F47 -> 705012976 | B34: Deep Black | C34: ='Weekly Plan'!G47 -> LH Fender | D34: =IF('Weekly Plan'!H47=0,"",'Weekly Plan'!H47) | E34: ='Weekly Plan'!A47 -> 2 | F34: =IFERROR(D34/E34,0) -> 0 | AC34: 2
A35: ='Weekly Plan'!F48 -> 705012868 | B35: Deep Black | C35: ='Weekly Plan'!G48 -> RH Fender | D35: =IF('Weekly Plan'!H48=0,"",'Weekly Plan'!H48) | E35: ='Weekly Plan'!A48 -> 2 | F35: =IFERROR(D35/E35,0) -> 0 | G35: Comments | M35: Colour | N35: Time (mins) | R35: 4 | AC35: 1
A36: ='Weekly Plan'!F49 -> 705011169 | B36: Deep Black | C36: ='Weekly Plan'!G49 -> LH Scoop | D36: =IF('Weekly Plan'!H49=0,"",'Weekly Plan'!H49) | E36: ='Weekly Plan'!A49 -> 2 | F36: =IFERROR(D36/E36,0) -> 0 | M36: =A4 -> Hyper Silver | N36: =SUM(F5:F18) -> 0 | R36: 2 | AC36: 1
A37: ='Weekly Plan'!F50 -> 705011170 | B37: Deep Black | C37: ='Weekly Plan'!G50 -> RH Scoop | D37: =IF('Weekly Plan'!H50=0,"",'Weekly Plan'!H50) | E37: ='Weekly Plan'!A50 -> 2 | F37: =IFERROR(D37/E37,0) -> 0 | M37: =A20 -> Deep Black | N37: =SUM(F21:F39) -> 0 | AC37: 1
