Workbook

Sheet Jan
A1: Date | B1: Into Buff from Line | C1: # Buffers | D1: Ttl Buffed | E1: Ave per person | F1: Ave/hr | G1: Target/ Hr | H1: % Efficiency | J1: Date | K1: Tania | L1: Amy | M1: Anna | N1: Anna D | O1: Hannah | P1: Brian | Q1: Robyn | R1: Renee | S1: Stephanie | T1: Raven | U1: Rachel | AG1: Date | AH1: Returned to Buff | AI1: RW after buff | AJ1: FTQ for buff
A2: 45293 | D2: 323 | E2: =D2/C2 -> #DIV/0! | F2: =E2/8.5 -> #DIV/0! | G2: 10 | H2: =F2/G2 -> #DIV/0! | J2: 44928 | AG2: 44928 | AJ2: =(D2-AH2-AI2)/D2 -> 1
A3: 44929 | D3: 560 | E3: =D3/C3 -> #DIV/0! | F3: =E3/8.5 -> #DIV/0! | G3: 10 | H3: =F3/G3 -> #DIV/0! | J3: 44929 | AG3: 44929 | AJ3: =(D3-AH3-AI3)/D3 -> 1
A4: 44930 | D4: 419 | E4: =D4/C4 -> #DIV/0! | F4: =E4/8.5 -> #DIV/0! | G4: 10 | H4: =F4/G4 -> #DIV/0! | J4: 44930 | AG4: 44930 | AJ4: =(D4-AH4-AI4)/D4 -> 1
A5: 44931 | D5: 402 | E5: =D5/C5 -> #DIV/0! | F5: =E5/8.5 -> #DIV/0! | G5: 10 | H5: =F5/G5 -> #DIV/0! | J5: 44931 | AG5: 44931 | AJ5: =(D5-AH5-AI5)/D5 -> 1
A6: 44934 | D6: 369 | E6: =D6/C6 -> #DIV/0! | F6: =E6/8.5 -> #DIV/0! | G6: 10 | H6: =F6/G6 -> #DIV/0! | J6: 44932 | AG6: 45299 | AJ6: =(D6-AH6-AI6)/D6 -> 1
A7: 44935 | D7: 532 | E7: =D7/C7 -> #DIV/0! | F7: =E7/7.5 -> #DIV/0! | G7: 10 | H7: =F7/G7 -> #DIV/0! | J7: 44935 | AG7: 44935 | AJ7: =(D7-AH7-AI7)/D7 -> 1
A8: 44936 | D8: 525 | E8: =D8/C8 -> #DIV/0! | F8: =E8/7.5 -> #DIV/0! | G8: 10 | H8: =F8/G8 -> #DIV/0! | J8: 44936 | AG8: 44936 | AJ8: =(D8-AH8-AI8)/D8 -> 1
A9: 44937 | D9: 855 | E9: =D9/C9 -> #DIV/0! | F9: =E9/7.5 -> #DIV/0! | G9: 10 | H9: =F9/G9 -> #DIV/0! | J9: 44937 | AG9: 44937 | AJ9: =(D9-AH9-AI9)/D9 -> 1
A10: 44938 | D10: 565 | E10: =D10/C10 -> #DIV/0! | F10: =E10/7.5 -> #DIV/0! | G10: 10 | H10: =F10/G10 -> #DIV/0! | J10: 44938 | AG10: 44938 | AJ10: =(D10-AH10-AI10)/D10 -> 1
A11: 44941 | D11: 603 | E11: =D11/C11 -> #DIV/0! | F11: =E11/7.5 -> #DIV/0! | G11: 10 | H11: =F11/G11 -> #DIV/0! | J11: 44941 | AG11: 44941 | AJ11: =(D11-AH11-AI11)/D11 -> 1
A12: 44942 | D12: 570 | E12: =D12/C12 -> #DIV/0! | F12: =E12/7.5 -> #DIV/0! | G12: 10 | H12: =F12/G12 -> #DIV/0! | J12: 44942 | AG12: 44942 | AJ12: =(D12-AH12-AI12)/D12 -> 1
A13: 44943 | D13: 562 | E13: =D13/C13 -> #DIV/0! | F13: =E13/7.5 -> #DIV/0! | G13: 10 | H13: =F13/G13 -> #DIV/0! | J13: 44943 | AG13: 44943 | AJ13: =(D13-AH13-AI13)/D13 -> 1
A14: 45309 | D14: 598 | E14: =D14/C14 -> #DIV/0! | F14: =E14/7.5 -> #DIV/0! | G14: 10 | H14: =F14/G14 -> #DIV/0! | J14: 44944 | AG14: 44944 | AJ14: =(D14-AH14-AI14)/D14 -> 1
A15: 44945 | D15: 472 | E15: =D15/C15 -> #DIV/0! | F15: =E15/7.5 -> #DIV/0! | G15: 10 | H15: =F15/G15 -> #DIV/0! | J15: 44945 | AG15: 44945 | AJ15: =(D15-AH15-AI15)/D15 -> 1
A16: 44946 | D16: =SUM(K16:AE16) -> 0 | E16: =D16/C16 -> #DIV/0! | F16: =E16/7.5 -> #DIV/0! | G16: 10 | H16: =F16/G16 -> #DIV/0! | J16: 44946 | AG16: 44946 | AJ16: =(D16-AH16-AI16)/D16 -> #DIV/0!
A17: 44949 | D17: =SUM(K17:AE17) -> 0 | E17: =D17/C17 -> #DIV/0! | F17: =E17/7.5 -> #DIV/0! | G17: 10 | H17: =F17/G17 -> #DIV/0! | J17: 44949 | AG17: 44949 | AJ17: =(D17-AH17-AI17)/D17 -> #DIV/0!
A18: 44950 | D18: =SUM(K18:AE18) -> 0 | E18: =D18/C18 -> #DIV/0! | F18: =E18/7.5 -> #DIV/0! | G18: 10 | H18: =F18/G18 -> #DIV/0! | J18: 44950 | AG18: 44950 | AJ18: =(D18-AH18-AI18)/D18 -> #DIV/0!
A19: 44951 | D19: =SUM(K19:AE19) -> 0 | E19: =D19/C19 -> #DIV/0! | F19: =E19/7.5 -> #DIV/0! | G19: 10 | H19: =F19/G19 -> #DIV/0! | J19: 44951 | AG19: 44951 | AJ19: =(D19-AH19-AI19)/D19 -> #DIV/0!
A20: 44952 | D20: =SUM(K20:AE20) -> 0 | E20: =D20/C20 -> #DIV/0! | F20: =E20/7.5 -> #DIV/0! | G20: 10 | H20: =F20/G20 -> #DIV/0! | J20: 44952 | AG20: 44952 | AJ20: =(D20-AH20-AI20)/D20 -> #DIV/0!
A21: 44953 | D21: =SUM(K21:AE21) -> 0 | E21: =D21/C21 -> #DIV/0! | F21: =E21/7.5 -> #DIV/0! | G21: 10 | H21: =F21/G21 -> #DIV/0! | J21: 44953 | AG21: 44953 | AJ21: =(D21-AH21-AI21)/D21 -> #DIV/0!
A22: 44956 | D22: =SUM(K22:AE22) -> 0 | E22: =D22/C22 -> #DIV/0! | F22: =E22/7.5 -> #DIV/0! | G22: 10 | H22: =F22/G22 -> #DIV/0! | J22: 44956 | AG22: 44956 | AJ22: =(D22-AH22-AI22)/D22 -> #DIV/0!
A23: 44957 | D23: =SUM(K23:AE23) -> 0 | E23: =D23/C23 -> #DIV/0! | F23: =E23/7.5 -> #DIV/0! | G23: 10 | H23: =F23/G23 -> #DIV/0! | J23: 44957 | AG23: 44957 | AJ23: =(D23-AH23-AI23)/D23 -> #DIV/0!
A24: Average | D24: =AVERAGE(D3:D23) -> 334.85714 | E24: =AVERAGE(E3:E23) -> #DIV/0! | F24: =E24/7.5 -> #DIV/0! | G24: 10 | H24: =F24/G24 -> #DIV/0! | J24: Average | K24: =AVERAGE(K3:K23) -> #DIV/0! | L24: =AVERAGE(L3:L23) -> #DIV/0! | M24: =AVERAGE(M3:M23) -> #DIV/0! | N24: =AVERAGE(N3:N23) -> #DIV/0! | O24: =AVERAGE(O3:O23) -> #DIV/0! | P24: =AVERAGE(P3:P23) -> #DIV/0! | Q24: =AVERAGE(Q3:Q23) -> #DIV/0! | R24: =AVERAGE(R3:R23) -> #DIV/0! | ... AE24: =AVERAGE(AE3:AE23) -> #DIV/0! | AG24: Average | AH24: =AVERAGE(AH3:AH23) -> #DIV/0! | AI24: =AVERAGE(AI3:AI23) -> #DIV/0! | AJ24: =AVERAGE(AJ3:AJ23) -> #DIV/0!

Sheet Feb
A1: Date | B1: Into Buff from Line | C1: # Buffers | D1: Ttl Buffed | E1: Ave per person | F1: Ave/hr | G1: Target/ Hr | H1: % Efficiency | J1: Date | K1: Akash | L1: Alex | M1: Amy | N1: Anna | O1: Anshad | P1: Arathi | Q1: Brian | R1: Felicia | S1: Gibi | T1: Hrithik | U1: Janice | V1: Jeff | W1: Jenda | X1: Jimmy | Y1: Joe | Z1: Justine | AA1: Kevin | AB1: Michaela | AC1: Nithin | AD1: Renee | AE1: Renjan | AF1: Reny | AG1: Robyn | AH1: Sam | AI1: Sarfraz | AJ1: Sony | AK1: Steph | AL1: Tania | AM1: Tiarra | AN1: Tara | AR1: Date | AS1: Returned to Buff | AT1: RW after buff | AU1: FTQ for buff
A2: 44958 | D2: =SUM(K2:AP2) -> 0 | E2: =D2/C2 -> #DIV/0! | F2: =E2/7.5 -> #DIV/0! | G2: 10 | H2: =F2/G2 -> #DIV/0! | J2: 44958 | AR2: 44958 | AU2: =(D2-AS2-AT2)/D2 -> #DIV/0!
A3: 44959 | D3: =SUM(K3:AP3) -> 0 | E3: =D3/C3 -> #DIV/0! | F3: =E3/7.5 -> #DIV/0! | G3: 10 | H3: =F3/G3 -> #DIV/0! | J3: 44959 | AR3: 44959 | AU3: =(D3-AS3-AT3)/D3 -> #DIV/0!
A4: 44960 | D4: =SUM(K4:AP4) -> 0 | E4: =D4/C4 -> #DIV/0! | F4: =E4/7.5 -> #DIV/0! | G4: 10 | H4: =F4/G4 -> #DIV/0! | J4: 44960 | AR4: 44960 | AU4: =(D4-AS4-AT4)/D4 -> #DIV/0!
A5: 44961 | D5: =SUM(K5:AP5) -> 0 | E5: =D5/C5 -> #DIV/0! | F5: =E5/5 -> #DIV/0! | G5: 10 | H5: =F5/G5 -> #DIV/0! | J5: 44961 | AR5: 44961 | AU5: =(D5-AS5-AT5)/D5 -> #DIV/0!
A6: 44963 | D6: =SUM(K6:AP6) -> 0 | E6: =D6/C6 -> #DIV/0! | F6: =E6/7.5 -> #DIV/0! | G6: 10 | H6: =F6/G6 -> #DIV/0! | J6: 44963 | AR6: 44963 | AU6: =(D6-AS6-AT6)/D6 -> #DIV/0!
A7: 44964 | D7: =SUM(K7:AP7) -> 0 | E7: =D7/C7 -> #DIV/0! | F7: =E7/7.5 -> #DIV/0! | G7: 10 | H7: =F7/G7 -> #DIV/0! | J7: 44964 | AR7: 44964 | AU7: =(D7-AS7-AT7)/D7 -> #DIV/0!
A8: 44965 | D8: =SUM(K8:AP8) -> 0 | E8: =D8/C8 -> #DIV/0! | F8: =E8/7.5 -> #DIV/0! | G8: 10 | H8: =F8/G8 -> #DIV/0! | J8: 44965 | AR8: 44965 | AU8: =(D8-AS8-AT8)/D8 -> #DIV/0!
A9: 44966 | D9: =SUM(K9:AP9) -> 0 | E9: =D9/C9 -> #DIV/0! | F9: =E9/7.5 -> #DIV/0! | G9: 10 | H9: =F9/G9 -> #DIV/0! | J9: 44966 | AR9: 44966 | AU9: =(D9-AS9-AT9)/D9 -> #DIV/0!
A10: 44967 | D10: =SUM(K10:AP10) -> 0 | E10: =D10/C10 -> #DIV/0! | F10: =E10/7.5 -> #DIV/0! | G10: 10 | H10: =F10/G10 -> #DIV/0! | J10: 44967 | AR10: 44967 | AU10: =(D10-AS10-AT10)/D10 -> #DIV/0!
A11: 44968 | D11: =SUM(K11:AP11) -> 0 | E11: =D11/C11 -> #DIV/0! | F11: =E11/5 -> #DIV/0! | G11: 10 | H11: =F11/G11 -> #DIV/0! | J11: 44968 | AR11: 44968 | AU11: =(D11-AS11-AT11)/D11 -> #DIV/0!
A12: 44970 | D12: =SUM(K12:AP12) -> 0 | E12: =D12/C12 -> #DIV/0! | F12: =E12/8.5 -> #DIV/0! | G12: 10 | H12: =F12/G12 -> #DIV/0! | J12: 44970 | AR12: 44970 | AU12: =(D12-AS12-AT12)/D12 -> #DIV/0!
A13: 44971 | D13: =SUM(K13:AP13) -> 0 | E13: =D13/C13 -> #DIV/0! | F13: =E13/8.5 -> #DIV/0! | G13: 10 | H13: =F13/G13 -> #DIV/0! | J13: 44971 | AR13: 44971 | AU13: =(D13-AS13-AT13)/D13 -> #DIV/0!
A14: 44972 | D14: =SUM(K14:AP14) -> 0 | E14: =D14/C14 -> #DIV/0! | F14: =E14/8.5 -> #DIV/0! | G14: 10 | H14: =F14/G14 -> #DIV/0! | J14: 44972 | AR14: 44972 | AU14: =(D14-AS14-AT14)/D14 -> #DIV/0!
A15: 44973 | D15: =SUM(K15:AP15) -> 0 | E15: =D15/C15 -> #DIV/0! | F15: =E15/8.5 -> #DIV/0! | G15: 10 | H15: =F15/G15 -> #DIV/0! | J15: 44973 | AR15: 44973 | AU15: =(D15-AS15-AT15)/D15 -> #DIV/0!
A16: 44974 | D16: =SUM(K16:AP16) -> 0 | E16: =D16/C16 -> #DIV/0! | F16: =E16/8.5 -> #DIV/0! | G16: 10 | H16: =F16/G16 -> #DIV/0! | J16: 44974 | AR16: 44974 | AU16: =(D16-AS16-AT16)/D16 -> #DIV/0!
A17: 44975 | D17: =SUM(K17:AP17) -> 0 | E17: =D17/C17 -> #DIV/0! | F17: =E17/4.5 -> #DIV/0! | G17: 10 | H17: =F17/G17 -> #DIV/0! | J17: 44975 | AR17: 44975 | AU17: =(D17-AS17-AT17)/D17 -> #DIV/0!
A18: 44977 | D18: =SUM(K18:AP18) -> 0 | E18: =D18/C18 -> #DIV/0! | F18: =E18/8.5 -> #DIV/0! | G18: 10 | H18: =F18/G18 -> #DIV/0! | J18: 44977 | AR18: 44977 | AU18: =(D18-AS18-AT18)/D18 -> #DIV/0!
A19: 44978 | D19: =SUM(K19:AP19) -> 0 | E19: =D19/C19 -> #DIV/0! | F19: =E19/8.5 -> #DIV/0! | G19: 10 | H19: =F19/G19 -> #DIV/0! | J19: 44978 | AR19: 44978 | AU19: =(D19-AS19-AT19)/D19 -> #DIV/0!
A20: 44979 | D20: =SUM(K20:AP20) -> 0 | E20: =D20/C20 -> #DIV/0! | F20: =E20/8.5 -> #DIV/0! | G20: 10 | H20: =F20/G20 -> #DIV/0! | J20: 44979 | AR20: 44979 | AU20: =(D20-AS20-AT20)/D20 -> #DIV/0!
A21: 44980 | D21: =SUM(K21:AP21) -> 0 | E21: =D21/C21 -> #DIV/0! | F21: =E21/8.5 -> #DIV/0! | G21: 10 | H21: =F21/G21 -> #DIV/0! | J21: 44980 | AR21: 44980 | AU21: =(D21-AS21-AT21)/D21 -> #DIV/0!
A22: 44981 | D22: =SUM(K22:AP22) -> 0 | E22: =D22/C22 -> #DIV/0! | F22: =E22/8.5 -> #DIV/0! | G22: 10 | H22: =F22/G22 -> #DIV/0! | J22: 44981 | AR22: 44981 | AU22: =(D22-AS22-AT22)/D22 -> #DIV/0!
A23: 44982 | D23: =SUM(K23:AP23) -> 0 | E23: =D23/C23 -> #DIV/0! | F23: =E23/4.75 -> #DIV/0! | G23: 10 | H23: =F23/G23 -> #DIV/0! | J23: 44982 | AR23: 44982 | AU23: =(D23-AS23-AT23)/D23 -> #DIV/0!
A24: 44984 | D24: =SUM(K24:AP24) -> 0 | E24: =D24/C24 -> #DIV/0! | F24: =E24/8.5 -> #DIV/0! | G24: 10 | H24: =F24/G24 -> #DIV/0! | J24: 44984 | AR24: 44984 | AU24: =(D24-AS24-AT24)/D24 -> #DIV/0!
A25: 44985 | D25: =SUM(K25:AP25) -> 0 | E25: =D25/C25 -> #DIV/0! | F25: =E25/8.5 -> #DIV/0! | G25: 10 | H25: =F25/G25 -> #DIV/0! | J25: 44985 | AR25: 44985 | AU25: =(D25-AS25-AT25)/D25 -> #DIV/0!
A26: Average | B26: =AVERAGE(B2:B25) -> #DIV/0! | C26: =AVERAGE(C2:C25) -> #DIV/0! | D26: =AVERAGE(D2:D25) -> 0 | E26: =AVERAGE(E2:E25) -> #DIV/0! | F26: =E26/8.5 -> #DIV/0! | G26: 10 | H26: =F26/G26 -> #DIV/0! | J26: Average | K26: =AVERAGE(K2:K25) -> #DIV/0! | L26: =AVERAGE(L2:L25) -> #DIV/0! | M26: =AVERAGE(M2:M25) -> #DIV/0! | N26: =AVERAGE(N2:N25) -> #DIV/0! | O26: =AVERAGE(O2:O25) -> #DIV/0! | P26: =AVERAGE(P2:P25) -> #DIV/0! | Q26: =AVERAGE(Q2:Q25) -> #DIV/0! | R26: =AVERAGE(R2:R25) -> #DIV/0! | ... AP26: =AVERAGE(AP2:AP25) -> #DIV/0! | AR26: Average | AS26: =AVERAGE(AS2:AS25) -> #DIV/0! | AT26: =AVERAGE(AT2:AT25) -> #DIV/0! | AU26: =AVERAGE(AU2:AU25) -> #DIV/0!
A27: Total | B27: =SUM(B2:B25) -> 0 | D27: =SUM(D2:D25) -> 0 | AS27: =SUM(AS2:AS25) -> 0 | AT27: =SUM(AT2:AT25) -> 0 | AU27: =(D27-AS27-AT27)/D27 -> #DIV/0!

Sheet Mar
A1: Date | B1: Into Buff from Line | C1: # Buffers | D1: Ttl Buffed | E1: Ave per person | F1: Ave/hr | G1: Target/ Hr | H1: % Efficiency | J1: Date | K1: Akash | L1: Alex | M1: Anshad | N1: Arathi | O1: Brian | P1: Felicia | Q1: Gibi | R1: Hrithik | S1: Janice | T1: Jeff | U1: Jenda | V1: Joseph | W1: Justine | X1: Renee | Y1: Renjan | Z1: Reny | AA1: Steph | AB1: Tania | AC1: Tiarra | AH1: Date | AI1: Returned to Buff | AJ1: RW after buff | AK1: FTQ for buff
A2: 44986 | D2: =SUM(K2:AF2) -> 0 | E2: =D2/C2 -> #DIV/0! | F2: =E2/8.5 -> #DIV/0! | G2: 10 | H2: =F2/G2 -> #DIV/0! | J2: 44986 | AH2: 44986 | AK2: =(D2-AI2-AJ2)/D2 -> #DIV/0!
A3: 44987 | D3: =SUM(K3:AF3) -> 0 | E3: =D3/C3 -> #DIV/0! | F3: =E3/8.5 -> #DIV/0! | G3: 10 | H3: =F3/G3 -> #DIV/0! | J3: 44987 | AH3: 44987 | AK3: =(D3-AI3-AJ3)/D3 -> #DIV/0!
A4: 44988 | D4: =SUM(K4:AF4) -> 0 | E4: =D4/C4 -> #DIV/0! | F4: =E4/8.5 -> #DIV/0! | G4: 10 | H4: =F4/G4 -> #DIV/0! | J4: 44988 | AH4: 44988 | AK4: =(D4-AI4-AJ4)/D4 -> #DIV/0!
A5: 44989 | D5: =SUM(K5:AF5) -> 0 | E5: =D5/C5 -> #DIV/0! | F5: =E5/4.75 -> #DIV/0! | G5: 10 | H5: =F5/G5 -> #DIV/0! | J5: 44989 | AH5: 44989 | AK5: =(D5-AI5-AJ5)/D5 -> #DIV/0!
A6: 44991 | D6: =SUM(K6:AF6) -> 0 | E6: =D6/C6 -> #DIV/0! | F6: =E6/8.5 -> #DIV/0! | G6: 10 | H6: =F6/G6 -> #DIV/0! | J6: 44991 | AH6: 44991 | AK6: =(D6-AI6-AJ6)/D6 -> #DIV/0!
A7: 44992 | D7: =SUM(K7:AF7) -> 0 | E7: =D7/C7 -> #DIV/0! | F7: =E7/8.5 -> #DIV/0! | G7: 10 | H7: =F7/G7 -> #DIV/0! | J7: 44992 | AH7: 44992 | AK7: =(D7-AI7-AJ7)/D7 -> #DIV/0!
A8: 44993 | D8: =SUM(K8:AF8) -> 0 | E8: =D8/C8 -> #DIV/0! | F8: =E8/8.5 -> #DIV/0! | G8: 10 | H8: =F8/G8 -> #DIV/0! | J8: 44993 | AH8: 44993 | AK8: =(D8-AI8-AJ8)/D8 -> #DIV/0!
A9: 44994 | D9: =SUM(K9:AF9) -> 0 | E9: =D9/C9 -> #DIV/0! | F9: =E9/8.5 -> #DIV/0! | G9: 10 | H9: =F9/G9 -> #DIV/0! | J9: 44994 | AH9: 44994 | AK9: =(D9-AI9-AJ9)/D9 -> #DIV/0!
A10: 44995 | D10: =SUM(K10:AF10) -> 0 | E10: =D10/C10 -> #DIV/0! | F10: =E10/8.5 -> #DIV/0! | G10: 10 | H10: =F10/G10 -> #DIV/0! | J10: 44995 | AH10: 44995 | AK10: =(D10-AI10-AJ10)/D10 -> #DIV/0!
A11: 44996 | D11: =SUM(K11:AF11) -> 0 | E11: =D11/C11 -> #DIV/0! | F11: =E11/4.75 -> #DIV/0! | G11: 10 | H11: =F11/G11 -> #DIV/0! | J11: 44996 | AH11: 44996 | AK11: =(D11-AI11-AJ11)/D11 -> #DIV/0!
A12: 44998 | D12: =SUM(K12:AF12) -> 0 | E12: =D12/C12 -> #DIV/0! | F12: =E12/8.5 -> #DIV/0! | G12: 10 | H12: =F12/G12 -> #DIV/0! | J12: 44998 | AH12: 44998 | AK12: =(D12-AI12-AJ12)/D12 -> #DIV/0!
A13: 44999 | D13: =SUM(K13:AF13) -> 0 | E13: =D13/C13 -> #DIV/0! | F13: =E13/8.5 -> #DIV/0! | G13: 10 | H13: =F13/G13 -> #DIV/0! | J13: 44999 | AH13: 44999 | AK13: =(D13-AI13-AJ13)/D13 -> #DIV/0!
A14: 45000 | D14: =SUM(K14:AF14) -> 0 | E14: =D14/C14 -> #DIV/0! | F14: =E14/8.5 -> #DIV/0! | G14: 10 | H14: =F14/G14 -> #DIV/0! | J14: 45000 | AH14: 45000 | AK14: =(D14-AI14-AJ14)/D14 -> #DIV/0!
A15: 45001 | D15: =SUM(K15:AF15) -> 0 | E15: =D15/C15 -> #DIV/0! | F15: =E15/8.5 -> #DIV/0! | G15: 10 | H15: =F15/G15 -> #DIV/0! | J15: 45001 | AH15: 45001 | AK15: =(D15-AI15-AJ15)/D15 -> #DIV/0!
A16: 45002 | D16: =SUM(K16:AF16) -> 0 | E16: =D16/C16 -> #DIV/0! | F16: =E16/8.5 -> #DIV/0! | G16: 10 | H16: =F16/G16 -> #DIV/0! | J16: 45002 | AH16: 45002 | AK16: =(D16-AI16-AJ16)/D16 -> #DIV/0!
A17: 45005 | D17: =SUM(K17:AF17) -> 0 | E17: =D17/C17 -> #DIV/0! | F17: =E17/8.5 -> #DIV/0! | G17: 10 | H17: =F17/G17 -> #DIV/0! | J17: 45005 | AH17: 45005 | AK17: =(D17-AI17-AJ17)/D17 -> #DIV/0!
A18: 45006 | D18: =SUM(K18:AF18) -> 0 | E18: =D18/C18 -> #DIV/0! | F18: =E18/8.5 -> #DIV/0! | G18: 10 | H18: =F18/G18 -> #DIV/0! | J18: 45006 | AH18: 45006 | AK18: =(D18-AI18-AJ18)/D18 -> #DIV/0!
A19: 45007 | D19: =SUM(K19:AF19) -> 0 | E19: =D19/C19 -> #DIV/0! | F19: =E19/8.5 -> #DIV/0! | G19: 10 | H19: =F19/G19 -> #DIV/0! | J19: 45007 | AH19: 45007 | AK19: =(D19-AI19-AJ19)/D19 -> #DIV/0!
A20: 45008 | D20: =SUM(K20:AF20) -> 0 | E20: =D20/C20 -> #DIV/0! | F20: =E20/8.5 -> #DIV/0! | G20: 10 | H20: =F20/G20 -> #DIV/0! | J20: 45008 | AH20: 45008 | AK20: =(D20-AI20-AJ20)/D20 -> #DIV/0!
A21: 45009 | D21: =SUM(K21:AF21) -> 0 | E21: =D21/C21 -> #DIV/0! | F21: =E21/8.5 -> #DIV/0! | G21: 10 | H21: =F21/G21 -> #DIV/0! | J21: 45009 | AH21: 45009 | AK21: =(D21-AI21-AJ21)/D21 -> #DIV/0!
A22: 45010 | D22: =SUM(K22:AF22) -> 0 | E22: =D22/C22 -> #DIV/0! | F22: =E22/8.5 -> #DIV/0! | G22: 11 | H22: =F22/G22 -> #DIV/0! | J22: 45010 | AH22: 45010 | AK22: =(D22-AI22-AJ22)/D22 -> #DIV/0!
A23: 45012 | D23: =SUM(K23:AF23) -> 0 | E23: =D23/C23 -> #DIV/0! | F23: =E23/8.5 -> #DIV/0! | G23: 10 | H23: =F23/G23 -> #DIV/0! | J23: 45012 | AH23: 45012 | AK23: =(D23-AI23-AJ23)/D23 -> #DIV/0!
... A27: 45016 | D27: =SUM(K27:AF27) -> 0 | E27: =D27/C27 -> #DIV/0! | F27: =E27/8.5 -> #DIV/0! | G27: 10 | H27: =F27/G27 -> #DIV/0! | J27: 45016 | AH27: 45016 | AK27: =(D27-AI27-AJ27)/D27 -> #DIV/0!
A28: Average | B28: =AVERAGE(B2:B27) -> #DIV/0! | D28: =AVERAGE(D2:D27) -> 0 | E28: =AVERAGE(E2:E27) -> #DIV/0! | F28: =E28/8.5 -> #DIV/0! | G28: 10 | H28: =F28/G28 -> #DIV/0! | J28: Average | K28: =AVERAGE(K2:K27) -> #DIV/0! | L28: =AVERAGE(L2:L27) -> #DIV/0! | M28: =AVERAGE(M2:M27) -> #DIV/0! | N28: =AVERAGE(N2:N27) -> #DIV/0! | O28: =AVERAGE(O2:O27) -> #DIV/0! | P28: =AVERAGE(P2:P27) -> #DIV/0! | Q28: =AVERAGE(Q2:Q27) -> #DIV/0! | R28: =AVERAGE(R2:R27) -> #DIV/0! | ... AF28: =AVERAGE(AF2:AF27) -> #DIV/0! | AH28: Average | AI28: =AVERAGE(AI2:AI27) -> #DIV/0! | AJ28: =AVERAGE(AJ2:AJ27) -> #DIV/0! | AK28: =AVERAGE(AK2:AK27) -> #DIV/0!

Sheet Apr
A1: Date | B1: Into Buff from Line | C1: # Buffers | D1: Ttl Buffed | E1: Ave per person | F1: Ave/hr | G1: Target/ Hr | H1: % Efficiency | J1: Date | K1: Brian | L1: Janice | M1: Renee | N1: Steph | O1: Tania | P1: Tiarra | Q1: Anna | R1: Raven | U1: Date | V1: Returned to Buff | W1: RW after buff | X1: FTQ for buff
A2: 45019 | D2: =SUM(K2:S2) -> 0 | E2: =D2/C2 -> #DIV/0! | F2: =E2/8.5 -> #DIV/0! | G2: 10 | H2: =F2/G2 -> #DIV/0! | J2: 45019 | U2: 45019 | X2: =(D2-V2-W2)/D2 -> #DIV/0!
A3: 45020 | D3: =SUM(K3:S3) -> 0 | E3: =D3/C3 -> #DIV/0! | F3: =E3/8.5 -> #DIV/0! | G3: 10 | H3: =F3/G3 -> #DIV/0! | J3: 45020 | U3: 45020 | X3: =(D3-V3-W3)/D3 -> #DIV/0!
A4: 45021 | D4: =SUM(K4:S4) -> 0 | E4: =D4/C4 -> #DIV/0! | F4: =E4/8.5 -> #DIV/0! | G4: 10 | H4: =F4/G4 -> #DIV/0! | J4: 45021 | U4: 45021 | X4: =(D4-V4-W4)/D4 -> #DIV/0!
A5: 45022 | D5: =SUM(K5:S5) -> 0 | E5: =D5/C5 -> #DIV/0! | F5: =E5/8.5 -> #DIV/0! | G5: 10 | H5: =F5/G5 -> #DIV/0! | J5: 45022 | U5: 45022 | X5: =(D5-V5-W5)/D5 -> #DIV/0!
A6: 45026 | D6: =SUM(K6:S6) -> 0 | E6: =D6/C6 -> #DIV/0! | F6: =E6/8.5 -> #DIV/0! | G6: 10 | H6: =F6/G6 -> #DIV/0! | J6: 45026 | U6: 45026 | X6: =(D6-V6-W6)/D6 -> #DIV/0!
A7: 45027 | D7: =SUM(K7:S7) -> 0 | E7: =D7/C7 -> #DIV/0! | F7: =E7/8.5 -> #DIV/0! | G7: 10 | H7: =F7/G7 -> #DIV/0! | J7: 45027 | U7: 45027 | X7: =(D7-V7-W7)/D7 -> #DIV/0!
A8: 45028 | D8: =SUM(K8:S8) -> 0 | E8: =D8/C8 -> #DIV/0! | F8: =E8/8.5 -> #DIV/0! | G8: 10 | H8: =F8/G8 -> #DIV/0! | J8: 45028 | U8: 45028 | X8: =(D8-V8-W8)/D8 -> #DIV/0!
A9: 45029 | D9: =SUM(K9:S9) -> 0 | E9: =D9/C9 -> #DIV/0! | F9: =E9/8.5 -> #DIV/0! | G9: 10 | H9: =F9/G9 -> #DIV/0! | J9: 45029 | U9: 45029 | X9: =(D9-V9-W9)/D9 -> #DIV/0!
A10: 45030 | D10: =SUM(K10:S10) -> 0 | E10: =D10/C10 -> #DIV/0! | F10: =E10/8.5 -> #DIV/0! | G10: 10 | H10: =F10/G10 -> #DIV/0! | J10: 45030 | U10: 45030 | X10: =(D10-V10-W10)/D10 -> #DIV/0!
A11: 45033 | D11: =SUM(K11:S11) -> 0 | E11: =D11/C11 -> #DIV/0! | F11: =E11/8.5 -> #DIV/0! | G11: 10 | H11: =F11/G11 -> #DIV/0! | J11: 45033 | U11: 45033 | X11: =(D11-V11-W11)/D11 -> #DIV/0!
A12: 45034 | D12: =SUM(K12:S12) -> 0 | E12: =D12/C12 -> #DIV/0! | F12: =E12/8.5 -> #DIV/0! | G12: 10 | H12: =F12/G12 -> #DIV/0! | J12: 45034 | U12: 45034 | X12: =(D12-V12-W12)/D12 -> #DIV/0!
A13: 45035 | D13: =SUM(K13:S13) -> 0 | E13: =D13/C13 -> #DIV/0! | F13: =E13/7.5 -> #DIV/0! | G13: 10 | H13: =F13/G13 -> #DIV/0! | J13: 45035 | U13: 45035 | X13: =(D13-V13-W13)/D13 -> #DIV/0!
A14: 45036 | D14: =SUM(K14:S14) -> 0 | E14: =D14/C14 -> #DIV/0! | F14: =E14/7.5 -> #DIV/0! | G14: 10 | H14: =F14/G14 -> #DIV/0! | J14: 45036 | U14: 45036 | X14: =(D14-V14-W14)/D14 -> #DIV/0!
A15: 45037 | D15: =SUM(K15:S15) -> 0 | E15: =D15/C15 -> #DIV/0! | F15: =E15/7.5 -> #DIV/0! | G15: 10 | H15: =F15/G15 -> #DIV/0! | J15: 45037 | U15: 45037 | X15: =(D15-V15-W15)/D15 -> #DIV/0!
A16: 45040 | D16: =SUM(K16:S16) -> 0 | E16: =D16/C16 -> #DIV/0! | F16: =E16/7.5 -> #DIV/0! | G16: 10 | H16: =F16/G16 -> #DIV/0! | J16: 45040 | U16: 45040 | X16: =(D16-V16-W16)/D16 -> #DIV/0!
A17: 45041 | D17: =SUM(K17:S17) -> 0 | E17: =D17/C17 -> #DIV/0! | F17: =E17/7.5 -> #DIV/0! | G17: 10 | H17: =F17/G17 -> #DIV/0! | J17: 45041 | U17: 45041 | X17: =(D17-V17-W17)/D17 -> #DIV/0!
A18: 45042 | D18: =SUM(K18:S18) -> 0 | E18: =D18/C18 -> #DIV/0! | F18: =E18/7.5 -> #DIV/0! | G18: 10 | H18: =F18/G18 -> #DIV/0! | J18: 45042 | U18: 45042 | X18: =(D18-V18-W18)/D18 -> #DIV/0!
A19: 45043 | D19: =SUM(K19:S19) -> 0 | E19: =D19/C19 -> #DIV/0! | F19: =E19/7.5 -> #DIV/0! | G19: 10 | H19: =F19/G19 -> #DIV/0! | J19: 45043 | U19: 45043 | X19: =(D19-V19-W19)/D19 -> #DIV/0!
A20: 45044 | D20: =SUM(K20:S20) -> 0 | E20: =D20/C20 -> #DIV/0! | F20: =E20/7.5 -> #DIV/0! | G20: 10 | H20: =F20/G20 -> #DIV/0! | J20: 45044 | U20: 45044 | X20: =(D20-V20-W20)/D20 -> #DIV/0!
A21: Average | D21: =AVERAGE(D2:D20) -> 0 | E21: =AVERAGE(E2:E20) -> #DIV/0! | F21: =E21/7.5 -> #DIV/0! | G21: 10 | H21: =F21/G21 -> #DIV/0! | J21: Average | K21: =AVERAGE(K2:K20) -> #DIV/0! | L21: =AVERAGE(L2:L20) -> #DIV/0! | M21: =AVERAGE(M2:M20) -> #DIV/0! | N21: =AVERAGE(N2:N20) -> #DIV/0! | O21: =AVERAGE(O2:O20) -> #DIV/0! | P21: =AVERAGE(P2:P20) -> #DIV/0! | Q21: =AVERAGE(Q2:Q20) -> #DIV/0! | R21: =AVERAGE(R2:R20) -> #DIV/0! | S21: =AVERAGE(S2:S20) -> #DIV/0! | U21: Average | V21: =AVERAGE(V2:V20) -> #DIV/0! | W21: =AVERAGE(W2:W20) -> #DIV/0! | X21: =AVERAGE(X2:X20) -> #DIV/0!

Sheet May
A1: Date | B1: Into Buff from Line | C1: # Buffers | D1: Ttl Buffed | E1: Ave per person | F1: Ave/hr | G1: Target/ Hr | H1: % Efficiency | J1: Date | K1: Akash | L1: Anna | M1: Brian | N1: Gibi | O1: Hannah | P1: Jeff | Q1: Joseph | R1: Raven | S1: Renee | T1: Steph | U1: Tiarra | Y1: Date | Z1: Returned to Buff | AA1: RW after buff | AB1: FTQ for buff
A2: 45047 | D2: =SUM(L2:W2) -> 0 | E2: =D2/C2 -> #DIV/0! | F2: =E2/7.5 -> #DIV/0! | G2: 10 | H2: =F2/G2 -> #DIV/0! | J2: 45047 | Y2: 45047 | AB2: =(D2-Z2-AA2)/D2 -> #DIV/0!
A3: 45048 | D3: =SUM(L3:W3) -> 0 | E3: =D3/C3 -> #DIV/0! | F3: =E3/7.5 -> #DIV/0! | G3: 10 | H3: =F3/G3 -> #DIV/0! | J3: 45048 | Y3: 45048 | AB3: =(D3-Z3-AA3)/D3 -> #DIV/0!
A4: 45049 | D4: =SUM(L4:W4) -> 0 | E4: =D4/C4 -> #DIV/0! | F4: =E4/7.5 -> #DIV/0! | G4: 10 | H4: =F4/G4 -> #DIV/0! | J4: 45049 | Y4: 45049 | AB4: =(D4-Z4-AA4)/D4 -> #DIV/0!
A5: 45050 | D5: =SUM(L5:W5) -> 0 | E5: =D5/C5 -> #DIV/0! | F5: =E5/7.5 -> #DIV/0! | G5: 10 | H5: =F5/G5 -> #DIV/0! | J5: 45050 | Y5: 45050 | AB5: =(D5-Z5-AA5)/D5 -> #DIV/0!
A6: 45051 | D6: =SUM(L6:W6) -> 0 | E6: =D6/C6 -> #DIV/0! | F6: =E6/7.5 -> #DIV/0! | G6: 10 | H6: =F6/G6 -> #DIV/0! | J6: 45051 | Y6: 45051 | AB6: =(D6-Z6-AA6)/D6 -> #DIV/0!
A7: 45054 | D7: =SUM(L7:W7) -> 0 | E7: =D7/C7 -> #DIV/0! | F7: =E7/7.5 -> #DIV/0! | G7: 10 | H7: =F7/G7 -> #DIV/0! | J7: 45054 | Y7: 45054 | AB7: =(D7-Z7-AA7)/D7 -> #DIV/0!
A8: 45055 | D8: =SUM(L8:W8) -> 0 | E8: =D8/C8 -> #DIV/0! | F8: =E8/7.5 -> #DIV/0! | G8: 10 | H8: =F8/G8 -> #DIV/0! | J8: 45055 | Y8: 45055 | AB8: =(D8-Z8-AA8)/D8 -> #DIV/0!
A9: 45056 | D9: =SUM(L9:W9) -> 0 | E9: =D9/C9 -> #DIV/0! | F9: =E9/7.5 -> #DIV/0! | G9: 10 | H9: =F9/G9 -> #DIV/0! | J9: 45056 | Y9: 45056 | AB9: =(D9-Z9-AA9)/D9 -> #DIV/0!
A10: 45057 | D10: =SUM(L10:W10) -> 0 | E10: =D10/C10 -> #DIV/0! | F10: =E10/7.5 -> #DIV/0! | G10: 10 | H10: =F10/G10 -> #DIV/0! | J10: 45057 | Y10: 45057 | AB10: =(D10-Z10-AA10)/D10 -> #DIV/0!
A11: 45058 | D11: =SUM(L11:W11) -> 0 | E11: =D11/C11 -> #DIV/0! | F11: =E11/7.5 -> #DIV/0! | G11: 10 | H11: =F11/G11 -> #DIV/0! | J11: 45058 | Y11: 45058 | AB11: =(D11-Z11-AA11)/D11 -> #DIV/0!
A12: 45061 | D12: =SUM(L12:W12) -> 0 | E12: =D12/C12 -> #DIV/0! | F12: =E12/7.5 -> #DIV/0! | G12: 10 | H12: =F12/G12 -> #DIV/0! | J12: 45061 | Y12: 45061 | AB12: =(D12-Z12-AA12)/D12 -> #DIV/0!
A13: 45062 | D13: =SUM(L13:W13) -> 0 | E13: =D13/C13 -> #DIV/0! | F13: =E13/7.5 -> #DIV/0! | G13: 10 | H13: =F13/G13 -> #DIV/0! | J13: 45062 | Y13: 45062 | AB13: =(D13-Z13-AA13)/D13 -> #DIV/0!
... A19: 45071 | D19: =SUM(L19:W19) -> 0 | E19: =D19/C19 -> #DIV/0! | F19: =E19/7.5 -> #DIV/0! | G19: 10 | H19: =F19/G19 -> #DIV/0! | J19: 45071 | Y19: 45071 | AB19: =(D19-Z19-AA19)/D19 -> #DIV/0!
A20: 45072 | D20: =SUM(L20:W20) -> 0 | E20: =D20/C20 -> #DIV/0! | F20: =E20/6.25 -> #DIV/0! | G20: 10 | H20: =F20/G20 -> #DIV/0! | J20: 45072 | Y20: 45072 | AB20: =(D20-Z20-AA20)/D20 -> #DIV/0!
A21: 45075 | D21: =SUM(L21:W21) -> 0 | E21: =D21/C21 -> #DIV/0! | F21: =E21/7.5 -> #DIV/0! | G21: 10 | H21: =F21/G21 -> #DIV/0! | J21: 45075 | Y21: 45075 | AB21: =(D21-Z21-AA21)/D21 -> #DIV/0!
A22: 45076 | D22: =SUM(L22:W22) -> 0 | E22: =D22/C22 -> #DIV/0! | F22: =E22/7.5 -> #DIV/0! | G22: 10 | H22: =F22/G22 -> #DIV/0! | J22: 45076 | Y22: 45076 | AB22: =(D22-Z22-AA22)/D22 -> #DIV/0!
A23: 45077 | D23: =SUM(L23:W23) -> 0 | E23: =D23/C23 -> #DIV/0! | F23: =E23/7.5 -> #DIV/0! | G23: 10 | H23: =F23/G23 -> #DIV/0! | J23: 45077 | Y23: 45077 | AB23: =(D23-Z23-AA23)/D23 -> #DIV/0!
A24: Average | D24: =AVERAGE(D2:D23) -> 0 | E24: =AVERAGE(E2:E23) -> #DIV/0! | F24: =E24/7.5 -> #DIV/0! | G24: 10 | H24: =F24/G24 -> #DIV/0! | J24: Average | K24: =AVERAGE(K2:K23) -> #DIV/0! | L24: =AVERAGE(L2:L23) -> #DIV/0! | M24: =AVERAGE(M2:M23) -> #DIV/0! | N24: =AVERAGE(N2:N23) -> #DIV/0! | O24: =AVERAGE(O2:O23) -> #DIV/0! | P24: =AVERAGE(P2:P23) -> #DIV/0! | Q24: =AVERAGE(Q2:Q23) -> #DIV/0! | R24: =AVERAGE(R2:R23) -> #DIV/0! | ... W24: =AVERAGE(W2:W23) -> #DIV/0! | Y24: Average | Z24: =AVERAGE(Z2:Z23) -> #DIV/0! | AA24: =AVERAGE(AA2:AA23) -> #DIV/0! | AB24: =AVERAGE(AB2:AB23) -> #DIV/0!
A25: TTL | B25: =SUM(B2:B23) -> 0 | D25: =SUM(D2:D23) -> 0 | K25: =SUM(K2:K23) -> 0 | L25: =SUM(L2:L23) -> 0 | M25: =SUM(M2:M23) -> 0 | N25: =SUM(N2:N23) -> 0 | O25: =SUM(O2:O23) -> 0 | P25: =SUM(P2:P23) -> 0 | Q25: =SUM(Q2:Q23) -> 0 | R25: =SUM(R2:R23) -> 0 | ... U25: =SUM(U2:U23) -> 0 | Z25: =SUM(Z2:Z23) -> 0 | AA25: =SUM(AA2:AA23) -> 0

Sheet June
A1: Date | B1: Into Buff from Line | C1: # Buffers | D1: Ttl Buffed | E1: Ave per person | F1: Ave/hr | G1: Target/ Hr | H1: % Efficiency | J1: Date | K1: Akash | L1: Amy | M1: Anna | N1: Anshad | O1: Brian | P1: Gibi | Q1: Hannah | R1: Jeff | S1: Justine | T1: Raven | U1: Renee | V1: Robyn | W1: Sara | X1: Steph | Y1: Tiarra | AB1: Date | AC1: Returned to Buff | AD1: RW after buff | AE1: FTQ for buff
A2: 45078 | D2: =SUM(K2:Z2) -> 0 | E2: =D2/C2 -> #DIV/0! | F2: =E2/7.5 -> #DIV/0! | G2: 10 | H2: =F2/G2 -> #DIV/0! | J2: 45078 | AB2: 45078 | AE2: =(D2-AC2-AD2)/D2 -> #DIV/0!
A3: 45079 | D3: =SUM(K3:Z3) -> 0 | E3: =D3/C3 -> #DIV/0! | F3: =E3/7.5 -> #DIV/0! | G3: 10 | H3: =F3/G3 -> #DIV/0! | J3: 45079 | AB3: 45079 | AE3: =(D3-AC3-AD3)/D3 -> #DIV/0!
A4: 45082 | D4: =SUM(K4:Z4) -> 0 | E4: =D4/C4 -> #DIV/0! | F4: =E4/7.5 -> #DIV/0! | G4: 10 | H4: =F4/G4 -> #DIV/0! | J4: 45082 | AB4: 45082 | AE4: =(D4-AC4-AD4)/D4 -> #DIV/0!
A5: 45083 | D5: =SUM(K5:Z5) -> 0 | E5: =D5/C5 -> #DIV/0! | F5: =E5/7.5 -> #DIV/0! | G5: 10 | H5: =F5/G5 -> #DIV/0! | J5: 45083 | AB5: 45083 | AE5: =(D5-AC5-AD5)/D5 -> #DIV/0!
A6: 45084 | D6: =SUM(K6:Z6) -> 0 | E6: =D6/C6 -> #DIV/0! | F6: =E6/7.5 -> #DIV/0! | G6: 10 | H6: =F6/G6 -> #DIV/0! | J6: 45084 | AB6: 45084 | AE6: =(D6-AC6-AD6)/D6 -> #DIV/0!
A7: 45085 | D7: =SUM(K7:Z7) -> 0 | E7: =D7/C7 -> #DIV/0! | F7: =E7/7.5 -> #DIV/0! | G7: 10 | H7: =F7/G7 -> #DIV/0! | J7: 45085 | AB7: 45085 | AE7: =(D7-AC7-AD7)/D7 -> #DIV/0!
A8: 45086 | D8: =SUM(K8:Z8) -> 0 | E8: =D8/C8 -> #DIV/0! | F8: =E8/7.5 -> #DIV/0! | G8: 10 | H8: =F8/G8 -> #DIV/0! | J8: 45086 | AB8: 45086 | AE8: =(D8-AC8-AD8)/D8 -> #DIV/0!
A9: 45089 | D9: =SUM(K9:Z9) -> 0 | E9: =D9/C9 -> #DIV/0! | F9: =E9/7.5 -> #DIV/0! | G9: 10 | H9: =F9/G9 -> #DIV/0! | J9: 45089 | AB9: 45089 | AE9: =(D9-AC9-AD9)/D9 -> #DIV/0!
A10: 45090 | D10: =SUM(K10:Z10) -> 0 | E10: =D10/C10 -> #DIV/0! | F10: =E10/7.5 -> #DIV/0! | G10: 10 | H10: =F10/G10 -> #DIV/0! | J10: 45090 | AB10: 45090 | AE10: =(D10-AC10-AD10)/D10 -> #DIV/0!
A11: 45098 | D11: =SUM(K11:Z11) -> 0 | E11: =D11/C11 -> #DIV/0! | F11: =E11/7.5 -> #DIV/0! | G11: 10 | H11: =F11/G11 -> #DIV/0! | J11: 45098 | AB11: 45098 | AE11: =(D11-AC11-AD11)/D11 -> #DIV/0!
A12: 45099 | D12: =SUM(K12:Z12) -> 0 | E12: =D12/C12 -> #DIV/0! | F12: =E12/7.5 -> #DIV/0! | G12: 10 | H12: =F12/G12 -> #DIV/0! | J12: 45099 | AB12: 45099 | AE12: =(D12-AC12-AD12)/D12 -> #DIV/0!
A13: 45100 | D13: =SUM(K13:Z13) -> 0 | E13: =D13/C13 -> #DIV/0! | F13: =E13/7.5 -> #DIV/0! | G13: 10 | H13: =F13/G13 -> #DIV/0! | J13: 45100 | AB13: 45100 | AE13: =(D13-AC13-AD13)/D13 -> #DIV/0!
... A17: 45107 | D17: =SUM(K17:Z17) -> 0 | E17: =D17/C17 -> #DIV/0! | F17: =E17/7.5 -> #DIV/0! | G17: 10 | H17: =F17/G17 -> #DIV/0! | J17: 45107 | AB17: 45107 | AE17: =(D17-AC17-AD17)/D17 -> #DIV/0!
A18: Average | B18: =AVERAGE(B2:B17) -> #DIV/0! | D18: =AVERAGE(D2:D17) -> 0 | E18: =AVERAGE(E2:E17) -> #DIV/0! | F18: =E18/7.5 -> #DIV/0! | G18: 10 | H18: =F18/G18 -> #DIV/0! | J18: Average | K18: =AVERAGE(K2:K17) -> #DIV/0! | L18: =AVERAGE(L2:L17) -> #DIV/0! | M18: =AVERAGE(M2:M17) -> #DIV/0! | N18: =AVERAGE(N2:N17) -> #DIV/0! | O18: =AVERAGE(O2:O17) -> #DIV/0! | P18: =AVERAGE(P2:P17) -> #DIV/0! | Q18: =AVERAGE(Q2:Q17) -> #DIV/0! | R18: =AVERAGE(R2:R17) -> #DIV/0! | ... U18: =AVERAGE(U2:U17) -> #DIV/0! | W18: =AVERAGE(W2:W17) -> #DIV/0! | X18: =AVERAGE(X2:X17) -> #DIV/0! | Y18: =AVERAGE(Y2:Y17) -> #DIV/0! | Z18: =AVERAGE(Z2:Z17) -> #DIV/0! | AB18: Average | AC18: =AVERAGE(AC2:AC17) -> #DIV/0! | AD18: =AVERAGE(AD2:AD17) -> #DIV/0! | AE18: =AVERAGE(AE2:AE17) -> #DIV/0!

Sheet July
A1: Date | B1: Into Buff from Line | C1: # Buffers | D1: Ttl Buffed | E1: Ave per person | F1: Ave/hr | G1: Target/ Hr | H1: % Efficiency | J1: Date | K1: Akash | L1: Amy | M1: Anna | N1: Anshad | O1: Brian | P1: Gibi | Q1: Hannah | R1: Jeff | S1: Raven | T1: Renee | U1: Robyn | V1: Sara | W1: Steph | X1: Tania | AC1: Date | AD1: Returned to Buff | AE1: RW after buff | AF1: FTQ for buff
A2: 45111 | D2: =SUM(K2:AA2) -> 0 | E2: =D2/C2 -> #DIV/0! | F2: =E2/7.5 -> #DIV/0! | G2: 10 | H2: =F2/G2 -> #DIV/0! | J2: 45111 | AC2: 45111 | AF2: =(D2-AD2-AE2)/D2 -> #DIV/0!
A3: 45112 | D3: =SUM(K3:AA3) -> 0 | E3: =D3/C3 -> #DIV/0! | F3: =E3/7.5 -> #DIV/0! | G3: 10 | H3: =F3/G3 -> #DIV/0! | J3: 45112 | AC3: 45112 | AF3: =(D3-AD3-AE3)/D3 -> #DIV/0!
A4: 45113 | D4: =SUM(K4:AA4) -> 0 | E4: =D4/C4 -> #DIV/0! | F4: =E4/7.5 -> #DIV/0! | G4: 10 | H4: =F4/G4 -> #DIV/0! | J4: 45113 | AC4: 45113 | AF4: =(D4-AD4-AE4)/D4 -> #DIV/0!
A5: 45114 | D5: =SUM(K5:AA5) -> 0 | E5: =D5/C5 -> #DIV/0! | F5: =E5/7.5 -> #DIV/0! | G5: 10 | H5: =F5/G5 -> #DIV/0! | J5: 45114 | AC5: 45114 | AF5: =(D5-AD5-AE5)/D5 -> #DIV/0!
A6: 45117 | D6: =SUM(K6:AA6) -> 0 | E6: =D6/C6 -> #DIV/0! | F6: =E6/7.5 -> #DIV/0! | G6: 10 | H6: =F6/G6 -> #DIV/0! | J6: 45117 | AC6: 45117 | AF6: =(D6-AD6-AE6)/D6 -> #DIV/0!
A7: 45118 | D7: =SUM(K7:AA7) -> 0 | E7: =D7/C7 -> #DIV/0! | F7: =E7/7.5 -> #DIV/0! | G7: 10 | H7: =F7/G7 -> #DIV/0! | J7: 45118 | AC7: 45118 | AF7: =(D7-AD7-AE7)/D7 -> #DIV/0!
A8: 45119 | D8: =SUM(K8:AA8) -> 0 | E8: =D8/C8 -> #DIV/0! | F8: =E8/7.5 -> #DIV/0! | G8: 10 | H8: =F8/G8 -> #DIV/0! | J8: 45119 | AC8: 45119 | AF8: =(D8-AD8-AE8)/D8 -> #DIV/0!
A9: 45120 | D9: =SUM(K9:AA9) -> 0 | E9: =D9/C9 -> #DIV/0! | F9: =E9/7.5 -> #DIV/0! | G9: 10 | H9: =F9/G9 -> #DIV/0! | J9: 45120 | AC9: 45120 | AF9: =(D9-AD9-AE9)/D9 -> #DIV/0!
A10: 45121 | D10: =SUM(K10:AA10) -> 0 | E10: =D10/C10 -> #DIV/0! | F10: =E10/7.5 -> #DIV/0! | G10: 10 | H10: =F10/G10 -> #DIV/0! | J10: 45121 | AC10: 45121 | AF10: =(D10-AD10-AE10)/D10 -> #DIV/0!
A11: 45124 | D11: =SUM(K11:AA11) -> 0 | E11: =D11/C11 -> #DIV/0! | F11: =E11/7.5 -> #DIV/0! | G11: 10 | H11: =F11/G11 -> #DIV/0! | J11: 45124 | AC11: 45124 | AF11: =(D11-AD11-AE11)/D11 -> #DIV/0!
A12: 45125 | D12: =SUM(K12:AA12) -> 0 | E12: =D12/C12 -> #DIV/0! | F12: =E12/7.5 -> #DIV/0! | G12: 10 | H12: =F12/G12 -> #DIV/0! | J12: 45125 | AC12: 45125 | AF12: =(D12-AD12-AE12)/D12 -> #DIV/0!
A13: 45126 | D13: =SUM(K13:AA13) -> 0 | E13: =D13/C13 -> #DIV/0! | F13: =E13/7.5 -> #DIV/0! | G13: 10 | H13: =F13/G13 -> #DIV/0! | J13: 45126 | AC13: 45126 | AF13: =(D13-AD13-AE13)/D13 -> #DIV/0!
... A21: 45138 | D21: =SUM(K21:AA21) -> 0 | E21: =D21/C21 -> #DIV/0! | F21: =E21/7.5 -> #DIV/0! | G21: 10 | H21: =F21/G21 -> #DIV/0! | J21: 45138 | AC21: 45138 | AF21: =(D21-AD21-AE21)/D21 -> #DIV/0!
A22: Average | D22: =AVERAGE(D2:D21) -> 0 | E22: =AVERAGE(E2:E21) -> #DIV/0! | F22: =E22/7.5 -> #DIV/0! | G22: 10 | H22: =F22/G22 -> #DIV/0! | J22: Average | K22: =AVERAGE(K2:K21) -> #DIV/0! | L22: =AVERAGE(L2:L21) -> #DIV/0! | M22: =AVERAGE(M2:M21) -> #DIV/0! | N22: =AVERAGE(N2:N21) -> #DIV/0! | O22: =AVERAGE(O2:O21) -> #DIV/0! | P22: =AVERAGE(P2:P21) -> #DIV/0! | Q22: =AVERAGE(Q2:Q21) -> #DIV/0! | R22: =AVERAGE(R2:R21) -> #DIV/0! | ... AA22: =AVERAGE(AA2:AA21) -> #DIV/0! | AC22: Average | AD22: =AVERAGE(AD2:AD21) -> #DIV/0! | AE22: =AVERAGE(AE2:AE21) -> #DIV/0! | AF22: =AVERAGE(AF2:AF21) -> #DIV/0!

Sheet Aug
A1: Date | B1: Into Buff from Line | C1: # Buffers | D1: Ttl Buffed | E1: Ave per person | F1: Ave/hr | G1: Target/ Hr | H1: % Efficiency | J1: Date | AC1: Date | AD1: Returned to Buff | AE1: RW after buff | AF1: FTQ for buff
A2: 45139 | E2: =D2/C2 -> #DIV/0! | F2: =E2/7.5 -> #DIV/0! | G2: 10 | H2: =F2/G2 -> #DIV/0! | J2: 45139 | AC2: 45139 | AF2: =(D2-AD2-AE2)/D2 -> #DIV/0!
A3: 45140 | E3: =D3/C3 -> #DIV/0! | F3: =E3/7.5 -> #DIV/0! | G3: 10 | H3: =F3/G3 -> #DIV/0! | J3: 45140 | AC3: 45140 | AF3: =(D3-AD3-AE3)/D3 -> #DIV/0!
A4: 45141 | E4: =D4/C4 -> #DIV/0! | F4: =E4/7.5 -> #DIV/0! | G4: 10 | H4: =F4/G4 -> #DIV/0! | J4: 45141 | AC4: 45141 | AF4: =(D4-AD4-AE4)/D4 -> #DIV/0!
A5: 45142 | E5: =D5/C5 -> #DIV/0! | F5: =E5/7.5 -> #DIV/0! | G5: 10 | H5: =F5/G5 -> #DIV/0! | J5: 45142 | AC5: 45142 | AF5: =(D5-AD5-AE5)/D5 -> #DIV/0!
A6: 45145 | E6: =D6/C6 -> #DIV/0! | F6: =E6/7.5 -> #DIV/0! | G6: 10 | H6: =F6/G6 -> #DIV/0! | J6: 45145 | AC6: 45145 | AF6: =(D6-AD6-AE6)/D6 -> #DIV/0!
A7: 45146 | E7: =D7/C7 -> #DIV/0! | F7: =E7/7.5 -> #DIV/0! | G7: 10 | H7: =F7/G7 -> #DIV/0! | J7: 45146 | AC7: 45146 | AF7: =(D7-AD7-AE7)/D7 -> #DIV/0!
A8: 503 | E8: =D8/C8 -> #DIV/0! | F8: =E8/7.5 -> #DIV/0! | G8: 10 | H8: =F8/G8 -> #DIV/0! | J8: 45147 | AC8: 45147 | AF8: =(D8-AD8-AE8)/D8 -> #DIV/0!
A9: 45148 | E9: =D9/C9 -> #DIV/0! | F9: =E9/7.5 -> #DIV/0! | G9: 10 | H9: =F9/G9 -> #DIV/0! | J9: 45148 | AC9: 45148 | AF9: =(D9-AD9-AE9)/D9 -> #DIV/0!
A10: 45149 | E10: =D10/C10 -> #DIV/0! | F10: =E10/7.5 -> #DIV/0! | G10: 10 | H10: =F10/G10 -> #DIV/0! | J10: 45149 | AC10: 45149 | AF10: =(D10-AD10-AE10)/D10 -> #DIV/0!
A11: 45152 | E11: =D11/C11 -> #DIV/0! | F11: =E11/7.5 -> #DIV/0! | G11: 10 | H11: =F11/G11 -> #DIV/0! | J11: 45152 | AC11: 45152 | AF11: =(D11-AD11-AE11)/D11 -> #DIV/0!
A12: 45153 | E12: =D12/C12 -> #DIV/0! | F12: =E12/7.5 -> #DIV/0! | G12: 10 | H12: =F12/G12 -> #DIV/0! | J12: 45153 | AC12: 45153 | AF12: =(D12-AD12-AE12)/D12 -> #DIV/0!
A13: 45154 | E13: =D13/C13 -> #DIV/0! | F13: =E13/7.5 -> #DIV/0! | G13: 10 | H13: =F13/G13 -> #DIV/0! | J13: 45154 | AC13: 45154 | AF13: =(D13-AD13-AE13)/D13 -> #DIV/0!
... A24: 45169 | E24: =D24/C24 -> #DIV/0! | F24: =E24/7.5 -> #DIV/0! | G24: 10 | H24: =F24/G24 -> #DIV/0! | J24: 45169 | AC24: 45169 | AF24: =(D24-AD24-AE24)/D24 -> #DIV/0!
A25: Average | B25: =AVERAGE(B2:B24) -> #DIV/0! | C25: =AVERAGE(C2:C24) -> #DIV/0! | D25: =AVERAGE(D2:D24) -> #DIV/0! | E25: =AVERAGE(E2:E24) -> #DIV/0! | F25: =E25/7.5 -> #DIV/0! | G25: 10 | H25: =F25/G25 -> #DIV/0! | J25: Average | K25: =AVERAGE(K2:K24) -> #DIV/0! | L25: =AVERAGE(L2:L24) -> #DIV/0! | M25: =AVERAGE(M2:M24) -> #DIV/0! | N25: =AVERAGE(N2:N24) -> #DIV/0! | O25: =AVERAGE(O2:O24) -> #DIV/0! | P25: =AVERAGE(P2:P24) -> #DIV/0! | Q25: =AVERAGE(Q2:Q24) -> #DIV/0! | R25: =AVERAGE(R2:R24) -> #DIV/0! | ... AA25: =AVERAGE(AA2:AA24) -> #DIV/0! | AC25: Average | AD25: =AVERAGE(AD2:AD24) -> #DIV/0! | AE25: =AVERAGE(AE2:AE24) -> #DIV/0! | AF25: =AVERAGE(AF2:AF24) -> #DIV/0!

Sheet Sept
A1: Date | B1: Into Buff from Line | C1: # Buffers | D1: Ttl Buffed | E1: Ave per person | F1: Ave/hr | G1: Target/ Hr | H1: % Efficiency | J1: Date | AC1: Date | AD1: Returned to Buff | AE1: RW after buff | AF1: FTQ for buff
A2: 37500 | E2: =D2/C2 -> #DIV/0! | F2: =E2/7.5 -> #DIV/0! | G2: 10 | H2: =F2/G2 -> #DIV/0! | J2: 37500 | AC2: 37500 | AF2: =(D2-AD2-AE2)/D2 -> #DIV/0!
A3: 45174 | E3: =D3/C3 -> #DIV/0! | F3: =E3/7.5 -> #DIV/0! | G3: 10 | H3: =F3/G3 -> #DIV/0! | J3: 45174 | AC3: 45174 | AF3: =(D3-AD3-AE3)/D3 -> #DIV/0!
A4: 45175 | E4: =D4/C4 -> #DIV/0! | F4: =E4/7.5 -> #DIV/0! | G4: 10 | H4: =F4/G4 -> #DIV/0! | J4: 45175 | AC4: 45175 | AF4: =(D4-AD4-AE4)/D4 -> #DIV/0!
A5: 45176 | E5: =D5/C5 -> #DIV/0! | F5: =E5/7.5 -> #DIV/0! | G5: 10 | H5: =F5/G5 -> #DIV/0! | J5: 45176 | AC5: 45176 | AF5: =(D5-AD5-AE5)/D5 -> #DIV/0!
A6: 45177 | E6: =D6/C6 -> #DIV/0! | F6: =E6/7.5 -> #DIV/0! | G6: 10 | H6: =F6/G6 -> #DIV/0! | J6: 45177 | AC6: 45177 | AF6: =(D6-AD6-AE6)/D6 -> #DIV/0!
A7: 45180 | E7: =D7/C7 -> #DIV/0! | F7: =E7/7.5 -> #DIV/0! | G7: 10 | H7: =F7/G7 -> #DIV/0! | J7: 45180 | AC7: 45180 | AF7: =(D7-AD7-AE7)/D7 -> #DIV/0!
A8: 45181 | E8: =D8/C8 -> #DIV/0! | F8: =E8/7.5 -> #DIV/0! | G8: 10 | H8: =F8/G8 -> #DIV/0! | J8: 45181 | AC8: 45181 | AF8: =(D8-AD8-AE8)/D8 -> #DIV/0!
A9: 45182 | E9: =D9/C9 -> #DIV/0! | F9: =E9/7.5 -> #DIV/0! | G9: 10 | H9: =F9/G9 -> #DIV/0! | J9: 45182 | AC9: 45182 | AF9: =(D9-AD9-AE9)/D9 -> #DIV/0!
A10: 45183 | E10: =D10/C10 -> #DIV/0! | F10: =E10/7.5 -> #DIV/0! | G10: 10 | H10: =F10/G10 -> #DIV/0! | J10: 45183 | AC10: 45183 | AF10: =(D10-AD10-AE10)/D10 -> #DIV/0!
A11: 45184 | E11: =D11/C11 -> #DIV/0! | F11: =E11/7.5 -> #DIV/0! | G11: 10 | H11: =F11/G11 -> #DIV/0! | J11: 45184 | AC11: 45184 | AF11: =(D11-AD11-AE11)/D11 -> #DIV/0!
A12: 45187 | E12: =D12/C12 -> #DIV/0! | F12: =E12/7.5 -> #DIV/0! | G12: 10 | H12: =F12/G12 -> #DIV/0! | J12: 45187 | AC12: 45187 | AF12: =(D12-AD12-AE12)/D12 -> #DIV/0!
A13: 45188 | E13: =D13/C13 -> #DIV/0! | F13: =E13/7.5 -> #DIV/0! | G13: 10 | H13: =F13/G13 -> #DIV/0! | J13: 45188 | AC13: 45188 | AF13: =(D13-AD13-AE13)/D13 -> #DIV/0!
... A21: 45198 | E21: =D21/C21 -> #DIV/0! | F21: =E21/7.5 -> #DIV/0! | G21: 10 | H21: =F21/G21 -> #DIV/0! | J21: 45198 | AC21: 45198 | AF21: =(D21-AD21-AE21)/D21 -> #DIV/0!
A22: Average | C22: =AVERAGE(C2:C21) -> #DIV/0! | D22: =AVERAGE(D2:D21) -> #DIV/0! | E22: =AVERAGE(E2:E21) -> #DIV/0! | F22: =E22/7.5 -> #DIV/0! | G22: 10 | H22: =F22/G22 -> #DIV/0! | J22: Average | K22: =AVERAGE(K2:K21) -> #DIV/0! | L22: =AVERAGE(L2:L21) -> #DIV/0! | M22: =AVERAGE(M2:M21) -> #DIV/0! | N22: =AVERAGE(N2:N21) -> #DIV/0! | O22: =AVERAGE(O2:O21) -> #DIV/0! | P22: =AVERAGE(P2:P21) -> #DIV/0! | Q22: =AVERAGE(Q2:Q21) -> #DIV/0! | R22: =AVERAGE(R2:R21) -> #DIV/0! | ... AA22: =AVERAGE(AA2:AA21) -> #DIV/0! | AC22: Average | AD22: =AVERAGE(AD2:AD21) -> #DIV/0! | AE22: =AVERAGE(AE2:AE21) -> #DIV/0! | AF22: =AVERAGE(AF2:AF21) -> #DIV/0!

Sheet Oct
A1: Date | B1: Into Buff from Line | C1: # Buffers | D1: Ttl Buffed | E1: Ave per person | F1: Ave/hr | G1: Target/ Hr | H1: % Efficiency | J1: Date | AC1: Date | AD1: Returned to Buff | AE1: RW after buff | AF1: FTQ for buff
A2: 45201 | E2: =D2/C2 -> #DIV/0! | F2: =E2/7.5 -> #DIV/0! | G2: 10 | H2: =F2/G2 -> #DIV/0! | J2: 45201 | AC2: 45201 | AF2: =(D2-AD2-AE2)/D2 -> #DIV/0!
A3: 45202 | E3: =D3/C3 -> #DIV/0! | F3: =E3/7.5 -> #DIV/0! | G3: 10 | H3: =F3/G3 -> #DIV/0! | J3: 45202 | AC3: 45202 | AF3: =(D3-AD3-AE3)/D3 -> #DIV/0!
A4: 45203 | E4: =D4/C4 -> #DIV/0! | F4: =E4/7.5 -> #DIV/0! | G4: 10 | H4: =F4/G4 -> #DIV/0! | J4: 45203 | AC4: 45203 | AF4: =(D4-AD4-AE4)/D4 -> #DIV/0!
A5: 45204 | E5: =D5/C5 -> #DIV/0! | F5: =E5/7.5 -> #DIV/0! | G5: 10 | H5: =F5/G5 -> #DIV/0! | J5: 45204 | AC5: 45204 | AF5: =(D5-AD5-AE5)/D5 -> #DIV/0!
A6: 45205 | E6: =D6/C6 -> #DIV/0! | F6: =E6/7.5 -> #DIV/0! | G6: 10 | H6: =F6/G6 -> #DIV/0! | J6: 45205 | AC6: 45205 | AF6: =(D6-AD6-AE6)/D6 -> #DIV/0!
A7: 45209 | E7: =D7/C7 -> #DIV/0! | F7: =E7/7.5 -> #DIV/0! | G7: 10 | H7: =F7/G7 -> #DIV/0! | J7: 45209 | AC7: 45209 | AF7: =(D7-AD7-AE7)/D7 -> #DIV/0!
A8: 45210 | E8: =D8/C8 -> #DIV/0! | F8: =E8/7.5 -> #DIV/0! | G8: 10 | H8: =F8/G8 -> #DIV/0! | J8: 45210 | AC8: 45210 | AF8: =(D8-AD8-AE8)/D8 -> #DIV/0!
A9: 45211 | E9: =D9/C9 -> #DIV/0! | F9: =E9/7.5 -> #DIV/0! | G9: 10 | H9: =F9/G9 -> #DIV/0! | J9: 45211 | AC9: 45211 | AF9: =(D9-AD9-AE9)/D9 -> #DIV/0!
A10: 45212 | E10: =D10/C10 -> #DIV/0! | F10: =E10/7.5 -> #DIV/0! | G10: 10 | H10: =F10/G10 -> #DIV/0! | J10: 45212 | AC10: 45212 | AF10: =(D10-AD10-AE10)/D10 -> #DIV/0!
A11: 45215 | E11: =D11/C11 -> #DIV/0! | F11: =E11/7.5 -> #DIV/0! | G11: 10 | H11: =F11/G11 -> #DIV/0! | J11: 45215 | AC11: 45215 | AF11: =(D11-AD11-AE11)/D11 -> #DIV/0!
A12: 45216 | E12: =D12/C12 -> #DIV/0! | F12: =E12/7.5 -> #DIV/0! | G12: 10 | H12: =F12/G12 -> #DIV/0! | J12: 45216 | AC12: 45216 | AF12: =(D12-AD12-AE12)/D12 -> #DIV/0!
A13: 45217 | E13: =D13/C13 -> #DIV/0! | F13: =E13/7.5 -> #DIV/0! | G13: 10 | H13: =F13/G13 -> #DIV/0! | J13: 45217 | AC13: 45217 | AF13: =(D13-AD13-AE13)/D13 -> #DIV/0!
... A22: 45230 | E22: =D22/C22 -> #DIV/0! | F22: =E22/7.5 -> #DIV/0! | G22: 10 | H22: =F22/G22 -> #DIV/0! | J22: 45230 | AC22: 45230 | AF22: =(D22-AD22-AE22)/D22 -> #DIV/0!
A23: Average | D23: =AVERAGE(D2:D22) -> #DIV/0! | E23: =AVERAGE(E2:E22) -> #DIV/0! | F23: =E23/7.5 -> #DIV/0! | G23: 10 | H23: =F23/G23 -> #DIV/0! | J23: Average | K23: =AVERAGE(K2:K22) -> #DIV/0! | L23: =AVERAGE(L2:L22) -> #DIV/0! | M23: =AVERAGE(M2:M22) -> #DIV/0! | N23: =AVERAGE(N2:N22) -> #DIV/0! | O23: =AVERAGE(O2:O22) -> #DIV/0! | P23: =AVERAGE(P2:P22) -> #DIV/0! | Q23: =AVERAGE(Q2:Q22) -> #DIV/0! | R23: =AVERAGE(R2:R22) -> #DIV/0! | ... AA23: =AVERAGE(AA2:AA22) -> #DIV/0! | AC23: Average | AD23: =AVERAGE(AD2:AD22) -> #DIV/0! | AE23: =AVERAGE(AE2:AE22) -> #DIV/0! | AF23: =AVERAGE(AF2:AF22) -> #DIV/0!
A24: Total | B24: =SUM(B2:B22) -> 0 | D24: =SUM(D2:D22) -> 0 | AC24: Total | AD24: =SUM(AD2:AD22) -> 0 | AE24: =SUM(AE2:AE22) -> 0 | AF24: 0.91

Sheet Daily Summary
A1: BUFFING SUMMARY | B1: 45310
B2: 742
A3: TOTAL PARTS BUFFED | B3: 472
A4: # OF DAYS IN STREAK (MORE OUT OF BUFF THAN INTO BUFF)
A5: AVERAGE PER PERSON | B5: 157
A6: AVERAGE PER HOUR | B6: 21
A7: % EFFICIENCY | B7: 2.1
A10: RETURN TO BUFF | B10: 15
A11: REWORK FROM BUFF | B11: 40
A12: FTQ FOR BUFFING | B12: 0.88

Sheet Nov
A1: Date | B1: Into Buff from Line | C1: # Buffers | D1: Ttl Buffed | E1: Ave per person | F1: Ave/hr | G1: Target/ Hr | H1: % Efficiency | J1: Date | AC1: Date | AD1: Returned to Buff | AE1: RW after buff | AF1: FTQ for buff
A2: 45231 | E2: =D2/C2 -> #DIV/0! | F2: =E2/8.5 -> #DIV/0! | G2: 10 | H2: =F2/G2 -> #DIV/0! | J2: 45231 | AC2: 45231 | AF2: =(D2-AD2-AE2)/D2 -> #DIV/0!
A3: 45232 | E3: =D3/C3 -> #DIV/0! | F3: =E3/8.5 -> #DIV/0! | G3: 10 | H3: =F3/G3 -> #DIV/0! | J3: 45232 | AC3: 45232 | AF3: =(D3-AD3-AE3)/D3 -> #DIV/0!
A4: 45233 | E4: =D4/C4 -> #DIV/0! | F4: =E4/8.5 -> #DIV/0! | G4: 10 | H4: =F4/G4 -> #DIV/0! | J4: 45233 | AC4: 45233 | AF4: =(D4-AD4-AE4)/D4 -> #DIV/0!
A5: 45236 | E5: =D5/C5 -> #DIV/0! | F5: =E5/8.5 -> #DIV/0! | G5: 10 | H5: =F5/G5 -> #DIV/0! | J5: 45236 | AC5: 45236 | AF5: =(D5-AD5-AE5)/D5 -> #DIV/0!
A6: 45237 | E6: =D6/C6 -> #DIV/0! | F6: =E6/8.5 -> #DIV/0! | G6: 10 | H6: =F6/G6 -> #DIV/0! | J6: 45237 | AC6: 45237 | AF6: =(D6-AD6-AE6)/D6 -> #DIV/0!
A7: 45238 | E7: =D7/C7 -> #DIV/0! | F7: =E7/8.5 -> #DIV/0! | G7: 10 | H7: =F7/G7 -> #DIV/0! | J7: 45238 | AC7: 45238 | AF7: =(D7-AD7-AE7)/D7 -> #DIV/0!
A8: 45239 | E8: =D8/C8 -> #DIV/0! | F8: =E8/8.5 -> #DIV/0! | G8: 10 | H8: =F8/G8 -> #DIV/0! | J8: 45239 | AC8: 45239 | AF8: =(D8-AD8-AE8)/D8 -> #DIV/0!
A9: 45240 | E9: =D9/C9 -> #DIV/0! | F9: =E9/8.5 -> #DIV/0! | G9: 10 | H9: =F9/G9 -> #DIV/0! | J9: 45240 | AC9: 45240 | AF9: =(D9-AD9-AE9)/D9 -> #DIV/0!
A10: 45243 | E10: =D10/C10 -> #DIV/0! | F10: =E10/8.5 -> #DIV/0! | G10: 10 | H10: =F10/G10 -> #DIV/0! | J10: 45243 | AC10: 45243 | AF10: =(D10-AD10-AE10)/D10 -> #DIV/0!
A11: 45244 | E11: =D11/C11 -> #DIV/0! | F11: =E11/8.5 -> #DIV/0! | G11: 10 | H11: =F11/G11 -> #DIV/0! | J11: 45244 | AC11: 45244 | AF11: =(D11-AD11-AE11)/D11 -> #DIV/0!
A12: 45245 | E12: =D12/C12 -> #DIV/0! | F12: =E12/8.5 -> #DIV/0! | G12: 10 | H12: =F12/G12 -> #DIV/0! | J12: 45245 | AC12: 45245 | AF12: =(D12-AD12-AE12)/D12 -> #DIV/0!
A13: 45246 | E13: =D13/C13 -> #DIV/0! | F13: =E13/8.5 -> #DIV/0! | G13: 10 | H13: =F13/G13 -> #DIV/0! | J13: 45246 | AC13: 45246 | AF13: =(D13-AD13-AE13)/D13 -> #DIV/0!
... A23: 45260 | E23: =D23/C23 -> #DIV/0! | F23: =E23/8.5 -> #DIV/0! | G23: 10 | H23: =F23/G23 -> #DIV/0! | J23: 45260 | AC23: 45260 | AF23: =(D23-AD23-AE23)/D23 -> #DIV/0!
A24: Average | D24: =AVERAGE(D2:D23) -> #DIV/0! | E24: =AVERAGE(E2:E23) -> #DIV/0! | F24: =E24/8.5 -> #DIV/0! | G24: 10 | H24: =F24/G24 -> #DIV/0! | J24: Average | K24: =AVERAGE(K2:K23) -> #DIV/0! | L24: =AVERAGE(L2:L23) -> #DIV/0! | M24: =AVERAGE(M2:M23) -> #DIV/0! | N24: =AVERAGE(N2:N23) -> #DIV/0! | O24: =AVERAGE(O2:O23) -> #DIV/0! | P24: =AVERAGE(P2:P23) -> #DIV/0! | Q24: =AVERAGE(Q2:Q23) -> #DIV/0! | R24: =AVERAGE(R2:R23) -> #DIV/0! | ... AA24: =AVERAGE(AA2:AA23) -> #DIV/0! | AC24: Average | AD24: =AVERAGE(AD2:AD23) -> #DIV/0! | AE24: =AVERAGE(AE2:AE23) -> #DIV/0! | AF24: =AVERAGE(AF2:AF23) -> #DIV/0!

Sheet Dec
A1: Date | B1: Into Buff from Line | C1: # Buffers | D1: Ttl Buffed | E1: Ave per person | F1: Ave/hr | G1: Target/ Hr | H1: % Efficiency | J1: Date | AC1: Date | AD1: Returned to Buff | AE1: RW after buff | AF1: FTQ for buff
A2: 45261 | E2: =D2/C2 -> #DIV/0! | F2: =E2/8.5 -> #DIV/0! | G2: 10 | H2: =F2/G2 -> #DIV/0! | J2: 45261 | AC2: 45261 | AF2: =(D2-AD2-AE2)/D2 -> #DIV/0!
A3: 45264 | E3: =D3/C3 -> #DIV/0! | F3: =E3/8.5 -> #DIV/0! | G3: 10 | H3: =F3/G3 -> #DIV/0! | J3: 45264 | AC3: 45264 | AF3: =(D3-AD3-AE3)/D3 -> #DIV/0!
A4: 45265 | E4: =D4/C4 -> #DIV/0! | F4: =E4/8.5 -> #DIV/0! | G4: 10 | H4: =F4/G4 -> #DIV/0! | J4: 45265 | AC4: 45265 | AF4: =(D4-AD4-AE4)/D4 -> #DIV/0!
A5: 45266 | E5: =D5/C5 -> #DIV/0! | F5: =E5/8.5 -> #DIV/0! | G5: 10 | H5: =F5/G5 -> #DIV/0! | J5: 45266 | AC5: 45266 | AF5: =(D5-AD5-AE5)/D5 -> #DIV/0!
A6: 45267 | E6: =D6/C6 -> #DIV/0! | F6: =E6/8.5 -> #DIV/0! | G6: 10 | H6: =F6/G6 -> #DIV/0! | J6: 45267 | AC6: 45267 | AF6: =(D6-AD6-AE6)/D6 -> #DIV/0!
A7: 45268 | E7: =D7/C7 -> #DIV/0! | F7: =E7/8.5 -> #DIV/0! | G7: 10 | H7: =F7/G7 -> #DIV/0! | J7: 45268 | AC7: 45268 | AF7: =(D7-AD7-AE7)/D7 -> #DIV/0!
A8: 45271 | E8: =D8/C8 -> #DIV/0! | F8: =E8/8.5 -> #DIV/0! | G8: 10 | H8: =F8/G8 -> #DIV/0! | J8: 45271 | AC8: 45271 | AF8: =(D8-AD8-AE8)/D8 -> #DIV/0!
A9: 45272 | E9: =D9/C9 -> #DIV/0! | F9: =E9/8.5 -> #DIV/0! | G9: 10 | H9: =F9/G9 -> #DIV/0! | J9: 45272 | AC9: 45272 | AF9: =(D9-AD9-AE9)/D9 -> #DIV/0!
A10: 45273 | E10: =D10/C10 -> #DIV/0! | F10: =E10/8.5 -> #DIV/0! | G10: 10 | H10: =F10/G10 -> #DIV/0! | J10: 45273 | AC10: 45273 | AF10: =(D10-AD10-AE10)/D10 -> #DIV/0!
A11: 45274 | E11: =D11/C11 -> #DIV/0! | F11: =E11/8.5 -> #DIV/0! | G11: 10 | H11: =F11/G11 -> #DIV/0! | J11: 45274 | AC11: 45274 | AF11: =(D11-AD11-AE11)/D11 -> #DIV/0!
A12: 45275 | E12: =D12/C12 -> #DIV/0! | F12: =E12/8.5 -> #DIV/0! | G12: 10 | H12: =F12/G12 -> #DIV/0! | J12: 45275 | AC12: 45275 | AF12: =(D12-AD12-AE12)/D12 -> #DIV/0!
A13: 45278 | E13: =D13/C13 -> #DIV/0! | F13: =E13/8.5 -> #DIV/0! | G13: 10 | H13: =F13/G13 -> #DIV/0! | J13: 45278 | AC13: 45278 | AF13: =(D13-AD13-AE13)/D13 -> #DIV/0!
... A19: 45288 | E19: =D19/C19 -> #DIV/0! | F19: =E19/8.5 -> #DIV/0! | G19: 10 | H19: =F19/G19 -> #DIV/0! | J19: 45288 | AC19: 45288 | AF19: =(D19-AD19-AE19)/D19 -> #DIV/0!
A20: 45289 | E20: =D20/C20 -> #DIV/0! | F20: =E20/8.5 -> #DIV/0! | G20: 10 | H20: =F20/G20 -> #DIV/0! | J20: 45289 | AC20: 45289
A21: Average | D21: =AVERAGE(D2:D20) -> #DIV/0! | E21: =AVERAGE(E2:E17) -> #DIV/0! | F21: =E21/8.5 -> #DIV/0! | G21: 10 | H21: =F21/G21 -> #DIV/0! | J21: Average | K21: =AVERAGE(K2:K17) -> #DIV/0! | L21: =AVERAGE(L2:L17) -> #DIV/0! | M21: =AVERAGE(M2:M17) -> #DIV/0! | N21: =AVERAGE(N2:N17) -> #DIV/0! | O21: =AVERAGE(O2:O17) -> #DIV/0! | P21: =AVERAGE(P2:P17) -> #DIV/0! | Q21: =AVERAGE(Q2:Q17) -> #DIV/0! | R21: =AVERAGE(R2:R17) -> #DIV/0! | ... AA21: =AVERAGE(AA2:AA17) -> #DIV/0! | AC21: Average | AD21: =AVERAGE(AD2:AD19) -> #DIV/0! | AE21: =AVERAGE(AE2:AE19) -> #DIV/0! | AF21: =AVERAGE(AF2:AF19) -> #DIV/0!

Sheet Montly Summary
A1: BUFFING SUMMARY | B1: OCT
A2: PARTS INTO BUFF FROM LINE | B2: =Oct!B24 -> 0
A3: TOTAL PARTS BUFFED | B3: =Oct!D24 -> 0
A4: AVERAGE PER PERSON | B4: 120
A5: AVERAGE PER HOUR | B5: 16
A6: % EFFICIENCY | B6: 1.59
A7: RETURNED TO BUFF | B7: =Oct!AD24 -> 0
A8: REWORK FROM BUFF | B8: =Oct!AE24 -> 0
A9: FTQ FOR BUFFING | B9: 0.91

Sheet Charts Info
A1: Date | B1: Into Buff from Line | C1: Ttl Buffed | D1: Ave/hr | E1: Returned to Buff | F1: RW after buff | G1: FTQ for buff
A2: 44929 | B2: =Jan!B3 -> 0 | C2: =Jan!D3 -> 560 | D2: =Jan!F3 -> #DIV/0! | E2: =Jan!AH3 -> 0 | F2: =Jan!AI3 -> 0 | G2: =Jan!AJ3 -> 1
A3: 44930 | B3: =Jan!B4 -> 0 | C3: =Jan!D4 -> 419 | D3: =Jan!F4 -> #DIV/0! | E3: =Jan!AH4 -> 0 | F3: =Jan!AI4 -> 0 | G3: =Jan!AJ4 -> 1
A4: 44931 | B4: =Jan!B5 -> 0 | C4: =Jan!D5 -> 402 | D4: =Jan!F5 -> #DIV/0! | E4: =Jan!AH5 -> 0 | F4: =Jan!AI5 -> 0 | G4: =Jan!AJ5 -> 1
A5: 44932 | B5: =Jan!B6 -> 0 | C5: =Jan!D6 -> 369 | D5: =Jan!F6 -> #DIV/0! | E5: =Jan!AH6 -> 0 | F5: =Jan!AI6 -> 0 | G5: =Jan!AJ6 -> 1
A6: 44935 | B6: =Jan!B7 -> 0 | C6: =Jan!D7 -> 532 | D6: =Jan!F7 -> #DIV/0! | E6: =Jan!AH7 -> 0 | F6: =Jan!AI7 -> 0 | G6: =Jan!AJ7 -> 1
A7: 44936 | B7: =Jan!B8 -> 0 | C7: =Jan!D8 -> 525 | D7: =Jan!F8 -> #DIV/0! | E7: =Jan!AH8 -> 0 | F7: =Jan!AI8 -> 0 | G7: =Jan!AJ8 -> 1
A8: 44937 | B8: =Jan!B9 -> 0 | C8: =Jan!D9 -> 855 | D8: =Jan!F9 -> #DIV/0! | E8: =Jan!AH9 -> 0 | F8: =Jan!AI9 -> 0 | G8: =Jan!AJ9 -> 1
A9: 44938 | B9: =Jan!B10 -> 0 | C9: =Jan!D10 -> 565 | D9: =Jan!F10 -> #DIV/0! | E9: =Jan!AH10 -> 0 | F9: =Jan!AI10 -> 0 | G9: =Jan!AJ10 -> 1
A10: 44939 | B10: =Jan!B11 -> 0 | C10: =Jan!D11 -> 603 | D10: =Jan!F11 -> #DIV/0! | E10: =Jan!AH11 -> 0 | F10: =Jan!AI11 -> 0 | G10: =Jan!AJ11 -> 1
A11: 44942 | B11: =Jan!B12 -> 0 | C11: =Jan!D12 -> 570 | D11: =Jan!F12 -> #DIV/0! | E11: =Jan!AH12 -> 0 | F11: =Jan!AI12 -> 0 | G11: =Jan!AJ12 -> 1
A12: 44943 | B12: =Jan!B13 -> 0 | C12: =Jan!D13 -> 562 | D12: =Jan!F13 -> #DIV/0! | E12: =Jan!AH13 -> 0 | F12: =Jan!AI13 -> 0 | G12: =Jan!AJ13 -> 1
A13: 44944 | B13: =Jan!B14 -> 0 | C13: =Jan!D14 -> 598 | D13: =Jan!F14 -> #DIV/0! | E13: =Jan!AH14 -> 0 | F13: =Jan!AI14 -> 0 | G13: =Jan!AJ14 -> 1
... A22: 44957 | B22: =Jan!B23 -> 0 | C22: =Jan!D23 -> 0 | D22: =Jan!F23 -> #DIV/0! | E22: =Jan!AH23 -> 0 | F22: =Jan!AI23 -> 0 | G22: =Jan!AJ23 -> #DIV/0!
A24: Date | B24: Into Buff from Line | C24: Ttl Buffed | D24: Ave/hr | E24: Returned to Buff | F24: RW after buff | G24: FTQ for buff
A25: 44958 | B25: =Feb!B2 -> 0 | C25: =Feb!D2 -> 0 | D25: =Feb!F2 -> #DIV/0! | E25: =Feb!AS2 -> 0 | F25: =Feb!AT2 -> 0 | G25: =Feb!AU2 -> #DIV/0!
A26: 44959 | B26: =Feb!B3 -> 0 | C26: =Feb!D3 -> 0 | D26: =Mar!F3 -> #DIV/0! | E26: =Feb!AS3 -> 0 | F26: =Feb!AT3 -> 0 | G26: =Feb!AU3 -> #DIV/0!
A27: 44960 | B27: =Feb!B4 -> 0 | C27: =Feb!D4 -> 0 | D27: =Feb!F4 -> #DIV/0! | E27: =Feb!AS4 -> 0 | F27: =Feb!AT4 -> 0 | G27: =Feb!AU4 -> #DIV/0!
A28: 44963 | B28: =Feb!B6 -> 0 | C28: =Feb!D6 -> 0 | D28: =Mar!F6 -> #DIV/0! | E28: =Feb!AS6 -> 0 | F28: =Feb!AT6 -> 0 | G28: =Feb!AU6 -> #DIV/0!
A29: 44964 | B29: =Feb!B7 -> 0 | C29: =Feb!D7 -> 0 | D29: =Feb!F7 -> #DIV/0! | E29: =Feb!AS7 -> 0 | F29: =Feb!AT7 -> 0 | G29: =Feb!AU7 -> #DIV/0!
A30: 44965 | B30: =Feb!B8 -> 0 | C30: =Feb!D8 -> 0 | D30: =Mar!F8 -> #DIV/0! | E30: =Feb!AS8 -> 0 | F30: =Feb!AT8 -> 0 | G30: =Feb!AU8 -> #DIV/0!
A31: 44966 | B31: =Feb!B9 -> 0 | C31: =Feb!D9 -> 0 | D31: =Feb!F9 -> #DIV/0! | E31: =Feb!AS9 -> 0 | F31: =Feb!AT9 -> 0 | G31: =Feb!AU9 -> #DIV/0!
A32: 44967 | B32: =Feb!B10 -> 0 | C32: =Feb!D10 -> 0 | D32: =Mar!F10 -> #DIV/0! | E32: =Feb!AS10 -> 0 | F32: =Feb!AT10 -> 0 | G32: =Feb!AU10 -> #DIV/0!
A33: 44970 | B33: =Feb!B12 -> 0 | C33: =Feb!D12 -> 0 | D33: =Feb!F12 -> #DIV/0! | E33: =Feb!AS12 -> 0 | F33: =Feb!AT12 -> 0 | G33: =Feb!AU12 -> #DIV/0!
A34: 44971 | B34: =Feb!B13 -> 0 | C34: =Feb!D13 -> 0 | D34: =Mar!F13 -> #DIV/0! | E34: =Feb!AS13 -> 0 | F34: =Feb!AT13 -> 0 | G34: =Feb!AU13 -> #DIV/0!
A35: 44972 | B35: =Feb!B14 -> 0 | C35: =Feb!D14 -> 0 | D35: =Feb!F14 -> #DIV/0! | E35: =Feb!AS14 -> 0 | F35: =Feb!AT14 -> 0 | G35: =Feb!AU14 -> #DIV/0!
A36: 44973 | B36: =Feb!B15 -> 0 | C36: =Feb!D15 -> 0 | D36: =Mar!F15 -> #DIV/0! | E36: =Feb!AS15 -> 0 | F36: =Feb!AT15 -> 0 | G36: =Feb!AU15 -> #DIV/0!
A37: 44974 | B37: =Feb!B16 -> 0 | C37: =Feb!D16 -> 0 | D37: =Feb!F16 -> #DIV/0! | E37: =Feb!AS16 -> 0 | F37: =Feb!AT16 -> 0 | G37: =Feb!AU16 -> #DIV/0!
A38: 44978 | B38: =Feb!B19 -> 0 | C38: =Feb!D19 -> 0 | D38: =Mar!F17 -> #DIV/0! | E38: =Feb!AS19 -> 0 | F38: =Feb!AT19 -> 0 | G38: =Feb!AU19 -> #DIV/0!
A39: 44979 | B39: =Feb!B20 -> 0 | C39: =Feb!D20 -> 0 | D39: =Feb!F20 -> #DIV/0! | E39: =Feb!AS20 -> 0 | F39: =Feb!AT20 -> 0 | G39: =Feb!AU20 -> #DIV/0!
A40: 44980 | B40: =Feb!B21 -> 0 | C40: =Feb!D21 -> 0 | D40: =Mar!F19 -> #DIV/0! | E40: =Feb!AS21 -> 0 | F40: =Feb!AT21 -> 0 | G40: =Feb!AU21 -> #DIV/0!
A41: 44981 | B41: =Feb!B22 -> 0 | C41: =Feb!D22 -> 0 | D41: =Feb!F22 -> #DIV/0! | E41: =Feb!AS22 -> 0 | F41: =Feb!AT22 -> 0 | G41: =Feb!AU22 -> #DIV/0!
A42: 44984 | B42: =Feb!B24 -> 0 | C42: =Feb!D24 -> 0 | D42: =Mar!F21 -> #DIV/0! | E42: =Feb!AS24 -> 0 | F42: =Feb!AT24 -> 0 | G42: =Feb!AU24 -> #DIV/0!
A43: 44985 | B43: =Feb!B25 -> 0 | C43: =Feb!D25 -> 0 | D43: =Mar!F23 -> #DIV/0! | E43: =Feb!AS25 -> 0 | F43: =Feb!AT25 -> 0 | G43: =Feb!AU25 -> #DIV/0!
A45: Date | B45: Into Buff from Line | C45: Ttl Buffed | D45: Ave/hr | E45: Returned to Buff | F45: RW after buff | G45: FTQ for buff
A46: 44986 | B46: =Mar!B2 -> 0 | C46: =Mar!D2 -> 0 | D46: =Mar!F2 -> #DIV/0! | E46: =Mar!AI2 -> 0 | F46: =Mar!AJ2 -> 0 | G46: =Mar!AK2 -> #DIV/0!
A47: 44987 | B47: =Mar!B3 -> 0 | C47: =Mar!D3 -> 0 | D47: =Mar!F3 -> #DIV/0! | E47: =Mar!AI3 -> 0 | F47: =Mar!AJ3 -> 0 | G47: =Mar!AK3 -> #DIV/0!
A48: 44988 | B48: =Mar!B4 -> 0 | C48: =Mar!D4 -> 0 | D48: =Mar!F4 -> #DIV/0! | E48: =Mar!AI4 -> 0 | F48: =Mar!AJ4 -> 0 | G48: =Mar!AK4 -> #DIV/0!
A49: 44991 | B49: =Mar!B6 -> 0 | C49: =Mar!D6 -> 0 | D49: =Mar!F6 -> #DIV/0! | E49: =Mar!AI6 -> 0 | F49: =Mar!AJ6 -> 0 | G49: =Mar!AK6 -> #DIV/0!
A50: 44992 | B50: =Mar!B7 -> 0 | C50: =Mar!D7 -> 0 | D50: =Mar!F7 -> #DIV/0! | E50: =Mar!AI7 -> 0 | F50: =Mar!AJ7 -> 0 | G50: =Mar!AK7 -> #DIV/0!
...
